{   "registryname": "fox_eating_melon",
    "localizedname": "吃瓜狐锂",
    "requires-blueprint": false,
    "color": "58c45c",
    "parts": [
        {
            "x": -9,
            "y": 9,
            "z": 7,
            "elements": [
                "minecraft:wool@5"
            ]
        },
        {
            "x": -5,
            "y": 14,
            "z": 8,
            "elements": [
                "minecraft:concrete@1"
            ]
        },
        {
            "x": -5,
            "y": 14,
            "z": 9,
            "elements": [
                "minecraft:concrete@1"
            ]
        },
        {
            "x": -5,
            "y": 14,
            "z": 6,
            "elements": [
                "minecraft:concrete@1"
            ]
        },
        {
            "x": -5,
            "y": 14,
            "z": 7,
            "elements": [
                "minecraft:concrete@1"
            ]
        },
        {
            "x": -1,
            "y": 19,
            "z": 6,
            "elements": [
                "minecraft:concrete@1"
            ]
        },
        {
            "x": -5,
            "y": 14,
            "z": 10,
            "elements": [
                "minecraft:concrete@1"
            ]
        },
        {
            "x": 2,
            "y": 23,
            "z": 3,
            "elements": [
                "minecraft:concrete@15"
            ]
        },
        {
            "x": -4,
            "y": 15,
            "z": 1,
            "elements": [
                "minecraft:concrete@1"
            ]
        },
        {
            "x": 0,
            "y": 20,
            "z": 2,
            "elements": [
                "minecraft:concrete@1"
            ]
        },
        {
            "x": -4,
            "y": 15,
            "z": 2,
            "elements": [
                "minecraft:concrete@1"
            ]
        },
        {
            "x": -8,
            "y": 10,
            "z": 3,
            "elements": [
                "minecraft:redstone_block@0"
            ]
        },
        {
            "x": -8,
            "y": 10,
            "z": 4,
            "elements": [
                "minecraft:redstone_block@0"
            ]
        },
        {
            "x": -8,
            "y": 10,
            "z": 1,
            "elements": [
                "minecraft:redstone_block@0"
            ]
        },
        {
            "x": -8,
            "y": 10,
            "z": 2,
            "elements": [
                "minecraft:redstone_block@0"
            ]
        },
        {
            "x": -8,
            "y": 10,
            "z": -1,
            "elements": [
                "minecraft:redstone_block@0"
            ]
        },
        {
            "x": -6,
            "y": 13,
            "z": 9,
            "elements": [
                "minecraft:concrete@1"
            ]
        },
        {
            "x": -8,
            "y": 10,
            "z": 0,
            "elements": [
                "minecraft:redstone_block@0"
            ]
        },
        {
            "x": -6,
            "y": 13,
            "z": 8,
            "elements": [
                "minecraft:concrete@1"
            ]
        },
        {
            "x": -8,
            "y": 10,
            "z": -2,
            "elements": [
                "minecraft:wool@5"
            ]
        },
        {
            "x": -6,
            "y": 13,
            "z": 10,
            "elements": [
                "minecraft:concrete@1"
            ]
        },
        {
            "x": -10,
            "y": 8,
            "z": 4,
            "elements": [
                "minecraft:wool@5"
            ]
        },
        {
            "x": -2,
            "y": 18,
            "z": 6,
            "elements": [
                "minecraft:concrete@1"
            ]
        },
        {
            "x": -10,
            "y": 8,
            "z": 3,
            "elements": [
                "minecraft:wool@5"
            ]
        },
        {
            "x": -10,
            "y": 8,
            "z": 2,
            "elements": [
                "minecraft:wool@5"
            ]
        },
        {
            "x": -6,
            "y": 13,
            "z": 7,
            "elements": [
                "minecraft:concrete@1"
            ]
        },
        {
            "x": -10,
            "y": 8,
            "z": 1,
            "elements": [
                "minecraft:wool@5"
            ]
        },
        {
            "x": -6,
            "y": 13,
            "z": 1,
            "elements": [
                "minecraft:wool@0"
            ]
        },
        {
            "x": -2,
            "y": 18,
            "z": 2,
            "elements": [
                "minecraft:quartz_block@0"
            ]
        },
        {
            "x": -8,
            "y": 10,
            "z": 7,
            "elements": [
                "minecraft:redstone_block@0"
            ]
        },
        {
            "x": -2,
            "y": 18,
            "z": 1,
            "elements": [
                "minecraft:concrete@1"
            ]
        },
        {
            "x": -8,
            "y": 10,
            "z": 8,
            "elements": [
                "appliedenergistics2:smooth_sky_stone_block@0"
            ]
        },
        {
            "x": -8,
            "y": 10,
            "z": 5,
            "elements": [
                "minecraft:redstone_block@0"
            ]
        },
        {
            "x": -10,
            "y": 8,
            "z": 6,
            "elements": [
                "minecraft:wool@5"
            ]
        },
        {
            "x": -10,
            "y": 8,
            "z": 5,
            "elements": [
                "minecraft:wool@5"
            ]
        },
        {
            "x": -8,
            "y": 10,
            "z": 6,
            "elements": [
                "minecraft:redstone_block@0"
            ]
        },
        {
            "x": 0,
            "y": 20,
            "z": 5,
            "elements": [
                "minecraft:concrete@1"
            ]
        },
        {
            "x": 0,
            "y": 20,
            "z": 3,
            "elements": [
                "minecraft:concrete@1"
            ]
        },
        {
            "x": -4,
            "y": 15,
            "z": 6,
            "elements": [
                "minecraft:concrete@1"
            ]
        },
        {
            "x": 0,
            "y": 20,
            "z": 4,
            "elements": [
                "minecraft:concrete@1"
            ]
        },
        {
            "x": -10,
            "y": 8,
            "z": 0,
            "elements": [
                "minecraft:wool@5"
            ]
        },
        {
            "x": -6,
            "y": 12,
            "z": 1,
            "elements": [
                "minecraft:wool@0"
            ]
        },
        {
            "x": 2,
            "y": 22,
            "z": 3,
            "elements": [
                "minecraft:wool@0"
            ]
        },
        {
            "x": 9,
            "y": 6,
            "z": -1,
            "elements": [
                "minecraft:wool@5"
            ]
        },
        {
            "x": -1,
            "y": 20,
            "z": 2,
            "elements": [
                "minecraft:concrete@1"
            ]
        },
        {
            "x": -6,
            "y": 12,
            "z": 8,
            "elements": [
                "minecraft:concrete@1"
            ]
        },
        {
            "x": -1,
            "y": 20,
            "z": 3,
            "elements": [
                "minecraft:concrete@1"
            ]
        },
        {
            "x": -6,
            "y": 12,
            "z": 7,
            "elements": [
                "minecraft:concrete@1"
            ]
        },
        {
            "x": -1,
            "y": 20,
            "z": 4,
            "elements": [
                "minecraft:concrete@1"
            ]
        },
        {
            "x": -6,
            "y": 12,
            "z": 10,
            "elements": [
                "minecraft:concrete@1"
            ]
        },
        {
            "x": -1,
            "y": 20,
            "z": 5,
            "elements": [
                "minecraft:concrete@1"
            ]
        },
        {
            "x": -6,
            "y": 12,
            "z": 9,
            "elements": [
                "minecraft:concrete@1"
            ]
        },
        {
            "x": -9,
            "y": 8,
            "z": 5,
            "elements": [
                "minecraft:wool@5"
            ]
        },
        {
            "x": -9,
            "y": 8,
            "z": 4,
            "elements": [
                "minecraft:wool@5"
            ]
        },
        {
            "x": -1,
            "y": 18,
            "z": 6,
            "elements": [
                "minecraft:concrete@1"
            ]
        },
        {
            "x": 10,
            "y": 7,
            "z": 1,
            "elements": [
                "minecraft:wool@5"
            ]
        },
        {
            "x": -7,
            "y": 11,
            "z": 1,
            "elements": [
                "minecraft:wool@0"
            ]
        },
        {
            "x": -4,
            "y": 16,
            "z": 1,
            "elements": [
                "minecraft:concrete@1"
            ]
        },
        {
            "x": -9,
            "y": 8,
            "z": 7,
            "elements": [
                "minecraft:wool@5"
            ]
        },
        {
            "x": 10,
            "y": 7,
            "z": 0,
            "elements": [
                "minecraft:wool@5"
            ]
        },
        {
            "x": -4,
            "y": 16,
            "z": 2,
            "elements": [
                "minecraft:concrete@1"
            ]
        },
        {
            "x": -9,
            "y": 8,
            "z": 6,
            "elements": [
                "minecraft:wool@5"
            ]
        },
        {
            "x": -9,
            "y": 8,
            "z": 1,
            "elements": [
                "minecraft:wool@5"
            ]
        },
        {
            "x": 10,
            "y": 7,
            "z": 3,
            "elements": [
                "minecraft:wool@5"
            ]
        },
        {
            "x": -9,
            "y": 10,
            "z": 6,
            "elements": [
                "minecraft:redstone_block@0"
            ]
        },
        {
            "x": -7,
            "y": 11,
            "z": -4,
            "elements": [
                "appliedenergistics2:smooth_sky_stone_block@0"
            ]
        },
        {
            "x": -9,
            "y": 8,
            "z": 0,
            "elements": [
                "minecraft:wool@5"
            ]
        },
        {
            "x": 10,
            "y": 7,
            "z": 2,
            "elements": [
                "minecraft:wool@5"
            ]
        },
        {
            "x": -9,
            "y": 10,
            "z": 7,
            "elements": [
                "minecraft:wool@5"
            ]
        },
        {
            "x": -7,
            "y": 11,
            "z": -3,
            "elements": [
                "appliedenergistics2:smooth_sky_stone_block@0"
            ]
        },
        {
            "x": -9,
            "y": 8,
            "z": 3,
            "elements": [
                "minecraft:wool@5"
            ]
        },
        {
            "x": 10,
            "y": 7,
            "z": 5,
            "elements": [
                "appliedenergistics2:smooth_sky_stone_block@0"
            ]
        },
        {
            "x": -9,
            "y": 8,
            "z": 2,
            "elements": [
                "minecraft:wool@5"
            ]
        },
        {
            "x": 10,
            "y": 7,
            "z": 4,
            "elements": [
                "minecraft:wool@5"
            ]
        },
        {
            "x": -9,
            "y": 10,
            "z": 2,
            "elements": [
                "minecraft:redstone_block@0"
            ]
        },
        {
            "x": 9,
            "y": 6,
            "z": 3,
            "elements": [
                "minecraft:wool@5"
            ]
        },
        {
            "x": 9,
            "y": 6,
            "z": 2,
            "elements": [
                "minecraft:wool@5"
            ]
        },
        {
            "x": -9,
            "y": 10,
            "z": 3,
            "elements": [
                "minecraft:redstone_block@0"
            ]
        },
        {
            "x": 10,
            "y": 7,
            "z": 6,
            "elements": [
                "appliedenergistics2:smooth_sky_stone_block@0"
            ]
        },
        {
            "x": 9,
            "y": 6,
            "z": 1,
            "elements": [
                "minecraft:wool@5"
            ]
        },
        {
            "x": -1,
            "y": 18,
            "z": 1,
            "elements": [
                "minecraft:wool@1"
            ]
        },
        {
            "x": -9,
            "y": 10,
            "z": 4,
            "elements": [
                "minecraft:redstone_block@0"
            ]
        },
        {
            "x": 9,
            "y": 6,
            "z": 0,
            "elements": [
                "minecraft:wool@5"
            ]
        },
        {
            "x": -9,
            "y": 10,
            "z": 5,
            "elements": [
                "minecraft:redstone_block@0"
            ]
        },
        {
            "x": 9,
            "y": 6,
            "z": 7,
            "elements": [
                "minecraft:wool@5"
            ]
        },
        {
            "x": -9,
            "y": 10,
            "z": -1,
            "elements": [
                "minecraft:wool@5"
            ]
        },
        {
            "x": -1,
            "y": 18,
            "z": 2,
            "elements": [
                "minecraft:quartz_block@0"
            ]
        },
        {
            "x": 9,
            "y": 6,
            "z": 6,
            "elements": [
                "minecraft:wool@5"
            ]
        },
        {
            "x": -9,
            "y": 10,
            "z": 0,
            "elements": [
                "minecraft:redstone_block@0"
            ]
        },
        {
            "x": 9,
            "y": 6,
            "z": 5,
            "elements": [
                "appliedenergistics2:smooth_sky_stone_block@0"
            ]
        },
        {
            "x": -9,
            "y": 10,
            "z": 1,
            "elements": [
                "minecraft:redstone_block@0"
            ]
        },
        {
            "x": 9,
            "y": 6,
            "z": 4,
            "elements": [
                "appliedenergistics2:smooth_sky_stone_block@0"
            ]
        },
        {
            "x": -4,
            "y": 16,
            "z": 6,
            "elements": [
                "minecraft:concrete@1"
            ]
        },
        {
            "x": -3,
            "y": 17,
            "z": 2,
            "elements": [
                "minecraft:quartz_block@0"
            ]
        },
        {
            "x": -8,
            "y": 9,
            "z": 8,
            "elements": [
                "minecraft:wool@5"
            ]
        },
        {
            "x": -3,
            "y": 17,
            "z": 1,
            "elements": [
                "minecraft:concrete@1"
            ]
        },
        {
            "x": -10,
            "y": 9,
            "z": 6,
            "elements": [
                "minecraft:wool@5"
            ]
        },
        {
            "x": -10,
            "y": 9,
            "z": 5,
            "elements": [
                "minecraft:wool@5"
            ]
        },
        {
            "x": -10,
            "y": 9,
            "z": 4,
            "elements": [
                "minecraft:wool@5"
            ]
        },
        {
            "x": -2,
            "y": 19,
            "z": 6,
            "elements": [
                "minecraft:concrete@1"
            ]
        },
        {
            "x": -10,
            "y": 9,
            "z": 3,
            "elements": [
                "minecraft:wool@5"
            ]
        },
        {
            "x": -3,
            "y": 17,
            "z": 6,
            "elements": [
                "minecraft:concrete@1"
            ]
        },
        {
            "x": 0,
            "y": 19,
            "z": 6,
            "elements": [
                "minecraft:concrete@1"
            ]
        },
        {
            "x": -10,
            "y": 9,
            "z": 2,
            "elements": [
                "minecraft:wool@5"
            ]
        },
        {
            "x": -10,
            "y": 9,
            "z": 1,
            "elements": [
                "minecraft:wool@5"
            ]
        },
        {
            "x": -10,
            "y": 9,
            "z": 0,
            "elements": [
                "minecraft:wool@5"
            ]
        },
        {
            "x": -2,
            "y": 19,
            "z": 1,
            "elements": [
                "minecraft:concrete@1"
            ]
        },
        {
            "x": -8,
            "y": 9,
            "z": -2,
            "elements": [
                "appliedenergistics2:smooth_sky_stone_block@0"
            ]
        },
        {
            "x": -7,
            "y": 11,
            "z": 9,
            "elements": [
                "appliedenergistics2:smooth_sky_stone_block@0"
            ]
        },
        {
            "x": 0,
            "y": 19,
            "z": 1,
            "elements": [
                "minecraft:concrete@1"
            ]
        },
        {
            "x": -7,
            "y": 11,
            "z": 10,
            "elements": [
                "minecraft:wool@5"
            ]
        },
        {
            "x": -5,
            "y": 14,
            "z": 4,
            "elements": [
                "minecraft:concrete@1"
            ]
        },
        {
            "x": -5,
            "y": 14,
            "z": 5,
            "elements": [
                "minecraft:concrete@1"
            ]
        },
        {
            "x": -5,
            "y": 14,
            "z": 2,
            "elements": [
                "minecraft:concrete@1"
            ]
        },
        {
            "x": -5,
            "y": 14,
            "z": 3,
            "elements": [
                "minecraft:concrete@1"
            ]
        },
        {
            "x": -7,
            "y": 10,
            "z": -4,
            "elements": [
                "appliedenergistics2:smooth_sky_stone_block@0"
            ]
        },
        {
            "x": -8,
            "y": 12,
            "z": 1,
            "elements": [
                "minecraft:wool@0"
            ]
        },
        {
            "x": 10,
            "y": 8,
            "z": 2,
            "elements": [
                "minecraft:wool@5"
            ]
        },
        {
            "x": -7,
            "y": 10,
            "z": -3,
            "elements": [
                "appliedenergistics2:smooth_sky_stone_block@0"
            ]
        },
        {
            "x": 10,
            "y": 8,
            "z": 1,
            "elements": [
                "minecraft:wool@5"
            ]
        },
        {
            "x": -7,
            "y": 10,
            "z": -2,
            "elements": [
                "minecraft:redstone_block@0"
            ]
        },
        {
            "x": 10,
            "y": 8,
            "z": 4,
            "elements": [
                "minecraft:wool@5"
            ]
        },
        {
            "x": -7,
            "y": 10,
            "z": -1,
            "elements": [
                "minecraft:redstone_block@0"
            ]
        },
        {
            "x": 10,
            "y": 8,
            "z": 3,
            "elements": [
                "minecraft:wool@5"
            ]
        },
        {
            "x": -7,
            "y": 10,
            "z": 0,
            "elements": [
                "minecraft:redstone_block@0"
            ]
        },
        {
            "x": -4,
            "y": 17,
            "z": 6,
            "elements": [
                "minecraft:concrete@1"
            ]
        },
        {
            "x": -7,
            "y": 10,
            "z": 1,
            "elements": [
                "minecraft:redstone_block@0"
            ]
        },
        {
            "x": 10,
            "y": 8,
            "z": 0,
            "elements": [
                "minecraft:wool@5"
            ]
        },
        {
            "x": -7,
            "y": 10,
            "z": 2,
            "elements": [
                "minecraft:redstone_block@0"
            ]
        },
        {
            "x": -7,
            "y": 10,
            "z": 3,
            "elements": [
                "appliedenergistics2:smooth_sky_stone_block@0"
            ]
        },
        {
            "x": -7,
            "y": 10,
            "z": 4,
            "elements": [
                "minecraft:redstone_block@0"
            ]
        },
        {
            "x": -7,
            "y": 10,
            "z": 5,
            "elements": [
                "minecraft:redstone_block@0"
            ]
        },
        {
            "x": -7,
            "y": 10,
            "z": 6,
            "elements": [
                "appliedenergistics2:smooth_sky_stone_block@0"
            ]
        },
        {
            "x": -7,
            "y": 10,
            "z": 7,
            "elements": [
                "minecraft:redstone_block@0"
            ]
        },
        {
            "x": -7,
            "y": 10,
            "z": 8,
            "elements": [
                "minecraft:redstone_block@0"
            ]
        },
        {
            "x": -7,
            "y": 10,
            "z": 9,
            "elements": [
                "appliedenergistics2:smooth_sky_stone_block@0"
            ]
        },
        {
            "x": -7,
            "y": 10,
            "z": 10,
            "elements": [
                "minecraft:wool@5"
            ]
        },
        {
            "x": -5,
            "y": 12,
            "z": 3,
            "elements": [
                "minecraft:concrete@1"
            ]
        },
        {
            "x": -5,
            "y": 12,
            "z": 2,
            "elements": [
                "minecraft:concrete@1"
            ]
        },
        {
            "x": -5,
            "y": 12,
            "z": 1,
            "elements": [
                "minecraft:concrete@1"
            ]
        },
        {
            "x": -1,
            "y": 17,
            "z": 6,
            "elements": [
                "minecraft:concrete@1"
            ]
        },
        {
            "x": -5,
            "y": 12,
            "z": 0,
            "elements": [
                "minecraft:concrete@15"
            ]
        },
        {
            "x": -1,
            "y": 17,
            "z": 2,
            "elements": [
                "minecraft:quartz_block@0"
            ]
        },
        {
            "x": -5,
            "y": 12,
            "z": 5,
            "elements": [
                "minecraft:concrete@1"
            ]
        },
        {
            "x": 8,
            "y": 6,
            "z": -2,
            "elements": [
                "minecraft:wool@5"
            ]
        },
        {
            "x": 4,
            "y": 1,
            "z": 1,
            "elements": [
                "appliedenergistics2:smooth_sky_stone_block@0"
            ]
        },
        {
            "x": -1,
            "y": 17,
            "z": 1,
            "elements": [
                "minecraft:wool@1"
            ]
        },
        {
            "x": -5,
            "y": 12,
            "z": 4,
            "elements": [
                "minecraft:concrete@1"
            ]
        },
        {
            "x": 4,
            "y": 1,
            "z": 2,
            "elements": [
                "appliedenergistics2:smooth_sky_stone_block@0"
            ]
        },
        {
            "x": 4,
            "y": 1,
            "z": 3,
            "elements": [
                "minecraft:wool@5"
            ]
        },
        {
            "x": 4,
            "y": 1,
            "z": 4,
            "elements": [
                "minecraft:wool@5"
            ]
        },
        {
            "x": 4,
            "y": 1,
            "z": 5,
            "elements": [
                "minecraft:wool@5"
            ]
        },
        {
            "x": -5,
            "y": 12,
            "z": -1,
            "elements": [
                "minecraft:concrete@15"
            ]
        },
        {
            "x": 8,
            "y": 6,
            "z": 8,
            "elements": [
                "minecraft:wool@5"
            ]
        },
        {
            "x": -7,
            "y": 13,
            "z": 1,
            "elements": [
                "minecraft:wool@0"
            ]
        },
        {
            "x": -7,
            "y": 13,
            "z": 8,
            "elements": [
                "minecraft:concrete@1"
            ]
        },
        {
            "x": -7,
            "y": 13,
            "z": 7,
            "elements": [
                "minecraft:concrete@1"
            ]
        },
        {
            "x": -5,
            "y": 12,
            "z": 10,
            "elements": [
                "minecraft:concrete@1"
            ]
        },
        {
            "x": -5,
            "y": 12,
            "z": 9,
            "elements": [
                "minecraft:concrete@1"
            ]
        },
        {
            "x": -7,
            "y": 13,
            "z": 10,
            "elements": [
                "minecraft:concrete@1"
            ]
        },
        {
            "x": -5,
            "y": 12,
            "z": 8,
            "elements": [
                "minecraft:concrete@1"
            ]
        },
        {
            "x": -7,
            "y": 13,
            "z": 9,
            "elements": [
                "minecraft:concrete@1"
            ]
        },
        {
            "x": 10,
            "y": 8,
            "z": 6,
            "elements": [
                "appliedenergistics2:smooth_sky_stone_block@0"
            ]
        },
        {
            "x": 10,
            "y": 8,
            "z": 5,
            "elements": [
                "appliedenergistics2:smooth_sky_stone_block@0"
            ]
        },
        {
            "x": -1,
            "y": 17,
            "z": 7,
            "elements": [
                "minecraft:concrete@1"
            ]
        },
        {
            "x": -10,
            "y": 7,
            "z": 1,
            "elements": [
                "minecraft:wool@5"
            ]
        },
        {
            "x": -10,
            "y": 7,
            "z": 0,
            "elements": [
                "minecraft:wool@5"
            ]
        },
        {
            "x": 1,
            "y": 19,
            "z": 6,
            "elements": [
                "minecraft:concrete@1"
            ]
        },
        {
            "x": -8,
            "y": 11,
            "z": -2,
            "elements": [
                "minecraft:wool@5"
            ]
        },
        {
            "x": 1,
            "y": 19,
            "z": 1,
            "elements": [
                "minecraft:concrete@1"
            ]
        },
        {
            "x": -5,
            "y": 15,
            "z": 5,
            "elements": [
                "minecraft:concrete@1"
            ]
        },
        {
            "x": -8,
            "y": 11,
            "z": 1,
            "elements": [
                "minecraft:wool@0"
            ]
        },
        {
            "x": -5,
            "y": 15,
            "z": 3,
            "elements": [
                "minecraft:concrete@1"
            ]
        },
        {
            "x": -8,
            "y": 8,
            "z": -2,
            "elements": [
                "appliedenergistics2:smooth_sky_stone_block@0"
            ]
        },
        {
            "x": -5,
            "y": 15,
            "z": 4,
            "elements": [
                "minecraft:concrete@1"
            ]
        },
        {
            "x": -3,
            "y": 19,
            "z": 1,
            "elements": [
                "minecraft:concrete@1"
            ]
        },
        {
            "x": -5,
            "y": 15,
            "z": 2,
            "elements": [
                "minecraft:concrete@1"
            ]
        },
        {
            "x": -2,
            "y": 15,
            "z": 2,
            "elements": [
                "minecraft:concrete@15"
            ]
        },
        {
            "x": -10,
            "y": 7,
            "z": 6,
            "elements": [
                "minecraft:wool@5"
            ]
        },
        {
            "x": -10,
            "y": 7,
            "z": 5,
            "elements": [
                "minecraft:wool@5"
            ]
        },
        {
            "x": 3,
            "y": 23,
            "z": 3,
            "elements": [
                "minecraft:concrete@15"
            ]
        },
        {
            "x": -10,
            "y": 7,
            "z": 4,
            "elements": [
                "minecraft:wool@5"
            ]
        },
        {
            "x": -10,
            "y": 7,
            "z": 3,
            "elements": [
                "minecraft:wool@5"
            ]
        },
        {
            "x": -3,
            "y": 19,
            "z": 6,
            "elements": [
                "minecraft:concrete@1"
            ]
        },
        {
            "x": -2,
            "y": 15,
            "z": 7,
            "elements": [
                "minecraft:concrete@1"
            ]
        },
        {
            "x": -8,
            "y": 11,
            "z": 8,
            "elements": [
                "appliedenergistics2:smooth_sky_stone_block@0"
            ]
        },
        {
            "x": -10,
            "y": 7,
            "z": 2,
            "elements": [
                "minecraft:wool@5"
            ]
        },
        {
            "x": -2,
            "y": 15,
            "z": 6,
            "elements": [
                "minecraft:concrete@1"
            ]
        },
        {
            "x": -4,
            "y": 14,
            "z": 9,
            "elements": [
                "minecraft:concrete@1"
            ]
        },
        {
            "x": -9,
            "y": 12,
            "z": 1,
            "elements": [
                "minecraft:wool@0"
            ]
        },
        {
            "x": -4,
            "y": 14,
            "z": 10,
            "elements": [
                "minecraft:concrete@1"
            ]
        },
        {
            "x": -9,
            "y": 12,
            "z": 2,
            "elements": [
                "minecraft:wool@0"
            ]
        },
        {
            "x": -4,
            "y": 14,
            "z": 11,
            "elements": [
                "minecraft:concrete@1"
            ]
        },
        {
            "x": -9,
            "y": 12,
            "z": 3,
            "elements": [
                "minecraft:wool@0"
            ]
        },
        {
            "x": -4,
            "y": 14,
            "z": 6,
            "elements": [
                "minecraft:concrete@1"
            ]
        },
        {
            "x": -4,
            "y": 14,
            "z": 7,
            "elements": [
                "minecraft:concrete@1"
            ]
        },
        {
            "x": -4,
            "y": 14,
            "z": 8,
            "elements": [
                "minecraft:concrete@1"
            ]
        },
        {
            "x": -4,
            "y": 14,
            "z": 1,
            "elements": [
                "minecraft:concrete@1"
            ]
        },
        {
            "x": -10,
            "y": 10,
            "z": 2,
            "elements": [
                "minecraft:wool@5"
            ]
        },
        {
            "x": -9,
            "y": 6,
            "z": 7,
            "elements": [
                "minecraft:wool@5"
            ]
        },
        {
            "x": -10,
            "y": 10,
            "z": 1,
            "elements": [
                "minecraft:wool@5"
            ]
        },
        {
            "x": -4,
            "y": 14,
            "z": 2,
            "elements": [
                "minecraft:concrete@1"
            ]
        },
        {
            "x": -9,
            "y": 6,
            "z": 6,
            "elements": [
                "minecraft:wool@5"
            ]
        },
        {
            "x": -10,
            "y": 10,
            "z": 0,
            "elements": [
                "minecraft:wool@5"
            ]
        },
        {
            "x": -3,
            "y": 16,
            "z": 6,
            "elements": [
                "minecraft:concrete@1"
            ]
        },
        {
            "x": -3,
            "y": 16,
            "z": 7,
            "elements": [
                "minecraft:concrete@1"
            ]
        },
        {
            "x": 7,
            "y": 4,
            "z": 0,
            "elements": [
                "minecraft:wool@5"
            ]
        },
        {
            "x": -9,
            "y": 6,
            "z": 3,
            "elements": [
                "minecraft:wool@5"
            ]
        },
        {
            "x": -9,
            "y": 12,
            "z": 4,
            "elements": [
                "minecraft:concrete@1"
            ]
        },
        {
            "x": -10,
            "y": 10,
            "z": 6,
            "elements": [
                "minecraft:wool@5"
            ]
        },
        {
            "x": 7,
            "y": 4,
            "z": 1,
            "elements": [
                "minecraft:wool@5"
            ]
        },
        {
            "x": -9,
            "y": 6,
            "z": 2,
            "elements": [
                "minecraft:wool@5"
            ]
        },
        {
            "x": -10,
            "y": 10,
            "z": 5,
            "elements": [
                "minecraft:wool@5"
            ]
        },
        {
            "x": -9,
            "y": 12,
            "z": 5,
            "elements": [
                "minecraft:concrete@1"
            ]
        },
        {
            "x": -4,
            "y": 14,
            "z": -1,
            "elements": [
                "minecraft:wool@13"
            ]
        },
        {
            "x": 7,
            "y": 4,
            "z": 2,
            "elements": [
                "appliedenergistics2:smooth_sky_stone_block@0"
            ]
        },
        {
            "x": -3,
            "y": 16,
            "z": 2,
            "elements": [
                "minecraft:quartz_block@0"
            ]
        },
        {
            "x": -10,
            "y": 10,
            "z": 4,
            "elements": [
                "minecraft:wool@5"
            ]
        },
        {
            "x": -9,
            "y": 6,
            "z": 5,
            "elements": [
                "minecraft:wool@5"
            ]
        },
        {
            "x": -9,
            "y": 12,
            "z": 6,
            "elements": [
                "minecraft:concrete@1"
            ]
        },
        {
            "x": 7,
            "y": 4,
            "z": 3,
            "elements": [
                "appliedenergistics2:smooth_sky_stone_block@0"
            ]
        },
        {
            "x": -10,
            "y": 10,
            "z": 3,
            "elements": [
                "minecraft:wool@5"
            ]
        },
        {
            "x": -9,
            "y": 6,
            "z": 4,
            "elements": [
                "minecraft:wool@5"
            ]
        },
        {
            "x": -8,
            "y": 8,
            "z": 8,
            "elements": [
                "minecraft:wool@5"
            ]
        },
        {
            "x": -9,
            "y": 6,
            "z": -1,
            "elements": [
                "appliedenergistics2:smooth_sky_stone_block@0"
            ]
        },
        {
            "x": 7,
            "y": 4,
            "z": 4,
            "elements": [
                "minecraft:wool@5"
            ]
        },
        {
            "x": 7,
            "y": 4,
            "z": 5,
            "elements": [
                "minecraft:wool@5"
            ]
        },
        {
            "x": -9,
            "y": 6,
            "z": 1,
            "elements": [
                "minecraft:wool@5"
            ]
        },
        {
            "x": 2,
            "y": 21,
            "z": 3,
            "elements": [
                "minecraft:wool@8"
            ]
        },
        {
            "x": 7,
            "y": 4,
            "z": 6,
            "elements": [
                "minecraft:wool@5"
            ]
        },
        {
            "x": -9,
            "y": 6,
            "z": 0,
            "elements": [
                "appliedenergistics2:smooth_sky_stone_block@0"
            ]
        },
        {
            "x": -9,
            "y": 9,
            "z": -1,
            "elements": [
                "minecraft:wool@5"
            ]
        },
        {
            "x": -4,
            "y": 17,
            "z": 1,
            "elements": [
                "minecraft:concrete@1"
            ]
        },
        {
            "x": 0,
            "y": 17,
            "z": 2,
            "elements": [
                "minecraft:quartz_block@0"
            ]
        },
        {
            "x": 0,
            "y": 17,
            "z": 1,
            "elements": [
                "minecraft:wool@1"
            ]
        },
        {
            "x": 4,
            "y": 2,
            "z": 6,
            "elements": [
                "minecraft:wool@5"
            ]
        },
        {
            "x": 4,
            "y": 2,
            "z": 7,
            "elements": [
                "appliedenergistics2:smooth_sky_stone_block@0"
            ]
        },
        {
            "x": -8,
            "y": 7,
            "z": 8,
            "elements": [
                "minecraft:wool@5"
            ]
        },
        {
            "x": 3,
            "y": 1,
            "z": 0,
            "elements": [
                "minecraft:wool@5"
            ]
        },
        {
            "x": 0,
            "y": 17,
            "z": 6,
            "elements": [
                "minecraft:concrete@1"
            ]
        },
        {
            "x": 0,
            "y": 17,
            "z": 7,
            "elements": [
                "minecraft:concrete@1"
            ]
        },
        {
            "x": 4,
            "y": 2,
            "z": -1,
            "elements": [
                "minecraft:wool@5"
            ]
        },
        {
            "x": 4,
            "y": 2,
            "z": 0,
            "elements": [
                "minecraft:wool@5"
            ]
        },
        {
            "x": -1,
            "y": 16,
            "z": 2,
            "elements": [
                "minecraft:quartz_block@0"
            ]
        },
        {
            "x": -1,
            "y": 16,
            "z": 7,
            "elements": [
                "minecraft:concrete@1"
            ]
        },
        {
            "x": -1,
            "y": 16,
            "z": 6,
            "elements": [
                "minecraft:concrete@1"
            ]
        },
        {
            "x": -6,
            "y": 10,
            "z": -4,
            "elements": [
                "minecraft:wool@5"
            ]
        },
        {
            "x": 9,
            "y": 8,
            "z": 1,
            "elements": [
                "minecraft:wool@5"
            ]
        },
        {
            "x": -8,
            "y": 14,
            "z": 6,
            "elements": [
                "minecraft:concrete@1"
            ]
        },
        {
            "x": -2,
            "y": 14,
            "z": 11,
            "elements": [
                "minecraft:concrete@1"
            ]
        },
        {
            "x": 5,
            "y": 3,
            "z": -1,
            "elements": [
                "minecraft:wool@5"
            ]
        },
        {
            "x": 9,
            "y": 8,
            "z": 0,
            "elements": [
                "minecraft:wool@5"
            ]
        },
        {
            "x": -8,
            "y": 14,
            "z": 5,
            "elements": [
                "minecraft:concrete@1"
            ]
        },
        {
            "x": -6,
            "y": 10,
            "z": -2,
            "elements": [
                "minecraft:redstone_block@0"
            ]
        },
        {
            "x": 9,
            "y": 8,
            "z": -1,
            "elements": [
                "minecraft:wool@5"
            ]
        },
        {
            "x": -8,
            "y": 14,
            "z": 8,
            "elements": [
                "minecraft:concrete@1"
            ]
        },
        {
            "x": -6,
            "y": 10,
            "z": -3,
            "elements": [
                "minecraft:redstone_block@0"
            ]
        },
        {
            "x": -8,
            "y": 14,
            "z": 7,
            "elements": [
                "minecraft:concrete@1"
            ]
        },
        {
            "x": -6,
            "y": 10,
            "z": 0,
            "elements": [
                "appliedenergistics2:smooth_sky_stone_block@0"
            ]
        },
        {
            "x": -8,
            "y": 14,
            "z": 2,
            "elements": [
                "minecraft:wool@0"
            ]
        },
        {
            "x": 9,
            "y": 8,
            "z": 5,
            "elements": [
                "minecraft:wool@5"
            ]
        },
        {
            "x": -6,
            "y": 10,
            "z": -1,
            "elements": [
                "minecraft:redstone_block@0"
            ]
        },
        {
            "x": -8,
            "y": 14,
            "z": 1,
            "elements": [
                "minecraft:wool@0"
            ]
        },
        {
            "x": 9,
            "y": 8,
            "z": 4,
            "elements": [
                "minecraft:wool@5"
            ]
        },
        {
            "x": -6,
            "y": 10,
            "z": 2,
            "elements": [
                "minecraft:redstone_block@0"
            ]
        },
        {
            "x": 9,
            "y": 8,
            "z": 3,
            "elements": [
                "minecraft:wool@5"
            ]
        },
        {
            "x": -8,
            "y": 14,
            "z": 4,
            "elements": [
                "minecraft:concrete@1"
            ]
        },
        {
            "x": -6,
            "y": 10,
            "z": 1,
            "elements": [
                "minecraft:redstone_block@0"
            ]
        },
        {
            "x": 9,
            "y": 8,
            "z": 2,
            "elements": [
                "minecraft:wool@5"
            ]
        },
        {
            "x": -8,
            "y": 14,
            "z": 3,
            "elements": [
                "minecraft:wool@0"
            ]
        },
        {
            "x": 5,
            "y": 3,
            "z": 7,
            "elements": [
                "minecraft:wool@5"
            ]
        },
        {
            "x": 9,
            "y": 8,
            "z": 7,
            "elements": [
                "minecraft:wool@5"
            ]
        },
        {
            "x": 9,
            "y": 8,
            "z": 6,
            "elements": [
                "minecraft:wool@5"
            ]
        },
        {
            "x": -2,
            "y": 14,
            "z": -1,
            "elements": [
                "appliedenergistics2:smooth_sky_stone_block@0"
            ]
        },
        {
            "x": 5,
            "y": 4,
            "z": -2,
            "elements": [
                "minecraft:wool@5"
            ]
        },
        {
            "x": -2,
            "y": 21,
            "z": 3,
            "elements": [
                "minecraft:wool@8"
            ]
        },
        {
            "x": 3,
            "y": 1,
            "z": 6,
            "elements": [
                "appliedenergistics2:smooth_sky_stone_block@0"
            ]
        },
        {
            "x": -2,
            "y": 14,
            "z": 2,
            "elements": [
                "minecraft:quartz_block@0"
            ]
        },
        {
            "x": 5,
            "y": 4,
            "z": -3,
            "elements": [
                "appliedenergistics2:smooth_sky_stone_block@0"
            ]
        },
        {
            "x": -2,
            "y": 14,
            "z": 6,
            "elements": [
                "minecraft:concrete@1"
            ]
        },
        {
            "x": -8,
            "y": 7,
            "z": -2,
            "elements": [
                "appliedenergistics2:smooth_sky_stone_block@0"
            ]
        },
        {
            "x": -2,
            "y": 14,
            "z": 7,
            "elements": [
                "minecraft:concrete@1"
            ]
        },
        {
            "x": -2,
            "y": 14,
            "z": 8,
            "elements": [
                "minecraft:concrete@1"
            ]
        },
        {
            "x": -2,
            "y": 14,
            "z": 9,
            "elements": [
                "minecraft:concrete@1"
            ]
        },
        {
            "x": -2,
            "y": 14,
            "z": 10,
            "elements": [
                "minecraft:concrete@1"
            ]
        },
        {
            "x": -7,
            "y": 14,
            "z": 7,
            "elements": [
                "minecraft:concrete@1"
            ]
        },
        {
            "x": 4,
            "y": 3,
            "z": -2,
            "elements": [
                "appliedenergistics2:smooth_sky_stone_block@0"
            ]
        },
        {
            "x": -7,
            "y": 14,
            "z": 6,
            "elements": [
                "minecraft:concrete@1"
            ]
        },
        {
            "x": -7,
            "y": 14,
            "z": 5,
            "elements": [
                "minecraft:concrete@1"
            ]
        },
        {
            "x": -7,
            "y": 14,
            "z": 4,
            "elements": [
                "minecraft:concrete@1"
            ]
        },
        {
            "x": -7,
            "y": 14,
            "z": 3,
            "elements": [
                "minecraft:concrete@1"
            ]
        },
        {
            "x": -7,
            "y": 14,
            "z": 2,
            "elements": [
                "minecraft:wool@0"
            ]
        },
        {
            "x": -7,
            "y": 14,
            "z": 1,
            "elements": [
                "minecraft:wool@0"
            ]
        },
        {
            "x": -1,
            "y": 15,
            "z": 6,
            "elements": [
                "minecraft:concrete@1"
            ]
        },
        {
            "x": -1,
            "y": 15,
            "z": 7,
            "elements": [
                "minecraft:concrete@1"
            ]
        },
        {
            "x": -1,
            "y": 15,
            "z": 2,
            "elements": [
                "minecraft:quartz_block@0"
            ]
        },
        {
            "x": -8,
            "y": 6,
            "z": -2,
            "elements": [
                "minecraft:wool@5"
            ]
        },
        {
            "x": 4,
            "y": 3,
            "z": 8,
            "elements": [
                "minecraft:wool@5"
            ]
        },
        {
            "x": -6,
            "y": 10,
            "z": 4,
            "elements": [
                "minecraft:redstone_block@0"
            ]
        },
        {
            "x": -8,
            "y": 6,
            "z": 8,
            "elements": [
                "minecraft:wool@5"
            ]
        },
        {
            "x": -6,
            "y": 10,
            "z": 3,
            "elements": [
                "minecraft:redstone_block@0"
            ]
        },
        {
            "x": -6,
            "y": 10,
            "z": 6,
            "elements": [
                "minecraft:redstone_block@0"
            ]
        },
        {
            "x": -3,
            "y": 12,
            "z": 10,
            "elements": [
                "minecraft:concrete@1"
            ]
        },
        {
            "x": -6,
            "y": 10,
            "z": 5,
            "elements": [
                "minecraft:redstone_block@0"
            ]
        },
        {
            "x": -3,
            "y": 12,
            "z": 11,
            "elements": [
                "minecraft:concrete@1"
            ]
        },
        {
            "x": -6,
            "y": 10,
            "z": 8,
            "elements": [
                "minecraft:redstone_block@0"
            ]
        },
        {
            "x": -6,
            "y": 10,
            "z": 7,
            "elements": [
                "minecraft:redstone_block@0"
            ]
        },
        {
            "x": -7,
            "y": 14,
            "z": 10,
            "elements": [
                "minecraft:concrete@1"
            ]
        },
        {
            "x": -3,
            "y": 12,
            "z": 6,
            "elements": [
                "minecraft:concrete@1"
            ]
        },
        {
            "x": -7,
            "y": 14,
            "z": 9,
            "elements": [
                "minecraft:concrete@1"
            ]
        },
        {
            "x": -6,
            "y": 10,
            "z": 10,
            "elements": [
                "minecraft:wool@5"
            ]
        },
        {
            "x": -7,
            "y": 14,
            "z": 8,
            "elements": [
                "minecraft:concrete@1"
            ]
        },
        {
            "x": -6,
            "y": 10,
            "z": 9,
            "elements": [
                "minecraft:redstone_block@0"
            ]
        },
        {
            "x": 10,
            "y": 10,
            "z": 4,
            "elements": [
                "minecraft:wool@5"
            ]
        },
        {
            "x": 10,
            "y": 10,
            "z": 3,
            "elements": [
                "minecraft:wool@5"
            ]
        },
        {
            "x": -7,
            "y": 8,
            "z": -4,
            "elements": [
                "minecraft:wool@5"
            ]
        },
        {
            "x": 10,
            "y": 10,
            "z": 6,
            "elements": [
                "minecraft:wool@5"
            ]
        },
        {
            "x": -7,
            "y": 8,
            "z": -3,
            "elements": [
                "minecraft:wool@5"
            ]
        },
        {
            "x": 10,
            "y": 10,
            "z": 5,
            "elements": [
                "minecraft:wool@5"
            ]
        },
        {
            "x": -7,
            "y": 8,
            "z": 9,
            "elements": [
                "appliedenergistics2:smooth_sky_stone_block@0"
            ]
        },
        {
            "x": -7,
            "y": 8,
            "z": 10,
            "elements": [
                "appliedenergistics2:smooth_sky_stone_block@0"
            ]
        },
        {
            "x": 10,
            "y": 10,
            "z": 0,
            "elements": [
                "minecraft:wool@5"
            ]
        },
        {
            "x": 10,
            "y": 10,
            "z": 2,
            "elements": [
                "minecraft:wool@5"
            ]
        },
        {
            "x": -8,
            "y": 12,
            "z": 7,
            "elements": [
                "minecraft:concrete@1"
            ]
        },
        {
            "x": 10,
            "y": 10,
            "z": 1,
            "elements": [
                "minecraft:wool@5"
            ]
        },
        {
            "x": -8,
            "y": 12,
            "z": 8,
            "elements": [
                "minecraft:concrete@1"
            ]
        },
        {
            "x": 5,
            "y": 5,
            "z": 10,
            "elements": [
                "minecraft:wool@5"
            ]
        },
        {
            "x": -6,
            "y": 11,
            "z": 10,
            "elements": [
                "minecraft:wool@5"
            ]
        },
        {
            "x": -2,
            "y": 13,
            "z": 2,
            "elements": [
                "minecraft:quartz_block@0"
            ]
        },
        {
            "x": 3,
            "y": 19,
            "z": 1,
            "elements": [
                "minecraft:concrete@1"
            ]
        },
        {
            "x": 1,
            "y": 20,
            "z": 2,
            "elements": [
                "minecraft:concrete@1"
            ]
        },
        {
            "x": 1,
            "y": 20,
            "z": 3,
            "elements": [
                "minecraft:concrete@1"
            ]
        },
        {
            "x": 1,
            "y": 20,
            "z": 4,
            "elements": [
                "minecraft:concrete@1"
            ]
        },
        {
            "x": 3,
            "y": 19,
            "z": 6,
            "elements": [
                "minecraft:concrete@1"
            ]
        },
        {
            "x": -2,
            "y": 13,
            "z": -1,
            "elements": [
                "minecraft:concrete@14"
            ]
        },
        {
            "x": 1,
            "y": 20,
            "z": 5,
            "elements": [
                "minecraft:concrete@1"
            ]
        },
        {
            "x": 6,
            "y": 6,
            "z": 10,
            "elements": [
                "minecraft:wool@5"
            ]
        },
        {
            "x": -2,
            "y": 13,
            "z": 11,
            "elements": [
                "minecraft:concrete@1"
            ]
        },
        {
            "x": 5,
            "y": 5,
            "z": -4,
            "elements": [
                "appliedenergistics2:smooth_sky_stone_block@0"
            ]
        },
        {
            "x": -2,
            "y": 13,
            "z": 6,
            "elements": [
                "minecraft:concrete@1"
            ]
        },
        {
            "x": 6,
            "y": 6,
            "z": -4,
            "elements": [
                "minecraft:wool@5"
            ]
        },
        {
            "x": -3,
            "y": 12,
            "z": 2,
            "elements": [
                "minecraft:concrete@1"
            ]
        },
        {
            "x": 8,
            "y": 5,
            "z": 6,
            "elements": [
                "minecraft:wool@5"
            ]
        },
        {
            "x": 8,
            "y": 5,
            "z": 7,
            "elements": [
                "minecraft:wool@5"
            ]
        },
        {
            "x": 8,
            "y": 5,
            "z": 4,
            "elements": [
                "appliedenergistics2:smooth_sky_stone_block@0"
            ]
        },
        {
            "x": 8,
            "y": 5,
            "z": 5,
            "elements": [
                "minecraft:wool@5"
            ]
        },
        {
            "x": 8,
            "y": 5,
            "z": 2,
            "elements": [
                "minecraft:wool@5"
            ]
        },
        {
            "x": -3,
            "y": 12,
            "z": -1,
            "elements": [
                "minecraft:wool@13"
            ]
        },
        {
            "x": 8,
            "y": 5,
            "z": 3,
            "elements": [
                "appliedenergistics2:smooth_sky_stone_block@0"
            ]
        },
        {
            "x": -9,
            "y": 11,
            "z": 7,
            "elements": [
                "minecraft:wool@5"
            ]
        },
        {
            "x": 6,
            "y": 7,
            "z": -4,
            "elements": [
                "minecraft:wool@5"
            ]
        },
        {
            "x": -3,
            "y": 11,
            "z": 2,
            "elements": [
                "minecraft:concrete@1"
            ]
        },
        {
            "x": -9,
            "y": 11,
            "z": -1,
            "elements": [
                "minecraft:wool@5"
            ]
        },
        {
            "x": -3,
            "y": 18,
            "z": 6,
            "elements": [
                "minecraft:concrete@1"
            ]
        },
        {
            "x": -9,
            "y": 11,
            "z": 1,
            "elements": [
                "minecraft:wool@0"
            ]
        },
        {
            "x": -3,
            "y": 18,
            "z": 1,
            "elements": [
                "minecraft:concrete@1"
            ]
        },
        {
            "x": -3,
            "y": 11,
            "z": 6,
            "elements": [
                "minecraft:concrete@1"
            ]
        },
        {
            "x": -3,
            "y": 18,
            "z": 2,
            "elements": [
                "minecraft:quartz_block@0"
            ]
        },
        {
            "x": -3,
            "y": 11,
            "z": 13,
            "elements": [
                "minecraft:wool@5"
            ]
        },
        {
            "x": -3,
            "y": 11,
            "z": 11,
            "elements": [
                "minecraft:concrete@1"
            ]
        },
        {
            "x": 3,
            "y": 0,
            "z": 6,
            "elements": [
                "minecraft:wool@5"
            ]
        },
        {
            "x": -7,
            "y": 9,
            "z": 9,
            "elements": [
                "appliedenergistics2:smooth_sky_stone_block@0"
            ]
        },
        {
            "x": -7,
            "y": 9,
            "z": 10,
            "elements": [
                "appliedenergistics2:smooth_sky_stone_block@0"
            ]
        },
        {
            "x": 3,
            "y": 0,
            "z": 4,
            "elements": [
                "modularmachinery:blockfluidinputhatch"
            ]
        },
        {
            "x": 3,
            "y": 0,
            "z": 5,
            "elements": [
                "minecraft:wool@5"
            ]
        },
        {
            "x": 3,
            "y": 0,
            "z": 2,
            "elements": [
                "modularmachinery:blockfluidinputhatch"
            ]
        },
        {
            "x": 3,
            "y": 0,
            "z": 3,
            "elements": [
                "modularmachinery:blockfluidinputhatch"
            ]
        },
        {
            "x": 3,
            "y": 0,
            "z": 0,
            "elements": [
                "minecraft:wool@5"
            ]
        },
        {
            "x": 0,
            "y": 18,
            "z": 1,
            "elements": [
                "minecraft:wool@1"
            ]
        },
        {
            "x": 5,
            "y": 4,
            "z": 9,
            "elements": [
                "minecraft:wool@5"
            ]
        },
        {
            "x": 3,
            "y": 0,
            "z": 1,
            "elements": [
                "minecraft:wool@5"
            ]
        },
        {
            "x": 0,
            "y": 18,
            "z": 2,
            "elements": [
                "minecraft:quartz_block@0"
            ]
        },
        {
            "x": 5,
            "y": 4,
            "z": 8,
            "elements": [
                "minecraft:wool@5"
            ]
        },
        {
            "x": 10,
            "y": 9,
            "z": 5,
            "elements": [
                "minecraft:wool@5"
            ]
        },
        {
            "x": 10,
            "y": 9,
            "z": 4,
            "elements": [
                "minecraft:wool@5"
            ]
        },
        {
            "x": -5,
            "y": 13,
            "z": 5,
            "elements": [
                "minecraft:wool@1"
            ]
        },
        {
            "x": -5,
            "y": 13,
            "z": 4,
            "elements": [
                "minecraft:concrete@1"
            ]
        },
        {
            "x": -7,
            "y": 9,
            "z": -4,
            "elements": [
                "minecraft:wool@5"
            ]
        },
        {
            "x": -5,
            "y": 13,
            "z": 3,
            "elements": [
                "minecraft:concrete@1"
            ]
        },
        {
            "x": 10,
            "y": 9,
            "z": 6,
            "elements": [
                "appliedenergistics2:smooth_sky_stone_block@0"
            ]
        },
        {
            "x": -5,
            "y": 13,
            "z": 2,
            "elements": [
                "minecraft:wool@1"
            ]
        },
        {
            "x": -8,
            "y": 13,
            "z": 8,
            "elements": [
                "minecraft:concrete@1"
            ]
        },
        {
            "x": -2,
            "y": 20,
            "z": 5,
            "elements": [
                "minecraft:concrete@1"
            ]
        },
        {
            "x": -8,
            "y": 13,
            "z": 7,
            "elements": [
                "minecraft:concrete@1"
            ]
        },
        {
            "x": 8,
            "y": 5,
            "z": 0,
            "elements": [
                "minecraft:wool@5"
            ]
        },
        {
            "x": 8,
            "y": 5,
            "z": 1,
            "elements": [
                "minecraft:wool@5"
            ]
        },
        {
            "x": 8,
            "y": 5,
            "z": -1,
            "elements": [
                "minecraft:wool@5"
            ]
        },
        {
            "x": -7,
            "y": 9,
            "z": -3,
            "elements": [
                "appliedenergistics2:smooth_sky_stone_block@0"
            ]
        },
        {
            "x": 10,
            "y": 9,
            "z": 1,
            "elements": [
                "minecraft:wool@5"
            ]
        },
        {
            "x": -5,
            "y": 13,
            "z": 10,
            "elements": [
                "minecraft:concrete@1"
            ]
        },
        {
            "x": 10,
            "y": 9,
            "z": 0,
            "elements": [
                "minecraft:wool@5"
            ]
        },
        {
            "x": -8,
            "y": 13,
            "z": 1,
            "elements": [
                "minecraft:wool@0"
            ]
        },
        {
            "x": -5,
            "y": 13,
            "z": 9,
            "elements": [
                "minecraft:concrete@1"
            ]
        },
        {
            "x": 10,
            "y": 9,
            "z": 3,
            "elements": [
                "minecraft:wool@5"
            ]
        },
        {
            "x": -5,
            "y": 13,
            "z": 8,
            "elements": [
                "minecraft:concrete@1"
            ]
        },
        {
            "x": 10,
            "y": 9,
            "z": 2,
            "elements": [
                "minecraft:wool@5"
            ]
        },
        {
            "x": -4,
            "y": 9,
            "z": 12,
            "elements": [
                "minecraft:wool@5"
            ]
        },
        {
            "x": 9,
            "y": 7,
            "z": 7,
            "elements": [
                "minecraft:wool@5"
            ]
        },
        {
            "x": -2,
            "y": 20,
            "z": 4,
            "elements": [
                "minecraft:concrete@1"
            ]
        },
        {
            "x": -2,
            "y": 20,
            "z": 3,
            "elements": [
                "minecraft:concrete@1"
            ]
        },
        {
            "x": -2,
            "y": 20,
            "z": 2,
            "elements": [
                "minecraft:concrete@1"
            ]
        },
        {
            "x": -6,
            "y": 11,
            "z": 1,
            "elements": [
                "minecraft:wool@0"
            ]
        },
        {
            "x": 0,
            "y": 18,
            "z": 6,
            "elements": [
                "minecraft:concrete@1"
            ]
        },
        {
            "x": -6,
            "y": 11,
            "z": -4,
            "elements": [
                "minecraft:wool@5"
            ]
        },
        {
            "x": 9,
            "y": 7,
            "z": 6,
            "elements": [
                "minecraft:wool@5"
            ]
        },
        {
            "x": 9,
            "y": 7,
            "z": 5,
            "elements": [
                "minecraft:wool@5"
            ]
        },
        {
            "x": 9,
            "y": 7,
            "z": 4,
            "elements": [
                "minecraft:wool@5"
            ]
        },
        {
            "x": 9,
            "y": 7,
            "z": 3,
            "elements": [
                "minecraft:wool@5"
            ]
        },
        {
            "x": 9,
            "y": 7,
            "z": 2,
            "elements": [
                "minecraft:wool@5"
            ]
        },
        {
            "x": 9,
            "y": 7,
            "z": 1,
            "elements": [
                "minecraft:wool@5"
            ]
        },
        {
            "x": 9,
            "y": 7,
            "z": 0,
            "elements": [
                "minecraft:wool@5"
            ]
        },
        {
            "x": 9,
            "y": 7,
            "z": -1,
            "elements": [
                "minecraft:wool@5"
            ]
        },
        {
            "x": -3,
            "y": 10,
            "z": -2,
            "elements": [
                "appliedenergistics2:smooth_sky_stone_block@0"
            ]
        },
        {
            "x": -3,
            "y": 10,
            "z": -1,
            "elements": [
                "minecraft:redstone_block@0"
            ]
        },
        {
            "x": -3,
            "y": 10,
            "z": -4,
            "elements": [
                "minecraft:redstone_block@0"
            ]
        },
        {
            "x": 1,
            "y": 15,
            "z": 2,
            "elements": [
                "minecraft:quartz_block@0"
            ]
        },
        {
            "x": -3,
            "y": 10,
            "z": -3,
            "elements": [
                "minecraft:redstone_block@0"
            ]
        },
        {
            "x": -3,
            "y": 10,
            "z": -6,
            "elements": [
                "minecraft:redstone_block@0"
            ]
        },
        {
            "x": -3,
            "y": 10,
            "z": -5,
            "elements": [
                "minecraft:redstone_block@0"
            ]
        },
        {
            "x": 1,
            "y": 15,
            "z": 6,
            "elements": [
                "minecraft:concrete@1"
            ]
        },
        {
            "x": -3,
            "y": 10,
            "z": -7,
            "elements": [
                "minecraft:wool@5"
            ]
        },
        {
            "x": -3,
            "y": 10,
            "z": 6,
            "elements": [
                "minecraft:redstone_block@0"
            ]
        },
        {
            "x": -3,
            "y": 10,
            "z": 7,
            "elements": [
                "minecraft:redstone_block@0"
            ]
        },
        {
            "x": -2,
            "y": 11,
            "z": 11,
            "elements": [
                "minecraft:concrete@1"
            ]
        },
        {
            "x": -2,
            "y": 11,
            "z": 13,
            "elements": [
                "appliedenergistics2:smooth_sky_stone_block@0"
            ]
        },
        {
            "x": -3,
            "y": 10,
            "z": 2,
            "elements": [
                "minecraft:redstone_block@0"
            ]
        },
        {
            "x": -2,
            "y": 11,
            "z": 6,
            "elements": [
                "minecraft:concrete@1"
            ]
        },
        {
            "x": -3,
            "y": 10,
            "z": 0,
            "elements": [
                "minecraft:redstone_block@0"
            ]
        },
        {
            "x": -3,
            "y": 10,
            "z": 1,
            "elements": [
                "minecraft:redstone_block@0"
            ]
        },
        {
            "x": -4,
            "y": 9,
            "z": -6,
            "elements": [
                "minecraft:wool@5"
            ]
        },
        {
            "x": -3,
            "y": 10,
            "z": 12,
            "elements": [
                "minecraft:redstone_block@0"
            ]
        },
        {
            "x": -3,
            "y": 10,
            "z": 13,
            "elements": [
                "minecraft:wool@5"
            ]
        },
        {
            "x": -3,
            "y": 10,
            "z": 10,
            "elements": [
                "appliedenergistics2:smooth_sky_stone_block@0"
            ]
        },
        {
            "x": 0,
            "y": 14,
            "z": -1,
            "elements": [
                "appliedenergistics2:smooth_sky_stone_block@0"
            ]
        },
        {
            "x": -3,
            "y": 10,
            "z": 11,
            "elements": [
                "minecraft:redstone_block@0"
            ]
        },
        {
            "x": -3,
            "y": 10,
            "z": 8,
            "elements": [
                "minecraft:redstone_block@0"
            ]
        },
        {
            "x": -3,
            "y": 10,
            "z": 9,
            "elements": [
                "minecraft:redstone_block@0"
            ]
        },
        {
            "x": 1,
            "y": 15,
            "z": 7,
            "elements": [
                "minecraft:concrete@1"
            ]
        },
        {
            "x": 0,
            "y": 14,
            "z": 2,
            "elements": [
                "minecraft:quartz_block@0"
            ]
        },
        {
            "x": 0,
            "y": 14,
            "z": 8,
            "elements": [
                "minecraft:concrete@1"
            ]
        },
        {
            "x": 0,
            "y": 14,
            "z": 7,
            "elements": [
                "minecraft:concrete@1"
            ]
        },
        {
            "x": 0,
            "y": 14,
            "z": 6,
            "elements": [
                "minecraft:concrete@1"
            ]
        },
        {
            "x": 0,
            "y": 0,
            "z": 4,
            "elements": [
                "minecraft:wool@5"
            ]
        },
        {
            "x": 0,
            "y": 0,
            "z": 3,
            "elements": [
                "minecraft:wool@5"
            ]
        },
        {
            "x": 0,
            "y": 0,
            "z": 6,
            "elements": [
                "modularmachinery:blockenergyinputhatch"
            ]
        },
        {
            "x": 0,
            "y": 0,
            "z": 5,
            "elements": [
                "minecraft:wool@5"
            ]
        },
        {
            "x": 1,
            "y": 2,
            "z": 8,
            "elements": [
                "minecraft:wool@5"
            ]
        },
        {
            "x": 0,
            "y": 0,
            "z": 2,
            "elements": [
                "minecraft:wool@5"
            ]
        },
        {
            "x": 0,
            "y": 0,
            "z": 1,
            "elements": [
                "minecraft:wool@5"
            ]
        },
        {
            "x": 1,
            "y": 2,
            "z": -2,
            "elements": [
                "minecraft:wool@5"
            ]
        },
        {
            "x": -2,
            "y": 11,
            "z": 3,
            "elements": [
                "minecraft:concrete@1"
            ]
        },
        {
            "x": 0,
            "y": 13,
            "z": 6,
            "elements": [
                "minecraft:concrete@1"
            ]
        },
        {
            "x": -2,
            "y": 11,
            "z": -1,
            "elements": [
                "minecraft:wool@13"
            ]
        },
        {
            "x": 0,
            "y": 13,
            "z": 2,
            "elements": [
                "minecraft:quartz_block@0"
            ]
        },
        {
            "x": -4,
            "y": 8,
            "z": 12,
            "elements": [
                "minecraft:wool@5"
            ]
        },
        {
            "x": -2,
            "y": 11,
            "z": -7,
            "elements": [
                "minecraft:wool@5"
            ]
        },
        {
            "x": 0,
            "y": 13,
            "z": 10,
            "elements": [
                "minecraft:concrete@1"
            ]
        },
        {
            "x": 2,
            "y": 17,
            "z": 6,
            "elements": [
                "minecraft:concrete@1"
            ]
        },
        {
            "x": 2,
            "y": 17,
            "z": 7,
            "elements": [
                "minecraft:wool@1"
            ]
        },
        {
            "x": -3,
            "y": 9,
            "z": 13,
            "elements": [
                "minecraft:wool@5"
            ]
        },
        {
            "x": -3,
            "y": 11,
            "z": -7,
            "elements": [
                "minecraft:wool@5"
            ]
        },
        {
            "x": 0,
            "y": 13,
            "z": -1,
            "elements": [
                "minecraft:concrete@14"
            ]
        },
        {
            "x": 9,
            "y": 11,
            "z": -1,
            "elements": [
                "appliedenergistics2:smooth_sky_stone_block@0"
            ]
        },
        {
            "x": 2,
            "y": 17,
            "z": 2,
            "elements": [
                "minecraft:quartz_block@0"
            ]
        },
        {
            "x": -3,
            "y": 9,
            "z": -7,
            "elements": [
                "minecraft:wool@5"
            ]
        },
        {
            "x": 9,
            "y": 11,
            "z": 7,
            "elements": [
                "appliedenergistics2:smooth_sky_stone_block@0"
            ]
        },
        {
            "x": 8,
            "y": 10,
            "z": -2,
            "elements": [
                "appliedenergistics2:smooth_sky_stone_block@0"
            ]
        },
        {
            "x": 8,
            "y": 10,
            "z": 0,
            "elements": [
                "minecraft:redstone_block@0"
            ]
        },
        {
            "x": 8,
            "y": 10,
            "z": -1,
            "elements": [
                "minecraft:redstone_block@0"
            ]
        },
        {
            "x": 8,
            "y": 10,
            "z": 2,
            "elements": [
                "minecraft:redstone_block@0"
            ]
        },
        {
            "x": 8,
            "y": 10,
            "z": 1,
            "elements": [
                "minecraft:redstone_block@0"
            ]
        },
        {
            "x": 8,
            "y": 10,
            "z": 4,
            "elements": [
                "minecraft:redstone_block@0"
            ]
        },
        {
            "x": 8,
            "y": 10,
            "z": 3,
            "elements": [
                "minecraft:redstone_block@0"
            ]
        },
        {
            "x": 8,
            "y": 10,
            "z": 6,
            "elements": [
                "minecraft:redstone_block@0"
            ]
        },
        {
            "x": -1,
            "y": 12,
            "z": 6,
            "elements": [
                "minecraft:concrete@1"
            ]
        },
        {
            "x": 8,
            "y": 10,
            "z": 5,
            "elements": [
                "minecraft:redstone_block@0"
            ]
        },
        {
            "x": 8,
            "y": 10,
            "z": 8,
            "elements": [
                "appliedenergistics2:smooth_sky_stone_block@0"
            ]
        },
        {
            "x": 0,
            "y": 14,
            "z": 10,
            "elements": [
                "minecraft:concrete@1"
            ]
        },
        {
            "x": 8,
            "y": 10,
            "z": 7,
            "elements": [
                "minecraft:redstone_block@0"
            ]
        },
        {
            "x": 0,
            "y": 14,
            "z": 9,
            "elements": [
                "minecraft:concrete@1"
            ]
        },
        {
            "x": -1,
            "y": 12,
            "z": 11,
            "elements": [
                "minecraft:concrete@1"
            ]
        },
        {
            "x": 7,
            "y": 8,
            "z": 9,
            "elements": [
                "minecraft:wool@5"
            ]
        },
        {
            "x": 7,
            "y": 8,
            "z": 10,
            "elements": [
                "minecraft:wool@5"
            ]
        },
        {
            "x": -3,
            "y": 23,
            "z": 3,
            "elements": [
                "minecraft:concrete@15"
            ]
        },
        {
            "x": -1,
            "y": 12,
            "z": -1,
            "elements": [
                "minecraft:concrete@14"
            ]
        },
        {
            "x": 7,
            "y": 8,
            "z": -4,
            "elements": [
                "minecraft:wool@5"
            ]
        },
        {
            "x": 7,
            "y": 8,
            "z": -3,
            "elements": [
                "appliedenergistics2:smooth_sky_stone_block@0"
            ]
        },
        {
            "x": -1,
            "y": 12,
            "z": 3,
            "elements": [
                "minecraft:wool@1"
            ]
        },
        {
            "x": -1,
            "y": 14,
            "z": 11,
            "elements": [
                "minecraft:concrete@1"
            ]
        },
        {
            "x": -1,
            "y": 14,
            "z": 10,
            "elements": [
                "minecraft:concrete@1"
            ]
        },
        {
            "x": 2,
            "y": 18,
            "z": 1,
            "elements": [
                "minecraft:concrete@1"
            ]
        },
        {
            "x": -5,
            "y": 6,
            "z": -5,
            "elements": [
                "minecraft:wool@5"
            ]
        },
        {
            "x": -1,
            "y": 14,
            "z": 2,
            "elements": [
                "minecraft:quartz_block@0"
            ]
        },
        {
            "x": 2,
            "y": 18,
            "z": 2,
            "elements": [
                "minecraft:quartz_block@0"
            ]
        },
        {
            "x": -1,
            "y": 11,
            "z": -7,
            "elements": [
                "minecraft:wool@5"
            ]
        },
        {
            "x": -1,
            "y": 14,
            "z": 7,
            "elements": [
                "minecraft:concrete@1"
            ]
        },
        {
            "x": -1,
            "y": 14,
            "z": 6,
            "elements": [
                "minecraft:concrete@1"
            ]
        },
        {
            "x": -1,
            "y": 14,
            "z": 9,
            "elements": [
                "minecraft:concrete@1"
            ]
        },
        {
            "x": -1,
            "y": 14,
            "z": 8,
            "elements": [
                "minecraft:concrete@1"
            ]
        },
        {
            "x": -1,
            "y": 11,
            "z": 3,
            "elements": [
                "minecraft:wool@1"
            ]
        },
        {
            "x": -1,
            "y": 11,
            "z": -1,
            "elements": [
                "minecraft:wool@5"
            ]
        },
        {
            "x": 2,
            "y": 18,
            "z": 6,
            "elements": [
                "minecraft:concrete@1"
            ]
        },
        {
            "x": -1,
            "y": 11,
            "z": 11,
            "elements": [
                "minecraft:concrete@1"
            ]
        },
        {
            "x": -5,
            "y": 6,
            "z": 11,
            "elements": [
                "appliedenergistics2:smooth_sky_stone_block@0"
            ]
        },
        {
            "x": -4,
            "y": 7,
            "z": 12,
            "elements": [
                "minecraft:wool@5"
            ]
        },
        {
            "x": 1,
            "y": 3,
            "z": 9,
            "elements": [
                "minecraft:wool@5"
            ]
        },
        {
            "x": -1,
            "y": 11,
            "z": 6,
            "elements": [
                "minecraft:concrete@1"
            ]
        },
        {
            "x": 1,
            "y": 3,
            "z": -3,
            "elements": [
                "minecraft:wool@5"
            ]
        },
        {
            "x": -2,
            "y": 0,
            "z": 3,
            "elements": [
                "minecraft:wool@5"
            ]
        },
        {
            "x": -2,
            "y": 0,
            "z": 4,
            "elements": [
                "minecraft:wool@5"
            ]
        },
        {
            "x": -2,
            "y": 0,
            "z": 1,
            "elements": [
                "minecraft:wool@5"
            ]
        },
        {
            "x": -3,
            "y": 22,
            "z": 3,
            "elements": [
                "minecraft:concrete@1"
            ]
        },
        {
            "x": -2,
            "y": 0,
            "z": 2,
            "elements": [
                "minecraft:wool@5"
            ]
        },
        {
            "x": 10,
            "y": 11,
            "z": 0,
            "elements": [
                "appliedenergistics2:smooth_sky_stone_block@0"
            ]
        },
        {
            "x": -2,
            "y": 0,
            "z": 5,
            "elements": [
                "minecraft:wool@5"
            ]
        },
        {
            "x": 10,
            "y": 11,
            "z": 1,
            "elements": [
                "minecraft:wool@5"
            ]
        },
        {
            "x": -2,
            "y": 0,
            "z": 6,
            "elements": [
                "minecraft:wool@5"
            ]
        },
        {
            "x": 10,
            "y": 11,
            "z": 2,
            "elements": [
                "minecraft:wool@5"
            ]
        },
        {
            "x": 10,
            "y": 11,
            "z": 3,
            "elements": [
                "minecraft:wool@5"
            ]
        },
        {
            "x": 10,
            "y": 11,
            "z": 4,
            "elements": [
                "minecraft:wool@5"
            ]
        },
        {
            "x": 10,
            "y": 11,
            "z": 5,
            "elements": [
                "minecraft:wool@5"
            ]
        },
        {
            "x": 10,
            "y": 11,
            "z": 6,
            "elements": [
                "minecraft:wool@5"
            ]
        },
        {
            "x": -2,
            "y": 0,
            "z": 0,
            "elements": [
                "minecraft:wool@5"
            ]
        },
        {
            "x": 2,
            "y": 5,
            "z": -5,
            "elements": [
                "minecraft:wool@5"
            ]
        },
        {
            "x": 1,
            "y": 16,
            "z": 2,
            "elements": [
                "minecraft:quartz_block@0"
            ]
        },
        {
            "x": -1,
            "y": 14,
            "z": -1,
            "elements": [
                "minecraft:concrete@14"
            ]
        },
        {
            "x": 8,
            "y": 9,
            "z": -2,
            "elements": [
                "appliedenergistics2:smooth_sky_stone_block@0"
            ]
        },
        {
            "x": -5,
            "y": 5,
            "z": 10,
            "elements": [
                "appliedenergistics2:smooth_sky_stone_block@0"
            ]
        },
        {
            "x": 1,
            "y": 16,
            "z": 6,
            "elements": [
                "minecraft:concrete@1"
            ]
        },
        {
            "x": 1,
            "y": 16,
            "z": 7,
            "elements": [
                "minecraft:concrete@1"
            ]
        },
        {
            "x": 8,
            "y": 9,
            "z": 8,
            "elements": [
                "minecraft:wool@5"
            ]
        },
        {
            "x": 2,
            "y": 5,
            "z": 11,
            "elements": [
                "appliedenergistics2:smooth_sky_stone_block@0"
            ]
        },
        {
            "x": -2,
            "y": 12,
            "z": 6,
            "elements": [
                "minecraft:concrete@1"
            ]
        },
        {
            "x": -4,
            "y": 8,
            "z": -6,
            "elements": [
                "minecraft:wool@5"
            ]
        },
        {
            "x": -2,
            "y": 12,
            "z": 11,
            "elements": [
                "minecraft:concrete@1"
            ]
        },
        {
            "x": -2,
            "y": 12,
            "z": -1,
            "elements": [
                "minecraft:wool@5"
            ]
        },
        {
            "x": 3,
            "y": 20,
            "z": 5,
            "elements": [
                "minecraft:wool@1"
            ]
        },
        {
            "x": 3,
            "y": 20,
            "z": 4,
            "elements": [
                "minecraft:concrete@1"
            ]
        },
        {
            "x": 3,
            "y": 20,
            "z": 3,
            "elements": [
                "minecraft:concrete@1"
            ]
        },
        {
            "x": 3,
            "y": 20,
            "z": 2,
            "elements": [
                "minecraft:wool@1"
            ]
        },
        {
            "x": -2,
            "y": 12,
            "z": 3,
            "elements": [
                "minecraft:concrete@1"
            ]
        },
        {
            "x": 7,
            "y": 7,
            "z": -3,
            "elements": [
                "appliedenergistics2:smooth_sky_stone_block@0"
            ]
        },
        {
            "x": -5,
            "y": 18,
            "z": 4,
            "elements": [
                "minecraft:concrete@1"
            ]
        },
        {
            "x": -5,
            "y": 18,
            "z": 5,
            "elements": [
                "minecraft:wool@1"
            ]
        },
        {
            "x": -5,
            "y": 18,
            "z": 2,
            "elements": [
                "minecraft:wool@1"
            ]
        },
        {
            "x": -5,
            "y": 18,
            "z": 3,
            "elements": [
                "minecraft:concrete@1"
            ]
        },
        {
            "x": 7,
            "y": 7,
            "z": -4,
            "elements": [
                "minecraft:wool@5"
            ]
        },
        {
            "x": -1,
            "y": 2,
            "z": 8,
            "elements": [
                "minecraft:wool@5"
            ]
        },
        {
            "x": -2,
            "y": 9,
            "z": 13,
            "elements": [
                "minecraft:wool@5"
            ]
        },
        {
            "x": 7,
            "y": 7,
            "z": 9,
            "elements": [
                "minecraft:wool@5"
            ]
        },
        {
            "x": 7,
            "y": 7,
            "z": 10,
            "elements": [
                "minecraft:wool@5"
            ]
        },
        {
            "x": 6,
            "y": 5,
            "z": 9,
            "elements": [
                "minecraft:wool@5"
            ]
        },
        {
            "x": -1,
            "y": 11,
            "z": 13,
            "elements": [
                "appliedenergistics2:smooth_sky_stone_block@0"
            ]
        },
        {
            "x": -1,
            "y": 2,
            "z": -2,
            "elements": [
                "minecraft:wool@5"
            ]
        },
        {
            "x": 0,
            "y": 1,
            "z": 7,
            "elements": [
                "minecraft:wool@5"
            ]
        },
        {
            "x": -2,
            "y": 9,
            "z": -7,
            "elements": [
                "minecraft:wool@5"
            ]
        },
        {
            "x": 0,
            "y": 1,
            "z": -1,
            "elements": [
                "minecraft:wool@5"
            ]
        },
        {
            "x": 6,
            "y": 5,
            "z": -3,
            "elements": [
                "appliedenergistics2:smooth_sky_stone_block@0"
            ]
        },
        {
            "x": 7,
            "y": 6,
            "z": -4,
            "elements": [
                "appliedenergistics2:smooth_sky_stone_block@0"
            ]
        },
        {
            "x": 7,
            "y": 6,
            "z": -3,
            "elements": [
                "appliedenergistics2:smooth_sky_stone_block@0"
            ]
        },
        {
            "x": -5,
            "y": 4,
            "z": 8,
            "elements": [
                "minecraft:wool@5"
            ]
        },
        {
            "x": -5,
            "y": 4,
            "z": 9,
            "elements": [
                "minecraft:wool@5"
            ]
        },
        {
            "x": 8,
            "y": 7,
            "z": 8,
            "elements": [
                "minecraft:wool@5"
            ]
        },
        {
            "x": -6,
            "y": 3,
            "z": 0,
            "elements": [
                "minecraft:wool@5"
            ]
        },
        {
            "x": 1,
            "y": 5,
            "z": 11,
            "elements": [
                "appliedenergistics2:smooth_sky_stone_block@0"
            ]
        },
        {
            "x": -6,
            "y": 3,
            "z": 1,
            "elements": [
                "appliedenergistics2:smooth_sky_stone_block@0"
            ]
        },
        {
            "x": 8,
            "y": 7,
            "z": -2,
            "elements": [
                "appliedenergistics2:smooth_sky_stone_block@0"
            ]
        },
        {
            "x": -6,
            "y": 3,
            "z": 6,
            "elements": [
                "minecraft:wool@5"
            ]
        },
        {
            "x": -3,
            "y": 7,
            "z": -6,
            "elements": [
                "minecraft:wool@5"
            ]
        },
        {
            "x": -6,
            "y": 3,
            "z": 4,
            "elements": [
                "minecraft:wool@5"
            ]
        },
        {
            "x": -3,
            "y": 7,
            "z": -7,
            "elements": [
                "minecraft:wool@5"
            ]
        },
        {
            "x": 0,
            "y": 4,
            "z": -4,
            "elements": [
                "minecraft:wool@5"
            ]
        },
        {
            "x": -6,
            "y": 3,
            "z": 5,
            "elements": [
                "minecraft:wool@5"
            ]
        },
        {
            "x": 2,
            "y": 6,
            "z": 12,
            "elements": [
                "minecraft:wool@5"
            ]
        },
        {
            "x": -6,
            "y": 3,
            "z": 2,
            "elements": [
                "appliedenergistics2:smooth_sky_stone_block@0"
            ]
        },
        {
            "x": -6,
            "y": 3,
            "z": 3,
            "elements": [
                "minecraft:wool@5"
            ]
        },
        {
            "x": 3,
            "y": 21,
            "z": 3,
            "elements": [
                "minecraft:concrete@1"
            ]
        },
        {
            "x": 1,
            "y": 5,
            "z": -5,
            "elements": [
                "minecraft:wool@5"
            ]
        },
        {
            "x": -4,
            "y": 19,
            "z": 6,
            "elements": [
                "minecraft:wool@1"
            ]
        },
        {
            "x": -4,
            "y": 19,
            "z": 5,
            "elements": [
                "minecraft:concrete@1"
            ]
        },
        {
            "x": 2,
            "y": 6,
            "z": -6,
            "elements": [
                "minecraft:wool@5"
            ]
        },
        {
            "x": -4,
            "y": 19,
            "z": 4,
            "elements": [
                "minecraft:concrete@1"
            ]
        },
        {
            "x": -4,
            "y": 19,
            "z": 3,
            "elements": [
                "minecraft:concrete@1"
            ]
        },
        {
            "x": -4,
            "y": 19,
            "z": 2,
            "elements": [
                "minecraft:concrete@1"
            ]
        },
        {
            "x": -4,
            "y": 19,
            "z": 1,
            "elements": [
                "minecraft:wool@1"
            ]
        },
        {
            "x": -3,
            "y": 7,
            "z": 13,
            "elements": [
                "minecraft:wool@5"
            ]
        },
        {
            "x": -3,
            "y": 7,
            "z": 12,
            "elements": [
                "minecraft:wool@5"
            ]
        },
        {
            "x": 3,
            "y": 8,
            "z": -7,
            "elements": [
                "minecraft:wool@5"
            ]
        },
        {
            "x": -4,
            "y": 5,
            "z": 10,
            "elements": [
                "appliedenergistics2:smooth_sky_stone_block@0"
            ]
        },
        {
            "x": 3,
            "y": 8,
            "z": -6,
            "elements": [
                "minecraft:wool@5"
            ]
        },
        {
            "x": -4,
            "y": 5,
            "z": 11,
            "elements": [
                "appliedenergistics2:smooth_sky_stone_block@0"
            ]
        },
        {
            "x": 7,
            "y": 6,
            "z": 10,
            "elements": [
                "minecraft:wool@5"
            ]
        },
        {
            "x": 3,
            "y": 8,
            "z": 13,
            "elements": [
                "minecraft:wool@5"
            ]
        },
        {
            "x": 3,
            "y": 8,
            "z": 12,
            "elements": [
                "minecraft:wool@5"
            ]
        },
        {
            "x": 9,
            "y": 9,
            "z": -1,
            "elements": [
                "appliedenergistics2:smooth_sky_stone_block@0"
            ]
        },
        {
            "x": 2,
            "y": 19,
            "z": 1,
            "elements": [
                "minecraft:concrete@1"
            ]
        },
        {
            "x": -4,
            "y": 5,
            "z": -4,
            "elements": [
                "minecraft:wool@5"
            ]
        },
        {
            "x": 2,
            "y": 19,
            "z": 6,
            "elements": [
                "minecraft:concrete@1"
            ]
        },
        {
            "x": -4,
            "y": 5,
            "z": -5,
            "elements": [
                "minecraft:wool@5"
            ]
        },
        {
            "x": 7,
            "y": 6,
            "z": 9,
            "elements": [
                "minecraft:wool@5"
            ]
        },
        {
            "x": 0,
            "y": 3,
            "z": -3,
            "elements": [
                "minecraft:wool@5"
            ]
        },
        {
            "x": 7,
            "y": 5,
            "z": 7,
            "elements": [
                "minecraft:wool@5"
            ]
        },
        {
            "x": 7,
            "y": 5,
            "z": 8,
            "elements": [
                "minecraft:wool@5"
            ]
        },
        {
            "x": 1,
            "y": 4,
            "z": 10,
            "elements": [
                "appliedenergistics2:smooth_sky_stone_block@0"
            ]
        },
        {
            "x": 7,
            "y": 5,
            "z": -1,
            "elements": [
                "minecraft:wool@5"
            ]
        },
        {
            "x": 0,
            "y": 16,
            "z": 7,
            "elements": [
                "minecraft:concrete@1"
            ]
        },
        {
            "x": 0,
            "y": 3,
            "z": 9,
            "elements": [
                "minecraft:wool@5"
            ]
        },
        {
            "x": -5,
            "y": 5,
            "z": -4,
            "elements": [
                "minecraft:wool@5"
            ]
        },
        {
            "x": 9,
            "y": 9,
            "z": 7,
            "elements": [
                "appliedenergistics2:smooth_sky_stone_block@0"
            ]
        },
        {
            "x": 7,
            "y": 5,
            "z": -2,
            "elements": [
                "minecraft:wool@5"
            ]
        },
        {
            "x": 0,
            "y": 16,
            "z": 2,
            "elements": [
                "minecraft:quartz_block@0"
            ]
        },
        {
            "x": -4,
            "y": 18,
