{   "registryname": "compressed_speeder",
    "localizedname": "压缩加速机",
    "color": "ffffff",
    "failure-action": "still",
    "parts": [
        {
            "x": 5,
            "y": -1,
            "z": 6,
            "elements": [
                "mekanism:slickplasticblock@2"
            ]
        },
        {
            "x": 5,
            "y": -1,
            "z": 7,
            "elements": [
                "mekanism:slickplasticblock@2"
            ]
        },
        {
            "x": 5,
            "y": -1,
            "z": 8,
            "elements": [
                "mekanism:slickplasticblock@2"
            ]
        },
        {
            "x": 5,
            "y": -1,
            "z": -2,
            "elements": [
                "mekanism:slickplasticblock@2"
            ]
        },
        {
            "x": 5,
            "y": -1,
            "z": -1,
            "elements": [
                "mekanism:slickplasticblock@2"
            ]
        },
        {
            "x": 5,
            "y": -1,
            "z": 0,
            "elements": [
                "mekanism:slickplasticblock@2"
            ]
        },
        {
            "x": 3,
            "y": -1,
            "z": 5,
            "elements": [
                "mekanism:slickplasticblock@2"
            ]
        },
        {
            "x": 3,
            "y": -1,
            "z": 6,
            "elements": [
                "mekanism:slickplasticblock@2"
            ]
        },
        {
            "x": 3,
            "y": -1,
            "z": 4,
            "elements": [
                "mekanism:slickplasticblock@2"
            ]
        },
        {
            "x": 3,
            "y": -1,
            "z": 1,
            "elements": [
                "mekanism:slickplasticblock@2"
            ]
        },
        {
            "x": 3,
            "y": -1,
            "z": 2,
            "elements": [
                "mekanism:slickplasticblock@2"
            ]
        },
        {
            "x": 3,
            "y": -1,
            "z": 0,
            "elements": [
                "mekanism:slickplasticblock@2"
            ]
        },
        {
            "x": -5,
            "y": 12,
            "z": 3,
            "elements": [
                "mekanism:glowplasticblock@11"
            ]
        },
        {
            "x": -5,
            "y": 12,
            "z": 2,
            "elements": [
                "mekanism:glowplasticblock@11"
            ]
        },
        {
            "x": -5,
            "y": 12,
            "z": 1,
            "elements": [
                "mekanism:glowplasticblock@11"
            ]
        },
        {
            "x": -5,
            "y": 12,
            "z": 0,
            "elements": [
                "mekanism:glowplasticblock@11"
            ]
        },
        {
            "x": -5,
            "y": 12,
            "z": 6,
            "elements": [
                "mekanism:glowplasticblock@11"
            ]
        },
        {
            "x": -5,
            "y": 12,
            "z": 5,
            "elements": [
                "mekanism:glowplasticblock@11"
            ]
        },
        {
            "x": -5,
            "y": 12,
            "z": 4,
            "elements": [
                "mekanism:glowplasticblock@11"
            ]
        },
        {
            "x": -5,
            "y": 12,
            "z": -1,
            "elements": [
                "mekanism:glowplasticblock@11"
            ]
        },
        {
            "x": -5,
            "y": 12,
            "z": -2,
            "elements": [
                "mekanism:glowplasticblock@11"
            ]
        },
        {
            "x": 2,
            "y": -1,
            "z": 5,
            "elements": [
                "mekanism:slickplasticblock@2"
            ]
        },
        {
            "x": 6,
            "y": -1,
            "z": 8,
            "elements": [
                "mekanism:slickplasticblock@2"
            ]
        },
        {
            "x": 2,
            "y": -1,
            "z": 1,
            "elements": [
                "mekanism:slickplasticblock@2"
            ]
        },
        {
            "x": 6,
            "y": -1,
            "z": 7,
            "elements": [
                "mekanism:slickplasticblock@2"
            ]
        },
        {
            "x": 2,
            "y": -1,
            "z": 0,
            "elements": [
                "mekanism:slickplasticblock@2"
            ]
        },
        {
            "x": 2,
            "y": -1,
            "z": 6,
            "elements": [
                "mekanism:slickplasticblock@2"
            ]
        },
        {
            "x": 5,
            "y": 3,
            "z": -2,
            "elements": [
                "mekanism:reinforcedplasticblock@14"
            ]
        },
        {
            "x": 6,
            "y": -1,
            "z": -1,
            "elements": [
                "mekanism:slickplasticblock@2"
            ]
        },
        {
            "x": 5,
            "y": 3,
            "z": -3,
            "elements": [
                "mekanism:reinforcedplasticblock@14"
            ]
        },
        {
            "x": 6,
            "y": -1,
            "z": -2,
            "elements": [
                "mekanism:slickplasticblock@2"
            ]
        },
        {
            "x": 3,
            "y": 1,
            "z": 1,
            "elements": [
                "mekanism:reinforcedplasticblock@14"
            ]
        },
        {
            "x": 4,
            "y": 2,
            "z": 5,
            "elements": [
                "mekanism:reinforcedplasticblock@14"
            ]
        },
        {
            "x": 3,
            "y": 1,
            "z": 2,
            "elements": [
                "mekanism:reinforcedplasticblock@14"
            ]
        },
        {
            "x": 4,
            "y": 2,
            "z": 6,
            "elements": [
                "mekanism:reinforcedplasticblock@14"
            ]
        },
        {
            "x": 3,
            "y": 1,
            "z": -1,
            "elements": [
                "mekanism:reinforcedplasticblock@14"
            ]
        },
        {
            "x": 4,
            "y": 2,
            "z": 7,
            "elements": [
                "mekanism:reinforcedplasticblock@14"
            ]
        },
        {
            "x": 3,
            "y": 1,
            "z": 0,
            "elements": [
                "mekanism:reinforcedplasticblock@14"
            ]
        },
        {
            "x": 4,
            "y": 2,
            "z": 1,
            "elements": [
                "mekanism:glowplasticblock@0"
            ]
        },
        {
            "x": 4,
            "y": 2,
            "z": 2,
            "elements": [
                "mekanism:glowplasticblock@0"
            ]
        },
        {
            "x": 4,
            "y": 2,
            "z": 3,
            "elements": [
                "mekanism:glowplasticblock@0"
            ]
        },
        {
            "x": 4,
            "y": 2,
            "z": 4,
            "elements": [
                "mekanism:reinforcedplasticblock@14"
            ]
        },
        {
            "x": 4,
            "y": 2,
            "z": -3,
            "elements": [
                "mekanism:reinforcedplasticblock@14"
            ]
        },
        {
            "x": 4,
            "y": 2,
            "z": -2,
            "elements": [
                "mekanism:reinforcedplasticblock@14"
            ]
        },
        {
            "x": 4,
            "y": 2,
            "z": -1,
            "elements": [
                "mekanism:reinforcedplasticblock@14"
            ]
        },
        {
            "x": 4,
            "y": 2,
            "z": 0,
            "elements": [
                "mekanism:reinforcedplasticblock@14"
            ]
        },
        {
            "x": 5,
            "y": 3,
            "z": 0,
            "elements": [
                "mekanism:reinforcedplasticblock@14"
            ]
        },
        {
            "x": 5,
            "y": 3,
            "z": -1,
            "elements": [
                "mekanism:reinforcedplasticblock@14"
            ]
        },
        {
            "x": 5,
            "y": 3,
            "z": 2,
            "elements": [
                "mekanism:reinforcedplasticblock@14"
            ]
        },
        {
            "x": 5,
            "y": 3,
            "z": 1,
            "elements": [
                "mekanism:reinforcedplasticblock@14"
            ]
        },
        {
            "x": -6,
            "y": 10,
            "z": 0,
            "elements": [
                "mekanism:reinforcedplasticblock@14"
            ]
        },
        {
            "x": 5,
            "y": 3,
            "z": 4,
            "elements": [
                "mekanism:reinforcedplasticblock@14"
            ]
        },
        {
            "x": -6,
            "y": 10,
            "z": -1,
            "elements": [
                "mekanism:reinforcedplasticblock@14"
            ]
        },
        {
            "x": 5,
            "y": 3,
            "z": 3,
            "elements": [
                "mekanism:reinforcedplasticblock@14"
            ]
        },
        {
            "x": -6,
            "y": 10,
            "z": 2,
            "elements": [
                "mekanism:reinforcedplasticblock@14"
            ]
        },
        {
            "x": 5,
            "y": 3,
            "z": 6,
            "elements": [
                "mekanism:reinforcedplasticblock@14"
            ]
        },
        {
            "x": -6,
            "y": 10,
            "z": 1,
            "elements": [
                "mekanism:reinforcedplasticblock@14"
            ]
        },
        {
            "x": 5,
            "y": 3,
            "z": 5,
            "elements": [
                "mekanism:reinforcedplasticblock@14"
            ]
        },
        {
            "x": 5,
            "y": 3,
            "z": 7,
            "elements": [
                "mekanism:reinforcedplasticblock@14"
            ]
        },
        {
            "x": 5,
            "y": 4,
            "z": 3,
            "elements": [
                "mekanism:glowplasticblock@11"
            ]
        },
        {
            "x": 5,
            "y": 4,
            "z": 2,
            "elements": [
                "mekanism:glowplasticblock@12"
            ]
        },
        {
            "x": 3,
            "y": 1,
            "z": 5,
            "elements": [
                "mekanism:reinforcedplasticblock@14"
            ]
        },
        {
            "x": 5,
            "y": 4,
            "z": -2,
            "elements": [
                "mekanism:reinforcedplasticblock@14"
            ]
        },
        {
            "x": -2,
            "y": 14,
            "z": 0,
            "elements": [
                "mekanism:reinforcedplasticblock@14"
            ]
        },
        {
            "x": 5,
            "y": 4,
            "z": 1,
            "elements": [
                "mekanism:glowplasticblock@11"
            ]
        },
        {
            "x": -2,
            "y": 14,
            "z": 1,
            "elements": [
                "mekanism:reinforcedplasticblock@14"
            ]
        },
        {
            "x": 3,
            "y": 1,
            "z": 3,
            "elements": [
                "mekanism:reinforcedplasticblock@14"
            ]
        },
        {
            "x": -2,
            "y": 14,
            "z": 2,
            "elements": [
                "mekanism:reinforcedplasticblock@14"
            ]
        },
        {
            "x": 3,
            "y": 1,
            "z": 4,
            "elements": [
                "mekanism:reinforcedplasticblock@14"
            ]
        },
        {
            "x": -2,
            "y": 14,
            "z": 3,
            "elements": [
                "mekanism:reinforcedplasticblock@14"
            ]
        },
        {
            "x": -2,
            "y": 14,
            "z": 4,
            "elements": [
                "mekanism:reinforcedplasticblock@14"
            ]
        },
        {
            "x": 5,
            "y": 4,
            "z": -3,
            "elements": [
                "mekanism:reinforcedplasticblock@14"
            ]
        },
        {
            "x": 4,
            "y": 3,
            "z": -3,
            "elements": [
                "minecraft:planks@0"
            ]
        },
        {
            "x": 4,
            "y": 3,
            "z": -4,
            "elements": [
                "mekanism:glowplasticblock@11"
            ]
        },
        {
            "x": 4,
            "y": 3,
            "z": 7,
            "elements": [
                "minecraft:planks@0"
            ]
        },
        {
            "x": 4,
            "y": 3,
            "z": 8,
            "elements": [
                "mekanism:glowplasticblock@11"
            ]
        },
        {
            "x": -6,
            "y": 10,
            "z": 4,
            "elements": [
                "mekanism:reinforcedplasticblock@14"
            ]
        },
        {
            "x": -6,
            "y": 10,
            "z": 3,
            "elements": [
                "mekanism:reinforcedplasticblock@14"
            ]
        },
        {
            "x": -6,
            "y": 10,
            "z": 5,
            "elements": [
                "mekanism:reinforcedplasticblock@14"
            ]
        },
        {
            "x": -3,
            "y": 12,
            "z": 6,
            "elements": [
                "mekanism:reinforcedplasticblock@14"
            ]
        },
        {
            "x": -3,
            "y": 12,
            "z": 7,
            "elements": [
                "mekanism:reinforcedplasticblock@14"
            ]
        },
        {
            "x": -7,
            "y": 8,
            "z": 0,
            "elements": [
                "mekanism:reinforcedplasticblock@14"
            ]
        },
        {
            "x": -7,
            "y": 8,
            "z": 1,
            "elements": [
                "mekanism:reinforcedplasticblock@14"
            ]
        },
        {
            "x": -7,
            "y": 8,
            "z": 2,
            "elements": [
                "mekanism:reinforcedplasticblock@14"
            ]
        },
        {
            "x": -7,
            "y": 8,
            "z": 3,
            "elements": [
                "mekanism:reinforcedplasticblock@14"
            ]
        },
        {
            "x": -7,
            "y": 8,
            "z": 4,
            "elements": [
                "mekanism:reinforcedplasticblock@14"
            ]
        },
        {
            "x": 5,
            "y": 5,
            "z": 7,
            "elements": [
                "mekanism:reinforcedplasticblock@14"
            ]
        },
        {
            "x": 5,
            "y": 5,
            "z": -3,
            "elements": [
                "mekanism:reinforcedplasticblock@14"
            ]
        },
        {
            "x": -2,
            "y": 13,
            "z": -2,
            "elements": [
                "mekanism:reinforcedplasticblock@14"
            ]
        },
        {
            "x": -2,
            "y": 13,
            "z": -1,
            "elements": [
                "mekanism:reinforcedplasticblock@14"
            ]
        },
        {
            "x": 6,
            "y": 6,
            "z": 5,
            "elements": [
                "mekanism:reinforcedplasticblock@14"
            ]
        },
        {
            "x": -2,
            "y": 13,
            "z": 5,
            "elements": [
                "mekanism:reinforcedplasticblock@14"
            ]
        },
        {
            "x": 6,
            "y": 6,
            "z": 6,
            "elements": [
                "mekanism:reinforcedplasticblock@14"
            ]
        },
        {
            "x": 6,
            "y": 6,
            "z": 3,
            "elements": [
                "appliedenergistics2:quartz_block@0"
            ]
        },
        {
            "x": -2,
            "y": 13,
            "z": 6,
            "elements": [
                "mekanism:reinforcedplasticblock@14"
            ]
        },
        {
            "x": 6,
            "y": 6,
            "z": 4,
            "elements": [
                "mekanism:glowplasticblock@12"
            ]
        },
        {
            "x": 6,
            "y": 6,
            "z": 1,
            "elements": [
                "appliedenergistics2:quartz_block@0"
            ]
        },
        {
            "x": 6,
            "y": 6,
            "z": 2,
            "elements": [
                "appliedenergistics2:quartz_block@0"
            ]
        },
        {
            "x": 6,
            "y": 6,
            "z": -1,
            "elements": [
                "mekanism:reinforcedplasticblock@14"
            ]
        },
        {
            "x": 6,
            "y": 6,
            "z": 0,
            "elements": [
                "mekanism:glowplasticblock@12"
            ]
        },
        {
            "x": 6,
            "y": 6,
            "z": -2,
            "elements": [
                "mekanism:reinforcedplasticblock@14"
            ]
        },
        {
            "x": -3,
            "y": 12,
            "z": -2,
            "elements": [
                "mekanism:reinforcedplasticblock@14"
            ]
        },
        {
            "x": -3,
            "y": 12,
            "z": -4,
            "elements": [
                "mekanism:slickplasticblock@2"
            ]
        },
        {
            "x": -3,
            "y": 12,
            "z": -3,
            "elements": [
                "mekanism:reinforcedplasticblock@14"
            ]
        },
        {
            "x": 6,
            "y": 7,
            "z": 0,
            "elements": [
                "mekanism:glowplasticblock@12"
            ]
        },
        {
            "x": 6,
            "y": 7,
            "z": 1,
            "elements": [
                "appliedenergistics2:quartz_block@0"
            ]
        },
        {
            "x": 6,
            "y": 7,
            "z": -2,
            "elements": [
                "mekanism:glowplasticblock@11"
            ]
        },
        {
            "x": 6,
            "y": 7,
            "z": -1,
            "elements": [
                "mekanism:glowplasticblock@11"
            ]
        },
        {
            "x": -3,
            "y": 11,
            "z": 8,
            "elements": [
                "mekanism:reinforcedplasticblock@14"
            ]
        },
        {
            "x": 5,
            "y": 4,
            "z": 7,
            "elements": [
                "mekanism:reinforcedplasticblock@14"
            ]
        },
        {
            "x": 5,
            "y": 4,
            "z": 6,
            "elements": [
                "mekanism:reinforcedplasticblock@14"
            ]
        },
        {
            "x": -7,
            "y": 9,
            "z": 1,
            "elements": [
                "mekanism:reinforcedplasticblock@14"
            ]
        },
        {
            "x": -7,
            "y": 9,
            "z": 2,
            "elements": [
                "mekanism:reinforcedplasticblock@14"
            ]
        },
        {
            "x": -7,
            "y": 9,
            "z": 3,
            "elements": [
                "mekanism:reinforcedplasticblock@14"
            ]
        },
        {
            "x": -7,
            "y": 9,
            "z": 4,
            "elements": [
                "mekanism:reinforcedplasticblock@14"
            ]
        },
        {
            "x": -7,
            "y": 9,
            "z": 0,
            "elements": [
                "mekanism:reinforcedplasticblock@14"
            ]
        },
        {
            "x": -3,
            "y": 10,
            "z": -4,
            "elements": [
                "mekanism:glowplasticblock@15"
            ]
        },
        {
            "x": -2,
            "y": 11,
            "z": 8,
            "elements": [
                "mekanism:reinforcedplasticblock@14"
            ]
        },
        {
            "x": -4,
            "y": 9,
            "z": -4,
            "elements": [
                "mekanism:reinforcedplasticblock@14"
            ]
        },
        {
            "x": 0,
            "y": 14,
            "z": 0,
            "elements": [
                "mekanism:glowplasticblock@11"
            ]
        },
        {
            "x": -3,
            "y": 10,
            "z": 8,
            "elements": [
                "mekanism:glowplasticblock@11"
            ]
        },
        {
            "x": 0,
            "y": 14,
            "z": 4,
            "elements": [
                "mekanism:glowplasticblock@11"
            ]
        },
        {
            "x": 0,
            "y": 14,
            "z": 3,
            "elements": [
                "mekanism:glowplasticblock@11"
            ]
        },
        {
            "x": 0,
            "y": 14,
            "z": 2,
            "elements": [
                "mekanism:glowplasticblock@11"
            ]
        },
        {
            "x": 0,
            "y": 14,
            "z": 1,
            "elements": [
                "mekanism:glowplasticblock@11"
            ]
        },
        {
            "x": -4,
            "y": 9,
            "z": 8,
            "elements": [
                "mekanism:reinforcedplasticblock@14"
            ]
        },
        {
            "x": 0,
            "y": 0,
            "z": 4,
            "elements": [
                "mekanism:glowplasticblock@11"
            ]
        },
        {
            "x": 0,
            "y": 0,
            "z": 3,
            "elements": [
                "mekanism:glowplasticblock@11"
            ]
        },
        {
            "x": 1,
            "y": 2,
            "z": 7,
            "elements": [
                "mekanism:reinforcedplasticblock@14"
            ]
        },
        {
            "x": 1,
            "y": 2,
            "z": 6,
            "elements": [
                "mekanism:glowplasticblock@0"
            ]
        },
        {
            "x": 0,
            "y": 0,
            "z": 2,
            "elements": [
                "mekanism:glowplasticblock@11"
            ]
        },
        {
            "x": 1,
            "y": 2,
            "z": 5,
            "elements": [
                "appliedenergistics2:quartz_block@0"
            ]
        },
        {
            "x": 0,
            "y": 0,
            "z": 1,
            "elements": [
                "mekanism:glowplasticblock@11"
            ]
        },
        {
            "x": 1,
            "y": 2,
            "z": 4,
            "elements": [
                "appliedenergistics2:quartz_block@0"
            ]
        },
        {
            "x": 1,
            "y": 2,
            "z": 3,
            "elements": [
                "mekanism:glowplasticblock@0"
            ]
        },
        {
            "x": 1,
            "y": 2,
            "z": 2,
            "elements": [
                "appliedenergistics2:quartz_block@0"
            ]
        },
        {
            "x": 1,
            "y": 2,
            "z": 1,
            "elements": [
                "appliedenergistics2:quartz_block@0"
            ]
        },
        {
            "x": 1,
            "y": 2,
            "z": 0,
            "elements": [
                "appliedenergistics2:quartz_block@0"
            ]
        },
        {
            "x": 1,
            "y": 2,
            "z": -1,
            "elements": [
                "appliedenergistics2:quartz_block@0"
            ]
        },
        {
            "x": 1,
            "y": 2,
            "z": -2,
            "elements": [
                "mekanism:glowplasticblock@0"
            ]
        },
        {
            "x": 1,
            "y": 2,
            "z": -3,
            "elements": [
                "mekanism:reinforcedplasticblock@14"
            ]
        },
        {
            "x": -4,
            "y": 8,
            "z": 8,
            "elements": [
                "mekanism:reinforcedplasticblock@14"
            ]
        },
        {
            "x": 0,
            "y": 13,
            "z": 6,
            "elements": [
                "mekanism:glowplasticblock@11"
            ]
        },
        {
            "x": 0,
            "y": 13,
            "z": 5,
            "elements": [
                "mekanism:glowplasticblock@11"
            ]
        },
        {
            "x": -2,
            "y": 11,
            "z": -4,
            "elements": [
                "mekanism:slickplasticblock@2"
            ]
        },
        {
            "x": 0,
            "y": 13,
            "z": -1,
            "elements": [
                "mekanism:glowplasticblock@11"
            ]
        },
        {
            "x": 0,
            "y": 13,
            "z": -2,
            "elements": [
                "mekanism:glowplasticblock@11"
            ]
        },
        {
            "x": -3,
            "y": 9,
            "z": 8,
            "elements": [
                "mekanism:reinforcedplasticblock@14"
            ]
        },
        {
            "x": -3,
            "y": 11,
            "z": -4,
            "elements": [
                "mekanism:reinforcedplasticblock@14"
            ]
        },
        {
            "x": -3,
            "y": 9,
            "z": -4,
            "elements": [
                "mekanism:glowplasticblock@15"
            ]
        },
        {
            "x": 7,
            "y": 8,
            "z": 0,
            "elements": [
                "mekanism:reinforcedplasticblock@14"
            ]
        },
        {
            "x": 7,
            "y": 8,
            "z": 1,
            "elements": [
                "mekanism:reinforcedplasticblock@14"
            ]
        },
        {
            "x": -1,
            "y": 12,
            "z": 7,
            "elements": [
                "mekanism:reinforcedplasticblock@14"
            ]
        },
        {
            "x": 7,
            "y": 8,
            "z": 2,
            "elements": [
                "mekanism:reinforcedplasticblock@14"
            ]
        },
        {
            "x": 7,
            "y": 8,
            "z": 3,
            "elements": [
                "mekanism:reinforcedplasticblock@14"
            ]
        },
        {
            "x": 7,
            "y": 8,
            "z": 4,
            "elements": [
                "mekanism:reinforcedplasticblock@14"
            ]
        },
        {
            "x": -2,
            "y": -1,
            "z": 6,
            "elements": [
                "mekanism:slickplasticblock@2"
            ]
        },
        {
            "x": -2,
            "y": -1,
            "z": 5,
            "elements": [
                "mekanism:slickplasticblock@2"
            ]
        },
        {
            "x": -2,
            "y": -1,
            "z": 0,
            "elements": [
                "mekanism:slickplasticblock@2"
            ]
        },
        {
            "x": -2,
            "y": -1,
            "z": 1,
            "elements": [
                "mekanism:slickplasticblock@2"
            ]
        },
        {
            "x": -1,
            "y": 12,
            "z": -3,
            "elements": [
                "mekanism:reinforcedplasticblock@14"
            ]
        },
        {
            "x": -4,
            "y": 7,
            "z": 7,
            "elements": [
                "mekanism:glowplasticblock@12"
            ]
        },
        {
            "x": -4,
            "y": 7,
            "z": 8,
            "elements": [
                "mekanism:glowplasticblock@11"
            ]
        },
        {
            "x": -4,
            "y": 7,
            "z": -3,
            "elements": [
                "mekanism:glowplasticblock@12"
            ]
        },
        {
            "x": -1,
            "y": 14,
            "z": 3,
            "elements": [
                "mekanism:reinforcedplasticblock@14"
            ]
        },
        {
            "x": -4,
            "y": 7,
            "z": -4,
            "elements": [
                "mekanism:glowplasticblock@11"
            ]
        },
        {
            "x": -1,
            "y": 11,
            "z": -4,
            "elements": [
                "mekanism:reinforcedplasticblock@14"
            ]
        },
        {
            "x": -1,
            "y": 14,
            "z": 2,
            "elements": [
                "mekanism:reinforcedplasticblock@14"
            ]
        },
        {
            "x": -5,
            "y": 6,
            "z": -3,
            "elements": [
                "mekanism:reinforcedplasticblock@14"
            ]
        },
        {
            "x": -1,
            "y": 14,
            "z": 4,
            "elements": [
                "mekanism:reinforcedplasticblock@14"
            ]
        },
        {
            "x": -5,
            "y": 6,
            "z": 5,
            "elements": [
                "mekanism:glowplasticblock@11"
            ]
        },
        {
            "x": -5,
            "y": 6,
            "z": -1,
            "elements": [
                "mekanism:glowplasticblock@11"
            ]
        },
        {
            "x": -5,
            "y": 6,
            "z": 7,
            "elements": [
                "mekanism:reinforcedplasticblock@14"
            ]
        },
        {
            "x": -1,
            "y": 11,
            "z": 8,
            "elements": [
                "mekanism:reinforcedplasticblock@14"
            ]
        },
        {
            "x": 1,
            "y": 3,
            "z": 8,
            "elements": [
                "mekanism:reinforcedplasticblock@14"
            ]
        },
        {
            "x": -2,
            "y": 0,
            "z": 3,
            "elements": [
                "mekanism:reinforcedplasticblock@14"
            ]
        },
        {
            "x": -2,
            "y": 0,
            "z": 4,
            "elements": [
                "mekanism:reinforcedplasticblock@14"
            ]
        },
        {
            "x": -2,
            "y": 0,
            "z": 1,
            "elements": [
                "mekanism:reinforcedplasticblock@14"
            ]
        },
        {
            "x": 1,
            "y": 3,
            "z": -4,
            "elements": [
                "mekanism:reinforcedplasticblock@14"
            ]
        },
        {
            "x": -2,
            "y": 0,
            "z": 2,
            "elements": [
                "mekanism:reinforcedplasticblock@14"
            ]
        },
        {
            "x": 2,
            "y": 5,
            "z": -4,
            "elements": [
                "mekanism:glowplasticblock@11"
            ]
        },
        {
            "x": -2,
            "y": 0,
            "z": 0,
            "elements": [
                "mekanism:reinforcedplasticblock@14"
            ]
        },
        {
            "x": -1,
            "y": 14,
            "z": 1,
            "elements": [
                "mekanism:reinforcedplasticblock@14"
            ]
        },
        {
            "x": -1,
            "y": 14,
            "z": 0,
            "elements": [
                "mekanism:reinforcedplasticblock@14"
            ]
        },
        {
            "x": -5,
            "y": 5,
            "z": 7,
            "elements": [
                "mekanism:reinforcedplasticblock@14"
            ]
        },
        {
            "x": 2,
            "y": 5,
            "z": 8,
            "elements": [
                "mekanism:glowplasticblock@11"
            ]
        },
        {
            "x": -2,
            "y": 12,
            "z": 7,
            "elements": [
                "mekanism:reinforcedplasticblock@14"
            ]
        },
        {
            "x": -2,
            "y": 12,
            "z": -3,
            "elements": [
                "mekanism:reinforcedplasticblock@14"
            ]
        },
        {
            "x": -4,
            "y": 8,
            "z": -4,
            "elements": [
                "mekanism:reinforcedplasticblock@14"
            ]
        },
        {
            "x": 7,
            "y": 7,
            "z": 0,
            "elements": [
                "mekanism:glowplasticblock@11"
            ]
        },
        {
            "x": 7,
            "y": 7,
            "z": 1,
            "elements": [
                "mekanism:glowplasticblock@11"
            ]
        },
        {
            "x": 7,
            "y": 7,
            "z": 2,
            "elements": [
                "mekanism:glowplasticblock@11"
            ]
        },
        {
            "x": 7,
            "y": 7,
            "z": 3,
            "elements": [
                "mekanism:glowplasticblock@11"
            ]
        },
        {
            "x": 7,
            "y": 7,
            "z": 4,
            "elements": [
                "mekanism:glowplasticblock@11"
            ]
        },
        {
            "x": 6,
            "y": 5,
            "z": 6,
            "elements": [
                "mekanism:reinforcedplasticblock@14"
            ]
        },
        {
            "x": 6,
            "y": 5,
            "z": 5,
            "elements": [
                "mekanism:reinforcedplasticblock@14"
            ]
        },
        {
            "x": -1,
            "y": 2,
            "z": 7,
            "elements": [
                "mekanism:reinforcedplasticblock@14"
            ]
        },
        {
            "x": -1,
            "y": 2,
            "z": 6,
            "elements": [
                "mekanism:glowplasticblock@0"
            ]
        },
        {
            "x": -2,
            "y": 9,
            "z": 8,
            "elements": [
                "mekanism:glowplasticblock@11"
            ]
        },
        {
            "x": -1,
            "y": 2,
            "z": 1,
            "elements": [
                "appliedenergistics2:quartz_block@0"
            ]
        },
        {
            "x": -1,
            "y": 2,
            "z": 0,
            "elements": [
                "appliedenergistics2:quartz_block@0"
            ]
        },
        {
            "x": -1,
            "y": 2,
            "z": -1,
            "elements": [
                "appliedenergistics2:quartz_block@0"
            ]
        },
        {
            "x": -1,
            "y": 2,
            "z": -2,
            "elements": [
                "mekanism:glowplasticblock@0"
            ]
        },
        {
            "x": -1,
            "y": 2,
            "z": 5,
            "elements": [
                "appliedenergistics2:quartz_block@0"
            ]
        },
        {
            "x": -1,
            "y": 2,
            "z": 4,
            "elements": [
                "appliedenergistics2:quartz_block@0"
            ]
        },
        {
            "x": -1,
            "y": 2,
            "z": 3,
            "elements": [
                "appliedenergistics2:quartz_block@0"
            ]
        },
        {
            "x": -1,
            "y": 2,
            "z": 2,
            "elements": [
                "appliedenergistics2:quartz_block@0"
            ]
        },
        {
            "x": -2,
            "y": 9,
            "z": -4,
            "elements": [
                "mekanism:glowplasticblock@12"
            ]
        },
        {
            "x": 0,
            "y": 1,
            "z": 6,
            "elements": [
                "mekanism:glowplasticblock@11"
            ]
        },
        {
            "x": -1,
            "y": 2,
            "z": -3,
            "elements": [
                "mekanism:reinforcedplasticblock@14"
            ]
        },
        {
            "x": 0,
            "y": 1,
            "z": -1,
            "elements": [
                "mekanism:glowplasticblock@11"
            ]
        },
        {
            "x": 6,
            "y": 5,
            "z": -1,
            "elements": [
                "mekanism:reinforcedplasticblock@14"
            ]
        },
        {
            "x": 0,
            "y": 1,
            "z": -2,
            "elements": [
                "mekanism:glowplasticblock@11"
            ]
        },
        {
            "x": 6,
            "y": 5,
            "z": -2,
            "elements": [
                "mekanism:reinforcedplasticblock@14"
            ]
        },
        {
            "x": 6,
            "y": 5,
            "z": 3,
            "elements": [
                "mekanism:glowplasticblock@12"
            ]
        },
        {
            "x": 6,
            "y": 5,
            "z": 2,
            "elements": [
                "mekanism:glowplasticblock@12"
            ]
        },
        {
            "x": 6,
            "y": 5,
            "z": 1,
            "elements": [
                "mekanism:glowplasticblock@12"
            ]
        },
        {
            "x": 0,
            "y": 1,
            "z": 5,
            "elements": [
                "mekanism:glowplasticblock@11"
            ]
        },
        {
            "x": 1,
            "y": 5,
            "z": 8,
            "elements": [
                "mekanism:reinforcedplasticblock@14"
            ]
        },
        {
            "x": 7,
            "y": 6,
            "z": 0,
            "elements": [
                "mekanism:reinforcedplasticblock@14"
            ]
        },
        {
            "x": 7,
            "y": 6,
            "z": 1,
            "elements": [
                "mekanism:reinforcedplasticblock@14"
            ]
        },
        {
            "x": -5,
            "y": 4,
            "z": 6,
            "elements": [
                "mekanism:reinforcedplasticblock@14"
            ]
        },
        {
            "x": -5,
            "y": 4,
            "z": 7,
            "elements": [
                "mekanism:reinforcedplasticblock@14"
            ]
        },
        {
            "x": -5,
            "y": 4,
            "z": 1,
            "elements": [
                "mekanism:glowplasticblock@11"
            ]
        },
        {
            "x": -5,
            "y": 4,
            "z": 2,
            "elements": [
                "mekanism:glowplasticblock@12"
            ]
        },
        {
            "x": -5,
            "y": 4,
            "z": 3,
            "elements": [
                "mekanism:glowplasticblock@11"
            ]
        },
        {
            "x": 2,
            "y": 6,
            "z": 8,
            "elements": [
                "mekanism:reinforcedplasticblock@14"
            ]
        },
        {
            "x": 0,
            "y": 4,
            "z": -4,
            "elements": [
                "mekanism:glowplasticblock@11"
            ]
        },
        {
            "x": 1,
            "y": 5,
            "z": -4,
            "elements": [
                "mekanism:reinforcedplasticblock@14"
            ]
        },
        {
            "x": -3,
            "y": 7,
            "z": -4,
            "elements": [
                "mekanism:glowplasticblock@11"
            ]
        },
        {
            "x": 3,
            "y": 8,
            "z": -4,
            "elements": [
                "mekanism:reinforcedplasticblock@14"
            ]
        },
        {
            "x": 2,
            "y": 6,
            "z": -4,
            "elements": [
                "mekanism:reinforcedplasticblock@14"
            ]
        },
        {
            "x": -3,
            "y": 7,
            "z": 8,
            "elements": [
                "mekanism:glowplasticblock@11"
            ]
        },
        {
            "x": -4,
            "y": 5,
            "z": 8,
            "elements": [
                "mekanism:reinforcedplasticblock@14"
            ]
        },
        {
            "x": -4,
            "y": 5,
            "z": 7,
            "elements": [
                "minecraft:planks@0"
            ]
        },
        {
            "x": 7,
            "y": 6,
            "z": 2,
            "elements": [
                "mekanism:reinforcedplasticblock@14"
            ]
        },
        {
            "x": 7,
            "y": 6,
            "z": 3,
            "elements": [
                "mekanism:reinforcedplasticblock@14"
            ]
        },
        {
            "x": 7,
            "y": 6,
            "z": 4,
            "elements": [
                "mekanism:reinforcedplasticblock@14"
            ]
        },
        {
            "x": -4,
            "y": 5,
            "z": -4,
            "elements": [
                "mekanism:reinforcedplasticblock@14"
            ]
        },
        {
            "x": -4,
            "y": 5,
            "z": -3,
            "elements": [
                "minecraft:planks@0"
            ]
        },
        {
            "x": 3,
            "y": 8,
            "z": 8,
            "elements": [
                "mekanism:reinforcedplasticblock@14"
            ]
        },
        {
            "x": 0,
            "y": 3,
            "z": -4,
            "elements": [
                "mekanism:glowplasticblock@11"
            ]
        },
        {
            "x": 7,
            "y": 5,
            "z": 3,
            "elements": [
                "mekanism:reinforcedplasticblock@14"
            ]
        },
        {
            "x": 7,
            "y": 5,
            "z": 4,
            "elements": [
                "mekanism:reinforcedplasticblock@14"
            ]
        },
        {
            "x": 7,
            "y": 5,
            "z": 0,
            "elements": [
                "mekanism:reinforcedplasticblock@14"
            ]
        },
        {
            "x": 7,
            "y": 5,
            "z": 1,
            "elements": [
                "mekanism:reinforcedplasticblock@14"
            ]
        },
        {
            "x": 7,
            "y": 5,
            "z": 2,
            "elements": [
                "mekanism:reinforcedplasticblock@14"
            ]
        },
        {
            "x": 0,
            "y": 3,
            "z": 8,
            "elements": [
                "mekanism:glowplasticblock@11"
            ]
        },
        {
            "x": -5,
            "y": 5,
            "z": -3,
            "elements": [
                "mekanism:reinforcedplasticblock@14"
            ]
        },
        {
            "x": 6,
            "y": 4,
            "z": 4,
            "elements": [
                "mekanism:reinforcedplasticblock@14"
            ]
        },
        {
            "x": 6,
            "y": 4,
            "z": 3,
            "elements": [
                "mekanism:reinforcedplasticblock@14"
            ]
        },
        {
            "x": 6,
            "y": 4,
            "z": 2,
            "elements": [
                "mekanism:reinforcedplasticblock@14"
            ]
        },
        {
            "x": 6,
            "y": 4,
            "z": 1,
            "elements": [
                "mekanism:reinforcedplasticblock@14"
            ]
        },
        {
            "x": 6,
            "y": 4,
            "z": 0,
            "elements": [
                "mekanism:reinforcedplasticblock@14"
            ]
        },
        {
            "x": 6,
            "y": 4,
            "z": -1,
            "elements": [
                "mekanism:reinforcedplasticblock@14"
            ]
        },
        {
            "x": 6,
            "y": 4,
            "z": 5,
            "elements": [
                "mekanism:reinforcedplasticblock@14"
            ]
        },
        {
            "x": -5,
            "y": 3,
            "z": -3,
            "elements": [
                "mekanism:reinforcedplasticblock@14"
            ]
        },
        {
            "x": -5,
            "y": 3,
            "z": -2,
            "elements": [
                "mekanism:reinforcedplasticblock@14"
            ]
        },
        {
            "x": -5,
            "y": 3,
            "z": -1,
            "elements": [
                "mekanism:reinforcedplasticblock@14"
            ]
        },
        {
            "x": -5,
            "y": 3,
            "z": 0,
            "elements": [
                "mekanism:reinforcedplasticblock@14"
            ]
        },
        {
            "x": -5,
            "y": 3,
            "z": 1,
            "elements": [
                "mekanism:reinforcedplasticblock@14"
            ]
        },
        {
            "x": -5,
            "y": 3,
            "z": 2,
            "elements": [
                "mekanism:reinforcedplasticblock@14"
            ]
        },
        {
            "x": -5,
            "y": 3,
            "z": 3,
            "elements": [
                "mekanism:reinforcedplasticblock@14"
            ]
        },
        {
            "x": -5,
            "y": 3,
            "z": 4,
            "elements": [
                "mekanism:reinforcedplasticblock@14"
            ]
        },
        {
            "x": -5,
            "y": 3,
            "z": 5,
            "elements": [
                "mekanism:reinforcedplasticblock@14"
            ]
        },
        {
            "x": -5,
            "y": 3,
            "z": 6,
            "elements": [
                "mekanism:reinforcedplasticblock@14"
            ]
        },
        {
            "x": -5,
            "y": 3,
            "z": 7,
            "elements": [
                "mekanism:reinforcedplasticblock@14"
            ]
        },
        {
            "x": 5,
            "y": 2,
            "z": -1,
            "elements": [
                "mekanism:glowplasticblock@11"
            ]
        },
        {
            "x": 5,
            "y": 2,
            "z": -2,
            "elements": [
                "mekanism:glowplasticblock@11"
            ]
        },
        {
            "x": 1,
            "y": 4,
            "z": -4,
            "elements": [
                "mekanism:reinforcedplasticblock@14"
            ]
        },
        {
            "x": 5,
            "y": 2,
            "z": 5,
            "elements": [
                "mekanism:glowplasticblock@11"
            ]
        },
        {
            "x": 1,
            "y": 4,
            "z": 8,
            "elements": [
                "mekanism:reinforcedplasticblock@14"
            ]
        },
        {
            "x": 5,
            "y": 2,
            "z": 4,
            "elements": [
                "mekanism:glowplasticblock@11"
            ]
        },
        {
            "x": 5,
            "y": 2,
            "z": 6,
            "elements": [
                "mekanism:glowplasticblock@11"
            ]
        },
        {
            "x": 5,
            "y": 2,
            "z": 1,
            "elements": [
                "mekanism:glowplasticblock@11"
            ]
        },
        {
            "x": 5,
            "y": 2,
            "z": 0,
            "elements": [
                "mekanism:glowplasticblock@11"
            ]
        },
        {
            "x": 5,
            "y": 2,
            "z": 3,
            "elements": [
                "mekanism:glowplasticblock@11"
            ]
        },
        {
            "x": 5,
            "y": 2,
            "z": 2,
            "elements": [
                "mekanism:glowplasticblock@11"
            ]
        },
        {
            "x": 0,
            "y": 2,
            "z": 6,
            "elements": [
                "mekanism:glowplasticblock@0"
            ]
        },
        {
            "x": 0,
            "y": 2,
            "z": 5,
            "elements": [
                "appliedenergistics2:quartz_block@0"
            ]
        },
        {
            "x": 0,
            "y": 2,
            "z": 7,
            "elements": [
                "mekanism:glowplasticblock@11"
            ]
        },
        {
            "x": -1,
            "y": 1,
            "z": 6,
            "elements": [
                "mekanism:reinforcedplasticblock@14"
            ]
        },
        {
            "x": -1,
            "y": 1,
            "z": 5,
            "elements": [
                "mekanism:reinforcedplasticblock@14"
            ]
        },
        {
            "x": 3,
            "y": 9,
            "z": -4,
            "elements": [
                "mekanism:glowplasticblock@15"
            ]
        },
        {
            "x": -1,
            "y": 1,
            "z": -1,
            "elements": [
                "mekanism:reinforcedplasticblock@14"
            ]
        },
        {
            "x": -1,
            "y": 1,
            "z": -2,
            "elements": [
                "mekanism:reinforcedplasticblock@14"
            ]
        },
        {
            "x": 0,
            "y": 2,
            "z": 2,
            "elements": [
                "mekanism:glowplasticblock@11"
            ]
        },
        {
            "x": 3,
            "y": 9,
            "z": 8,
            "elements": [
                "mekanism:reinforcedplasticblock@14"
            ]
        },
        {
            "x": 0,
            "y": 2,
            "z": 1,
            "elements": [
                "mekanism:glowplasticblock@0"
            ]
        },
        {
            "x": 0,
            "y": 2,
            "z": 4,
            "elements": [
                "appliedenergistics2:quartz_block@0"
            ]
        },
        {
            "x": 0,
            "y": 2,
            "z": 3,
            "elements": [
                "appliedenergistics2:quartz_block@0"
            ]
        },
        {
            "x": 0,
            "y": 2,
            "z": -2,
            "elements": [
                "mekanism:glowplasticblock@0"
            ]
        },
        {
            "x": -2,
            "y": 10,
            "z": -4,
            "elements": [
                "mekanism:glowplasticblock@15"
            ]
        },
        {
            "x": 0,
            "y": 2,
            "z": -3,
            "elements": [
                "mekanism:glowplasticblock@11"
            ]
        },
        {
            "x": 0,
            "y": 2,
            "z": 0,
            "elements": [
                "mekanism:glowplasticblock@0"
            ]
        },
        {
            "x": 0,
            "y": 2,
            "z": -1,
            "elements": [
                "appliedenergistics2:quartz_block@0"
            ]
        },
        {
            "x": -2,
            "y": 10,
            "z": 8,
            "elements": [
                "mekanism:reinforcedplasticblock@14"
            ]
        },
        {
            "x": 4,
            "y": 11,
            "z": -4,
            "elements": [
                "mekanism:glowplasticblock@11"
            ]
        },
        {
            "x": -3,
            "y": 8,
            "z": 8,
            "elements": [
                "mekanism:reinforcedplasticblock@14"
            ]
        },
        {
            "x": -3,
            "y": 8,
            "z": -4,
            "elements": [
                "mekanism:reinforcedplasticblock@14"
            ]
        },
        {
            "x": 4,
            "y": 11,
            "z": 8,
            "elements": [
                "mekanism:glowplasticblock@11"
            ]
        },
        {
            "x": -1,
            "y": 0,
            "z": 3,
            "elements": [
                "mekanism:reinforcedplasticblock@14"
            ]
        },
        {
            "x": -1,
            "y": 0,
            "z": 2,
            "elements": [
                "mekanism:reinforcedplasticblock@14"
            ]
        },
        {
            "x": 2,
            "y": 7,
            "z": 8,
            "elements": [
                "mekanism:glowplasticblock@11"
            ]
        },
        {
            "x": -1,
            "y": 0,
            "z": 1,
            "elements": [
                "mekanism:reinforcedplasticblock@14"
            ]
        },
        {
            "x": -1,
            "y": 0,
            "z": 0,
            "elements": [
                "mekanism:reinforcedplasticblock@14"
            ]
        },
        {
            "x": -1,
            "y": 0,
            "z": 4,
            "elements": [
                "mekanism:reinforcedplasticblock@14"
            ]
        },
        {
            "x": -4,
            "y": 6,
            "z": 8,
            "elements": [
                "mekanism:reinforcedplasticblock@14"
            ]
        },
        {
            "x": -4,
            "y": 6,
            "z": 7,
            "elements": [
                "minecraft:planks@0"
            ]
        },
        {
            "x": -4,
            "y": 6,
            "z": -3,
            "elements": [
                "minecraft:planks@0"
            ]
        },
        {
            "x": -1,
            "y": 13,
            "z": 6,
            "elements": [
                "mekanism:reinforcedplasticblock@14"
            ]
        },
        {
            "x": -1,
            "y": 13,
            "z": 5,
            "elements": [
                "mekanism:reinforcedplasticblock@14"
            ]
        },
        {
            "x": -1,
            "y": 13,
            "z": -1,
            "elements": [
                "mekanism:reinforcedplasticblock@14"
            ]
        },
        {
            "x": -4,
            "y": 6,
            "z": -4,
            "elements": [
                "mekanism:reinforcedplasticblock@14"
            ]
        },
        {
            "x": -1,
            "y": 13,
            "z": -2,
            "elements": [
                "mekanism:reinforcedplasticblock@14"
            ]
        },
        {
            "x": 4,
            "y": -1,
            "z": 4,
            "elements": [
                "mekanism:slickplasticblock@2"
            ]
        },
        {
            "x": -5,
            "y": 4,
            "z": -3,
            "elements": [
                "mekanism:reinforcedplasticblock@14"
            ]
        },
        {
            "x": 4,
            "y": -1,
            "z": 5,
            "elements": [
                "mekanism:slickplasticblock@2"
            ]
        },
        {
            "x": -5,
            "y": 4,
            "z": -2,
            "elements": [
                "mekanism:reinforcedplasticblock@14"
            ]
        },
        {
            "x": 4,
            "y": -1,
            "z": 6,
            "elements": [
                "mekanism:slickplasticblock@2"
            ]
        },
        {
            "x": 4,
            "y": -1,
            "z": 7,
            "elements": [
                "mekanism:slickplasticblock@2"
            ]
        },
        {
            "x": 2,
            "y": 7,
            "z": -4,
            "elements": [
                "mekanism:glowplasticblock@11"
            ]
        },
        {
            "x": 4,
            "y": -1,
            "z": -1,
            "elements": [
                "mekanism:slickplasticblock@2"
            ]
        },
        {
            "x": 4,
            "y": -1,
            "z": 0,
            "elements": [
                "mekanism:slickplasticblock@2"
            ]
        },
        {
            "x": 4,
            "y": -1,
            "z": 1,
            "elements": [
                "mekanism:slickplasticblock@2"
            ]
        },
        {
            "x": 4,
            "y": -1,
            "z": 2,
            "elements": [
                "mekanism:slickplasticblock@2"
            ]
        },
        {
            "x": -4,
            "y": 2,
            "z": 7,
            "elements": [
                "mekanism:reinforcedplasticblock@14"
            ]
        },
        {
            "x": 0,
            "y": 7,
            "z": 8,
            "elements": [
                "minecraft:concrete@15"
            ]
        },
        {
            "x": 0,
            "y": 7,
            "z": 9,
            "elements": [
                "minecraft:concrete@15"
            ]
        },
        {
            "x": -4,
            "y": 2,
            "z": 5,
            "elements": [
                "mekanism:reinforcedplasticblock@14"
            ]
        },
        {
            "x": 4,
            "y": 12,
            "z": 7,
            "elements": [
                "mekanism:reinforcedplasticblock@14"
            ]
        },
        {
            "x": 0,
            "y": 7,
            "z": 10,
            "elements": [
                "minecraft:concrete@15"
            ]
        },
        {
            "x": -4,
            "y": 2,
            "z": 6,
            "elements": [
                "mekanism:reinforcedplasticblock@14"
            ]
        },
        {
            "x": 0,
            "y": 7,
            "z": 11,
            "elements": [
                "mekanism:glowplasticblock@5"
            ]
        },
        {
            "x": -4,
            "y": 2,
            "z": 3,
            "elements": [
                "mekanism:glowplasticblock@0"
            ]
        },
        {
            "x": -4,
            "y": 2,
            "z": 4,
            "elements": [
                "mekanism:reinforcedplasticblock@14"
            ]
        },
        {
            "x": -4,
            "y": 2,
            "z": 1,
            "elements": [
                "mekanism:glowplasticblock@0"
            ]
        },
        {
            "x": -4,
            "y": 2,
            "z": 2,
            "elements": [
                "mekanism:glowplasticblock@0"
            ]
        },
        {
            "x": -4,
            "y": 2,
            "z": -1,
            "elements": [
                "mekanism:reinforcedplasticblock@14"
            ]
        },
        {
            "x": -4,
            "y": 2,
            "z": 0,
            "elements": [
                "mekanism:reinforcedplasticblock@14"
            ]
        },
        {
            "x": -4,
            "y": 2,
            "z": -3,
            "elements": [
                "mekanism:reinforcedplasticblock@14"
            ]
        },
        {
            "x": -4,
            "y": 2,
            "z": -2,
            "elements": [
                "mekanism:reinforcedplasticblock@14"
            ]
        },
        {
            "x": 3,
            "y": 11,
            "z": 8,
            "elements": [
                "mekanism:reinforcedplasticblock@14"
            ]
        },
        {
            "x": 0,
            "y": 7,
            "z": -4,
            "elements": [
                "modularmachinery:blockinputbus"
            ]
        },
        {
            "x": 4,
            "y": 12,
            "z": -3,
            "elements": [
                "mekanism:slickplasticblock@2"
            ]
        },
        {
            "x": -1,
            "y": 6,
            "z": 8,
            "elements": [
                "mekanism:glowplasticblock@11"
            ]
        },
        {
            "x": 1,
            "y": 8,
            "z": 8,
            "elements": [
                "mekanism:glowplasticblock@11"
            ]
        },
        {
            "x": 4,
            "y": 12,
            "z": -2,
            "elements": [
                "mekanism:reinforcedplasticblock@14"
            ]
        },
        {
            "x": -3,
            "y": 3,
            "z": 8,
            "elements": [
                "mekanism:reinforcedplasticblock@14"
            ]
        },
        {
            "x": -1,
            "y": 6,
            "z": -4,
            "elements": [
                "mekanism:glowplasticblock@11"
            ]
        },
        {
            "x": 4,
            "y": 12,
            "z": -1,
            "elements": [
                "mekanism:reinforcedplasticblock@14"
            ]
        },
        {
            "x": 4,
            "y": 12,
            "z": 5,
            "elements": [
                "mekanism:reinforcedplasticblock@14"
            ]
        },
        {
            "x": 4,
            "y": 12,
            "z": 6,
            "elements": [
                "mekanism:reinforcedplasticblock@14"
            ]
        },
        {
            "x": 3,
            "y": 11,
            "z": -4,
            "elements": [
                "mekanism:reinforcedplasticblock@14"
            ]
        },
        {
            "x": -6,
            "y": -1,
            "z": 8,
            "elements": [
                "mekanism:slickplasticblock@2"
            ]
        },
        {
            "x": -6,
            "y": -1,
            "z": 7,
            "elements": [
                "mekanism:slickplasticblock@2"
            ]
        },
        {
            "x": -2,
            "y": 4,
            "z": 8,
            "elements": [
                "mekanism:reinforcedplasticblock@14"
            ]
        },
        {
            "x": 1,
            "y": 9,
            "z": -4,
            "elements": [
                "mekanism:reinforcedplasticblock@14"
            ]
        },
        {
            "x": 2,
            "y": 9,
            "z": 8,
            "elements": [
                "mekanism:glowplasticblock@11"
            ]
        },
        {
            "x": 2,
            "y": 9,
            "z": -4,
            "elements": [
                "mekanism:glowplasticblock@12"
            ]
        },
        {
            "x": 1,
            "y": 9,
            "z": 8,
            "elements": [
                "mekanism:reinforcedplasticblock@14"
            ]
        },
        {
            "x": -2,
            "y": 4,
            "z": -4,
            "elements": [
                "mekanism:reinforcedplasticblock@14"
            ]
        },
        {
            "x": -6,
            "y": -1,
            "z": -1,
            "elements": [
                "mekanism:slickplasticblock@2"
            ]
        },
        {
            "x": -6,
            "y": -1,
            "z": -2,
            "elements": [
                "mekanism:slickplasticblock@2"
            ]
        },
        {
            "x": 0,
            "y": 8,
            "z": -4,
            "elements": [
                "mekanism:glowplasticblock@11"
            ]
        },
        {
            "x": 3,
            "y": 10,
            "z": 8,
            "elements": [
                "mekanism:glowplasticblock@11"
            ]
        },
        {
            "x": -7,
            "y": -1,
            "z": 9,
            "elements": [
                "mekanism:slickplasticblock@2"
            ]
        },
        {
            "x": -7,
            "y": -1,
            "z": -3,
            "elements": [
                "mekanism:slickplasticblock@2"
            ]
        },
        {
            "x": -3,
            "y": 3,
            "z": -4,
            "elements": [
                "mekanism:reinforcedplasticblock@14"
            ]
        },
        {
            "x": 1,
            "y": 7,
            "z": 8,
            "elements": [
                "mekanism:glowplasticblock@11"
            ]
        },
        {
            "x": -2,
            "y": 5,
            "z": -4,
            "elements": [
                "mekanism:glowplasticblock@11"
            ]
        },
        {
            "x": 2,
            "y": 11,
            "z": -4,
            "elements": [
                "mekanism:slickplasticblock@2"
            ]
        },
        {
            "x": -2,
            "y": 5,
            "z": 8,
            "elements": [
                "mekanism:glowplasticblock@11"
            ]
        },
        {
            "x": 0,
            "y": 8,
            "z": 8,
            "elements": [
                "mekanism:glowplasticblock@11"
            ]
        },
        {
            "x": 3,
            "y": 10,
            "z": -4,
            "elements": [
                "mekanism:glowplasticblock@15"
            ]
        },
        {
            "x": 2,
            "y": 8,
            "z": -4,
            "elements": [
                "mekanism:reinforcedplasticblock@14"
            ]
        },
        {
            "x": -2,
            "y": 3,
            "z": -4,
            "elements": [
                "mekanism:reinforcedplasticblock@14"
            ]
        },
        {
            "x": 1,
            "y": 10,
            "z": -4,
            "elements": [
                "mekanism:reinforcedplasticblock@14"
            ]
        },
        {
            "x": -4,
            "y": 4,
            "z": -3,
            "elements": [
                "minecraft:planks@0"
            ]
        },
        {
            "x": -5,
            "y": -1,
            "z": -2,
            "elements": [
                "mekanism:slickplasticblock@2"
            ]
        },
        {
            "x": -5,
            "y": -1,
            "z": 0,
            "elements": [
                "mekanism:slickplasticblock@2"
            ]
        },
        {
            "x": -4,
            "y": 4,
            "z": -4,
            "elements": [
                "mekanism:reinforcedplasticblock@14"
            ]
        },
        {
            "x": -5,
            "y": -1,
            "z": -1,
            "elements": [
                "mekanism:slickplasticblock@2"
            ]
        },
        {
            "x": -2,
            "y": 6,
            "z": 8,
            "elements": [
                "mekanism:reinforcedplasticblock@14"
            ]
        },
        {
            "x": 2,
            "y": 8,
            "z": 8,
            "elements": [
                "mekanism:reinforcedplasticblock@14"
            ]
        },
        {
            "x": 2,
            "y": 11,
            "z": 8,
            "elements": [
                "mekanism:reinforcedplasticblock@14"
            ]
        },
        {
            "x": 1,
            "y": 7,
            "z": -4,
            "elements": [
                "mekanism:glowplasticblock@11"
            ]
        },
        {
            "x": -2,
            "y": 3,
            "z": 8,
            "elements": [
                "mekanism:reinforcedplasticblock@14"
            ]
        },
        {
            "x": -5,
            "y": -1,
            "z": 6,
            "elements": [
                "mekanism:slickplasticblock@2"
            ]
        },
        {
            "x": 1,
            "y": 10,
            "z": 8,
            "elements": [
                "mekanism:reinforcedplasticblock@14"
            ]
        },
        {
            "x": -5,
            "y": -1,
            "z": 8,
            "elements": [
                "mekanism:slickplasticblock@2"
            ]
        },
        {
            "x": -5,
            "y": -1,
            "z": 7,
            "elements": [
                "mekanism:slickplasticblock@2"
            ]
        },
        {
            "x": -5,
            "y": 2,
            "z": 6,
            "elements": [
                "mekanism:glowplasticblock@11"
            ]
        },
        {
            "x": -5,
            "y": 2,
            "z": 2,
            "elements": [
                "mekanism:glowplasticblock@11"
            ]
        },
        {
            "x": -5,
            "y": 2,
            "z": 3,
            "elements": [
                "mekanism:glowplasticblock@11"
            ]
        },
        {
            "x": -5,
            "y": 2,
            "z": 4,
            "elements": [
                "mekanism:glowplasticblock@11"
            ]
        },
        {
            "x": -4,
            "y": 4,
            "z": 7,
            "elements": [
                "minecraft:planks@0"
            ]
        },
        {
            "x": -5,
            "y": 2,
            "z": 5,
            "elements": [
                "mekanism:glowplasticblock@11"
            ]
        },
        {
            "x": -4,
            "y": 4,
            "z": 8,
            "elements": [
                "mekanism:reinforcedplasticblock@14"
            ]
        },
        {
            "x": 1,
            "y": 6,
            "z": 8,
            "elements": [
                "mekanism:glowplasticblock@11"
            ]
        },
        {
            "x": -3,
            "y": 1,
            "z": 5,
            "elements": [
                "mekanism:reinforcedplasticblock@14"
            ]
        },
        {
            "x": -3,
            "y": 1,
            "z": 1,
            "elements": [
                "mekanism:reinforcedplasticblock@14"
            ]
        },
        {
            "x": -3,
            "y": 1,
            "z": 2,
            "elements": [
                "mekanism:reinforcedplasticblock@14"
            ]
        },
        {
            "x": -3,
            "y": 1,
            "z": 3,
            "elements": [
                "mekanism:reinforcedplasticblock@14"
            ]
        },
        {
            "x": -3,
            "y": 1,
            "z": 4,
            "elements": [
                "mekanism:reinforcedplasticblock@14"
            ]
        },
        {
            "x": -5,
            "y": 2,
            "z": -2,
            "elements": [
                "mekanism:glowplasticblock@11"
            ]
        },
        {
            "x": -5,
            "y": 2,
            "z": -1,
            "elements": [
                "mekanism:glowplasticblock@11"
            ]
        },
        {
            "x": 1,
            "y": 6,
            "z": -4,
            "elements": [
                "mekanism:glowplasticblock@11"
            ]
        },
        {
            "x": -3,
            "y": 1,
            "z": -1,
            "elements": [
                "mekanism:reinforcedplasticblock@14"
            ]
        },
        {
            "x": -5,
            "y": 2,
            "z": 0,
            "elements": [
                "mekanism:glowplasticblock@11"
            ]
        },
        {
            "x": -3,
            "y": 1,
            "z": 0,
            "elements": [
                "mekanism:reinforcedplasticblock@14"
            ]
        },
        {
            "x": -5,
            "y": 2,
            "z": 1,
            "elements": [
                "mekanism:glowplasticblock@11"
            ]
        },
        {
            "x": -5,
            "y": 2,
            "z": -3,
            "elements": [
                "mekanism:glowplasticblock@11"
            ]
        },
        {
            "x": 4,
            "y": 13,
            "z": -3,
            "elements": [
                "mekanism:slickplasticblock@2"
            ]
        },
        {
            "x": 2,
            "y": 12,
            "z": 7,
            "elements": [
                "mekanism:reinforcedplasticblock@14"
            ]
        },
        {
            "x": -3,
            "y": 4,
            "z": 8,
            "elements": [
                "mekanism:glowplasticblock@11"
            ]
        },
        {
            "x": -1,
            "y": 5,
            "z": -4,
            "elements": [
                "mekanism:reinforcedplasticblock@14"
            ]
        },
        {
            "x": 2,
            "y": 12,
            "z": -3,
            "elements": [
                "mekanism:reinforcedplasticblock@14"
            ]
        },
        {
            "x": -3,
            "y": 4,
            "z": -4,
            "elements": [
                "mekanism:glowplasticblock@11"
            ]
        },
        {
            "x": 5,
            "y": 12,
            "z": 6,
            "elements": [
                "mekanism:glowplasticblock@11"
            ]
        },
        {
            "x": 4,
            "y": 10,
            "z": 8,
            "elements": [
                "mekanism:reinforcedplasticblock@14"
            ]
        },
        {
            "x": -1,
            "y": 8,
            "z": -4,
            "elements": [
                "mekanism:glowplasticblock@11"
            ]
        },
        {
            "x": -2,
            "y": 6,
            "z": -4,
            "elements": [
                "mekanism:reinforcedplasticblock@14"
            ]
        },
        {
            "x": 5,
            "y": 12,
            "z": 2,
            "elements": [
                "mekanism:glowplasticblock@11"
            ]
        },
        {
            "x": 0,
            "y": 4,
            "z": 8,
            "elements": [
                "mekanism:glowplasticblock@11"
            ]
        },
        {
            "x": 4,
            "y": 10,
            "z": -4,
            "elements": [
                "mekanism:reinforcedplasticblock@14"
            ]
        },
        {
            "x": 5,
            "y": 12,
            "z": 3,
            "elements": [
                "mekanism:glowplasticblock@11"
            ]
        },
        {
            "x": 5,
            "y": 12,
            "z": 4,
            "elements": [
                "mekanism:glowplasticblock@11"
            ]
        },
        {
            "x": 5,
            "y": 12,
            "z": 5,
            "elements": [
                "mekanism:glowplasticblock@11"
            ]
        },
        {
            "x": 5,
            "y": 12,
            "z": -2,
            "elements": [
                "mekanism:glowplasticblock@11"
            ]
        },
        {
            "x": 5,
            "y": 12,
            "z": -1,
            "elements": [
                "mekanism:glowplasticblock@11"
            ]
        },
        {
            "x": 5,
            "y": 12,
            "z": 0,
            "elements": [
                "mekanism:glowplasticblock@11"
            ]
        },
        {
            "x": 5,
            "y": 12,
            "z": 1,
            "elements": [
                "mekanism:glowplasticblock@11"
            ]
        },
        {
            "x": -1,
            "y": 8,
            "z": 8,
            "elements": [
                "mekanism:glowplasticblock@11"
            ]
        },
        {
            "x": 4,
            "y": 13,
            "z": 4,
            "elements": [
                "mekanism:reinforcedplasticblock@14"
            ]
        },
        {
            "x": 4,
            "y": 13,
            "z": 2,
            "elements": [
                "mekanism:reinforcedplasticblock@14"
            ]
        },
        {
            "x": -1,
            "y": 5,
            "z": 8,
            "elements": [
                "mekanism:reinforcedplasticblock@14"
            ]
        },
        {
            "x": 4,
            "y": 13,
            "z": 3,
            "elements": [
                "mekanism:reinforcedplasticblock@14"
            ]
        },
        {
            "x": 4,
            "y": 13,
            "z": 0,
            "elements": [
                "mekanism:reinforcedplasticblock@14"
            ]
        },
        {
            "x": 4,
            "y": 13,
            "z": 1,
            "elements": [
                "mekanism:reinforcedplasticblock@14"
            ]
        },
        {
            "x": 5,
            "y": 10,
            "z": 6,
            "elements": [
                "mekanism:reinforcedplasticblock@14"
            ]
        },
        {
            "x": -2,
            "y": 8,
            "z": -4,
            "elements": [
                "mekanism:reinforcedplasticblock@14"
            ]
        },
        {
            "x": 5,
            "y": 10,
            "z": 7,
            "elements": [
                "mekanism:reinforcedplasticblock@14"
            ]
        },
        {
            "x": 5,
            "y": 10,
            "z": 1,
            "elements": [
                "mekanism:glowplasticblock@11"
            ]
        },
        {
            "x": 5,
            "y": 10,
            "z": 2,
            "elements": [
                "mekanism:glowplasticblock@12"
            ]
        },
        {
            "x": 5,
            "y": 10,
            "z": 3,
            "elements": [
                "mekanism:glowplasticblock@11"
            ]
        },
        {
            "x": -1,
            "y": 9,
            "z": 8,
            "elements": [
                "mekanism:reinforcedplasticblock@14"
            ]
        },
        {
            "x": -2,
            "y": 1,
            "z": 6,
            "elements": [
                "mekanism:reinforcedplasticblock@14"
            ]
        },
        {
            "x": -2,
            "y": 1,
            "z": 5,
            "elements": [
                "mekanism:reinforcedplasticblock@14"
            ]
        },
        {
            "x": 4,
            "y": 9,
            "z": -4,
            "elements": [
                "mekanism:reinforcedplasticblock@14"
            ]
        },
        {
            "x": 5,
            "y": 10,
            "z": -3,
            "elements": [
                "mekanism:reinforcedplasticblock@14"
            ]
        },
        {
            "x": 5,
            "y": 10,
            "z": -2,
            "elements": [
                "mekanism:reinforcedplasticblock@14"
            ]
        },
        {
            "x": -2,
            "y": 8,
            "z": 8,
            "elements": [
                "mekanism:reinforcedplasticblock@14"
            ]
        },
        {
            "x": -1,
            "y": 3,
            "z": -4,
            "elements": [
                "mekanism:reinforcedplasticblock@14"
            ]
        },
        {
            "x": -2,
            "y": 1,
            "z": -2,
            "elements": [
                "mekanism:reinforcedplasticblock@14"
            ]
        },
        {
            "x": -2,
            "y": 1,
            "z": -1,
            "elements": [
                "mekanism:reinforcedplasticblock@14"
            ]
        },
        {
            "x": -1,
            "y": 3,
            "z": 8,
            "elements": [
                "mekanism:reinforcedplasticblock@14"
            ]
        },
        {
            "x": -2,
            "y": 2,
            "z": 7,
            "elements": [
                "mekanism:reinforcedplasticblock@14"
            ]
        },
        {
            "x": -2,
            "y": 7,
            "z": 8,
            "elements": [
                "mekanism:glowplasticblock@11"
            ]
        },
        {
            "x": 5,
            "y": 11,
            "z": -3,
            "elements": [
                "mekanism:reinforcedplasticblock@14"
            ]
        },
        {
            "x": 5,
            "y": 11,
            "z": -2,
            "elements": [
                "mekanism:reinforcedplasticblock@14"
            ]
        },
        {
            "x": 5,
            "y": 11,
            "z": -1,
            "elements": [
                "mekanism:reinforcedplasticblock@14"
            ]
        },
        {
            "x": 5,
            "y": 11,
            "z": 0,
            "elements": [
                "mekanism:reinforcedplasticblock@14"
            ]
        },
        {
            "x": 5,
            "y": 11,
            "z": 1,
            "elements": [
                "mekanism:reinforcedplasticblock@14"
            ]
        },
        {
            "x": 5,
            "y": 11,
            "z": 2,
            "elements": [
                "mekanism:reinforcedplasticblock@14"
            ]
        },
        {
            "x": 0,
            "y": 11,
            "z": 8,
            "elements": [
                "mekanism:glowplasticblock@11"
            ]
        },
        {
            "x": 5,
            "y": 11,
            "z": 3,
            "elements": [
                "mekanism:reinforcedplasticblock@14"
            ]
        },
        {
            "x": 5,
            "y": 11,
            "z": 4,
            "elements": [
                "mekanism:reinforcedplasticblock@14"
            ]
        },
        {
            "x": 5,
            "y": 11,
            "z": 5,
            "elements": [
                "mekanism:reinforcedplasticblock@14"
            ]
        },
        {
            "x": -2,
            "y": 7,
            "z": -4,
            "elements": [
                "mekanism:glowplasticblock@11"
            ]
        },
        {
            "x": 5,
            "y": 11,
            "z": 6,
            "elements": [
                "mekanism:reinforcedplasticblock@14"
            ]
        },
        {
            "x": 5,
            "y": 11,
            "z": 7,
            "elements": [
                "mekanism:reinforcedplasticblock@14"
            ]
        },
        {
            "x": 0,
            "y": 11,
            "z": -4,
            "elements": [
                "mekanism:glowplasticblock@11"
            ]
        },
        {
            "x": 0,
            "y": 5,
            "z": 8,
            "elements": [
                "mekanism:glowplasticblock@11"
            ]
        },
        {
            "x": 3,
            "y": 7,
            "z": 8,
            "elements": [
                "mekanism:glowplasticblock@11"
            ]
        },
        {
            "x": 3,
            "y": 13,
            "z": 3,
            "elements": [
                "mekanism:reinforcedplasticblock@14"
            ]
        },
        {
            "x": 3,
            "y": 13,
            "z": 4,
            "elements": [
                "mekanism:reinforcedplasticblock@14"
            ]
        },
        {
            "x": 4,
            "y": 9,
            "z": 8,
            "elements": [
                "mekanism:reinforcedplasticblock@14"
            ]
        },
        {
            "x": 0,
            "y": 5,
            "z": -4,
            "elements": [
                "mekanism:glowplasticblock@11"
            ]
        },
        {
            "x": 3,
            "y": 13,
            "z": 5,
            "elements": [
                "mekanism:reinforcedplasticblock@14"
            ]
        },
        {
            "x": 3,
            "y": 13,
            "z": -1,
            "elements": [
                "mekanism:reinforcedplasticblock@14"
            ]
        },
        {
            "x": 3,
            "y": 13,
            "z": 0,
            "elements": [
                "mekanism:reinforcedplasticblock@14"
            ]
        },
        {
            "x": 3,
            "y": 13,
            "z": 1,
            "elements": [
                "mekanism:reinforcedplasticblock@14"
            ]
        },
        {
            "x": 3,
            "y": 13,
            "z": 2,
            "elements": [
                "mekanism:reinforcedplasticblock@14"
            ]
        },
        {
            "x": 3,
            "y": 7,
            "z": -4,
            "elements": [
                "mekanism:glowplasticblock@11"
            ]
        },
        {
            "x": -1,
            "y": 9,
            "z": -4,
            "elements": [
                "mekanism:reinforcedplasticblock@14"
            ]
        },
        {
            "x": -6,
            "y": 4,
            "z": -1,
            "elements": [
                "mekanism:reinforcedplasticblock@14"
            ]
        },
        {
            "x": -6,
            "y": 4,
            "z": 0,
            "elements": [
                "mekanism:reinforcedplasticblock@14"
            ]
        },
        {
            "x": -3,
            "y": 6,
            "z": -4,
            "elements": [
                "mekanism:reinforcedplasticblock@14"
            ]
        },
        {
            "x": -2,
            "y": 2,
            "z": -3,
            "elements": [
                "mekanism:reinforcedplasticblock@14"
            ]
        },
        {
            "x": -2,
            "y": 2,
            "z": 0,
            "elements": [
                "appliedenergistics2:quartz_block@0"
            ]
        },
        {
            "x": -6,
            "y": 4,
            "z": 3,
            "elements": [
                "mekanism:reinforcedplasticblock@14"
            ]
        },
        {
            "x": -2,
            "y": 2,
            "z": -1,
            "elements": [
                "mekanism:glowplasticblock@0"
            ]
        },
        {
            "x": -6,
            "y": 4,
            "z": 4,
            "elements": [
                "mekanism:reinforcedplasticblock@14"
            ]
        },
        {
            "x": -6,
            "y": 4,
            "z": 1,
            "elements": [
                "mekanism:reinforcedplasticblock@14"
            ]
        },
        {
            "x": -2,
            "y": 2,
            "z": 2,
            "elements": [
                "appliedenergistics2:quartz_block@0"
            ]
        },
        {
            "x": -2,
            "y": 2,
            "z": 1,
            "elements": [
                "appliedenergistics2:quartz_block@0"
            ]
        },
        {
            "x": -6,
            "y": 4,
            "z": 2,
            "elements": [
                "mekanism:reinforcedplasticblock@14"
            ]
        },
        {
            "x": -3,
            "y": 6,
            "z": 8,
            "elements": [
                "mekanism:reinforcedplasticblock@14"
            ]
        },
        {
            "x": -2,
            "y": 2,
            "z": 4,
            "elements": [
                "appliedenergistics2:quartz_block@0"
            ]
        },
        {
            "x": -2,
            "y": 2,
            "z": 3,
            "elements": [
                "appliedenergistics2:quartz_block@0"
            ]
        },
        {
            "x": -6,
            "y": 4,
            "z": 5,
            "elements": [
                "mekanism:reinforcedplasticblock@14"
            ]
        },
        {
            "x": -2,
            "y": 2,
            "z": 5,
            "elements": [
                "mekanism:glowplasticblock@0"
            ]
        },
        {
            "x": 3,
            "y": 6,
            "z": -4,
            "elements": [
                "mekanism:reinforcedplasticblock@14"
            ]
        },
        {
            "x": 0,
            "y": 12,
            "z": 7,
            "elements": [
                "mekanism:glowplasticblock@11"
            ]
        },
        {
            "x": 0,
            "y": 12,
            "z": -3,
            "elements": [
                "mekanism:glowplasticblock@11"
            ]
        },
        {
            "x": -3,
            "y": 5,
            "z": -4,
            "elements": [
                "mekanism:reinforcedplasticblock@14"
            ]
        },
        {
            "x": -1,
            "y": 4,
            "z": -4,
            "elements": [
                "mekanism:reinforcedplasticblock@14"
            ]
        },
        {
            "x": -3,
            "y": 5,
            "z": 8,
            "elements": [
                "mekanism:reinforcedplasticblock@14"
            ]
        },
        {
            "x": -1,
            "y": 4,
            "z": 8,
            "elements": [
                "mekanism:reinforcedplasticblock@14"
            ]
        },
        {
            "x": 3,
            "y": 12,
            "z": 6,
            "elements": [
                "mekanism:reinforcedplasticblock@14"
            ]
        },
        {
            "x": 0,
            "y": 6,
            "z": -4,
            "elements": [
                "mekanism:glowplasticblock@11"
            ]
        },
        {
            "x": 3,
            "y": 12,
            "z": 7,
            "elements": [
                "mekanism:reinforcedplasticblock@14"
            ]
        },
        {
            "x": 0,
            "y": 6,
            "z": 8,
            "elements": [
                "modularmachinery:blockoutputbus"
            ]
        },
        {
            "x": 3,
            "y": 12,
            "z": -4,
            "elements": [
                "mekanism:slickplasticblock@2"
            ]
        },
        {
            "x": 3,
            "y": 12,
            "z": -3,
            "elements": [
                "mekanism:reinforcedplasticblock@14"
            ]
        },
        {
            "x": 3,
            "y": 12,
            "z": -2,
            "elements": [
                "mekanism:reinforcedplasticblock@14"
            ]
        },
        {
            "x": -1,
            "y": 10,
            "z": 8,
            "elements": [
                "mekanism:reinforcedplasticblock@14"
            ]
        },
        {
            "x": 4,
            "y": 8,
            "z": -4,
            "elements": [
                "mekanism:reinforcedplasticblock@14"
            ]
        },
        {
            "x": -4,
            "y": 3,
            "z": -4,
            "elements": [
                "mekanism:glowplasticblock@11"
            ]
        },
        {
            "x": -4,
            "y": 3,
            "z": -3,
            "elements": [
                "minecraft:planks@0"
            ]
        },
        {
            "x": 1,
            "y": 14,
            "z": 4,
            "elements": [
                "mekanism:reinforcedplasticblock@14"
            ]
        },
        {
            "x": 2,
            "y": 4,
            "z": -4,
            "elements": [
                "mekanism:reinforcedplasticblock@14"
            ]
        },
        {
            "x": -1,
            "y": 10,
            "z": -4,
            "elements": [
                "mekanism:reinforcedplasticblock@14"
            ]
        },
        {
            "x": 1,
            "y": 14,
            "z": 1,
            "elements": [
                "mekanism:reinforcedplasticblock@14"
            ]
        },
        {
            "x": 1,
            "y": 14,
            "z": 0,
            "elements": [
                "mekanism:reinforcedplasticblock@14"
            ]
        },
        {
            "x": 1,
            "y": 14,
            "z": 3,
            "elements": [
                "mekanism:reinforcedplasticblock@14"
            ]
        },
        {
            "x": 4,
            "y": 8,
            "z": 8,
            "elements": [
                "mekanism:reinforcedplasticblock@14"
            ]
        },
        {
            "x": 1,
            "y": 14,
            "z": 2,
            "elements": [
                "mekanism:reinforcedplasticblock@14"
            ]
        },
        {
            "x": 2,
            "y": 4,
            "z": 8,
            "elements": [
                "mekanism:reinforcedplasticblock@14"
            ]
        },
        {
            "x": -6,
            "y": 5,
            "z": 6,
            "elements": [
                "mekanism:reinforcedplasticblock@14"
            ]
        },
        {
            "x": -6,
            "y": 5,
            "z": 5,
            "elements": [
                "mekanism:reinforcedplasticblock@14"
            ]
        },
        {
            "x": -6,
            "y": 5,
            "z": 2,
            "elements": [
                "mekanism:glowplasticblock@12"
            ]
        },
        {
            "x": -6,
            "y": 5,
            "z": 3,
            "elements": [
                "mekanism:glowplasticblock@12"
            ]
        },
        {
            "x": -6,
            "y": 5,
            "z": 1,
            "elements": [
                "mekanism:glowplasticblock@12"
            ]
        },
        {
            "x": 1,
            "y": 8,
            "z": -4,
            "elements": [
                "mekanism:glowplasticblock@11"
            ]
        },
        {
            "x": -6,
            "y": 5,
            "z": -2,
            "elements": [
                "mekanism:reinforcedplasticblock@14"
            ]
        },
        {
            "x": -5,
            "y": 7,
            "z": 5,
            "elements": [
                "mekanism:glowplasticblock@12"
            ]
        },
        {
            "x": -6,
            "y": 5,
            "z": -1,
            "elements": [
                "mekanism:reinforcedplasticblock@14"
            ]
        },
        {
            "x": -5,
            "y": 7,
            "z": 7,
            "elements": [
                "mekanism:glowplasticblock@11"
            ]
        },
        {
            "x": 2,
            "y": 10,
            "z": -4,
            "elements": [
                "mekanism:glowplasticblock@15"
            ]
        },
        {
            "x": 2,
            "y": 10,
            "z": 8,
            "elements": [
                "mekanism:reinforcedplasticblock@14"
            ]
        },
        {
            "x": -3,
            "y": -1,
            "z": 0,
            "elements": [
                "mekanism:slickplasticblock@2"
            ]
        },
        {
            "x": -3,
            "y": -1,
            "z": 1,
            "elements": [
                "mekanism:slickplasticblock@2"
            ]
        },
        {
            "x": -4,
            "y": 3,
            "z": 8,
            "elements": [
                "mekanism:glowplasticblock@11"
            ]
        },
        {
            "x": -3,
            "y": -1,
            "z": 2,
            "elements": [
                "mekanism:slickplasticblock@2"
            ]
        },
        {
            "x": 3,
            "y": 6,
            "z": 8,
            "elements": [
                "mekanism:reinforcedplasticblock@14"
            ]
        },
        {
            "x": -5,
            "y": 7,
            "z": -3,
            "elements": [
                "mekanism:glowplasticblock@11"
            ]
        },
        {
            "x": -5,
            "y": 7,
            "z": -1,
            "elements": [
                "mekanism:glowplasticblock@12"
            ]
        },
        {
            "x": -3,
            "y": -1,
            "z": 4,
            "elements": [
                "mekanism:slickplasticblock@2"
            ]
        },
        {
            "x": -4,
            "y": 3,
            "z": 7,
            "elements": [
                "minecraft:planks@0"
            ]
        },
        {
            "x": -3,
            "y": -1,
            "z": 5,
            "elements": [
                "mekanism:slickplasticblock@2"
            ]
        },
        {
            "x": -3,
            "y": -1,
            "z": 6,
            "elements": [
                "mekanism:slickplasticblock@2"
            ]
        },
        {
            "x": 6,
            "y": 8,
            "z": -1,
            "elements": [
                "mekanism:reinforcedplasticblock@14"
            ]
        },
        {
            "x": 6,
            "y": 8,
            "z": 0,
            "elements": [
                "mekanism:glowplasticblock@12"
            ]
        },
        {
            "x": 6,
            "y": 8,
            "z": -2,
            "elements": [
                "mekanism:reinforcedplasticblock@14"
            ]
        },
        {
            "x": -7,
            "y": 5,
            "z": 0,
            "elements": [
                "mekanism:reinforcedplasticblock@14"
            ]
        },
        {
            "x": 2,
            "y": 3,
            "z": -4,
            "elements": [
                "mekanism:reinforcedplasticblock@14"
            ]
        },
        {
            "x": 6,
            "y": 8,
            "z": 5,
            "elements": [
                "mekanism:reinforcedplasticblock@14"
            ]
        },
        {
            "x": 2,
            "y": 3,
            "z": 8,
            "elements": [
                "mekanism:reinforcedplasticblock@14"
            ]
        },
        {
            "x": 3,
            "y": 4,
            "z": 8,
            "elements": [
                "mekanism:glowplasticblock@11"
            ]
        },
        {
            "x": 6,
            "y": 8,
            "z": 6,
            "elements": [
                "mekanism:reinforcedplasticblock@14"
            ]
        },
        {
            "x": -7,
            "y": 5,
            "z": 1,
            "elements": [
                "mekanism:reinforcedplasticblock@14"
            ]
        },
        {
            "x": 6,
            "y": 8,
            "z": 3,
            "elements": [
                "appliedenergistics2:quartz_block@0"
            ]
        },
        {
            "x": -7,
            "y": 5,
            "z": 2,
            "elements": [
                "mekanism:reinforcedplasticblock@14"
            ]
        },
        {
            "x": 6,
            "y": 8,
            "z": 4,
            "elements": [
                "mekanism:glowplasticblock@12"
            ]
        },
        {
            "x": 6,
            "y": 8,
            "z": 1,
            "elements": [
                "appliedenergistics2:quartz_block@0"
            ]
        },
        {
            "x": -7,
            "y": 5,
            "z": 3,
            "elements": [
                "mekanism:reinforcedplasticblock@14"
            ]
        },
        {
            "x": 6,
            "y": 8,
            "z": 2,
            "elements": [
                "appliedenergistics2:quartz_block@0"
            ]
        },
        {
            "x": -7,
            "y": 5,
            "z": 4,
            "elements": [
                "mekanism:reinforcedplasticblock@14"
            ]
        },
        {
            "x": 7,
            "y": 9,
            "z": 3,
            "elements": [
                "mekanism:reinforcedplasticblock@14"
            ]
        },
        {
            "x": 7,
            "y": 9,
            "z": 4,
            "elements": [
                "mekanism:reinforcedplasticblock@14"
            ]
        },
        {
            "x": 7,
            "y": 9,
            "z": 0,
            "elements": [
                "mekanism:reinforcedplasticblock@14"
            ]
        },
        {
            "x": 7,
            "y": 9,
            "z": 1,
            "elements": [
                "mekanism:reinforcedplasticblock@14"
            ]
        },
        {
            "x": 7,
            "y": 9,
            "z": 2,
            "elements": [
                "mekanism:reinforcedplasticblock@14"
            ]
        },
        {
            "x": 4,
            "y": 5,
            "z": 8,
            "elements": [
                "mekanism:reinforcedplasticblock@14"
            ]
        },
        {
            "x": 3,
            "y": 4,
            "z": -4,
            "elements": [
                "mekanism:glowplasticblock@11"
            ]
        },
        {
            "x": 4,
            "y": 5,
            "z": 7,
            "elements": [
                "minecraft:planks@0"
            ]
        },
        {
            "x": 4,
            "y": 5,
            "z": -3,
            "elements": [
                "minecraft:planks@0"
            ]
        },
        {
            "x": 4,
            "y": 5,
            "z": -4,
