{   "registryname": "speeder",
    "localizedname": "加速机",
    "color": "ffffff",
    "failure-action": "still",
    "parts": [
        {
            "x": -1,
            "y": 0,
            "z": 0,
            "elements": [
                "mekanism:reinforcedplasticblock@14"
            ]
        },
        {
            "x": 4,
            "y": 8,
            "z": 4,
            "elements": [
                "mekanism:glowplasticblock@11"
            ]
        },
        {
            "x": -2,
            "y": 0,
            "z": 0,
            "elements": [
                "mekanism:reinforcedplasticblock@14"
            ]
        },
        {
            "x": 1,
            "y": 0,
            "z": 0,
            "elements": [
                "mekanism:reinforcedplasticblock@14"
            ]
        },
        {
            "x": 5,
            "y": 8,
            "z": 4,
            "elements": [
                "mekanism:reinforcedplasticblock@14"
            ]
        },
        {
            "x": -3,
            "y": 0,
            "z": 0,
            "elements": [
                "mekanism:reinforcedplasticblock@14"
            ]
        },
        {
            "x": 2,
            "y": 0,
            "z": 0,
            "elements": [
                "mekanism:reinforcedplasticblock@14"
            ]
        },
        {
            "x": 5,
            "y": 6,
            "z": 3,
            "elements": [
                "mekanism:reinforcedplasticblock@14"
            ]
        },
        {
            "x": -4,
            "y": 0,
            "z": 0,
            "elements": [
                "mekanism:glowplasticblock@11"
            ]
        },
        {
            "x": 3,
            "y": 0,
            "z": 0,
            "elements": [
                "mekanism:reinforcedplasticblock@14"
            ]
        },
        {
            "x": 5,
            "y": 4,
            "z": 2,
            "elements": [
                "mekanism:glowplasticblock@11"
            ]
        },
        {
            "x": 4,
            "y": 0,
            "z": 0,
            "elements": [
                "mekanism:glowplasticblock@11"
            ]
        },
        {
            "x": 5,
            "y": 2,
            "z": 1,
            "elements": [
                "mekanism:reinforcedplasticblock@14"
            ]
        },
        {
            "x": -5,
            "y": 9,
            "z": 4,
            "elements": [
                "mekanism:glowplasticblock@11"
            ]
        },
        {
            "x": 7,
            "y": -1,
            "z": 0,
            "elements": [
                "mekanism:slickplasticblock@2"
            ]
        },
        {
            "x": -5,
            "y": 7,
            "z": 3,
            "elements": [
                "mekanism:reinforcedplasticblock@14"
            ]
        },
        {
            "x": -4,
            "y": 9,
            "z": 4,
            "elements": [
                "mekanism:reinforcedplasticblock@14"
            ]
        },
        {
            "x": -5,
            "y": 5,
            "z": 2,
            "elements": [
                "mekanism:reinforcedplasticblock@14"
            ]
        },
        {
            "x": -3,
            "y": 9,
            "z": 4,
            "elements": [
                "mekanism:reinforcedplasticblock@14"
            ]
        },
        {
            "x": -5,
            "y": 3,
            "z": 1,
            "elements": [
                "mekanism:reinforcedplasticblock@14"
            ]
        },
        {
            "x": -2,
            "y": 9,
            "z": 4,
            "elements": [
                "mekanism:reinforcedplasticblock@14"
            ]
        },
        {
            "x": -5,
            "y": 1,
            "z": 0,
            "elements": [
                "mekanism:reinforcedplasticblock@14"
            ]
        },
        {
            "x": -1,
            "y": 9,
            "z": 4,
            "elements": [
                "mekanism:reinforcedplasticblock@14"
            ]
        },
        {
            "x": -4,
            "y": 1,
            "z": 0,
            "elements": [
                "minecraft:planks@0"
            ]
        },
        {
            "x": 0,
            "y": 9,
            "z": 4,
            "elements": [
                "mekanism:glowplasticblock@11"
            ]
        },
        {
            "x": 1,
            "y": 9,
            "z": 4,
            "elements": [
                "mekanism:reinforcedplasticblock@14"
            ]
        },
        {
            "x": 2,
            "y": 9,
            "z": 4,
            "elements": [
                "mekanism:reinforcedplasticblock@14"
            ]
        },
        {
            "x": 3,
            "y": 9,
            "z": 4,
            "elements": [
                "mekanism:reinforcedplasticblock@14"
            ]
        },
        {
            "x": 0,
            "y": 1,
            "z": 0,
            "elements": [
                "mekanism:glowplasticblock@0"
            ]
        },
        {
            "x": 4,
            "y": 9,
            "z": 4,
            "elements": [
                "mekanism:reinforcedplasticblock@14"
            ]
        },
        {
            "x": 1,
            "y": 1,
            "z": 0,
            "elements": [
                "mekanism:glowplasticblock@0"
            ]
        },
        {
            "x": 5,
            "y": 9,
            "z": 4,
            "elements": [
                "mekanism:glowplasticblock@11"
            ]
        },
        {
            "x": 5,
            "y": 7,
            "z": 3,
            "elements": [
                "mekanism:reinforcedplasticblock@14"
            ]
        },
        {
            "x": 5,
            "y": 5,
            "z": 2,
            "elements": [
                "mekanism:reinforcedplasticblock@14"
            ]
        },
        {
            "x": 4,
            "y": 1,
            "z": 0,
            "elements": [
                "minecraft:planks@0"
            ]
        },
        {
            "x": 5,
            "y": 3,
            "z": 1,
            "elements": [
                "mekanism:reinforcedplasticblock@14"
            ]
        },
        {
            "x": 5,
            "y": 1,
            "z": 0,
            "elements": [
                "mekanism:reinforcedplasticblock@14"
            ]
        },
        {
            "x": -7,
            "y": -1,
            "z": 0,
            "elements": [
                "mekanism:slickplasticblock@2"
            ]
        },
        {
            "x": -5,
            "y": 8,
            "z": 3,
            "elements": [
                "mekanism:reinforcedplasticblock@14"
            ]
        },
        {
            "x": -5,
            "y": 6,
            "z": 2,
            "elements": [
                "mekanism:reinforcedplasticblock@14"
            ]
        },
        {
            "x": -5,
            "y": 4,
            "z": 1,
            "elements": [
                "mekanism:glowplasticblock@11"
            ]
        },
        {
            "x": -5,
            "y": 2,
            "z": 0,
            "elements": [
                "mekanism:reinforcedplasticblock@14"
            ]
        },
        {
            "x": -4,
            "y": 2,
            "z": 0,
            "elements": [
                "minecraft:planks@0"
            ]
        },
        {
            "x": 5,
            "y": 8,
            "z": 3,
            "elements": [
                "mekanism:reinforcedplasticblock@14"
            ]
        },
        {
            "x": 5,
            "y": 6,
            "z": 2,
            "elements": [
                "mekanism:reinforcedplasticblock@14"
            ]
        },
        {
            "x": 4,
            "y": 2,
            "z": 0,
            "elements": [
                "minecraft:planks@0"
            ]
        },
        {
            "x": 5,
            "y": 4,
            "z": 1,
            "elements": [
                "mekanism:glowplasticblock@11"
            ]
        },
        {
            "x": 5,
            "y": 2,
            "z": 0,
            "elements": [
                "mekanism:reinforcedplasticblock@14"
            ]
        },
        {
            "x": -5,
            "y": 9,
            "z": 3,
            "elements": [
                "mekanism:glowplasticblock@11"
            ]
        },
        {
            "x": -5,
            "y": 7,
            "z": 2,
            "elements": [
                "mekanism:reinforcedplasticblock@14"
            ]
        },
        {
            "x": -4,
            "y": 9,
            "z": 3,
            "elements": [
                "mekanism:reinforcedplasticblock@14"
            ]
        },
        {
            "x": -5,
            "y": 5,
            "z": 1,
            "elements": [
                "mekanism:reinforcedplasticblock@14"
            ]
        },
        {
            "x": -3,
            "y": 9,
            "z": 3,
            "elements": [
                "mekanism:reinforcedplasticblock@14"
            ]
        },
        {
            "x": -5,
            "y": 3,
            "z": 0,
            "elements": [
                "mekanism:reinforcedplasticblock@14"
            ]
        },
        {
            "x": -2,
            "y": 9,
            "z": 3,
            "elements": [
                "mekanism:reinforcedplasticblock@14"
            ]
        },
        {
            "x": -4,
            "y": 3,
            "z": 0,
            "elements": [
                "minecraft:planks@0"
            ]
        },
        {
            "x": -1,
            "y": 9,
            "z": 3,
            "elements": [
                "mekanism:reinforcedplasticblock@14"
            ]
        },
        {
            "x": 0,
            "y": 9,
            "z": 3,
            "elements": [
                "mekanism:glowplasticblock@11"
            ]
        },
        {
            "x": 1,
            "y": 9,
            "z": 3,
            "elements": [
                "mekanism:reinforcedplasticblock@14"
            ]
        },
        {
            "x": 2,
            "y": 9,
            "z": 3,
            "elements": [
                "mekanism:reinforcedplasticblock@14"
            ]
        },
        {
            "x": 3,
            "y": 9,
            "z": 3,
            "elements": [
                "mekanism:reinforcedplasticblock@14"
            ]
        },
        {
            "x": 4,
            "y": 9,
            "z": 3,
            "elements": [
                "mekanism:reinforcedplasticblock@14"
            ]
        },
        {
            "x": 5,
            "y": 9,
            "z": 3,
            "elements": [
                "mekanism:glowplasticblock@11"
            ]
        },
        {
            "x": 5,
            "y": 7,
            "z": 2,
            "elements": [
                "mekanism:reinforcedplasticblock@14"
            ]
        },
        {
            "x": 4,
            "y": 3,
            "z": 0,
            "elements": [
                "minecraft:planks@0"
            ]
        },
        {
            "x": 5,
            "y": 5,
            "z": 1,
            "elements": [
                "mekanism:reinforcedplasticblock@14"
            ]
        },
        {
            "x": 5,
            "y": 3,
            "z": 0,
            "elements": [
                "mekanism:reinforcedplasticblock@14"
            ]
        },
        {
            "x": -5,
            "y": 8,
            "z": 2,
            "elements": [
                "mekanism:reinforcedplasticblock@14"
            ]
        },
        {
            "x": -5,
            "y": 6,
            "z": 1,
            "elements": [
                "mekanism:reinforcedplasticblock@14"
            ]
        },
        {
            "x": -5,
            "y": 4,
            "z": 0,
            "elements": [
                "mekanism:glowplasticblock@11"
            ]
        },
        {
            "x": -4,
            "y": 4,
            "z": 0,
            "elements": [
                "mekanism:glowplasticblock@12"
            ]
        },
        {
            "x": 5,
            "y": 8,
            "z": 2,
            "elements": [
                "mekanism:reinforcedplasticblock@14"
            ]
        },
        {
            "x": 5,
            "y": 6,
            "z": 1,
            "elements": [
                "mekanism:reinforcedplasticblock@14"
            ]
        },
        {
            "x": 4,
            "y": 4,
            "z": 0,
            "elements": [
                "mekanism:glowplasticblock@12"
            ]
        },
        {
            "x": 5,
            "y": 4,
            "z": 0,
            "elements": [
                "mekanism:glowplasticblock@11"
            ]
        },
        {
            "x": -5,
            "y": 9,
            "z": 2,
            "elements": [
                "mekanism:glowplasticblock@11"
            ]
        },
        {
            "x": -5,
            "y": 7,
            "z": 1,
            "elements": [
                "mekanism:reinforcedplasticblock@14"
            ]
        },
        {
            "x": -4,
            "y": 9,
            "z": 2,
            "elements": [
                "mekanism:reinforcedplasticblock@14"
            ]
        },
        {
            "x": -5,
            "y": 5,
            "z": 0,
            "elements": [
                "mekanism:reinforcedplasticblock@14"
            ]
        },
        {
            "x": -3,
            "y": 9,
            "z": 2,
            "elements": [
                "mekanism:reinforcedplasticblock@14"
            ]
        },
        {
            "x": -2,
            "y": 9,
            "z": 2,
            "elements": [
                "mekanism:reinforcedplasticblock@14"
            ]
        },
        {
            "x": -1,
            "y": 9,
            "z": 2,
            "elements": [
                "mekanism:reinforcedplasticblock@14"
            ]
        },
        {
            "x": 0,
            "y": 9,
            "z": 2,
            "elements": [
                "mekanism:glowplasticblock@11"
            ]
        },
        {
            "x": 1,
            "y": 9,
            "z": 2,
            "elements": [
                "mekanism:reinforcedplasticblock@14"
            ]
        },
        {
            "x": 2,
            "y": 9,
            "z": 2,
            "elements": [
                "mekanism:reinforcedplasticblock@14"
            ]
        },
        {
            "x": 3,
            "y": 9,
            "z": 2,
            "elements": [
                "mekanism:reinforcedplasticblock@14"
            ]
        },
        {
            "x": 4,
            "y": 9,
            "z": 2,
            "elements": [
                "mekanism:reinforcedplasticblock@14"
            ]
        },
        {
            "x": 5,
            "y": 9,
            "z": 2,
            "elements": [
                "mekanism:glowplasticblock@11"
            ]
        },
        {
            "x": 5,
            "y": 7,
            "z": 1,
            "elements": [
                "mekanism:reinforcedplasticblock@14"
            ]
        },
        {
            "x": 5,
            "y": 5,
            "z": 0,
            "elements": [
                "mekanism:reinforcedplasticblock@14"
            ]
        },
        {
            "x": -5,
            "y": 8,
            "z": 1,
            "elements": [
                "mekanism:reinforcedplasticblock@14"
            ]
        },
        {
            "x": -5,
            "y": 6,
            "z": 0,
            "elements": [
                "mekanism:reinforcedplasticblock@14"
            ]
        },
        {
            "x": 5,
            "y": 8,
            "z": 1,
            "elements": [
                "mekanism:reinforcedplasticblock@14"
            ]
        },
        {
            "x": 5,
            "y": 6,
            "z": 0,
            "elements": [
                "mekanism:reinforcedplasticblock@14"
            ]
        },
        {
            "x": -5,
            "y": 9,
            "z": 1,
            "elements": [
                "mekanism:glowplasticblock@11"
            ]
        },
        {
            "x": -5,
            "y": 7,
            "z": 0,
            "elements": [
                "mekanism:reinforcedplasticblock@14"
            ]
        },
        {
            "x": -4,
            "y": 9,
            "z": 1,
            "elements": [
                "mekanism:reinforcedplasticblock@14"
            ]
        },
        {
            "x": -3,
            "y": 9,
            "z": 1,
            "elements": [
                "mekanism:reinforcedplasticblock@14"
            ]
        },
        {
            "x": -2,
            "y": 9,
            "z": 1,
            "elements": [
                "mekanism:reinforcedplasticblock@14"
            ]
        },
        {
            "x": -1,
            "y": 9,
            "z": 1,
            "elements": [
                "mekanism:reinforcedplasticblock@14"
            ]
        },
        {
            "x": 0,
            "y": 9,
            "z": 1,
            "elements": [
                "mekanism:glowplasticblock@11"
            ]
        },
        {
            "x": 1,
            "y": 9,
            "z": 1,
            "elements": [
                "mekanism:reinforcedplasticblock@14"
            ]
        },
        {
            "x": 2,
            "y": 9,
            "z": 1,
            "elements": [
                "mekanism:reinforcedplasticblock@14"
            ]
        },
        {
            "x": 3,
            "y": 9,
            "z": 1,
            "elements": [
                "mekanism:reinforcedplasticblock@14"
            ]
        },
        {
            "x": 4,
            "y": 9,
            "z": 1,
            "elements": [
                "mekanism:reinforcedplasticblock@14"
            ]
        },
        {
            "x": 5,
            "y": 9,
            "z": 1,
            "elements": [
                "mekanism:glowplasticblock@11"
            ]
        },
        {
            "x": 5,
            "y": 7,
            "z": 0,
            "elements": [
                "mekanism:reinforcedplasticblock@14"
            ]
        },
        {
            "x": -7,
            "y": -1,
            "z": 12,
            "elements": [
                "mekanism:slickplasticblock@2"
            ]
        },
        {
            "x": -5,
            "y": 8,
            "z": 0,
            "elements": [
                "mekanism:reinforcedplasticblock@14"
            ]
        },
        {
            "x": 7,
            "y": -1,
            "z": 12,
            "elements": [
                "mekanism:slickplasticblock@2"
            ]
        },
        {
            "x": 5,
            "y": 8,
            "z": 0,
            "elements": [
                "mekanism:reinforcedplasticblock@14"
            ]
        },
        {
            "x": 0,
            "y": 4,
            "z": 14,
            "elements": [
                "mekanism:glowplasticblock@5"
            ]
        },
        {
            "x": -5,
            "y": 9,
            "z": 0,
            "elements": [
                "mekanism:glowplasticblock@11"
            ]
        },
        {
            "x": -4,
            "y": 9,
            "z": 0,
            "elements": [
                "mekanism:reinforcedplasticblock@14"
            ]
        },
        {
            "x": -3,
            "y": 9,
            "z": 0,
            "elements": [
                "mekanism:reinforcedplasticblock@14"
            ]
        },
        {
            "x": -2,
            "y": 9,
            "z": 0,
            "elements": [
                "mekanism:reinforcedplasticblock@14"
            ]
        },
        {
            "x": -1,
            "y": 9,
            "z": 0,
            "elements": [
                "mekanism:reinforcedplasticblock@14"
            ]
        },
        {
            "x": 0,
            "y": 9,
            "z": 0,
            "elements": [
                "mekanism:glowplasticblock@11"
            ]
        },
        {
            "x": 1,
            "y": 9,
            "z": 0,
            "elements": [
                "mekanism:reinforcedplasticblock@14"
            ]
        },
        {
            "x": 2,
            "y": 9,
            "z": 0,
            "elements": [
                "mekanism:reinforcedplasticblock@14"
            ]
        },
        {
            "x": 3,
            "y": 9,
            "z": 0,
            "elements": [
                "mekanism:reinforcedplasticblock@14"
            ]
        },
        {
            "x": 4,
            "y": 9,
            "z": 0,
            "elements": [
                "mekanism:reinforcedplasticblock@14"
            ]
        },
        {
            "x": 5,
            "y": 9,
            "z": 0,
            "elements": [
                "mekanism:glowplasticblock@11"
            ]
        },
        {
            "x": -6,
            "y": -1,
            "z": 11,
            "elements": [
                "mekanism:slickplasticblock@2"
            ]
        },
        {
            "x": -5,
            "y": -1,
            "z": 11,
            "elements": [
                "mekanism:slickplasticblock@2"
            ]
        },
        {
            "x": 5,
            "y": -1,
            "z": 11,
            "elements": [
                "mekanism:slickplasticblock@2"
            ]
        },
        {
            "x": 6,
            "y": -1,
            "z": 11,
            "elements": [
                "mekanism:slickplasticblock@2"
            ]
        },
        {
            "x": 0,
            "y": 4,
            "z": 13,
            "elements": [
                "minecraft:concrete@15"
            ]
        },
        {
            "x": -6,
            "y": -1,
            "z": 10,
            "elements": [
                "mekanism:slickplasticblock@2"
            ]
        },
        {
            "x": -5,
            "y": -1,
            "z": 10,
            "elements": [
                "mekanism:slickplasticblock@2"
            ]
        },
        {
            "x": -4,
            "y": 1,
            "z": 11,
            "elements": [
                "mekanism:reinforcedplasticblock@14"
            ]
        },
        {
            "x": -4,
            "y": -1,
            "z": 10,
            "elements": [
                "mekanism:slickplasticblock@2"
            ]
        },
        {
            "x": -3,
            "y": 1,
            "z": 11,
            "elements": [
                "mekanism:glowplasticblock@11"
            ]
        },
        {
            "x": -2,
            "y": 1,
            "z": 11,
            "elements": [
                "mekanism:reinforcedplasticblock@14"
            ]
        },
        {
            "x": -1,
            "y": 1,
            "z": 11,
            "elements": [
                "mekanism:reinforcedplasticblock@14"
            ]
        },
        {
            "x": 0,
            "y": 1,
            "z": 11,
            "elements": [
                "mekanism:glowplasticblock@11"
            ]
        },
        {
            "x": 1,
            "y": 1,
            "z": 11,
            "elements": [
                "mekanism:reinforcedplasticblock@14"
            ]
        },
        {
            "x": 2,
            "y": 1,
            "z": 11,
            "elements": [
                "mekanism:reinforcedplasticblock@14"
            ]
        },
        {
            "x": 3,
            "y": 1,
            "z": 11,
            "elements": [
                "mekanism:glowplasticblock@11"
            ]
        },
        {
            "x": 4,
            "y": 1,
            "z": 11,
            "elements": [
                "mekanism:reinforcedplasticblock@14"
            ]
        },
        {
            "x": 4,
            "y": -1,
            "z": 10,
            "elements": [
                "mekanism:slickplasticblock@2"
            ]
        },
        {
            "x": 5,
            "y": -1,
            "z": 10,
            "elements": [
                "mekanism:slickplasticblock@2"
            ]
        },
        {
            "x": 6,
            "y": -1,
            "z": 10,
            "elements": [
                "mekanism:slickplasticblock@2"
            ]
        },
        {
            "x": -4,
            "y": 2,
            "z": 11,
            "elements": [
                "mekanism:reinforcedplasticblock@14"
            ]
        },
        {
            "x": -4,
            "y": 0,
            "z": 10,
            "elements": [
                "mekanism:glowplasticblock@11"
            ]
        },
        {
            "x": -3,
            "y": 2,
            "z": 11,
            "elements": [
                "mekanism:reinforcedplasticblock@14"
            ]
        },
        {
            "x": -3,
            "y": 0,
            "z": 10,
            "elements": [
                "mekanism:reinforcedplasticblock@14"
            ]
        },
        {
            "x": -2,
            "y": 2,
            "z": 11,
            "elements": [
                "mekanism:glowplasticblock@11"
            ]
        },
        {
            "x": -2,
            "y": 0,
            "z": 10,
            "elements": [
                "mekanism:reinforcedplasticblock@14"
            ]
        },
        {
            "x": -1,
            "y": 2,
            "z": 11,
            "elements": [
                "mekanism:reinforcedplasticblock@14"
            ]
        },
        {
            "x": 0,
            "y": 4,
            "z": 12,
            "elements": [
                "minecraft:concrete@15"
            ]
        },
        {
            "x": -1,
            "y": 0,
            "z": 10,
            "elements": [
                "mekanism:reinforcedplasticblock@14"
            ]
        },
        {
            "x": 0,
            "y": 2,
            "z": 11,
            "elements": [
                "mekanism:glowplasticblock@11"
            ]
        },
        {
            "x": 0,
            "y": 0,
            "z": 10,
            "elements": [
                "mekanism:glowplasticblock@11"
            ]
        },
        {
            "x": 1,
            "y": 2,
            "z": 11,
            "elements": [
                "mekanism:reinforcedplasticblock@14"
            ]
        },
        {
            "x": 1,
            "y": 0,
            "z": 10,
            "elements": [
                "mekanism:reinforcedplasticblock@14"
            ]
        },
        {
            "x": 2,
            "y": 2,
            "z": 11,
            "elements": [
                "mekanism:glowplasticblock@11"
            ]
        },
        {
            "x": 2,
            "y": 0,
            "z": 10,
            "elements": [
                "mekanism:reinforcedplasticblock@14"
            ]
        },
        {
            "x": 3,
            "y": 2,
            "z": 11,
            "elements": [
                "mekanism:reinforcedplasticblock@14"
            ]
        },
        {
            "x": 3,
            "y": 0,
            "z": 10,
            "elements": [
                "mekanism:reinforcedplasticblock@14"
            ]
        },
        {
            "x": 4,
            "y": 2,
            "z": 11,
            "elements": [
                "mekanism:reinforcedplasticblock@14"
            ]
        },
        {
            "x": 4,
            "y": 0,
            "z": 10,
            "elements": [
                "mekanism:glowplasticblock@11"
            ]
        },
        {
            "x": -5,
            "y": 1,
            "z": 10,
            "elements": [
                "mekanism:reinforcedplasticblock@14"
            ]
        },
        {
            "x": -4,
            "y": 3,
            "z": 11,
            "elements": [
                "mekanism:reinforcedplasticblock@14"
            ]
        },
        {
            "x": -5,
            "y": -1,
            "z": 9,
            "elements": [
                "mekanism:slickplasticblock@2"
            ]
        },
        {
            "x": -4,
            "y": 1,
            "z": 10,
            "elements": [
                "minecraft:planks@0"
            ]
        },
        {
            "x": -3,
            "y": 3,
            "z": 11,
            "elements": [
                "mekanism:reinforcedplasticblock@14"
            ]
        },
        {
            "x": -4,
            "y": -1,
            "z": 9,
            "elements": [
                "mekanism:slickplasticblock@2"
            ]
        },
        {
            "x": -2,
            "y": 3,
            "z": 11,
            "elements": [
                "mekanism:reinforcedplasticblock@14"
            ]
        },
        {
            "x": -3,
            "y": -1,
            "z": 9,
            "elements": [
                "mekanism:slickplasticblock@2"
            ]
        },
        {
            "x": -1,
            "y": 3,
            "z": 11,
            "elements": [
                "mekanism:glowplasticblock@11"
            ]
        },
        {
            "x": -2,
            "y": -1,
            "z": 9,
            "elements": [
                "mekanism:slickplasticblock@2"
            ]
        },
        {
            "x": -1,
            "y": 1,
            "z": 10,
            "elements": [
                "mekanism:glowplasticblock@0"
            ]
        },
        {
            "x": 0,
            "y": 3,
            "z": 11,
            "elements": [
                "mekanism:glowplasticblock@11"
            ]
        },
        {
            "x": 0,
            "y": 1,
            "z": 10,
            "elements": [
                "mekanism:glowplasticblock@0"
            ]
        },
        {
            "x": 1,
            "y": 3,
            "z": 11,
            "elements": [
                "mekanism:glowplasticblock@11"
            ]
        },
        {
            "x": 1,
            "y": 1,
            "z": 10,
            "elements": [
                "mekanism:glowplasticblock@0"
            ]
        },
        {
            "x": 2,
            "y": 3,
            "z": 11,
            "elements": [
                "mekanism:reinforcedplasticblock@14"
            ]
        },
        {
            "x": 3,
            "y": 3,
            "z": 11,
            "elements": [
                "mekanism:reinforcedplasticblock@14"
            ]
        },
        {
            "x": 2,
            "y": -1,
            "z": 9,
            "elements": [
                "mekanism:slickplasticblock@2"
            ]
        },
        {
            "x": 4,
            "y": 3,
            "z": 11,
            "elements": [
                "mekanism:reinforcedplasticblock@14"
            ]
        },
        {
            "x": 3,
            "y": -1,
            "z": 9,
            "elements": [
                "mekanism:slickplasticblock@2"
            ]
        },
        {
            "x": 4,
            "y": 1,
            "z": 10,
            "elements": [
                "minecraft:planks@0"
            ]
        },
        {
            "x": 4,
            "y": -1,
            "z": 9,
            "elements": [
                "mekanism:slickplasticblock@2"
            ]
        },
        {
            "x": 5,
            "y": 1,
            "z": 10,
            "elements": [
                "mekanism:reinforcedplasticblock@14"
            ]
        },
        {
            "x": 5,
            "y": -1,
            "z": 9,
            "elements": [
                "mekanism:slickplasticblock@2"
            ]
        },
        {
            "x": -5,
            "y": 2,
            "z": 10,
            "elements": [
                "mekanism:reinforcedplasticblock@14"
            ]
        },
        {
            "x": -4,
            "y": 4,
            "z": 11,
            "elements": [
                "mekanism:glowplasticblock@11"
            ]
        },
        {
            "x": -4,
            "y": 2,
            "z": 10,
            "elements": [
                "minecraft:planks@0"
            ]
        },
        {
            "x": -3,
            "y": 4,
            "z": 11,
            "elements": [
                "mekanism:glowplasticblock@11"
            ]
        },
        {
            "x": -4,
            "y": 0,
            "z": 9,
            "elements": [
                "mekanism:glowplasticblock@11"
            ]
        },
        {
            "x": -2,
            "y": 4,
            "z": 11,
            "elements": [
                "mekanism:glowplasticblock@11"
            ]
        },
        {
            "x": -3,
            "y": 0,
            "z": 9,
            "elements": [
                "mekanism:reinforcedplasticblock@14"
            ]
        },
        {
            "x": -1,
            "y": 4,
            "z": 11,
            "elements": [
                "mekanism:glowplasticblock@11"
            ]
        },
        {
            "x": -2,
            "y": 0,
            "z": 9,
            "elements": [
                "mekanism:reinforcedplasticblock@14"
            ]
        },
        {
            "x": 0,
            "y": 4,
            "z": 11,
            "elements": [
                "minecraft:concrete@15"
            ]
        },
        {
            "x": -1,
            "y": 0,
            "z": 9,
            "elements": [
                "mekanism:reinforcedplasticblock@14"
            ]
        },
        {
            "x": 1,
            "y": 4,
            "z": 11,
            "elements": [
                "mekanism:glowplasticblock@11"
            ]
        },
        {
            "x": 0,
            "y": 0,
            "z": 9,
            "elements": [
                "mekanism:glowplasticblock@11"
            ]
        },
        {
            "x": 2,
            "y": 4,
            "z": 11,
            "elements": [
                "mekanism:glowplasticblock@11"
            ]
        },
        {
            "x": 1,
            "y": 0,
            "z": 9,
            "elements": [
                "mekanism:reinforcedplasticblock@14"
            ]
        },
        {
            "x": 3,
            "y": 4,
            "z": 11,
            "elements": [
                "mekanism:glowplasticblock@11"
            ]
        },
        {
            "x": 2,
            "y": 0,
            "z": 9,
            "elements": [
                "mekanism:reinforcedplasticblock@14"
            ]
        },
        {
            "x": 4,
            "y": 4,
            "z": 11,
            "elements": [
                "mekanism:glowplasticblock@11"
            ]
        },
        {
            "x": 3,
            "y": 0,
            "z": 9,
            "elements": [
                "mekanism:reinforcedplasticblock@14"
            ]
        },
        {
            "x": 4,
            "y": 2,
            "z": 10,
            "elements": [
                "minecraft:planks@0"
            ]
        },
        {
            "x": 4,
            "y": 0,
            "z": 9,
            "elements": [
                "mekanism:glowplasticblock@11"
            ]
        },
        {
            "x": 5,
            "y": 2,
            "z": 10,
            "elements": [
                "mekanism:reinforcedplasticblock@14"
            ]
        },
        {
            "x": -5,
            "y": 3,
            "z": 10,
            "elements": [
                "mekanism:reinforcedplasticblock@14"
            ]
        },
        {
            "x": -4,
            "y": 5,
            "z": 11,
            "elements": [
                "mekanism:reinforcedplasticblock@14"
            ]
        },
        {
            "x": -5,
            "y": 1,
            "z": 9,
            "elements": [
                "mekanism:reinforcedplasticblock@14"
            ]
        },
        {
            "x": -4,
            "y": 3,
            "z": 10,
            "elements": [
                "minecraft:planks@0"
            ]
        },
        {
            "x": -3,
            "y": 5,
            "z": 11,
            "elements": [
                "mekanism:reinforcedplasticblock@14"
            ]
        },
        {
            "x": -2,
            "y": 5,
            "z": 11,
            "elements": [
                "mekanism:reinforcedplasticblock@14"
            ]
        },
        {
            "x": -4,
            "y": -1,
            "z": 8,
            "elements": [
                "mekanism:slickplasticblock@2"
            ]
        },
        {
            "x": -1,
            "y": 5,
            "z": 11,
            "elements": [
                "mekanism:glowplasticblock@11"
            ]
        },
        {
            "x": -3,
            "y": -1,
            "z": 8,
            "elements": [
                "mekanism:slickplasticblock@2"
            ]
        },
        {
            "x": -2,
            "y": 1,
            "z": 9,
            "elements": [
                "mekanism:glowplasticblock@0"
            ]
        },
        {
            "x": 0,
            "y": 5,
            "z": 11,
            "elements": [
                "modularmachinery:blockoutputbus"
            ]
        },
        {
            "x": -2,
            "y": -1,
            "z": 8,
            "elements": [
                "mekanism:slickplasticblock@2"
            ]
        },
        {
            "x": -1,
            "y": 1,
            "z": 9,
            "elements": [
                "appliedenergistics2:quartz_block@0"
            ]
        },
        {
            "x": 1,
            "y": 5,
            "z": 11,
            "elements": [
                "mekanism:glowplasticblock@11"
            ]
        },
        {
            "x": 0,
            "y": 1,
            "z": 9,
            "elements": [
                "appliedenergistics2:quartz_block@0"
            ]
        },
        {
            "x": 2,
            "y": 5,
            "z": 11,
            "elements": [
                "mekanism:reinforcedplasticblock@14"
            ]
        },
        {
            "x": 1,
            "y": 1,
            "z": 9,
            "elements": [
                "appliedenergistics2:quartz_block@0"
            ]
        },
        {
            "x": 3,
            "y": 5,
            "z": 11,
            "elements": [
                "mekanism:reinforcedplasticblock@14"
            ]
        },
        {
            "x": 2,
            "y": 1,
            "z": 9,
            "elements": [
                "mekanism:glowplasticblock@0"
            ]
        },
        {
            "x": 4,
            "y": 5,
            "z": 11,
            "elements": [
                "mekanism:reinforcedplasticblock@14"
            ]
        },
        {
            "x": 2,
            "y": -1,
            "z": 8,
            "elements": [
                "mekanism:slickplasticblock@2"
            ]
        },
        {
            "x": 4,
            "y": 3,
            "z": 10,
            "elements": [
                "minecraft:planks@0"
            ]
        },
        {
            "x": 3,
            "y": -1,
            "z": 8,
            "elements": [
                "mekanism:slickplasticblock@2"
            ]
        },
        {
            "x": 5,
            "y": 3,
            "z": 10,
            "elements": [
                "mekanism:reinforcedplasticblock@14"
            ]
        },
        {
            "x": 4,
            "y": -1,
            "z": 8,
            "elements": [
                "mekanism:slickplasticblock@2"
            ]
        },
        {
            "x": 5,
            "y": 1,
            "z": 9,
            "elements": [
                "mekanism:reinforcedplasticblock@14"
            ]
        },
        {
            "x": -5,
            "y": 4,
            "z": 10,
            "elements": [
                "mekanism:glowplasticblock@11"
            ]
        },
        {
            "x": -4,
            "y": 6,
            "z": 11,
            "elements": [
                "mekanism:reinforcedplasticblock@14"
            ]
        },
        {
            "x": -5,
            "y": 2,
            "z": 9,
            "elements": [
                "mekanism:reinforcedplasticblock@14"
            ]
        },
        {
            "x": -4,
            "y": 4,
            "z": 10,
            "elements": [
                "mekanism:glowplasticblock@12"
            ]
        },
        {
            "x": -3,
            "y": 6,
            "z": 11,
            "elements": [
                "mekanism:reinforcedplasticblock@14"
            ]
        },
        {
            "x": -2,
            "y": 6,
            "z": 11,
            "elements": [
                "mekanism:glowplasticblock@11"
            ]
        },
        {
            "x": -4,
            "y": 0,
            "z": 8,
            "elements": [
                "mekanism:glowplasticblock@11"
            ]
        },
        {
            "x": -1,
            "y": 6,
            "z": 11,
            "elements": [
                "mekanism:reinforcedplasticblock@14"
            ]
        },
        {
            "x": -3,
            "y": 0,
            "z": 8,
            "elements": [
                "mekanism:reinforcedplasticblock@14"
            ]
        },
        {
            "x": 0,
            "y": 6,
            "z": 11,
            "elements": [
                "mekanism:glowplasticblock@11"
            ]
        },
        {
            "x": -2,
            "y": 0,
            "z": 8,
            "elements": [
                "mekanism:reinforcedplasticblock@14"
            ]
        },
        {
            "x": 1,
            "y": 6,
            "z": 11,
            "elements": [
                "mekanism:reinforcedplasticblock@14"
            ]
        },
        {
            "x": -1,
            "y": 0,
            "z": 8,
            "elements": [
                "mekanism:reinforcedplasticblock@14"
            ]
        },
        {
            "x": 2,
            "y": 6,
            "z": 11,
            "elements": [
                "mekanism:glowplasticblock@11"
            ]
        },
        {
            "x": 0,
            "y": 0,
            "z": 8,
            "elements": [
                "mekanism:glowplasticblock@11"
            ]
        },
        {
            "x": 3,
            "y": 6,
            "z": 11,
            "elements": [
                "mekanism:reinforcedplasticblock@14"
            ]
        },
        {
            "x": 1,
            "y": 0,
            "z": 8,
            "elements": [
                "mekanism:reinforcedplasticblock@14"
            ]
        },
        {
            "x": 4,
            "y": 6,
            "z": 11,
            "elements": [
                "mekanism:reinforcedplasticblock@14"
            ]
        },
        {
            "x": 2,
            "y": 0,
            "z": 8,
            "elements": [
                "mekanism:reinforcedplasticblock@14"
            ]
        },
        {
            "x": 4,
            "y": 4,
            "z": 10,
            "elements": [
                "mekanism:glowplasticblock@12"
            ]
        },
        {
            "x": 3,
            "y": 0,
            "z": 8,
            "elements": [
                "mekanism:reinforcedplasticblock@14"
            ]
        },
        {
            "x": 5,
            "y": 4,
            "z": 10,
            "elements": [
                "mekanism:glowplasticblock@11"
            ]
        },
        {
            "x": 4,
            "y": 0,
            "z": 8,
            "elements": [
                "mekanism:glowplasticblock@11"
            ]
        },
        {
            "x": 5,
            "y": 2,
            "z": 9,
            "elements": [
                "mekanism:reinforcedplasticblock@14"
            ]
        },
        {
            "x": -5,
            "y": 5,
            "z": 10,
            "elements": [
                "mekanism:reinforcedplasticblock@14"
            ]
        },
        {
            "x": -4,
            "y": 7,
            "z": 11,
            "elements": [
                "mekanism:reinforcedplasticblock@14"
            ]
        },
        {
            "x": -5,
            "y": 3,
            "z": 9,
            "elements": [
                "mekanism:reinforcedplasticblock@14"
            ]
        },
        {
            "x": -3,
            "y": 7,
            "z": 11,
            "elements": [
                "mekanism:glowplasticblock@11"
            ]
        },
        {
            "x": -5,
            "y": 1,
            "z": 8,
            "elements": [
                "mekanism:reinforcedplasticblock@14"
            ]
        },
        {
            "x": -2,
            "y": 7,
            "z": 11,
            "elements": [
                "mekanism:reinforcedplasticblock@14"
            ]
        },
        {
            "x": -1,
            "y": 7,
            "z": 11,
            "elements": [
                "mekanism:reinforcedplasticblock@14"
            ]
        },
        {
            "x": -4,
            "y": -1,
            "z": 7,
            "elements": [
                "mekanism:slickplasticblock@2"
            ]
        },
        {
            "x": -3,
            "y": 1,
            "z": 8,
            "elements": [
                "mekanism:glowplasticblock@0"
            ]
        },
        {
            "x": 0,
            "y": 7,
            "z": 11,
            "elements": [
                "mekanism:glowplasticblock@11"
            ]
        },
        {
            "x": -3,
            "y": -1,
            "z": 7,
            "elements": [
                "mekanism:slickplasticblock@2"
            ]
        },
        {
            "x": -2,
            "y": 1,
            "z": 8,
            "elements": [
                "appliedenergistics2:quartz_block@0"
            ]
        },
        {
            "x": 1,
            "y": 7,
            "z": 11,
            "elements": [
                "mekanism:reinforcedplasticblock@14"
            ]
        },
        {
            "x": -1,
            "y": 1,
            "z": 8,
            "elements": [
                "appliedenergistics2:quartz_block@0"
            ]
        },
        {
            "x": 2,
            "y": 7,
            "z": 11,
            "elements": [
                "mekanism:reinforcedplasticblock@14"
            ]
        },
        {
            "x": 0,
            "y": 1,
            "z": 8,
            "elements": [
                "appliedenergistics2:quartz_block@0"
            ]
        },
        {
            "x": 3,
            "y": 7,
            "z": 11,
            "elements": [
                "mekanism:glowplasticblock@11"
            ]
        },
        {
            "x": 1,
            "y": 1,
            "z": 8,
            "elements": [
                "appliedenergistics2:quartz_block@0"
            ]
        },
        {
            "x": 4,
            "y": 7,
            "z": 11,
            "elements": [
                "mekanism:reinforcedplasticblock@14"
            ]
        },
        {
            "x": 2,
            "y": 1,
            "z": 8,
            "elements": [
                "appliedenergistics2:quartz_block@0"
            ]
        },
        {
            "x": 3,
            "y": 1,
            "z": 8,
            "elements": [
                "mekanism:glowplasticblock@0"
            ]
        },
        {
            "x": 5,
            "y": 5,
            "z": 10,
            "elements": [
                "mekanism:reinforcedplasticblock@14"
            ]
        },
        {
            "x": 3,
            "y": -1,
            "z": 7,
            "elements": [
                "mekanism:slickplasticblock@2"
            ]
        },
        {
            "x": 5,
            "y": 3,
            "z": 9,
            "elements": [
                "mekanism:reinforcedplasticblock@14"
            ]
        },
        {
            "x": 4,
            "y": -1,
            "z": 7,
            "elements": [
                "mekanism:slickplasticblock@2"
            ]
        },
        {
            "x": 5,
            "y": 1,
            "z": 8,
            "elements": [
                "mekanism:reinforcedplasticblock@14"
            ]
        },
        {
            "x": -5,
            "y": 6,
            "z": 10,
            "elements": [
                "mekanism:reinforcedplasticblock@14"
            ]
        },
        {
            "x": -4,
            "y": 8,
            "z": 11,
            "elements": [
                "mekanism:glowplasticblock@11"
            ]
        },
        {
            "x": -5,
            "y": 4,
            "z": 9,
            "elements": [
                "mekanism:glowplasticblock@11"
            ]
        },
        {
            "x": -3,
            "y": 8,
            "z": 11,
            "elements": [
                "mekanism:reinforcedplasticblock@14"
            ]
        },
        {
            "x": -5,
            "y": 2,
            "z": 8,
            "elements": [
                "mekanism:reinforcedplasticblock@14"
            ]
        },
        {
            "x": -2,
            "y": 8,
            "z": 11,
            "elements": [
                "mekanism:reinforcedplasticblock@14"
            ]
        },
        {
            "x": -1,
            "y": 8,
            "z": 11,
            "elements": [
                "mekanism:reinforcedplasticblock@14"
            ]
        },
        {
            "x": -4,
            "y": 0,
            "z": 7,
            "elements": [
                "mekanism:glowplasticblock@11"
            ]
        },
        {
            "x": 0,
            "y": 8,
            "z": 11,
            "elements": [
                "mekanism:glowplasticblock@11"
            ]
        },
        {
            "x": -3,
            "y": 0,
            "z": 7,
            "elements": [
                "mekanism:reinforcedplasticblock@14"
            ]
        },
        {
            "x": 1,
            "y": 8,
            "z": 11,
            "elements": [
                "mekanism:reinforcedplasticblock@14"
            ]
        },
        {
            "x": -2,
            "y": 0,
            "z": 7,
            "elements": [
                "mekanism:reinforcedplasticblock@14"
            ]
        },
        {
            "x": 2,
            "y": 8,
            "z": 11,
            "elements": [
                "mekanism:reinforcedplasticblock@14"
            ]
        },
        {
            "x": -1,
            "y": 0,
            "z": 7,
            "elements": [
                "mekanism:reinforcedplasticblock@14"
            ]
        },
        {
            "x": 3,
            "y": 8,
            "z": 11,
            "elements": [
                "mekanism:reinforcedplasticblock@14"
            ]
        },
        {
            "x": 0,
            "y": 0,
            "z": 7,
            "elements": [
                "mekanism:glowplasticblock@11"
            ]
        },
        {
            "x": 4,
            "y": 8,
            "z": 11,
            "elements": [
                "mekanism:glowplasticblock@11"
            ]
        },
        {
            "x": 1,
            "y": 0,
            "z": 7,
            "elements": [
                "mekanism:reinforcedplasticblock@14"
            ]
        },
        {
            "x": 2,
            "y": 0,
            "z": 7,
            "elements": [
                "mekanism:reinforcedplasticblock@14"
            ]
        },
        {
            "x": 5,
            "y": 6,
            "z": 10,
            "elements": [
                "mekanism:reinforcedplasticblock@14"
            ]
        },
        {
            "x": 3,
            "y": 0,
            "z": 7,
            "elements": [
                "mekanism:reinforcedplasticblock@14"
            ]
        },
        {
            "x": 5,
            "y": 4,
            "z": 9,
            "elements": [
                "mekanism:glowplasticblock@11"
            ]
        },
        {
            "x": 4,
            "y": 0,
            "z": 7,
            "elements": [
                "mekanism:glowplasticblock@11"
            ]
        },
        {
            "x": 5,
            "y": 2,
            "z": 8,
            "elements": [
                "mekanism:reinforcedplasticblock@14"
            ]
        },
        {
            "x": -5,
            "y": 7,
            "z": 10,
            "elements": [
                "mekanism:reinforcedplasticblock@14"
            ]
        },
        {
            "x": -5,
            "y": 5,
            "z": 9,
            "elements": [
                "mekanism:reinforcedplasticblock@14"
            ]
        },
        {
            "x": -5,
            "y": 3,
            "z": 8,
            "elements": [
                "mekanism:reinforcedplasticblock@14"
            ]
        },
        {
            "x": -5,
            "y": 1,
            "z": 7,
            "elements": [
                "mekanism:reinforcedplasticblock@14"
            ]
        },
        {
            "x": -4,
            "y": 1,
            "z": 7,
            "elements": [
                "mekanism:glowplasticblock@0"
            ]
        },
        {
            "x": -3,
            "y": 1,
            "z": 7,
            "elements": [
                "appliedenergistics2:quartz_block@0"
            ]
        },
        {
            "x": -2,
            "y": 1,
            "z": 7,
            "elements": [
                "appliedenergistics2:quartz_block@0"
            ]
        },
        {
            "x": -1,
            "y": 1,
            "z": 7,
            "elements": [
                "appliedenergistics2:quartz_block@0"
            ]
        },
        {
            "x": 0,
            "y": 1,
            "z": 7,
            "elements": [
                "appliedenergistics2:quartz_block@0"
            ]
        },
        {
            "x": 1,
            "y": 1,
            "z": 7,
            "elements": [
                "mekanism:glowplasticblock@0"
            ]
        },
        {
            "x": 2,
            "y": 1,
            "z": 7,
            "elements": [
                "appliedenergistics2:quartz_block@0"
            ]
        },
        {
            "x": 5,
            "y": 7,
            "z": 10,
            "elements": [
                "mekanism:reinforcedplasticblock@14"
            ]
        },
        {
            "x": 3,
            "y": 1,
            "z": 7,
            "elements": [
                "appliedenergistics2:quartz_block@0"
            ]
        },
        {
            "x": 5,
            "y": 5,
            "z": 9,
            "elements": [
                "mekanism:reinforcedplasticblock@14"
            ]
        },
        {
            "x": 4,
            "y": 1,
            "z": 7,
            "elements": [
                "mekanism:glowplasticblock@0"
            ]
        },
        {
            "x": 5,
            "y": 3,
            "z": 8,
            "elements": [
                "mekanism:reinforcedplasticblock@14"
            ]
        },
        {
            "x": 5,
            "y": 1,
            "z": 7,
            "elements": [
                "mekanism:reinforcedplasticblock@14"
            ]
        },
        {
            "x": -5,
            "y": 8,
            "z": 10,
            "elements": [
                "mekanism:reinforcedplasticblock@14"
            ]
        },
        {
            "x": -5,
            "y": 6,
            "z": 9,
            "elements": [
                "mekanism:reinforcedplasticblock@14"
            ]
        },
        {
            "x": -5,
            "y": 4,
            "z": 8,
            "elements": [
                "mekanism:glowplasticblock@11"
            ]
        },
        {
            "x": -5,
            "y": 2,
            "z": 7,
            "elements": [
                "mekanism:reinforcedplasticblock@14"
            ]
        },
        {
            "x": -4,
            "y": 0,
            "z": 6,
            "elements": [
                "mekanism:glowplasticblock@11"
            ]
        },
        {
            "x": -3,
            "y": 0,
            "z": 6,
            "elements": [
                "mekanism:reinforcedplasticblock@14"
            ]
        },
        {
            "x": -2,
            "y": 0,
            "z": 6,
            "elements": [
                "mekanism:reinforcedplasticblock@14"
            ]
        },
        {
            "x": -1,
            "y": 0,
            "z": 6,
            "elements": [
                "mekanism:reinforcedplasticblock@14"
            ]
        },
        {
            "x": 0,
            "y": 0,
            "z": 6,
            "elements": [
                "mekanism:glowplasticblock@11"
            ]
        },
        {
            "x": 1,
            "y": 0,
            "z": 6,
            "elements": [
                "mekanism:reinforcedplasticblock@14"
            ]
        },
        {
            "x": 5,
            "y": 8,
            "z": 10,
            "elements": [
                "mekanism:reinforcedplasticblock@14"
            ]
        },
        {
            "x": 2,
            "y": 0,
            "z": 6,
            "elements": [
                "mekanism:reinforcedplasticblock@14"
            ]
        },
        {
            "x": 5,
            "y": 6,
            "z": 9,
            "elements": [
                "mekanism:reinforcedplasticblock@14"
            ]
        },
        {
            "x": 3,
            "y": 0,
            "z": 6,
            "elements": [
                "mekanism:reinforcedplasticblock@14"
            ]
        },
        {
            "x": 5,
            "y": 4,
            "z": 8,
            "elements": [
                "mekanism:glowplasticblock@11"
            ]
        },
        {
            "x": 4,
            "y": 0,
            "z": 6,
            "elements": [
                "mekanism:glowplasticblock@11"
            ]
        },
        {
            "x": 5,
            "y": 2,
            "z": 7,
            "elements": [
                "mekanism:reinforcedplasticblock@14"
            ]
        },
        {
            "x": -5,
            "y": 9,
            "z": 10,
            "elements": [
                "mekanism:glowplasticblock@11"
            ]
        },
        {
            "x": -5,
            "y": 7,
            "z": 9,
            "elements": [
                "mekanism:reinforcedplasticblock@14"
            ]
        },
        {
            "x": -4,
            "y": 9,
            "z": 10,
            "elements": [
                "mekanism:reinforcedplasticblock@14"
            ]
        },
        {
            "x": -5,
            "y": 5,
            "z": 8,
            "elements": [
                "mekanism:reinforcedplasticblock@14"
            ]
        },
        {
            "x": -3,
            "y": 9,
            "z": 10,
            "elements": [
                "mekanism:reinforcedplasticblock@14"
            ]
        },
        {
            "x": -5,
            "y": 3,
            "z": 7,
            "elements": [
                "mekanism:reinforcedplasticblock@14"
            ]
        },
        {
            "x": -2,
            "y": 9,
            "z": 10,
            "elements": [
                "mekanism:reinforcedplasticblock@14"
            ]
        },
        {
            "x": -5,
            "y": 1,
            "z": 6,
            "elements": [
                "mekanism:reinforcedplasticblock@14"
            ]
        },
        {
            "x": -1,
            "y": 9,
            "z": 10,
            "elements": [
                "mekanism:reinforcedplasticblock@14"
            ]
        },
        {
            "x": -4,
            "y": 1,
            "z": 6,
            "elements": [
                "mekanism:glowplasticblock@0"
            ]
        },
        {
            "x": 0,
            "y": 9,
            "z": 10,
            "elements": [
                "mekanism:glowplasticblock@11"
            ]
        },
        {
            "x": -4,
            "y": -1,
            "z": 5,
            "elements": [
                "mekanism:slickplasticblock@2"
            ]
        },
        {
            "x": -3,
            "y": 1,
            "z": 6,
            "elements": [
                "appliedenergistics2:quartz_block@0"
            ]
        },
        {
            "x": 1,
            "y": 9,
            "z": 10,
            "elements": [
                "mekanism:reinforcedplasticblock@14"
            ]
        },
        {
            "x": -3,
            "y": -1,
            "z": 5,
            "elements": [
                "mekanism:slickplasticblock@2"
            ]
        },
        {
            "x": -2,
            "y": 1,
            "z": 6,
            "elements": [
                "appliedenergistics2:quartz_block@0"
            ]
        },
        {
            "x": 2,
            "y": 9,
            "z": 10,
            "elements": [
                "mekanism:reinforcedplasticblock@14"
            ]
        },
        {
            "x": -1,
            "y": 1,
            "z": 6,
            "elements": [
                "appliedenergistics2:quartz_block@0"
            ]
        },
        {
            "x": 3,
            "y": 9,
            "z": 10,
            "elements": [
                "mekanism:reinforcedplasticblock@14"
            ]
        },
        {
            "x": 4,
            "y": 9,
            "z": -1,
            "elements": [
                "mekanism:slickplasticblock@2"
            ]
        },
        {
            "x": 0,
            "y": 1,
            "z": 6,
            "elements": [
                "mekanism:glowplasticblock@11"
            ]
        },
        {
            "x": 4,
            "y": 9,
            "z": 10,
            "elements": [
                "mekanism:reinforcedplasticblock@14"
            ]
        },
        {
            "x": 3,
            "y": 9,
            "z": -1,
            "elements": [
                "mekanism:slickplasticblock@2"
            ]
        },
        {
            "x": 1,
            "y": 1,
            "z": 6,
            "elements": [
                "appliedenergistics2:quartz_block@0"
            ]
        },
        {
            "x": 5,
            "y": 9,
            "z": 10,
            "elements": [
                "mekanism:glowplasticblock@11"
            ]
        },
        {
            "x": 2,
            "y": 1,
            "z": 6,
            "elements": [
                "appliedenergistics2:quartz_block@0"
            ]
        },
        {
            "x": 5,
            "y": 7,
            "z": 9,
            "elements": [
                "mekanism:reinforcedplasticblock@14"
            ]
        },
        {
            "x": 3,
            "y": 1,
            "z": 6,
            "elements": [
                "appliedenergistics2:quartz_block@0"
            ]
        },
        {
            "x": 5,
            "y": 5,
            "z": 8,
            "elements": [
                "mekanism:reinforcedplasticblock@14"
            ]
        },
        {
            "x": 3,
            "y": -1,
            "z": 5,
            "elements": [
                "mekanism:slickplasticblock@2"
            ]
        },
        {
            "x": 4,
            "y": 1,
            "z": 6,
            "elements": [
                "mekanism:glowplasticblock@0"
            ]
        },
        {
            "x": 5,
            "y": 3,
            "z": 7,
            "elements": [
                "mekanism:reinforcedplasticblock@14"
            ]
        },
        {
            "x": 4,
            "y": -1,
            "z": 5,
            "elements": [
                "mekanism:slickplasticblock@2"
            ]
        },
        {
            "x": 5,
            "y": 1,
            "z": 6,
            "elements": [
                "mekanism:reinforcedplasticblock@14"
            ]
        },
        {
            "x": -3,
            "y": 9,
            "z": -1,
            "elements": [
                "mekanism:slickplasticblock@2"
            ]
        },
        {
            "x": -4,
            "y": 9,
            "z": -1,
            "elements": [
                "mekanism:slickplasticblock@2"
            ]
        },
        {
            "x": -5,
            "y": 8,
            "z": 9,
            "elements": [
                "mekanism:reinforcedplasticblock@14"
            ]
        },
        {
            "x": -5,
            "y": 6,
            "z": 8,
            "elements": [
                "mekanism:reinforcedplasticblock@14"
            ]
        },
        {
            "x": -5,
            "y": 4,
            "z": 7,
            "elements": [
                "mekanism:glowplasticblock@11"
            ]
        },
        {
            "x": -5,
            "y": 2,
            "z": 6,
            "elements": [
                "mekanism:reinforcedplasticblock@14"
            ]
        },
        {
            "x": -4,
            "y": 4,
            "z": 7,
            "elements": [
                "mekanism:glowplasticblock@12"
            ]
        },
        {
            "x": -4,
            "y": 0,
            "z": 5,
            "elements": [
                "mekanism:glowplasticblock@11"
            ]
        },
        {
            "x": -3,
            "y": 0,
            "z": 5,
            "elements": [
                "mekanism:reinforcedplasticblock@14"
            ]
        },
        {
            "x": -2,
            "y": 0,
            "z": 5,
            "elements": [
                "mekanism:reinforcedplasticblock@14"
            ]
        },
        {
            "x": 4,
            "y": 8,
            "z": -1,
            "elements": [
                "mekanism:glowplasticblock@11"
            ]
        },
        {
            "x": -1,
            "y": 0,
            "z": 5,
            "elements": [
                "mekanism:reinforcedplasticblock@14"
            ]
        },
        {
            "x": 3,
            "y": 8,
            "z": -1,
            "elements": [
                "mekanism:reinforcedplasticblock@14"
            ]
        },
        {
            "x": 0,
            "y": 0,
            "z": 5,
            "elements": [
                "mekanism:glowplasticblock@11"
            ]
        },
        {
            "x": 2,
            "y": 8,
            "z": -1,
            "elements": [
                "mekanism:slickplasticblock@2"
            ]
        },
        {
            "x": 1,
            "y": 0,
            "z": 5,
            "elements": [
                "mekanism:reinforcedplasticblock@14"
            ]
        },
        {
            "x": 5,
            "y": 8,
            "z": 9,
            "elements": [
                "mekanism:reinforcedplasticblock@14"
            ]
        },
        {
            "x": 1,
            "y": 8,
            "z": -1,
            "elements": [
                "mekanism:reinforcedplasticblock@14"
            ]
        },
        {
            "x": 2,
            "y": 0,
            "z": 5,
            "elements": [
                "mekanism:reinforcedplasticblock@14"
            ]
        },
        {
            "x": 4,
            "y": 4,
            "z": 7,
            "elements": [
                "mekanism:glowplasticblock@12"
            ]
        },
        {
            "x": 5,
            "y": 6,
            "z": 8,
            "elements": [
                "mekanism:reinforcedplasticblock@14"
            ]
        },
        {
            "x": 0,
            "y": 8,
            "z": -1,
            "elements": [
                "mekanism:glowplasticblock@11"
            ]
        },
        {
            "x": 3,
            "y": 0,
            "z": 5,
            "elements": [
                "mekanism:reinforcedplasticblock@14"
            ]
        },
        {
            "x": 5,
            "y": 4,
            "z": 7,
            "elements": [
                "mekanism:glowplasticblock@11"
            ]
        },
        {
            "x": -1,
            "y": 8,
            "z": -1,
            "elements": [
                "mekanism:reinforcedplasticblock@14"
            ]
        },
        {
            "x": 4,
            "y": 0,
            "z": 5,
            "elements": [
                "mekanism:glowplasticblock@11"
            ]
        },
        {
            "x": 5,
            "y": 2,
            "z": 6,
            "elements": [
                "mekanism:reinforcedplasticblock@14"
            ]
        },
        {
            "x": -2,
            "y": 8,
            "z": -1,
            "elements": [
                "mekanism:slickplasticblock@2"
            ]
        },
        {
            "x": -3,
            "y": 8,
            "z": -1,
            "elements": [
                "mekanism:reinforcedplasticblock@14"
            ]
        },
        {
            "x": -4,
            "y": 8,
            "z": -1,
            "elements": [
                "mekanism:glowplasticblock@11"
            ]
        },
        {
            "x": -5,
            "y": 9,
            "z": 9,
            "elements": [
                "mekanism:glowplasticblock@11"
            ]
        },
        {
            "x": -5,
            "y": 7,
            "z": 8,
            "elements": [
                "mekanism:reinforcedplasticblock@14"
            ]
        },
        {
            "x": -4,
            "y": 9,
            "z": 9,
            "elements": [
                "mekanism:reinforcedplasticblock@14"
            ]
        },
        {
            "x": -5,
            "y": 5,
            "z": 7,
            "elements": [
                "mekanism:reinforcedplasticblock@14"
            ]
        },
        {
            "x": -3,
            "y": 9,
            "z": 9,
            "elements": [
                "mekanism:reinforcedplasticblock@14"
            ]
        },
        {
            "x": -5,
            "y": 3,
            "z": 6,
            "elements": [
                "mekanism:reinforcedplasticblock@14"
            ]
        },
        {
            "x": -4,
            "y": 5,
            "z": 7,
            "elements": [
                "mekanism:glowplasticblock@12"
            ]
        },
        {
            "x": -2,
            "y": 9,
            "z": 9,
            "elements": [
                "mekanism:reinforcedplasticblock@14"
            ]
        },
        {
            "x": -5,
            "y": 1,
            "z": 5,
            "elements": [
                "mekanism:reinforcedplasticblock@14"
            ]
        },
        {
            "x": -4,
            "y": 3,
            "z": 6,
            "elements": [
                "mekanism:glowplasticblock@12"
            ]
        },
        {
            "x": -1,
            "y": 9,
            "z": 9,
            "elements": [
                "mekanism:reinforcedplasticblock@14"
            ]
        },
        {
            "x": -4,
            "y": 1,
            "z": 5,
            "elements": [
                "mekanism:glowplasticblock@0"
            ]
        },
        {
            "x": 0,
            "y": 9,
            "z": 9,
            "elements": [
                "mekanism:glowplasticblock@11"
            ]
        },
        {
            "x": -4,
            "y": -1,
            "z": 4,
            "elements": [
                "mekanism:slickplasticblock@2"
            ]
        },
        {
            "x": -3,
            "y": 1,
            "z": 5,
            "elements": [
                "appliedenergistics2:quartz_block@0"
            ]
        },
        {
            "x": 1,
            "y": 9,
            "z": 9,
            "elements": [
                "mekanism:reinforcedplasticblock@14"
            ]
        },
        {
            "x": -3,
            "y": -1,
            "z": 4,
            "elements": [
                "mekanism:slickplasticblock@2"
            ]
        },
        {
            "x": -2,
            "y": 1,
            "z": 5,
            "elements": [
                "appliedenergistics2:quartz_block@0"
            ]
        },
        {
            "x": 2,
            "y": 9,
            "z": 9,
            "elements": [
                "mekanism:reinforcedplasticblock@14"
            ]
        },
        {
            "x": 4,
            "y": 7,
            "z": -1,
            "elements": [
                "mekanism:reinforcedplasticblock@14"
            ]
        },
        {
            "x": -2,
            "y": -1,
            "z": 4,
            "elements": [
                "mekanism:slickplasticblock@2"
            ]
        },
        {
            "x": -1,
            "y": 1,
            "z": 5,
            "elements": [
                "appliedenergistics2:quartz_block@0"
            ]
        },
        {
            "x": 3,
            "y": 9,
            "z": 9,
            "elements": [
                "mekanism:reinforcedplasticblock@14"
            ]
        },
        {
            "x": 3,
            "y": 7,
            "z": -1,
            "elements": [
                "mekanism:glowplasticblock@15"
            ]
        },
        {
            "x": 0,
            "y": 1,
            "z": 5,
            "elements": [
                "mekanism:glowplasticblock@0"
            ]
        },
        {
            "x": 4,
            "y": 9,
            "z": 9,
            "elements": [
                "mekanism:reinforcedplasticblock@14"
            ]
        },
        {
            "x": 2,
            "y": 7,
            "z": -1,
            "elements": [
                "mekanism:glowplasticblock@15"
            ]
        },
        {
            "x": 1,
            "y": 1,
            "z": 5,
            "elements": [
                "appliedenergistics2:quartz_block@0"
            ]
        },
        {
            "x": 5,
            "y": 9,
            "z": 9,
            "elements": [
                "mekanism:glowplasticblock@11"
            ]
        },
        {
            "x": 1,
            "y": 7,
            "z": -1,
            "elements": [
                "mekanism:reinforcedplasticblock@14"
            ]
        },
        {
            "x": 2,
            "y": 1,
            "z": 5,
            "elements": [
                "appliedenergistics2:quartz_block@0"
            ]
        },
        {
            "x": 4,
            "y": 5,
            "z": 7,
            "elements": [
                "mekanism:glowplasticblock@12"
            ]
        },
        {
            "x": 5,
            "y": 7,
            "z": 8,
            "elements": [
                "mekanism:reinforcedplasticblock@14"
            ]
        },
        {
            "x": 0,
            "y": 7,
            "z": -1,
            "elements": [
                "mekanism:glowplasticblock@11"
            ]
        },
        {
            "x": 2,
            "y": -1,
            "z": 4,
            "elements": [
                "mekanism:slickplasticblock@2"
            ]
        },
        {
            "x": 3,
            "y": 1,
            "z": 5,
            "elements": [
                "appliedenergistics2:quartz_block@0"
            ]
        },
        {
            "x": 4,
            "y": 3,
            "z": 6,
            "elements": [
                "mekanism:glowplasticblock@12"
            ]
        },
        {
            "x": 5,
            "y": 5,
            "z": 7,
            "elements": [
                "mekanism:reinforcedplasticblock@14"
            ]
        },
        {
            "x": -1,
            "y": 7,
            "z": -1,
            "elements": [
                "mekanism:reinforcedplasticblock@14"
            ]
        },
        {
            "x": 3,
            "y": -1,
            "z": 4,
            "elements": [
                "mekanism:slickplasticblock@2"
            ]
        },
        {
            "x": 4,
            "y": 1,
            "z": 5,
            "elements": [
                "mekanism:glowplasticblock@0"
            ]
        },
        {
            "x": 5,
            "y": 3,
            "z": 6,
            "elements": [
                "mekanism:reinforcedplasticblock@14"
            ]
        },
        {
            "x": -2,
            "y": 7,
            "z": -1,
            "elements": [
                "mekanism:glowplasticblock@15"
            ]
        },
        {
            "x": 4,
            "y": -1,
            "z": 4,
            "elements": [
                "mekanism:slickplasticblock@2"
            ]
        },
        {
            "x": 5,
            "y": 1,
            "z": 5,
            "elements": [
                "mekanism:reinforcedplasticblock@14"
            ]
        },
        {
            "x": -3,
            "y": 7,
            "z": -1,
            "elements": [
                "mekanism:glowplasticblock@15"
            ]
        },
        {
            "x": -4,
            "y": 7,
            "z": -1,
            "elements": [
                "mekanism:reinforcedplasticblock@14"
            ]
        },
        {
            "x": -5,
            "y": 8,
            "z": 8,
            "elements": [
                "mekanism:reinforcedplasticblock@14"
            ]
        },
        {
            "x": -5,
            "y": 6,
            "z": 7,
            "elements": [
                "mekanism:reinforcedplasticblock@14"
            ]
        },
        {
            "x": -5,
            "y": 4,
            "z": 6,
            "elements": [
                "mekanism:glowplasticblock@11"
            ]
        },
        {
            "x": -5,
            "y": 2,
            "z": 5,
            "elements": [
                "mekanism:reinforcedplasticblock@14"
            ]
        },
        {
            "x": -4,
            "y": 4,
            "z": 6,
            "elements": [
                "appliedenergistics2:quartz_block@0"
            ]
        },
        {
            "x": -4,
            "y": 0,
            "z": 4,
            "elements": [
                "mekanism:glowplasticblock@11"
            ]
        },
        {
            "x": -3,
            "y": 0,
            "z": 4,
            "elements": [
                "mekanism:reinforcedplasticblock@14"
            ]
        },
        {
            "x": 4,
            "y": 6,
            "z": -1,
            "elements": [
                "mekanism:reinforcedplasticblock@14"
            ]
        },
        {
            "x": -2,
            "y": 0,
            "z": 4,
            "elements": [
                "mekanism:reinforcedplasticblock@14"
            ]
        },
        {
            "x": 3,
            "y": 6,
            "z": -1,
            "elements": [
                "mekanism:glowplasticblock@15"
            ]
        },
        {
            "x": -1,
            "y": 0,
            "z": 4,
            "elements": [
                "mekanism:reinforcedplasticblock@14"
            ]
        },
        {
            "x": 2,
            "y": 6,
            "z": -1,
            "elements": [
                "mekanism:glowplasticblock@12"
            ]
        },
        {
            "x": 0,
            "y": 0,
            "z": 4,
            "elements": [
                "mekanism:glowplasticblock@11"
            ]
        },
        {
            "x": 1,
            "y": 6,
            "z": -1,
            "elements": [
                "mekanism:reinforcedplasticblock@14"
            ]
        },
        {
            "x": 1,
            "y": 0,
            "z": 4,
            "elements": [
                "mekanism:reinforcedplasticblock@14"
            ]
        },
        {
            "x": 5,
            "y": 8,
            "z": 8,
            "elements": [
                "mekanism:reinforcedplasticblock@14"
            ]
        },
        {
            "x": 0,
            "y": 6,
            "z": -1,
            "elements": [
                "mekanism:glowplasticblock@11"
            ]
        },
        {
            "x": 2,
            "y": 0,
            "z": 4,
            "elements": [
                "mekanism:reinforcedplasticblock@14"
            ]
        },
        {
            "x": 4,
            "y": 4,
            "z": 6,
            "elements": [
                "appliedenergistics2:quartz_block@0"
            ]
        },
        {
            "x": 5,
            "y": 6,
            "z": 7,
            "elements": [
                "mekanism:reinforcedplasticblock@14"
            ]
        },
        {
            "x": -1,
            "y": 6,
            "z": -1,
            "elements": [
                "mekanism:reinforcedplasticblock@14"
            ]
        },
        {
            "x": 3,
            "y": 0,
            "z": 4,
            "elements": [
                "mekanism:reinforcedplasticblock@14"
            ]
        },
        {
            "x": 5,
            "y": 4,
            "z": 6,
            "elements": [
                "mekanism:glowplasticblock@11"
            ]
        },
        {
            "x": -2,
            "y": 6,
            "z": -1,
            "elements": [
                "mekanism:glowplasticblock@12"
            ]
        },
        {
            "x": 4,
            "y": 0,
            "z": 4,
            "elements": [
                "mekanism:glowplasticblock@11"
            ]
        },
        {
            "x": 5,
            "y": 2,
            "z": 5,
            "elements": [
                "mekanism:reinforcedplasticblock@14"
            ]
        },
        {
            "x": -3,
            "y": 6,
            "z": -1,
            "elements": [
                "mekanism:glowplasticblock@15"
            ]
        },
        {
            "x": -4,
            "y": 6,
            "z": -1,
            "elements": [
                "mekanism:reinforcedplasticblock@14"
            ]
        },
        {
            "x": -5,
            "y": 9,
            "z": 8,
            "elements": [
                "mekanism:glowplasticblock@11"
            ]
        },
        {
            "x": -5,
            "y": 7,
            "z": 7,
            "elements": [
                "mekanism:reinforcedplasticblock@14"
            ]
        },
        {
            "x": -4,
            "y": 9,
            "z": 8,
            "elements": [
                "mekanism:reinforcedplasticblock@14"
            ]
        },
        {
            "x": -5,
            "y": 5,
            "z": 6,
            "elements": [
                "mekanism:reinforcedplasticblock@14"
            ]
        },
        {
            "x": -3,
            "y": 9,
            "z": 8,
            "elements": [
                "mekanism:reinforcedplasticblock@14"
            ]
        },
        {
            "x": -5,
            "y": 3,
            "z": 5,
            "elements": [
                "mekanism:reinforcedplasticblock@14"
            ]
        },
        {
            "x": -4,
            "y": 5,
            "z": 6,
            "elements": [
                "appliedenergistics2:quartz_block@0"
            ]
        },
        {
            "x": -2,
            "y": 9,
            "z": 8,
            "elements": [
                "mekanism:reinforcedplasticblock@14"
            ]
        },
        {
            "x": -5,
            "y": 1,
            "z": 4,
            "elements": [
                "mekanism:reinforcedplasticblock@14"
            ]
        },
        {
            "x": -4,
            "y": 3,
            "z": 5,
            "elements": [
                "mekanism:glowplasticblock@12"
            ]
        },
        {
            "x": -1,
            "y": 9,
            "z": 8,
            "elements": [
                "mekanism:reinforcedplasticblock@14"
            ]
        },
        {
            "x": -5,
            "y": -1,
            "z": 3,
            "elements": [
                "mekanism:slickplasticblock@2"
            ]
        },
        {
            "x": 0,
            "y": 9,
            "z": 8,
            "elements": [
                "mekanism:glowplasticblock@11"
            ]
        },
        {
            "x": -4,
            "y": -1,
            "z": 3,
            "elements": [
                "mekanism:slickplasticblock@2"
            ]
        },
        {
            "x": -3,
            "y": 1,
            "z": 4,
            "elements": [
                "mekanism:glowplasticblock@0"
            ]
        },
        {
            "x": 1,
            "y": 9,
            "z": 8,
            "elements": [
                "mekanism:reinforcedplasticblock@14"
            ]
        },
        {
            "x": 4,
            "y": 5,
            "z": -1,
            "elements": [
                "mekanism:reinforcedplasticblock@14"
            ]
        },
        {
            "x": -3,
            "y": -1,
            "z": 3,
            "elements": [
                "mekanism:slickplasticblock@2"
            ]
        },
        {
            "x": -2,
            "y": 1,
            "z": 4,
            "elements": [
                "appliedenergistics2:quartz_block@0"
            ]
        },
        {
            "x": 2,
            "y": 9,
            "z": 8,
            "elements": [
                "mekanism:reinforcedplasticblock@14"
            ]
        },
        {
            "x": 3,
            "y": 5,
            "z": -1,
            "elements": [
                "mekanism:reinforcedplasticblock@14"
            ]
        },
        {
            "x": -2,
            "y": -1,
            "z": 3,
            "elements": [
                "mekanism:slickplasticblock@2"
            ]
        },
        {
            "x": -1,
            "y": 1,
            "z": 4,
            "elements": [
                "appliedenergistics2:quartz_block@0"
            ]
        },
        {
            "x": 3,
            "y": 9,
            "z": 8,
            "elements": [
                "mekanism:reinforcedplasticblock@14"
            ]
        },
        {
            "x": 2,
            "y": 5,
            "z": -1,
            "elements": [
                "mekanism:reinforcedplasticblock@14"
            ]
        },
        {
            "x": 0,
            "y": 1,
            "z": 4,
            "elements": [
                "mekanism:glowplasticblock@0"
            ]
        },
        {
            "x": 4,
            "y": 9,
            "z": 8,
            "elements": [
                "mekanism:reinforcedplasticblock@14"
            ]
        },
        {
            "x": 1,
            "y": 5,
            "z": -1,
            "elements": [
                "mekanism:glowplasticblock@11"
            ]
        },
        {
            "x": 1,
            "y": 1,
            "z": 4,
            "elements": [
                "appliedenergistics2:quartz_block@0"
            ]
        },
        {
            "x": 5,
            "y": 9,
            "z": 8,
            "elements": [
                "mekanism:glowplasticblock@11"
            ]
        },
        {
            "x": 0,
            "y": 5,
            "z": -1,
            "elements": [
                "mekanism:glowplasticblock@11"
            ]
        },
        {
            "x": 2,
            "y": 1,
            "z": 4,
            "elements": [
                "appliedenergistics2:quartz_block@0"
            ]
        },
        {
            "x": 4,
            "y": 5,
            "z": 6,
            "elements": [
                "appliedenergistics2:quartz_block@0"
            ]
        },
        {
            "x": 5,
            "y": 7,
            "z": 7,
            "elements": [
                "mekanism:reinforcedplasticblock@14"
            ]
        },
        {
            "x": -1,
            "y": 5,
            "z": -1,
            "elements": [
                "mekanism:glowplasticblock@11"
            ]
        },
        {
            "x": 2,
            "y": -1,
            "z": 3,
            "elements": [
                "mekanism:slickplasticblock@2"
            ]
        },
        {
            "x": 3,
            "y": 1,
            "z": 4,
            "elements": [
                "mekanism:glowplasticblock@0"
            ]
        },
        {
            "x": 4,
            "y": 3,
            "z": 5,
            "elements": [
                "mekanism:glowplasticblock@12"
            ]
        },
        {
            "x": 5,
            "y": 5,
            "z": 6,
            "elements": [
                "mekanism:reinforcedplasticblock@14"
            ]
        },
        {
            "x": -2,
            "y": 5,
            "z": -1,
            "elements": [
                "mekanism:reinforcedplasticblock@14"
            ]
        },
        {
            "x": 3,
            "y": -1,
            "z": 3,
            "elements": [
                "mekanism:slickplasticblock@2"
            ]
        },
        {
            "x": 5,
            "y": 3,
            "z": 5,
            "elements": [
                "mekanism:reinforcedplasticblock@14"
            ]
        },
        {
            "x": -3,
            "y": 5,
            "z": -1,
            "elements": [
                "mekanism:reinforcedplasticblock@14"
            ]
        },
        {
            "x": 4,
            "y": -1,
            "z": 3,
            "elements": [
                "mekanism:slickplasticblock@2"
            ]
        },
        {
            "x": 5,
            "y": 1,
            "z": 4,
            "elements": [
                "mekanism:reinforcedplasticblock@14"
            ]
        },
        {
            "x": -4,
            "y": 5,
            "z": -1,
            "elements": [
                "mekanism:reinforcedplasticblock@14"
            ]
        },
        {
            "x": 5,
            "y": -1,
            "z": 3,
            "elements": [
                "mekanism:slickplasticblock@2"
            ]
        },
        {
            "x": -5,
            "y": 8,
            "z": 7,
            "elements": [
                "mekanism:reinforcedplasticblock@14"
            ]
        },
        {
            "x": -5,
            "y": 6,
            "z": 6,
            "elements": [
                "mekanism:reinforcedplasticblock@14"
            ]
        },
        {
            "x": -5,
            "y": 4,
            "z": 5,
            "elements": [
                "mekanism:glowplasticblock@11"
            ]
        },
        {
            "x": -4,
            "y": 6,
            "z": 6,
            "elements": [
                "mekanism:glowplasticblock@12"
            ]
        },
        {
            "x": -5,
            "y": 2,
            "z": 4,
            "elements": [
                "mekanism:reinforcedplasticblock@14"
            ]
        },
        {
            "x": -4,
            "y": 4,
            "z": 5,
            "elements": [
                "appliedenergistics2:quartz_block@0"
            ]
        },
        {
            "x": -4,
            "y": 0,
            "z": 3,
            "elements": [
                "mekanism:glowplasticblock@11"
            ]
        },
        {
            "x": 4,
            "y": 4,
            "z": -1,
            "elements": [
                "mekanism:glowplasticblock@11"
            ]
        },
        {
            "x": -3,
            "y": 0,
            "z": 3,
            "elements": [
                "mekanism:reinforcedplasticblock@14"
            ]
        },
        {
            "x": 3,
            "y": 4,
            "z": -1,
            "elements": [
                "mekanism:glowplasticblock@11"
            ]
        },
        {
            "x": -2,
            "y": 0,
            "z": 3,
            "elements": [
                "mekanism:reinforcedplasticblock@14"
            ]
        },
        {
            "x": 2,
            "y": 4,
            "z": -1,
            "elements": [
                "mekanism:glowplasticblock@11"
            ]
        },
        {
            "x": -1,
            "y": 0,
            "z": 3,
            "elements": [
                "mekanism:reinforcedplasticblock@14"
            ]
        },
        {
            "x": 1,
            "y": 4,
            "z": -1,
            "elements": [
                "mekanism:glowplasticblock@11"
            ]
        },
        {
            "x": 0,
            "y": 0,
            "z": 3,
            "elements": [
                "mekanism:glowplasticblock@11"
            ]
        },
        {
            "x": 0,
            "y": 4,
            "z": -1,
            "elements": [
                "modularmachinery:blockinputbus"
            ]
        },
        {
            "x": 1,
            "y": 0,
            "z": 3,
            "elements": [
                "mekanism:reinforcedplasticblock@14"
            ]
        },
        {
            "x": 4,
            "y": 6,
            "z": 6,
            "elements": [
                "mekanism:glowplasticblock@12"
            ]
        },
        {
            "x": 5,
            "y": 8,
            "z": 7,
            "elements": [
                "mekanism:reinforcedplasticblock@14"
            ]
        },
        {
            "x": -1,
            "y": 4,
            "z": -1,
            "elements": [
                "mekanism:glowplasticblock@11"
            ]
        },
        {
            "x": 2,
            "y": 0,
            "z": 3,
            "elements": [
                "mekanism:reinforcedplasticblock@14"
            ]
        },
        {
            "x": 4,
            "y": 4,
            "z": 5,
            "elements": [
                "appliedenergistics2:quartz_block@0"
            ]
        },
        {
            "x": 5,
            "y": 6,
            "z": 6,
            "elements": [
                "mekanism:reinforcedplasticblock@14"
            ]
        },
        {
            "x": -2,
            "y": 4,
            "z": -1,
            "elements": [
                "mekanism:glowplasticblock@11"
            ]
        },
        {
            "x": 3,
            "y": 0,
            "z": 3,
            "elements": [
                "mekanism:reinforcedplasticblock@14"
            ]
        },
        {
            "x": 5,
            "y": 4,
            "z": 5,
            "elements": [
                "mekanism:glowplasticblock@11"
            ]
        },
        {
            "x": -3,
            "y": 4,
            "z": -1,
            "elements": [
                "mekanism:glowplasticblock@11"
            ]
        },
        {
            "x": 4,
            "y": 0,
            "z": 3,
            "elements": [
                "mekanism:glowplasticblock@11"
            ]
        },
        {
            "x": 5,
            "y": 2,
            "z": 4,
            "elements": [
                "mekanism:reinforcedplasticblock@14"
            ]
        },
        {
            "x": -4,
            "y": 4,
            "z": -1,
            "elements": [
                "mekanism:glowplasticblock@11"
            ]
        },
        {
            "x": -5,
            "y": 9,
            "z": 7,
            "elements": [
                "mekanism:glowplasticblock@11"
            ]
        },
        {
            "x": -5,
            "y": 7,
            "z": 6,
            "elements": [
                "mekanism:reinforcedplasticblock@14"
            ]
        },
        {
            "x": -4,
            "y": 9,
            "z": 7,
            "elements": [
                "mekanism:reinforcedplasticblock@14"
            ]
        },
        {
            "x": -5,
            "y": 5,
            "z": 5,
            "elements": [
                "mekanism:reinforcedplasticblock@14"
            ]
        },
        {
            "x": -4,
            "y": 7,
            "z": 6,
            "elements": [
                "mekanism:glowplasticblock@11"
            ]
        },
        {
            "x": -3,
            "y": 9,
            "z": 7,
            "elements": [
                "mekanism:reinforcedplasticblock@14"
            ]
        },
        {
            "x": -5,
            "y": 3,
            "z": 4,
            "elements": [
                "mekanism:reinforcedplasticblock@14"
            ]
        },
        {
            "x": -4,
            "y": 5,
            "z": 5,
            "elements": [
                "appliedenergistics2:quartz_block@0"
            ]
        },
        {
            "x": -2,
            "y": 9,
            "z": 7,
            "elements": [
                "mekanism:reinforcedplasticblock@14"
            ]
        },
        {
            "x": -6,
            "y": -1,
            "z": 2,
            "elements": [
                "mekanism:slickplasticblock@2"
            ]
        },
        {
            "x": -5,
            "y": 1,
            "z": 3,
            "elements": [
                "mekanism:reinforcedplasticblock@14"
            ]
        },
        {
            "x": -4,
            "y": 3,
            "z": 4,
            "elements": [
                "mekanism:glowplasticblock@12"
            ]
        },
        {
            "x": -1,
            "y": 9,
            "z": 7,
            "elements": [
                "mekanism:reinforcedplasticblock@14"
            ]
        },
        {
            "x": -5,
            "y": -1,
            "z": 2,
            "elements": [
                "mekanism:slickplasticblock@2"
            ]
        },
        {
            "x": 0,
            "y": 9,
            "z": 7,
            "elements": [
                "mekanism:glowplasticblock@11"
            ]
        },
        {
            "x": 4,
            "y": 3,
            "z": -1,
            "elements": [
                "mekanism:reinforcedplasticblock@14"
            ]
        },
        {
            "x": -4,
            "y": -1,
            "z": 2,
            "elements": [
                "mekanism:slickplasticblock@2"
            ]
        },
        {
            "x": 1,
            "y": 9,
            "z": 7,
            "elements": [
                "mekanism:reinforcedplasticblock@14"
            ]
        },
        {
            "x": 3,
            "y": 3,
            "z": -1,
            "elements": [
                "mekanism:reinforcedplasticblock@14"
            ]
        },
        {
            "x": -2,
            "y": 1,
            "z": 3,
            "elements": [
                "mekanism:glowplasticblock@0"
            ]
        },
        {
            "x": 2,
            "y": 9,
            "z": 7,
            "elements": [
                "mekanism:reinforcedplasticblock@14"
            ]
        },
        {
            "x": 2,
            "y": 3,
            "z": -1,
            "elements": [
                "mekanism:reinforcedplasticblock@14"
            ]
        },
        {
