{   "registryname": "computer2",
    "localizedname": "量子计算机",
    "requires_blueprint": false,
    "color": "000000",
    "failure-action": "still",
    "parts": [
        {
            "x": -1,
            "y": 0,
            "z": 0,
            "elements": [
                "modularmachinery:blockenergyinputhatch"
            ]
        },
        {
            "x": 1,
            "y": 0,
            "z": 0,
            "elements": [
                "modularmachinery:blockenergyinputhatch"
            ]
        },
        {
            "x": -2,
            "y": 0,
            "z": 0,
            "elements": [
                "mekanism:reinforcedplasticblock@8"
            ]
        },
        {
            "x": -3,
            "y": 0,
            "z": 0,
            "elements": [
                "mekanism:plasticblock@7"
            ]
        },
        {
            "x": 2,
            "y": 0,
            "z": 0,
            "elements": [
                "mekanism:reinforcedplasticblock@8"
            ]
        },
        {
            "x": -4,
            "y": 0,
            "z": 0,
            "elements": [
                "thermalfoundation:glass_alloy@7"
            ]
        },
        {
            "x": 3,
            "y": 0,
            "z": 0,
            "elements": [
                "mekanism:plasticblock@7"
            ]
        },
        {
            "x": 4,
            "y": 0,
            "z": 0,
            "elements": [
                "thermalfoundation:glass_alloy@7"
            ]
        },
        {
            "x": -6,
            "y": 2,
            "z": 17,
            "elements": [
                "thermalfoundation:glass_alloy@7"
            ]
        },
        {
            "x": -3,
            "y": 2,
            "z": 17,
            "elements": [
                "enderio:block_alloy@6"
            ]
        },
        {
            "x": -2,
            "y": 2,
            "z": 17,
            "elements": [
                "thermalfoundation:glass_alloy@7"
            ]
        },
        {
            "x": -1,
            "y": 2,
            "z": 17,
            "elements": [
                "enderio:block_alloy@6"
            ]
        },
        {
            "x": -4,
            "y": -6,
            "z": 13,
            "elements": [
                "thermalfoundation:glass_alloy@7"
            ]
        },
        {
            "x": 0,
            "y": 2,
            "z": 17,
            "elements": [
                "enderio:block_alloy@6"
            ]
        },
        {
            "x": 1,
            "y": 2,
            "z": 17,
            "elements": [
                "enderio:block_alloy@6"
            ]
        },
        {
            "x": 2,
            "y": 2,
            "z": 17,
            "elements": [
                "thermalfoundation:glass_alloy@7"
            ]
        },
        {
            "x": -1,
            "y": -6,
            "z": 13,
            "elements": [
                "appliedenergistics2:controller@0"
            ]
        },
        {
            "x": 3,
            "y": 2,
            "z": 17,
            "elements": [
                "enderio:block_alloy@6"
            ]
        },
        {
            "x": 1,
            "y": -6,
            "z": 13,
            "elements": [
                "appliedenergistics2:controller@0"
            ]
        },
        {
            "x": 6,
            "y": 2,
            "z": 17,
            "elements": [
                "thermalfoundation:glass_alloy@7"
            ]
        },
        {
            "x": 4,
            "y": -6,
            "z": 13,
            "elements": [
                "thermalfoundation:glass_alloy@7"
            ]
        },
        {
            "x": 4,
            "y": -1,
            "z": 0,
            "elements": [
                "thermalfoundation:glass_alloy@7"
            ]
        },
        {
            "x": 3,
            "y": -1,
            "z": 0,
            "elements": [
                "mekanism:plasticblock@7"
            ]
        },
        {
            "x": -4,
            "y": 1,
            "z": 0,
            "elements": [
                "thermalfoundation:glass_alloy@7"
            ]
        },
        {
            "x": -3,
            "y": 1,
            "z": 0,
            "elements": [
                "mekanism:plasticblock@7"
            ]
        },
        {
            "x": 2,
            "y": -1,
            "z": 0,
            "elements": [
                "mekanism:reinforcedplasticblock@8"
            ]
        },
        {
            "x": 1,
            "y": -1,
            "z": 0,
            "elements": [
                "avaritia:block_resource@2"
            ]
        },
        {
            "x": -2,
            "y": 1,
            "z": 0,
            "elements": [
                "mekanism:reinforcedplasticblock@8"
            ]
        },
        {
            "x": -1,
            "y": 1,
            "z": 0,
            "elements": [
                "avaritia:block_resource@2"
            ]
        },
        {
            "x": 0,
            "y": -1,
            "z": 0,
            "elements": [
                "modularmachinery:blockoutputbus"
            ]
        },
        {
            "x": 0,
            "y": 1,
            "z": 0,
            "elements": [
                "modularmachinery:blockinputbus"
            ]
        },
        {
            "x": -1,
            "y": -1,
            "z": 0,
            "elements": [
                "avaritia:block_resource@2"
            ]
        },
        {
            "x": -2,
            "y": -1,
            "z": 0,
            "elements": [
                "mekanism:reinforcedplasticblock@8"
            ]
        },
        {
            "x": 1,
            "y": 1,
            "z": 0,
            "elements": [
                "avaritia:block_resource@2"
            ]
        },
        {
            "x": -3,
            "y": -1,
            "z": 0,
            "elements": [
                "mekanism:plasticblock@7"
            ]
        },
        {
            "x": 2,
            "y": 1,
            "z": 0,
            "elements": [
                "mekanism:reinforcedplasticblock@8"
            ]
        },
        {
            "x": -4,
            "y": -1,
            "z": 0,
            "elements": [
                "thermalfoundation:glass_alloy@7"
            ]
        },
        {
            "x": 3,
            "y": 1,
            "z": 0,
            "elements": [
                "mekanism:plasticblock@7"
            ]
        },
        {
            "x": 4,
            "y": 1,
            "z": 0,
            "elements": [
                "thermalfoundation:glass_alloy@7"
            ]
        },
        {
            "x": -6,
            "y": 3,
            "z": 17,
            "elements": [
                "thermalfoundation:glass_alloy@7"
            ]
        },
        {
            "x": -5,
            "y": -5,
            "z": 13,
            "elements": [
                "thermalfoundation:glass_alloy@7"
            ]
        },
        {
            "x": -1,
            "y": 3,
            "z": 17,
            "elements": [
                "appliedenergistics2:sky_stone_brick_slab@8"
            ]
        },
        {
            "x": 0,
            "y": 3,
            "z": 17,
            "elements": [
                "immersiveengineering:sheetmetal@3"
            ]
        },
        {
            "x": 1,
            "y": 3,
            "z": 17,
            "elements": [
                "appliedenergistics2:sky_stone_brick_slab@8"
            ]
        },
        {
            "x": 6,
            "y": 3,
            "z": 17,
            "elements": [
                "thermalfoundation:glass_alloy@7"
            ]
        },
        {
            "x": 5,
            "y": -5,
            "z": 13,
            "elements": [
                "thermalfoundation:glass_alloy@7"
            ]
        },
        {
            "x": 2,
            "y": -2,
            "z": 0,
            "elements": [
                "mekanism:reinforcedplasticblock@8"
            ]
        },
        {
            "x": 1,
            "y": -2,
            "z": 0,
            "elements": [
                "avaritia:block_resource@0"
            ]
        },
        {
            "x": -2,
            "y": 2,
            "z": 0,
            "elements": [
                "mekanism:reinforcedplasticblock@8"
            ]
        },
        {
            "x": -1,
            "y": 2,
            "z": 0,
            "elements": [
                "avaritia:block_resource@0"
            ]
        },
        {
            "x": 0,
            "y": -2,
            "z": 0,
            "elements": [
                "mekanism:glowplasticblock@8"
            ]
        },
        {
            "x": 0,
            "y": 2,
            "z": 0,
            "elements": [
                "mekanism:reinforcedplasticblock@8"
            ]
        },
        {
            "x": -1,
            "y": -2,
            "z": 0,
            "elements": [
                "avaritia:block_resource@0"
            ]
        },
        {
            "x": -2,
            "y": -2,
            "z": 0,
            "elements": [
                "mekanism:reinforcedplasticblock@8"
            ]
        },
        {
            "x": 1,
            "y": 2,
            "z": 0,
            "elements": [
                "avaritia:block_resource@0"
            ]
        },
        {
            "x": 2,
            "y": 2,
            "z": 0,
            "elements": [
                "mekanism:reinforcedplasticblock@8"
            ]
        },
        {
            "x": -6,
            "y": 4,
            "z": 17,
            "elements": [
                "thermalfoundation:glass_alloy@7"
            ]
        },
        {
            "x": -6,
            "y": -4,
            "z": 13,
            "elements": [
                "thermalfoundation:glass_alloy@7"
            ]
        },
        {
            "x": -1,
            "y": 4,
            "z": 17,
            "elements": [
                "immersiveengineering:sheetmetal@3"
            ]
        },
        {
            "x": 1,
            "y": 4,
            "z": 17,
            "elements": [
                "immersiveengineering:sheetmetal@3"
            ]
        },
        {
            "x": -3,
            "y": -4,
            "z": 13,
            "elements": [
                "appliedenergistics2:sky_stone_brick_stairs@4"
            ]
        },
        {
            "x": -2,
            "y": -4,
            "z": 13,
            "elements": [
                "appliedenergistics2:sky_stone_brick_stairs@7"
            ]
        },
        {
            "x": -1,
            "y": -4,
            "z": 13,
            "elements": [
                "enderio:block_alloy@6"
            ]
        },
        {
            "x": 0,
            "y": -4,
            "z": 13,
            "elements": [
                "enderio:block_alloy@6"
            ]
        },
        {
            "x": 1,
            "y": -4,
            "z": 13,
            "elements": [
                "enderio:block_alloy@6"
            ]
        },
        {
            "x": 6,
            "y": 4,
            "z": 17,
            "elements": [
                "thermalfoundation:glass_alloy@7"
            ]
        },
        {
            "x": 2,
            "y": -4,
            "z": 13,
            "elements": [
                "appliedenergistics2:sky_stone_brick_stairs@7"
            ]
        },
        {
            "x": 3,
            "y": -4,
            "z": 13,
            "elements": [
                "appliedenergistics2:sky_stone_brick_stairs@5"
            ]
        },
        {
            "x": 6,
            "y": -4,
            "z": 13,
            "elements": [
                "thermalfoundation:glass_alloy@7"
            ]
        },
        {
            "x": -6,
            "y": 5,
            "z": 17,
            "elements": [
                "thermalfoundation:glass_alloy@7"
            ]
        },
        {
            "x": -6,
            "y": -3,
            "z": 13,
            "elements": [
                "thermalfoundation:glass_alloy@7"
            ]
        },
        {
            "x": -1,
            "y": 5,
            "z": 17,
            "elements": [
                "appliedenergistics2:sky_stone_brick_slab@0"
            ]
        },
        {
            "x": 0,
            "y": 5,
            "z": 17,
            "elements": [
                "immersiveengineering:sheetmetal@3"
            ]
        },
        {
            "x": 1,
            "y": 5,
            "z": 17,
            "elements": [
                "appliedenergistics2:sky_stone_brick_slab@0"
            ]
        },
        {
            "x": -3,
            "y": -3,
            "z": 13,
            "elements": [
                "mekanism:glowplasticblock@8"
            ]
        },
        {
            "x": -2,
            "y": -3,
            "z": 13,
            "elements": [
                "thermalfoundation:glass_alloy@7"
            ]
        },
        {
            "x": -1,
            "y": -3,
            "z": 13,
            "elements": [
                "thermalfoundation:glass_alloy@7"
            ]
        },
        {
            "x": 0,
            "y": -3,
            "z": 13,
            "elements": [
                "thermalfoundation:glass_alloy@7"
            ]
        },
        {
            "x": 1,
            "y": -3,
            "z": 13,
            "elements": [
                "thermalfoundation:glass_alloy@7"
            ]
        },
        {
            "x": 6,
            "y": 5,
            "z": 17,
            "elements": [
                "thermalfoundation:glass_alloy@7"
            ]
        },
        {
            "x": 2,
            "y": -3,
            "z": 13,
            "elements": [
                "thermalfoundation:glass_alloy@7"
            ]
        },
        {
            "x": 3,
            "y": -3,
            "z": 13,
            "elements": [
                "mekanism:glowplasticblock@8"
            ]
        },
        {
            "x": 6,
            "y": -3,
            "z": 13,
            "elements": [
                "thermalfoundation:glass_alloy@7"
            ]
        },
        {
            "x": -5,
            "y": 6,
            "z": 17,
            "elements": [
                "thermalfoundation:glass_alloy@7"
            ]
        },
        {
            "x": -6,
            "y": -2,
            "z": 13,
            "elements": [
                "thermalfoundation:glass_alloy@7"
            ]
        },
        {
            "x": -3,
            "y": -2,
            "z": 13,
            "elements": [
                "mekanism:glowplasticblock@8"
            ]
        },
        {
            "x": -2,
            "y": -2,
            "z": 13,
            "elements": [
                "thermalfoundation:glass_alloy@7"
            ]
        },
        {
            "x": -1,
            "y": -2,
            "z": 13,
            "elements": [
                "thermalfoundation:glass_alloy@7"
            ]
        },
        {
            "x": 0,
            "y": -2,
            "z": 13,
            "elements": [
                "thermalfoundation:glass_alloy@7"
            ]
        },
        {
            "x": 5,
            "y": 6,
            "z": 17,
            "elements": [
                "thermalfoundation:glass_alloy@7"
            ]
        },
        {
            "x": 1,
            "y": -2,
            "z": 13,
            "elements": [
                "thermalfoundation:glass_alloy@7"
            ]
        },
        {
            "x": 2,
            "y": -2,
            "z": 13,
            "elements": [
                "thermalfoundation:glass_alloy@7"
            ]
        },
        {
            "x": 3,
            "y": -2,
            "z": 13,
            "elements": [
                "mekanism:glowplasticblock@8"
            ]
        },
        {
            "x": 6,
            "y": -2,
            "z": 13,
            "elements": [
                "thermalfoundation:glass_alloy@7"
            ]
        },
        {
            "x": -4,
            "y": 7,
            "z": 17,
            "elements": [
                "thermalfoundation:glass_alloy@7"
            ]
        },
        {
            "x": -6,
            "y": -1,
            "z": 13,
            "elements": [
                "thermalfoundation:glass_alloy@7"
            ]
        },
        {
            "x": -1,
            "y": 7,
            "z": 17,
            "elements": [
                "appliedenergistics2:controller@0"
            ]
        },
        {
            "x": 0,
            "y": 7,
            "z": 17,
            "elements": [
                "mekanism:glowplasticblock@8"
            ]
        },
        {
            "x": 1,
            "y": 7,
            "z": 17,
            "elements": [
                "appliedenergistics2:controller@0"
            ]
        },
        {
            "x": -3,
            "y": -1,
            "z": 13,
            "elements": [
                "mekanism:glowplasticblock@8"
            ]
        },
        {
            "x": -2,
            "y": -1,
            "z": 13,
            "elements": [
                "thermalfoundation:glass_alloy@7"
            ]
        },
        {
            "x": -1,
            "y": -1,
            "z": 13,
            "elements": [
                "thermalfoundation:glass_alloy@7"
            ]
        },
        {
            "x": 4,
            "y": 7,
            "z": 17,
            "elements": [
                "thermalfoundation:glass_alloy@7"
            ]
        },
        {
            "x": 0,
            "y": -1,
            "z": 13,
            "elements": [
                "thermalfoundation:glass_alloy@7"
            ]
        },
        {
            "x": 1,
            "y": -1,
            "z": 13,
            "elements": [
                "thermalfoundation:glass_alloy@7"
            ]
        },
        {
            "x": 2,
            "y": -1,
            "z": 13,
            "elements": [
                "thermalfoundation:glass_alloy@7"
            ]
        },
        {
            "x": 3,
            "y": -1,
            "z": 13,
            "elements": [
                "mekanism:glowplasticblock@8"
            ]
        },
        {
            "x": 6,
            "y": -1,
            "z": 13,
            "elements": [
                "thermalfoundation:glass_alloy@7"
            ]
        },
        {
            "x": -3,
            "y": 8,
            "z": 17,
            "elements": [
                "mekanism:plasticblock@7"
            ]
        },
        {
            "x": -6,
            "y": 0,
            "z": 13,
            "elements": [
                "thermalfoundation:glass_alloy@7"
            ]
        },
        {
            "x": -1,
            "y": 8,
            "z": 17,
            "elements": [
                "mekanism:reinforcedplasticblock@8"
            ]
        },
        {
            "x": 1,
            "y": 8,
            "z": 17,
            "elements": [
                "mekanism:reinforcedplasticblock@8"
            ]
        },
        {
            "x": -3,
            "y": 0,
            "z": 13,
            "elements": [
                "mekanism:glowplasticblock@8"
            ]
        },
        {
            "x": -2,
            "y": 0,
            "z": 13,
            "elements": [
                "thermalfoundation:glass_alloy@7"
            ]
        },
        {
            "x": 3,
            "y": 8,
            "z": 17,
            "elements": [
                "mekanism:plasticblock@7"
            ]
        },
        {
            "x": -1,
            "y": 0,
            "z": 13,
            "elements": [
                "thermalfoundation:glass_alloy@7"
            ]
        },
        {
            "x": 0,
            "y": 0,
            "z": 13,
            "elements": [
                "thermalfoundation:glass_alloy@7"
            ]
        },
        {
            "x": 1,
            "y": 0,
            "z": 13,
            "elements": [
                "thermalfoundation:glass_alloy@7"
            ]
        },
        {
            "x": 2,
            "y": 0,
            "z": 13,
            "elements": [
                "thermalfoundation:glass_alloy@7"
            ]
        },
        {
            "x": 3,
            "y": 0,
            "z": 13,
            "elements": [
                "mekanism:glowplasticblock@8"
            ]
        },
        {
            "x": 6,
            "y": 0,
            "z": 13,
            "elements": [
                "thermalfoundation:glass_alloy@7"
            ]
        },
        {
            "x": -6,
            "y": 1,
            "z": 13,
            "elements": [
                "thermalfoundation:glass_alloy@7"
            ]
        },
        {
            "x": -2,
            "y": 9,
            "z": 17,
            "elements": [
                "mekanism:reinforcedplasticblock@8"
            ]
        },
        {
            "x": -3,
            "y": 1,
            "z": 13,
            "elements": [
                "mekanism:glowplasticblock@8"
            ]
        },
        {
            "x": 2,
            "y": 9,
            "z": 17,
            "elements": [
                "mekanism:reinforcedplasticblock@8"
            ]
        },
        {
            "x": -2,
            "y": 1,
            "z": 13,
            "elements": [
                "thermalfoundation:glass_alloy@7"
            ]
        },
        {
            "x": -1,
            "y": 1,
            "z": 13,
            "elements": [
                "thermalfoundation:glass_alloy@7"
            ]
        },
        {
            "x": 0,
            "y": 1,
            "z": 13,
            "elements": [
                "enderio:block_alloy@6"
            ]
        },
        {
            "x": -3,
            "y": -7,
            "z": 9,
            "elements": [
                "mekanism:plasticblock@7"
            ]
        },
        {
            "x": 1,
            "y": 1,
            "z": 13,
            "elements": [
                "thermalfoundation:glass_alloy@7"
            ]
        },
        {
            "x": -2,
            "y": -7,
            "z": 9,
            "elements": [
                "mekanism:reinforcedplasticblock@8"
            ]
        },
        {
            "x": 2,
            "y": 1,
            "z": 13,
            "elements": [
                "thermalfoundation:glass_alloy@7"
            ]
        },
        {
            "x": 3,
            "y": 1,
            "z": 13,
            "elements": [
                "mekanism:glowplasticblock@8"
            ]
        },
        {
            "x": 0,
            "y": -7,
            "z": 9,
            "elements": [
                "mekanism:glowplasticblock@8"
            ]
        },
        {
            "x": 6,
            "y": 1,
            "z": 13,
            "elements": [
                "thermalfoundation:glass_alloy@7"
            ]
        },
        {
            "x": 2,
            "y": -7,
            "z": 9,
            "elements": [
                "mekanism:reinforcedplasticblock@8"
            ]
        },
        {
            "x": 3,
            "y": -7,
            "z": 9,
            "elements": [
                "mekanism:plasticblock@7"
            ]
        },
        {
            "x": -6,
            "y": 2,
            "z": 13,
            "elements": [
                "thermalfoundation:glass_alloy@7"
            ]
        },
        {
            "x": -3,
            "y": 2,
            "z": 13,
            "elements": [
                "mekanism:glowplasticblock@8"
            ]
        },
        {
            "x": -2,
            "y": 2,
            "z": 13,
            "elements": [
                "thermalfoundation:glass_alloy@7"
            ]
        },
        {
            "x": -1,
            "y": 2,
            "z": 13,
            "elements": [
                "enderio:block_alloy@6"
            ]
        },
        {
            "x": -4,
            "y": -6,
            "z": 9,
            "elements": [
                "thermalfoundation:glass_alloy@7"
            ]
        },
        {
            "x": 0,
            "y": 2,
            "z": 13,
            "elements": [
                "enderio:block_alloy@6"
            ]
        },
        {
            "x": 1,
            "y": 2,
            "z": 13,
            "elements": [
                "enderio:block_alloy@6"
            ]
        },
        {
            "x": 2,
            "y": 2,
            "z": 13,
            "elements": [
                "thermalfoundation:glass_alloy@7"
            ]
        },
        {
            "x": -1,
            "y": -6,
            "z": 9,
            "elements": [
                "appliedenergistics2:controller@0"
            ]
        },
        {
            "x": 3,
            "y": 2,
            "z": 13,
            "elements": [
                "mekanism:glowplasticblock@8"
            ]
        },
        {
            "x": 1,
            "y": -6,
            "z": 9,
            "elements": [
                "appliedenergistics2:controller@0"
            ]
        },
        {
            "x": 6,
            "y": 2,
            "z": 13,
            "elements": [
                "thermalfoundation:glass_alloy@7"
            ]
        },
        {
            "x": 4,
            "y": -6,
            "z": 9,
            "elements": [
                "thermalfoundation:glass_alloy@7"
            ]
        },
        {
            "x": -6,
            "y": 3,
            "z": 13,
            "elements": [
                "thermalfoundation:glass_alloy@7"
            ]
        },
        {
            "x": -3,
            "y": 3,
            "z": 13,
            "elements": [
                "mekanism:glowplasticblock@8"
            ]
        },
        {
            "x": -2,
            "y": 3,
            "z": 13,
            "elements": [
                "thermalfoundation:glass_alloy@7"
            ]
        },
        {
            "x": -5,
            "y": -5,
            "z": 9,
            "elements": [
                "thermalfoundation:glass_alloy@7"
            ]
        },
        {
            "x": -1,
            "y": 3,
            "z": 13,
            "elements": [
                "enderio:block_alloy@6"
            ]
        },
        {
            "x": 0,
            "y": 3,
            "z": 13,
            "elements": [
                "thermalfoundation:fluid_cryotheum@0"
            ]
        },
        {
            "x": 1,
            "y": 3,
            "z": 13,
            "elements": [
                "enderio:block_alloy@6"
            ]
        },
        {
            "x": -2,
            "y": -5,
            "z": 9,
            "elements": [
                "modularmachinery:blockcasing@0"
            ]
        },
        {
            "x": 2,
            "y": 3,
            "z": 13,
            "elements": [
                "thermalfoundation:glass_alloy@7"
            ]
        },
        {
            "x": -1,
            "y": -5,
            "z": 9,
            "elements": [
                "mekanism:glowplasticblock@8"
            ]
        },
        {
            "x": 3,
            "y": 3,
            "z": 13,
            "elements": [
                "mekanism:glowplasticblock@8"
            ]
        },
        {
            "x": 0,
            "y": -5,
            "z": 9,
            "elements": [
                "mekanism:glowplasticblock@8"
            ]
        },
        {
            "x": 1,
            "y": -5,
            "z": 9,
            "elements": [
                "mekanism:glowplasticblock@8"
            ]
        },
        {
            "x": 6,
            "y": 3,
            "z": 13,
            "elements": [
                "thermalfoundation:glass_alloy@7"
            ]
        },
        {
            "x": 2,
            "y": -5,
            "z": 9,
            "elements": [
                "modularmachinery:blockcasing@0"
            ]
        },
        {
            "x": 5,
            "y": -5,
            "z": 9,
            "elements": [
                "thermalfoundation:glass_alloy@7"
            ]
        },
        {
            "x": -6,
            "y": 4,
            "z": 13,
            "elements": [
                "thermalfoundation:glass_alloy@7"
            ]
        },
        {
            "x": -3,
            "y": 4,
            "z": 13,
            "elements": [
                "appliedenergistics2:sky_stone_brick_stairs@3"
            ]
        },
        {
            "x": -6,
            "y": -4,
            "z": 9,
            "elements": [
                "thermalfoundation:glass_alloy@7"
            ]
        },
        {
            "x": -2,
            "y": 4,
            "z": 13,
            "elements": [
                "appliedenergistics2:sky_stone_brick_stairs@3"
            ]
        },
        {
            "x": -1,
            "y": 4,
            "z": 13,
            "elements": [
                "enderio:block_alloy@6"
            ]
        },
        {
            "x": 1,
            "y": 4,
            "z": 13,
            "elements": [
                "enderio:block_alloy@6"
            ]
        },
        {
            "x": -3,
            "y": -4,
            "z": 9,
            "elements": [
                "mekanism:glowplasticblock@8"
            ]
        },
        {
            "x": -2,
            "y": -4,
            "z": 9,
            "elements": [
                "tconevo:metal_block@7"
            ]
        },
        {
            "x": 2,
            "y": 4,
            "z": 13,
            "elements": [
                "appliedenergistics2:sky_stone_brick_stairs@3"
            ]
        },
        {
            "x": -1,
            "y": -4,
            "z": 9,
            "elements": [
                "appliedenergistics2:controller@0"
            ]
        },
        {
            "x": 3,
            "y": 4,
            "z": 13,
            "elements": [
                "appliedenergistics2:sky_stone_brick_stairs@3"
            ]
        },
        {
            "x": 0,
            "y": -4,
            "z": 9,
            "elements": [
                "immersiveengineering:metal_decoration0@3"
            ]
        },
        {
            "x": 1,
            "y": -4,
            "z": 9,
            "elements": [
                "appliedenergistics2:controller@0"
            ]
        },
        {
            "x": 6,
            "y": 4,
            "z": 13,
            "elements": [
                "thermalfoundation:glass_alloy@7"
            ]
        },
        {
            "x": 2,
            "y": -4,
            "z": 9,
            "elements": [
                "tconevo:metal_block@7"
            ]
        },
        {
            "x": 3,
            "y": -4,
            "z": 9,
            "elements": [
                "mekanism:glowplasticblock@8"
            ]
        },
        {
            "x": 6,
            "y": -4,
            "z": 9,
            "elements": [
                "thermalfoundation:glass_alloy@7"
            ]
        },
        {
            "x": -6,
            "y": 5,
            "z": 13,
            "elements": [
                "thermalfoundation:glass_alloy@7"
            ]
        },
        {
            "x": -6,
            "y": -3,
            "z": 9,
            "elements": [
                "thermalfoundation:glass_alloy@7"
            ]
        },
        {
            "x": -1,
            "y": 5,
            "z": 13,
            "elements": [
                "appliedenergistics2:sky_stone_brick_slab@0"
            ]
        },
        {
            "x": 0,
            "y": 5,
            "z": 13,
            "elements": [
                "enderio:block_alloy@6"
            ]
        },
        {
            "x": 1,
            "y": 5,
            "z": 13,
            "elements": [
                "appliedenergistics2:sky_stone_brick_slab@0"
            ]
        },
        {
            "x": -3,
            "y": -3,
            "z": 9,
            "elements": [
                "thermalfoundation:glass_alloy@7"
            ]
        },
        {
            "x": -2,
            "y": -3,
            "z": 9,
            "elements": [
                "thermalfoundation:fluid_cryotheum@0"
            ]
        },
        {
            "x": -1,
            "y": -3,
            "z": 9,
            "elements": [
                "immersiveengineering:sheetmetal@3"
            ]
        },
        {
            "x": 0,
            "y": -3,
            "z": 9,
            "elements": [
                "thermalfoundation:fluid_cryotheum@0"
            ]
        },
        {
            "x": 1,
            "y": -3,
            "z": 9,
            "elements": [
                "immersiveengineering:sheetmetal@3"
            ]
        },
        {
            "x": 6,
            "y": 5,
            "z": 13,
            "elements": [
                "thermalfoundation:glass_alloy@7"
            ]
        },
        {
            "x": 2,
            "y": -3,
            "z": 9,
            "elements": [
                "thermalfoundation:fluid_cryotheum@0"
            ]
        },
        {
            "x": 3,
            "y": -3,
            "z": 9,
            "elements": [
                "thermalfoundation:glass_alloy@7"
            ]
        },
        {
            "x": 6,
            "y": -3,
            "z": 9,
            "elements": [
                "thermalfoundation:glass_alloy@7"
            ]
        },
        {
            "x": -5,
            "y": 6,
            "z": 13,
            "elements": [
                "thermalfoundation:glass_alloy@7"
            ]
        },
        {
            "x": -6,
            "y": -2,
            "z": 9,
            "elements": [
                "thermalfoundation:glass_alloy@7"
            ]
        },
        {
            "x": -3,
            "y": -2,
            "z": 9,
            "elements": [
                "thermalfoundation:glass_alloy@7"
            ]
        },
        {
            "x": -2,
            "y": -2,
            "z": 9,
            "elements": [
                "thermalfoundation:fluid_cryotheum@0"
            ]
        },
        {
            "x": -1,
            "y": -2,
            "z": 9,
            "elements": [
                "minecraft:prismarine@1"
            ]
        },
        {
            "x": 0,
            "y": -2,
            "z": 9,
            "elements": [
                "thermalfoundation:storage_alloy@7"
            ]
        },
        {
            "x": 5,
            "y": 6,
            "z": 13,
            "elements": [
                "thermalfoundation:glass_alloy@7"
            ]
        },
        {
            "x": 1,
            "y": -2,
            "z": 9,
            "elements": [
                "minecraft:prismarine@1"
            ]
        },
        {
            "x": 2,
            "y": -2,
            "z": 9,
            "elements": [
                "thermalfoundation:fluid_cryotheum@0"
            ]
        },
        {
            "x": 3,
            "y": -2,
            "z": 9,
            "elements": [
                "thermalfoundation:glass_alloy@7"
            ]
        },
        {
            "x": 6,
            "y": -2,
            "z": 9,
            "elements": [
                "thermalfoundation:glass_alloy@7"
            ]
        },
        {
            "x": -4,
            "y": 7,
            "z": 13,
            "elements": [
                "thermalfoundation:glass_alloy@7"
            ]
        },
        {
            "x": -6,
            "y": -1,
            "z": 9,
            "elements": [
                "thermalfoundation:glass_alloy@7"
            ]
        },
        {
            "x": -1,
            "y": 7,
            "z": 13,
            "elements": [
                "appliedenergistics2:controller@0"
            ]
        },
        {
            "x": 0,
            "y": 7,
            "z": 13,
            "elements": [
                "mekanism:glowplasticblock@8"
            ]
        },
        {
            "x": 1,
            "y": 7,
            "z": 13,
            "elements": [
                "appliedenergistics2:controller@0"
            ]
        },
        {
            "x": -3,
            "y": -1,
            "z": 9,
            "elements": [
                "thermalfoundation:glass_alloy@7"
            ]
        },
        {
            "x": -2,
            "y": -1,
            "z": 9,
            "elements": [
                "thermalfoundation:fluid_cryotheum@0"
            ]
        },
        {
            "x": -1,
            "y": -1,
            "z": 9,
            "elements": [
                "minecraft:prismarine@1"
            ]
        },
        {
            "x": 4,
            "y": 7,
            "z": 13,
            "elements": [
                "thermalfoundation:glass_alloy@7"
            ]
        },
        {
            "x": 0,
            "y": -1,
            "z": 9,
            "elements": [
                "immersiveengineering:metal_decoration0@5"
            ]
        },
        {
            "x": 1,
            "y": -1,
            "z": 9,
            "elements": [
                "minecraft:prismarine@1"
            ]
        },
        {
            "x": 2,
            "y": -1,
            "z": 9,
            "elements": [
                "thermalfoundation:fluid_cryotheum@0"
            ]
        },
        {
            "x": 3,
            "y": -1,
            "z": 9,
            "elements": [
                "thermalfoundation:glass_alloy@7"
            ]
        },
        {
            "x": 6,
            "y": -1,
            "z": 9,
            "elements": [
                "thermalfoundation:glass_alloy@7"
            ]
        },
        {
            "x": -4,
            "y": -7,
            "z": 22,
            "elements": [
                "modularmachinery:blockcasing@4"
            ]
        },
        {
            "x": -3,
            "y": -7,
            "z": 22,
            "elements": [
                "modularmachinery:blockcasing@4"
            ]
        },
        {
            "x": -2,
            "y": -7,
            "z": 22,
            "elements": [
                "mekanism:reinforcedplasticblock@8"
            ]
        },
        {
            "x": 0,
            "y": -7,
            "z": 22,
            "elements": [
                "mekanism:glowplasticblock@8"
            ]
        },
        {
            "x": 2,
            "y": -7,
            "z": 22,
            "elements": [
                "mekanism:reinforcedplasticblock@8"
            ]
        },
        {
            "x": 3,
            "y": -7,
            "z": 22,
            "elements": [
                "modularmachinery:blockcasing@4"
            ]
        },
        {
            "x": 4,
            "y": -7,
            "z": 22,
            "elements": [
                "modularmachinery:blockcasing@4"
            ]
        },
        {
            "x": -3,
            "y": 8,
            "z": 13,
            "elements": [
                "mekanism:plasticblock@7"
            ]
        },
        {
            "x": -6,
            "y": 0,
            "z": 9,
            "elements": [
                "thermalfoundation:glass_alloy@7"
            ]
        },
        {
            "x": -1,
            "y": 8,
            "z": 13,
            "elements": [
                "mekanism:reinforcedplasticblock@8"
            ]
        },
        {
            "x": 1,
            "y": 8,
            "z": 13,
            "elements": [
                "mekanism:reinforcedplasticblock@8"
            ]
        },
        {
            "x": -3,
            "y": 0,
            "z": 9,
            "elements": [
                "thermalfoundation:glass_alloy@7"
            ]
        },
        {
            "x": -2,
            "y": 0,
            "z": 9,
            "elements": [
                "thermalfoundation:fluid_cryotheum@0"
            ]
        },
        {
            "x": 3,
            "y": 8,
            "z": 13,
            "elements": [
                "mekanism:plasticblock@7"
            ]
        },
        {
            "x": -1,
            "y": 0,
            "z": 9,
            "elements": [
                "tconevo:metal_block@6"
            ]
        },
        {
            "x": 0,
            "y": 0,
            "z": 9,
            "elements": [
                "draconicevolution:draconic_block@0"
            ]
        },
        {
            "x": 1,
            "y": 0,
            "z": 9,
            "elements": [
                "tconevo:metal_block@6"
            ]
        },
        {
            "x": 2,
            "y": 0,
            "z": 9,
            "elements": [
                "thermalfoundation:fluid_cryotheum@0"
            ]
        },
        {
            "x": 3,
            "y": 0,
            "z": 9,
            "elements": [
                "thermalfoundation:glass_alloy@7"
            ]
        },
        {
            "x": 6,
            "y": 0,
            "z": 9,
            "elements": [
                "thermalfoundation:glass_alloy@7"
            ]
        },
        {
            "x": -4,
            "y": -6,
            "z": 22,
            "elements": [
                "modularmachinery:blockcasing@4"
            ]
        },
        {
            "x": -3,
            "y": -6,
            "z": 22,
            "elements": [
                "mekanism:plasticblock@7"
            ]
        },
        {
            "x": -2,
            "y": -6,
            "z": 22,
            "elements": [
                "mekanism:reinforcedplasticblock@8"
            ]
        },
        {
            "x": -1,
            "y": -6,
            "z": 22,
            "elements": [
                "modularmachinery:blockcasing@4"
            ]
        },
        {
            "x": 0,
            "y": -6,
            "z": 22,
            "elements": [
                "mekanism:glowplasticblock@8"
            ]
        },
        {
            "x": 1,
            "y": -6,
            "z": 22,
            "elements": [
                "modularmachinery:blockcasing@4"
            ]
        },
        {
            "x": 2,
            "y": -6,
            "z": 22,
            "elements": [
                "mekanism:reinforcedplasticblock@8"
            ]
        },
        {
            "x": 3,
            "y": -6,
            "z": 22,
            "elements": [
                "mekanism:plasticblock@7"
            ]
        },
        {
            "x": 4,
            "y": -6,
            "z": 22,
            "elements": [
                "modularmachinery:blockcasing@4"
            ]
        },
        {
            "x": -6,
            "y": 1,
            "z": 9,
            "elements": [
                "thermalfoundation:glass_alloy@7"
            ]
        },
        {
            "x": -2,
            "y": 9,
            "z": 13,
            "elements": [
                "mekanism:reinforcedplasticblock@8"
            ]
        },
        {
            "x": -3,
            "y": 1,
            "z": 9,
            "elements": [
                "thermalfoundation:glass_alloy@7"
            ]
        },
        {
            "x": 2,
            "y": 9,
            "z": 13,
            "elements": [
                "mekanism:reinforcedplasticblock@8"
            ]
        },
        {
            "x": -2,
            "y": 1,
            "z": 9,
            "elements": [
                "thermalfoundation:fluid_cryotheum@0"
            ]
        },
        {
            "x": -1,
            "y": 1,
            "z": 9,
            "elements": [
                "minecraft:prismarine@1"
            ]
        },
        {
            "x": 0,
            "y": 1,
            "z": 9,
            "elements": [
                "immersiveengineering:metal_decoration0@5"
            ]
        },
        {
            "x": -3,
            "y": -7,
            "z": 5,
            "elements": [
                "mekanism:plasticblock@7"
            ]
        },
        {
            "x": 1,
            "y": 1,
            "z": 9,
            "elements": [
                "minecraft:prismarine@1"
            ]
        },
        {
            "x": -2,
            "y": -7,
            "z": 5,
            "elements": [
                "mekanism:reinforcedplasticblock@8"
            ]
        },
        {
            "x": 2,
            "y": 1,
            "z": 9,
            "elements": [
                "thermalfoundation:fluid_cryotheum@0"
            ]
        },
        {
            "x": 3,
            "y": 1,
            "z": 9,
            "elements": [
                "thermalfoundation:glass_alloy@7"
            ]
        },
        {
            "x": 0,
            "y": -7,
            "z": 5,
            "elements": [
                "mekanism:glowplasticblock@8"
            ]
        },
        {
            "x": 6,
            "y": 1,
            "z": 9,
            "elements": [
                "thermalfoundation:glass_alloy@7"
            ]
        },
        {
            "x": 2,
            "y": -7,
            "z": 5,
            "elements": [
                "mekanism:reinforcedplasticblock@8"
            ]
        },
        {
            "x": 3,
            "y": -7,
            "z": 5,
            "elements": [
                "mekanism:plasticblock@7"
            ]
        },
        {
            "x": -4,
            "y": -5,
            "z": 22,
            "elements": [
                "thermalfoundation:glass_alloy@7"
            ]
        },
        {
            "x": -3,
            "y": -5,
            "z": 22,
            "elements": [
                "mekanism:plasticblock@7"
            ]
        },
        {
            "x": -2,
            "y": -5,
            "z": 22,
            "elements": [
                "mekanism:reinforcedplasticblock@8"
            ]
        },
        {
            "x": -1,
            "y": -5,
            "z": 22,
            "elements": [
                "appliedenergistics2:controller@0"
            ]
        },
        {
            "x": 0,
            "y": -5,
            "z": 22,
            "elements": [
                "mekanism:glowplasticblock@8"
            ]
        },
        {
            "x": 1,
            "y": -5,
            "z": 22,
            "elements": [
                "appliedenergistics2:controller@0"
            ]
        },
        {
            "x": 2,
            "y": -5,
            "z": 22,
            "elements": [
                "mekanism:reinforcedplasticblock@8"
            ]
        },
        {
            "x": 3,
            "y": -5,
            "z": 22,
            "elements": [
                "mekanism:plasticblock@7"
            ]
        },
        {
            "x": 4,
            "y": -5,
            "z": 22,
            "elements": [
                "thermalfoundation:glass_alloy@7"
            ]
        },
        {
            "x": -6,
            "y": 2,
            "z": 9,
            "elements": [
                "thermalfoundation:glass_alloy@7"
            ]
        },
        {
            "x": -3,
            "y": 2,
            "z": 9,
            "elements": [
                "thermalfoundation:glass_alloy@7"
            ]
        },
        {
            "x": -2,
            "y": 2,
            "z": 9,
            "elements": [
                "thermalfoundation:fluid_cryotheum@0"
            ]
        },
        {
            "x": -1,
            "y": 2,
            "z": 9,
            "elements": [
                "minecraft:prismarine@1"
            ]
        },
        {
            "x": -4,
            "y": -6,
            "z": 5,
            "elements": [
                "thermalfoundation:glass_alloy@7"
            ]
        },
        {
            "x": 0,
            "y": 2,
            "z": 9,
            "elements": [
                "tconevo:metal_block@8"
            ]
        },
        {
            "x": 1,
            "y": 2,
            "z": 9,
            "elements": [
                "minecraft:prismarine@1"
            ]
        },
        {
            "x": 2,
            "y": 2,
            "z": 9,
            "elements": [
                "thermalfoundation:fluid_cryotheum@0"
            ]
        },
        {
            "x": -1,
            "y": -6,
            "z": 5,
            "elements": [
                "appliedenergistics2:controller@0"
            ]
        },
        {
            "x": 3,
            "y": 2,
            "z": 9,
            "elements": [
                "thermalfoundation:glass_alloy@7"
            ]
        },
        {
            "x": 1,
            "y": -6,
            "z": 5,
            "elements": [
                "appliedenergistics2:controller@0"
            ]
        },
        {
            "x": 6,
            "y": 2,
            "z": 9,
            "elements": [
                "thermalfoundation:glass_alloy@7"
            ]
        },
        {
            "x": 4,
            "y": -6,
            "z": 5,
            "elements": [
                "thermalfoundation:glass_alloy@7"
            ]
        },
        {
            "x": -5,
            "y": -4,
            "z": 22,
            "elements": [
                "thermalfoundation:glass_alloy@7"
            ]
        },
        {
            "x": -4,
            "y": -4,
            "z": 22,
            "elements": [
                "thermalfoundation:glass_alloy@7"
            ]
        },
        {
            "x": -1,
            "y": -4,
            "z": 22,
            "elements": [
                "appliedenergistics2:controller@0"
            ]
        },
        {
            "x": 1,
            "y": -4,
            "z": 22,
            "elements": [
                "appliedenergistics2:controller@0"
            ]
        },
        {
            "x": 4,
            "y": -4,
            "z": 22,
            "elements": [
                "thermalfoundation:glass_alloy@7"
            ]
        },
        {
            "x": 5,
            "y": -4,
            "z": 22,
            "elements": [
                "thermalfoundation:glass_alloy@7"
            ]
        },
        {
            "x": -6,
            "y": 3,
            "z": 9,
            "elements": [
                "thermalfoundation:glass_alloy@7"
            ]
        },
        {
            "x": -3,
            "y": 3,
            "z": 9,
            "elements": [
                "thermalfoundation:glass_alloy@7"
            ]
        },
        {
            "x": -2,
            "y": 3,
            "z": 9,
            "elements": [
                "thermalfoundation:fluid_cryotheum@0"
            ]
        },
        {
            "x": -5,
            "y": -5,
            "z": 5,
            "elements": [
                "thermalfoundation:glass_alloy@7"
            ]
        },
        {
            "x": -1,
            "y": 3,
            "z": 9,
            "elements": [
                "appliedenergistics2:controller@0"
            ]
        },
        {
            "x": 0,
            "y": 3,
            "z": 9,
            "elements": [
                "minecraft:prismarine@1"
            ]
        },
        {
            "x": 1,
            "y": 3,
            "z": 9,
            "elements": [
                "appliedenergistics2:controller@0"
            ]
        },
        {
            "x": -2,
            "y": -5,
            "z": 5,
            "elements": [
                "modularmachinery:blockcasing@4"
            ]
        },
        {
            "x": 2,
            "y": 3,
            "z": 9,
            "elements": [
                "thermalfoundation:fluid_cryotheum@1"
            ]
        },
        {
            "x": -1,
            "y": -5,
            "z": 5,
            "elements": [
                "modularmachinery:blockcasing@4"
            ]
        },
        {
            "x": 3,
            "y": 3,
            "z": 9,
            "elements": [
                "thermalfoundation:glass_alloy@7"
            ]
        },
        {
            "x": 0,
            "y": -5,
            "z": 5,
            "elements": [
                "modularmachinery:blockcasing@0"
            ]
        },
        {
            "x": 1,
            "y": -5,
            "z": 5,
            "elements": [
                "modularmachinery:blockcasing@4"
            ]
        },
        {
            "x": 6,
            "y": 3,
            "z": 9,
            "elements": [
                "thermalfoundation:glass_alloy@7"
            ]
        },
        {
            "x": 2,
            "y": -5,
            "z": 5,
            "elements": [
                "modularmachinery:blockcasing@4"
            ]
        },
        {
            "x": 5,
            "y": -5,
            "z": 5,
            "elements": [
                "thermalfoundation:glass_alloy@7"
            ]
        },
        {
            "x": -6,
            "y": -3,
            "z": 22,
            "elements": [
                "thermalfoundation:glass_alloy@7"
            ]
        },
        {
            "x": -5,
            "y": -3,
            "z": 22,
            "elements": [
                "thermalfoundation:glass_alloy@7"
            ]
        },
        {
            "x": -4,
            "y": -3,
            "z": 22,
            "elements": [
                "thermalfoundation:glass_alloy@7"
            ]
        },
        {
            "x": 4,
            "y": -3,
            "z": 22,
            "elements": [
                "thermalfoundation:glass_alloy@7"
            ]
        },
        {
            "x": 5,
            "y": -3,
            "z": 22,
            "elements": [
                "thermalfoundation:glass_alloy@7"
            ]
        },
        {
            "x": -6,
            "y": 4,
            "z": 9,
            "elements": [
                "thermalfoundation:glass_alloy@7"
            ]
        },
        {
            "x": 6,
            "y": -3,
            "z": 22,
            "elements": [
                "thermalfoundation:glass_alloy@7"
            ]
        },
        {
            "x": -3,
            "y": 4,
            "z": 9,
            "elements": [
                "appliedenergistics2:sky_stone_brick_slab@0"
            ]
        },
        {
            "x": -6,
            "y": -4,
            "z": 5,
            "elements": [
                "thermalfoundation:glass_alloy@7"
            ]
        },
        {
            "x": -2,
            "y": 4,
            "z": 9,
            "elements": [
                "immersiveengineering:metal_decoration0@5"
            ]
        },
        {
            "x": -1,
            "y": 4,
            "z": 9,
            "elements": [
                "thermalfoundation:glass_alloy@7"
            ]
        },
        {
            "x": 0,
            "y": 4,
            "z": 9,
            "elements": [
                "appliedenergistics2:sky_stone_brick_slab@0"
            ]
        },
        {
            "x": 1,
            "y": 4,
            "z": 9,
            "elements": [
                "thermalfoundation:glass_alloy@7"
            ]
        },
        {
            "x": -3,
            "y": -4,
            "z": 5,
            "elements": [
                "appliedenergistics2:sky_stone_brick_stairs@4"
            ]
        },
        {
            "x": -2,
            "y": -4,
            "z": 5,
            "elements": [
                "contenttweaker:zl_block@0"
            ]
        },
        {
            "x": 2,
            "y": 4,
            "z": 9,
            "elements": [
                "immersiveengineering:metal_decoration0@5"
            ]
        },
        {
            "x": -1,
            "y": -4,
            "z": 5,
            "elements": [
                "tconevo:metal_block@4"
            ]
        },
        {
            "x": 3,
            "y": 4,
            "z": 9,
            "elements": [
                "appliedenergistics2:sky_stone_brick_slab@0"
            ]
        },
        {
            "x": 0,
            "y": -4,
            "z": 5,
            "elements": [
                "contenttweaker:zl_block@0"
            ]
        },
        {
            "x": 1,
            "y": -4,
            "z": 5,
            "elements": [
                "tconevo:metal_block@4"
            ]
        },
        {
            "x": 6,
            "y": 4,
            "z": 9,
            "elements": [
                "thermalfoundation:glass_alloy@7"
            ]
        },
        {
            "x": 2,
            "y": -4,
            "z": 5,
            "elements": [
                "contenttweaker:zl_block@0"
            ]
        },
        {
            "x": 3,
            "y": -4,
            "z": 5,
            "elements": [
                "appliedenergistics2:sky_stone_brick_stairs@5"
            ]
        },
        {
            "x": 6,
            "y": -4,
            "z": 5,
            "elements": [
                "thermalfoundation:glass_alloy@7"
            ]
        },
        {
            "x": -6,
            "y": -2,
            "z": 22,
            "elements": [
                "thermalfoundation:glass_alloy@7"
            ]
        },
        {
            "x": -5,
            "y": -2,
            "z": 22,
            "elements": [
                "thermalfoundation:glass_alloy@7"
            ]
        },
        {
            "x": -4,
            "y": -2,
            "z": 22,
            "elements": [
                "thermalfoundation:glass_alloy@7"
            ]
        },
        {
            "x": 4,
            "y": -2,
            "z": 22,
            "elements": [
                "thermalfoundation:glass_alloy@7"
            ]
        },
        {
            "x": 5,
            "y": -2,
            "z": 22,
            "elements": [
                "thermalfoundation:glass_alloy@7"
            ]
        },
        {
            "x": -6,
            "y": 5,
            "z": 9,
            "elements": [
                "thermalfoundation:glass_alloy@7"
            ]
        },
        {
            "x": 6,
            "y": -2,
            "z": 22,
            "elements": [
                "thermalfoundation:glass_alloy@7"
            ]
        },
        {
            "x": -6,
            "y": -3,
            "z": 5,
            "elements": [
                "thermalfoundation:glass_alloy@7"
            ]
        },
        {
            "x": -2,
            "y": 5,
            "z": 9,
            "elements": [
                "appliedenergistics2:sky_stone_brick_slab@0"
            ]
        },
        {
            "x": 0,
            "y": 5,
            "z": 9,
            "elements": [
                "immersiveengineering:metal_decoration0@5"
            ]
        },
        {
            "x": -3,
            "y": -3,
            "z": 5,
            "elements": [
                "thermalfoundation:glass_alloy@7"
            ]
        },
        {
            "x": 2,
            "y": 5,
            "z": 9,
            "elements": [
                "appliedenergistics2:sky_stone_brick_slab@0"
            ]
        },
        {
            "x": -2,
            "y": -3,
            "z": 5,
            "elements": [
                "thermalfoundation:storage_alloy@6"
            ]
        },
        {
            "x": -1,
            "y": -3,
            "z": 5,
            "elements": [
                "thermalfoundation:storage_alloy@6"
            ]
        },
        {
            "x": 0,
            "y": -3,
            "z": 5,
            "elements": [
                "thermalfoundation:storage_alloy@6"
            ]
        },
        {
            "x": 1,
            "y": -3,
            "z": 5,
            "elements": [
                "thermalfoundation:storage_alloy@6"
            ]
        },
        {
            "x": 6,
            "y": 5,
            "z": 9,
            "elements": [
                "thermalfoundation:glass_alloy@7"
            ]
        },
        {
            "x": 2,
            "y": -3,
            "z": 5,
            "elements": [
                "thermalfoundation:storage_alloy@6"
            ]
        },
        {
            "x": 3,
            "y": -3,
            "z": 5,
            "elements": [
                "thermalfoundation:glass_alloy@7"
            ]
        },
        {
            "x": 6,
            "y": -3,
            "z": 5,
            "elements": [
                "thermalfoundation:glass_alloy@7"
            ]
        },
        {
            "x": -6,
            "y": -1,
            "z": 22,
            "elements": [
                "thermalfoundation:glass_alloy@7"
            ]
        },
        {
            "x": -5,
            "y": -1,
            "z": 22,
            "elements": [
                "thermalfoundation:glass_alloy@7"
            ]
        },
        {
            "x": -4,
            "y": -1,
            "z": 22,
            "elements": [
                "thermalfoundation:glass_alloy@7"
            ]
        },
        {
            "x": 4,
            "y": -1,
            "z": 22,
            "elements": [
                "thermalfoundation:glass_alloy@7"
            ]
        },
        {
            "x": 5,
            "y": -1,
            "z": 22,
            "elements": [
                "thermalfoundation:glass_alloy@7"
            ]
        },
        {
            "x": 6,
            "y": -1,
            "z": 22,
            "elements": [
                "thermalfoundation:glass_alloy@7"
            ]
        },
        {
            "x": -5,
            "y": 6,
            "z": 9,
            "elements": [
                "thermalfoundation:glass_alloy@7"
            ]
        },
        {
            "x": -6,
            "y": -2,
            "z": 5,
            "elements": [
                "thermalfoundation:glass_alloy@7"
            ]
        },
        {
            "x": 0,
            "y": 6,
            "z": 9,
            "elements": [
                "avaritia:block_resource@2"
            ]
        },
        {
            "x": -3,
            "y": -2,
            "z": 5,
            "elements": [
                "thermalfoundation:glass_alloy@7"
            ]
        },
        {
            "x": -2,
            "y": -2,
            "z": 5,
            "elements": [
                "thermalfoundation:fluid_cryotheum@0"
            ]
        },
        {
            "x": -1,
            "y": -2,
            "z": 5,
            "elements": [
                "tconevo:metal_block@7"
            ]
        },
        {
            "x": 0,
            "y": -2,
            "z": 5,
            "elements": [
                "tconevo:metal_block@8"
            ]
        },
        {
            "x": 5,
            "y": 6,
            "z": 9,
            "elements": [
                "thermalfoundation:glass_alloy@7"
            ]
        },
        {
            "x": 1,
            "y": -2,
            "z": 5,
            "elements": [
                "tconevo:metal_block@7"
            ]
        },
        {
            "x": 2,
            "y": -2,
            "z": 5,
            "elements": [
                "thermalfoundation:fluid_cryotheum@0"
            ]
        },
        {
            "x": 3,
            "y": -2,
            "z": 5,
            "elements": [
                "thermalfoundation:glass_alloy@7"
            ]
        },
        {
            "x": 6,
            "y": -2,
            "z": 5,
            "elements": [
                "thermalfoundation:glass_alloy@7"
            ]
        },
        {
            "x": -6,
            "y": 0,
            "z": 22,
            "elements": [
                "thermalfoundation:glass_alloy@7"
            ]
        },
        {
            "x": -5,
            "y": 0,
            "z": 22,
            "elements": [
                "thermalfoundation:glass_alloy@7"
            ]
        },
        {
            "x": -4,
            "y": 0,
            "z": 22,
            "elements": [
                "thermalfoundation:glass_alloy@7"
            ]
        },
        {
            "x": 4,
            "y": 0,
            "z": 22,
            "elements": [
                "thermalfoundation:glass_alloy@7"
            ]
        },
        {
            "x": 5,
            "y": 0,
            "z": 22,
            "elements": [
                "thermalfoundation:glass_alloy@7"
            ]
        },
        {
            "x": 6,
            "y": 0,
            "z": 22,
            "elements": [
                "thermalfoundation:glass_alloy@7"
            ]
        },
        {
            "x": -4,
            "y": 7,
            "z": 9,
            "elements": [
                "thermalfoundation:glass_alloy@7"
            ]
        },
        {
            "x": -6,
            "y": -1,
            "z": 5,
            "elements": [
                "thermalfoundation:glass_alloy@7"
            ]
        },
        {
            "x": -1,
            "y": 7,
            "z": 9,
            "elements": [
                "appliedenergistics2:controller@0"
            ]
        },
        {
            "x": 0,
            "y": 7,
            "z": 9,
            "elements": [
                "mekanism:glowplasticblock@8"
            ]
        },
        {
            "x": 1,
            "y": 7,
            "z": 9,
            "elements": [
                "appliedenergistics2:controller@0"
            ]
        },
        {
            "x": -3,
            "y": -1,
            "z": 5,
            "elements": [
                "thermalfoundation:glass_alloy@7"
            ]
        },
        {
            "x": -2,
            "y": -1,
            "z": 5,
            "elements": [
                "thermalfoundation:fluid_cryotheum@0"
            ]
        },
        {
            "x": -1,
            "y": -1,
            "z": 5,
            "elements": [
                "avaritia:block_resource@2"
            ]
        },
        {
            "x": 4,
            "y": 7,
            "z": 9,
            "elements": [
                "thermalfoundation:glass_alloy@7"
            ]
        },
        {
            "x": 0,
            "y": -1,
            "z": 5,
            "elements": [
                "immersiveengineering:metal_decoration0@5"
            ]
        },
        {
            "x": 1,
            "y": -1,
            "z": 5,
            "elements": [
                "avaritia:block_resource@2"
            ]
        },
        {
            "x": 2,
            "y": -1,
            "z": 5,
            "elements": [
                "thermalfoundation:fluid_cryotheum@0"
            ]
        },
        {
            "x": 3,
            "y": -1,
            "z": 5,
            "elements": [
                "thermalfoundation:glass_alloy@7"
            ]
        },
        {
            "x": 6,
            "y": -1,
            "z": 5,
            "elements": [
                "thermalfoundation:glass_alloy@7"
            ]
        },
        {
            "x": -6,
            "y": 1,
            "z": 22,
            "elements": [
                "thermalfoundation:glass_alloy@7"
            ]
        },
        {
            "x": -5,
            "y": 1,
            "z": 22,
            "elements": [
                "thermalfoundation:glass_alloy@7"
            ]
        },
        {
            "x": -4,
            "y": 1,
            "z": 22,
            "elements": [
                "thermalfoundation:glass_alloy@7"
            ]
        },
        {
            "x": -3,
            "y": -7,
            "z": 18,
            "elements": [
                "mekanism:plasticblock@7"
            ]
        },
        {
            "x": -2,
            "y": -7,
            "z": 18,
            "elements": [
                "mekanism:reinforcedplasticblock@8"
            ]
        },
        {
            "x": 4,
            "y": 1,
            "z": 22,
            "elements": [
                "thermalfoundation:glass_alloy@7"
            ]
        },
        {
            "x": 0,
            "y": -7,
            "z": 18,
            "elements": [
                "mekanism:glowplasticblock@8"
            ]
        },
        {
            "x": 5,
            "y": 1,
            "z": 22,
            "elements": [
                "thermalfoundation:glass_alloy@7"
            ]
        },
        {
            "x": 6,
            "y": 1,
            "z": 22,
            "elements": [
                "thermalfoundation:glass_alloy@7"
            ]
        },
        {
            "x": 2,
            "y": -7,
            "z": 18,
            "elements": [
                "mekanism:reinforcedplasticblock@8"
            ]
        },
        {
            "x": 3,
            "y": -7,
            "z": 18,
            "elements": [
                "mekanism:plasticblock@7"
            ]
        },
        {
            "x": -3,
            "y": 8,
            "z": 9,
            "elements": [
                "mekanism:plasticblock@7"
            ]
        },
        {
            "x": -6,
            "y": 0,
            "z": 5,
            "elements": [
                "thermalfoundation:glass_alloy@7"
            ]
        },
        {
            "x": -1,
            "y": 8,
            "z": 9,
            "elements": [
                "mekanism:reinforcedplasticblock@8"
            ]
        },
        {
            "x": 1,
            "y": 8,
            "z": 9,
            "elements": [
                "mekanism:reinforcedplasticblock@8"
            ]
        },
        {
            "x": -3,
            "y": 0,
            "z": 5,
            "elements": [
                "thermalfoundation:glass_alloy@7"
            ]
        },
        {
            "x": -2,
            "y": 0,
            "z": 5,
            "elements": [
                "thermalfoundation:fluid_cryotheum@0"
            ]
        },
        {
            "x": 3,
            "y": 8,
            "z": 9,
            "elements": [
                "mekanism:plasticblock@7"
            ]
        },
        {
            "x": -1,
            "y": 0,
            "z": 5,
            "elements": [
                "avaritia:block_resource@2"
            ]
        },
        {
            "x": 0,
            "y": 0,
            "z": 5,
            "elements": [
                "immersiveengineering:sheetmetal@10"
            ]
        },
        {
            "x": 1,
            "y": 0,
            "z": 5,
            "elements": [
                "avaritia:block_resource@2"
            ]
        },
        {
            "x": 2,
            "y": 0,
            "z": 5,
            "elements": [
                "thermalfoundation:fluid_cryotheum@0"
            ]
        },
        {
            "x": 3,
            "y": 0,
            "z": 5,
            "elements": [
                "thermalfoundation:glass_alloy@7"
            ]
        },
        {
            "x": 6,
            "y": 0,
            "z": 5,
            "elements": [
                "thermalfoundation:glass_alloy@7"
            ]
        },
        {
            "x": -5,
            "y": 2,
            "z": 22,
            "elements": [
                "thermalfoundation:glass_alloy@7"
            ]
        },
        {
            "x": -4,
            "y": 2,
            "z": 22,
            "elements": [
                "thermalfoundation:glass_alloy@7"
            ]
        },
        {
            "x": -1,
            "y": 2,
            "z": 22,
            "elements": [
                "appliedenergistics2:controller@0"
            ]
        },
        {
            "x": -4,
            "y": -6,
            "z": 18,
            "elements": [
                "thermalfoundation:glass_alloy@7"
            ]
        },
        {
            "x": 1,
            "y": 2,
            "z": 22,
            "elements": [
                "appliedenergistics2:controller@0"
            ]
        },
        {
            "x": -1,
            "y": -6,
            "z": 18,
            "elements": [
                "appliedenergistics2:controller@0"
            ]
        },
        {
            "x": 4,
            "y": 2,
            "z": 22,
            "elements": [
                "thermalfoundation:glass_alloy@7"
            ]
        },
        {
            "x": 1,
            "y": -6,
            "z": 18,
            "elements": [
                "appliedenergistics2:controller@0"
            ]
        },
        {
            "x": 5,
            "y": 2,
            "z": 22,
            "elements": [
                "thermalfoundation:glass_alloy@7"
            ]
        },
        {
            "x": 4,
            "y": -6,
            "z": 18,
            "elements": [
                "thermalfoundation:glass_alloy@7"
            ]
        },
        {
            "x": -6,
            "y": 1,
            "z": 5,
            "elements": [
                "thermalfoundation:glass_alloy@7"
            ]
        },
        {
            "x": -2,
            "y": 9,
            "z": 9,
            "elements": [
                "mekanism:reinforcedplasticblock@8"
            ]
        },
        {
            "x": -3,
            "y": 1,
            "z": 5,
            "elements": [
                "thermalfoundation:glass_alloy@7"
            ]
        },
        {
            "x": 2,
            "y": 9,
            "z": 9,
            "elements": [
                "mekanism:reinforcedplasticblock@8"
            ]
        },
        {
            "x": -2,
            "y": 1,
            "z": 5,
            "elements": [
                "thermalfoundation:fluid_cryotheum@0"
            ]
        },
        {
            "x": -1,
            "y": 1,
            "z": 5,
            "elements": [
                "appliedenergistics2:controller@0"
            ]
        },
        {
            "x": 0,
            "y": 1,
            "z": 5,
            "elements": [
                "immersiveengineering:sheetmetal@10"
            ]
        },
        {
            "x": 1,
            "y": 1,
            "z": 5,
            "elements": [
                "appliedenergistics2:controller@0"
            ]
        },
        {
            "x": 2,
            "y": 1,
            "z": 5,
            "elements": [
                "thermalfoundation:fluid_cryotheum@0"
            ]
        },
        {
            "x": 3,
            "y": 1,
            "z": 5,
            "elements": [
                "thermalfoundation:glass_alloy@7"
            ]
        },
        {
            "x": 6,
            "y": 1,
            "z": 5,
            "elements": [
                "thermalfoundation:glass_alloy@7"
            ]
        },
        {
            "x": -4,
            "y": 3,
            "z": 22,
            "elements": [
                "thermalfoundation:glass_alloy@7"
            ]
        },
        {
            "x": -3,
            "y": 3,
            "z": 22,
            "elements": [
                "mekanism:plasticblock@7"
            ]
        },
        {
            "x": -2,
            "y": 3,
            "z": 22,
            "elements": [
                "mekanism:reinforcedplasticblock@8"
            ]
        },
        {
            "x": -5,
            "y": -5,
            "z": 18,
            "elements": [
                "thermalfoundation:glass_alloy@7"
            ]
        },
        {
            "x": -1,
            "y": 3,
            "z": 22,
            "elements": [
                "appliedenergistics2:controller@0"
            ]
        },
        {
            "x": 0,
            "y": 3,
            "z": 22,
            "elements": [
                "mekanism:glowplasticblock@8"
            ]
        },
        {
            "x": 1,
            "y": 3,
            "z": 22,
            "elements": [
                "appliedenergistics2:controller@0"
            ]
        },
        {
            "x": -3,
            "y": -5,
            "z": 18,
            "elements": [
                "enderio:block_alloy@6"
            ]
        },
        {
            "x": -2,
            "y": -5,
            "z": 18,
            "elements": [
                "immersiveengineering:metal_decoration0@5"
            ]
        },
        {
            "x": 2,
            "y": 3,
            "z": 22,
            "elements": [
                "mekanism:reinforcedplasticblock@8"
            ]
        },
        {
            "x": -1,
            "y": -5,
            "z": 18,
            "elements": [
                "immersiveengineering:metal_decoration0@5"
            ]
        },
        {
            "x": 3,
            "y": 3,
            "z": 22,
            "elements": [
                "mekanism:plasticblock@7"
            ]
        },
        {
            "x": 4,
            "y": 3,
            "z": 22,
            "elements": [
                "thermalfoundation:glass_alloy@7"
            ]
        },
        {
            "x": 0,
            "y": -5,
            "z": 18,
            "elements": [
                "minecraft:sea_lantern@0"
            ]
        },
        {
            "x": 1,
            "y": -5,
            "z": 18,
            "elements": [
                "immersiveengineering:metal_decoration0@5"
            ]
        },
        {
            "x": 2,
            "y": -5,
            "z": 18,
            "elements": [
                "immersiveengineering:metal_decoration0@5"
            ]
        },
        {
            "x": 3,
            "y": -5,
            "z": 18,
            "elements": [
                "enderio:block_alloy@6"
            ]
        },
        {
            "x": 5,
            "y": -5,
            "z": 18,
            "elements": [
                "thermalfoundation:glass_alloy@7"
            ]
        },
        {
            "x": -6,
            "y": 2,
            "z": 5,
            "elements": [
                "thermalfoundation:glass_alloy@7"
            ]
        },
        {
            "x": -3,
            "y": 2,
            "z": 5,
            "elements": [
                "thermalfoundation:glass_alloy@7"
            ]
        },
        {
            "x": -2,
            "y": 2,
            "z": 5,
            "elements": [
                "thermalfoundation:fluid_cryotheum@0"
            ]
        },
        {
            "x": -1,
            "y": 2,
            "z": 5,
            "elements": [
                "tconevo:metal_block@7"
            ]
        },
        {
            "x": 0,
            "y": 2,
            "z": 5,
            "elements": [
                "thermalfoundation:storage_alloy@7"
            ]
        },
        {
            "x": 1,
            "y": 2,
            "z": 5,
            "elements": [
                "tconevo:metal_block@7"
            ]
        },
        {
            "x": 2,
            "y": 2,
            "z": 5,
            "elements": [
                "thermalfoundation:fluid_cryotheum@0"
            ]
        },
        {
            "x": 3,
            "y": 2,
            "z": 5,
            "elements": [
                "thermalfoundation:glass_alloy@7"
            ]
        },
        {
            "x": 6,
            "y": 2,
            "z": 5,
            "elements": [
                "thermalfoundation:glass_alloy@7"
            ]
        },
        {
            "x": -4,
            "y": 4,
            "z": 22,
            "elements": [
                "thermalfoundation:glass_alloy@7"
            ]
        },
        {
            "x": -3,
            "y": 4,
            "z": 22,
            "elements": [
                "mekanism:plasticblock@7"
            ]
        },
        {
            "x": -6,
            "y": -4,
            "z": 18,
            "elements": [
                "thermalfoundation:glass_alloy@7"
            ]
        },
        {
            "x": -2,
            "y": 4,
            "z": 22,
            "elements": [
                "mekanism:reinforcedplasticblock@8"
            ]
        },
        {
            "x": -1,
            "y": 4,
            "z": 22,
            "elements": [
                "appliedenergistics2:controller@0"
            ]
        },
        {
            "x": 0,
            "y": 4,
            "z": 22,
            "elements": [
                "mekanism:glowplasticblock@8"
            ]
        },
        {
            "x": 1,
            "y": 4,
            "z": 22,
            "elements": [
                "appliedenergistics2:controller@0"
            ]
        },
        {
            "x": -3,
            "y": -4,
            "z": 18,
            "elements": [
                "appliedenergistics2:controller@0"
            ]
        },
        {
            "x": -2,
            "y": -4,
            "z": 18,
            "elements": [
                "enderio:block_dark_iron_bars@0"
            ]
        },
        {
            "x": 2,
            "y": 4,
            "z": 22,
            "elements": [
                "mekanism:reinforcedplasticblock@8"
            ]
        },
        {
            "x": -1,
            "y": -4,
            "z": 18,
            "elements": [
                "enderio:block_dark_iron_bars@0"
            ]
        },
        {
            "x": 3,
            "y": 4,
            "z": 22,
            "elements": [
                "mekanism:plasticblock@7"
            ]
        },
        {
            "x": 0,
            "y": -4,
            "z": 18,
            "elements": [
                "enderio:block_alloy@6"
            ]
        },
        {
            "x": 4,
            "y": 4,
            "z": 22,
            "elements": [
                "thermalfoundation:glass_alloy@7"
            ]
        },
        {
            "x": 1,
            "y": -4,
            "z": 18,
            "elements": [
                "enderio:block_dark_iron_bars@0"
            ]
        },
        {
            "x": 2,
            "y": -4,
            "z": 18,
            "elements": [
                "enderio:block_dark_iron_bars@0"
            ]
        },
        {
            "x": 3,
            "y": -4,
            "z": 18,
            "elements": [
                "appliedenergistics2:controller@0"
            ]
        },
        {
            "x": 6,
            "y": -4,
            "z": 18,
            "elements": [
                "thermalfoundation:glass_alloy@7"
            ]
        },
        {
            "x": -6,
            "y": 3,
            "z": 5,
            "elements": [
                "thermalfoundation:glass_alloy@7"
            ]
        },
        {
            "x": -3,
            "y": 3,
            "z": 5,
            "elements": [
                "thermalfoundation:glass_alloy@7"
            ]
        },
        {
            "x": -2,
            "y": 3,
            "z": 5,
            "elements": [
                "thermalfoundation:fluid_cryotheum@0"
            ]
        },
        {
            "x": -1,
            "y": 3,
            "z": 5,
            "elements": [
                "appliedenergistics2:controller@0"
            ]
        },
        {
            "x": 0,
            "y": 3,
            "z": 5,
            "elements": [
                "minecraft:prismarine@1"
            ]
        },
        {
            "x": 1,
            "y": 3,
            "z": 5,
            "elements": [
                "appliedenergistics2:controller@0"
            ]
        },
        {
            "x": 2,
            "y": 3,
            "z": 5,
            "elements": [
                "thermalfoundation:fluid_cryotheum@0"
            ]
        },
        {
            "x": 3,
            "y": 3,
            "z": 5,
            "elements": [
                "thermalfoundation:glass_alloy@7"
            ]
        },
        {
            "x": 6,
            "y": 3,
            "z": 5,
            "elements": [
                "thermalfoundation:glass_alloy@7"
            ]
        },
        {
            "x": -6,
            "y": -3,
            "z": 18,
            "elements": [
                "thermalfoundation:glass_alloy@7"
            ]
        },
        {
            "x": -2,
            "y": 5,
            "z": 22,
            "elements": [
                "mekanism:reinforcedplasticblock@8"
            ]
        },
        {
            "x": -1,
            "y": 5,
            "z": 22,
            "elements": [
                "avaritia:block_resource@0"
            ]
        },
        {
            "x": 0,
            "y": 5,
            "z": 22,
            "elements": [
                "mekanism:glowplasticblock@8"
            ]
        },
        {
            "x": 1,
            "y": 5,
            "z": 22,
            "elements": [
                "avaritia:block_resource@0"
            ]
        },
        {
            "x": -3,
            "y": -3,
            "z": 18,
            "elements": [
                "appliedenergistics2:controller@0"
            ]
        },
        {
            "x": 2,
            "y": 5,
            "z": 22,
            "elements": [
                "mekanism:reinforcedplasticblock@8"
            ]
        },
        {
            "x": -2,
            "y": -3,
            "z": 18,
            "elements": [
                "enderio:block_dark_iron_bars@0"
            ]
        },
        {
            "x": -1,
            "y": -3,
            "z": 18,
            "elements": [
                "enderio:block_dark_iron_bars@0"
            ]
        },
        {
            "x": 0,
            "y": -3,
            "z": 18,
            "elements": [
                "enderio:block_alloy@6"
            ]
        },
        {
            "x": 1,
            "y": -3,
            "z": 18,
            "elements": [
                "enderio:block_dark_iron_bars@0"
            ]
        },
        {
            "x": 2,
            "y": -3,
            "z": 18,
            "elements": [
                "enderio:block_dark_iron_bars@0"
            ]
        },
        {
            "x": 3,
            "y": -3,
            "z": 18,
            "elements": [
                "appliedenergistics2:controller@0"
            ]
        },
        {
            "x": -6,
            "y": 4,
            "z": 5,
            "elements": [
                "thermalfoundation:glass_alloy@7"
            ]
        },
        {
            "x": 6,
            "y": -3,
            "z": 18,
            "elements": [
                "thermalfoundation:glass_alloy@7"
            ]
        },
        {
            "x": -3,
            "y": 4,
            "z": 5,
            "elements": [
                "appliedenergistics2:sky_stone_brick_stairs@0"
            ]
        },
        {
            "x": -2,
            "y": 4,
            "z": 5,
            "elements": [
                "immersiveengineering:metal_decoration0@5"
            ]
        },
        {
            "x": -1,
            "y": 4,
            "z": 5,
            "elements": [
                "thermalfoundation:glass_alloy@7"
            ]
        },
        {
            "x": 0,
            "y": 4,
            "z": 5,
            "elements": [
                "appliedenergistics2:sky_stone_brick_slab@0"
            ]
        },
        {
            "x": 1,
            "y": 4,
            "z": 5,
            "elements": [
                "thermalfoundation:glass_alloy@7"
            ]
        },
        {
            "x": 2,
            "y": 4,
            "z": 5,
            "elements": [
                "immersiveengineering:metal_decoration0@5"
            ]
        },
        {
            "x": -2,
            "y": -4,
            "z": 1,
            "elements": [
                "mekanism:reinforcedplasticblock@8"
            ]
        },
        {
            "x": -1,
            "y": -4,
            "z": 1,
            "elements": [
                "avaritia:block_resource@0"
            ]
        },
        {
            "x": 3,
            "y": 4,
            "z": 5,
            "elements": [
                "appliedenergistics2:sky_stone_brick_stairs@1"
            ]
        },
        {
            "x": 0,
            "y": -4,
            "z": 1,
            "elements": [
                "mekanism:glowplasticblock@8"
            ]
        },
        {
            "x": 1,
            "y": -4,
            "z": 1,
            "elements": [
                "avaritia:block_resource@0"
            ]
        },
        {
            "x": 6,
            "y": 4,
            "z": 5,
            "elements": [
                "thermalfoundation:glass_alloy@7"
            ]
        },
        {
            "x": 2,
            "y": -4,
            "z": 1,
            "elements": [
                "mekanism:reinforcedplasticblock@8"
            ]
        },
        {
            "x": -6,
            "y": -2,
            "z": 18,
            "elements": [
                "thermalfoundation:glass_alloy@7"
            ]
        },
        {
            "x": -3,
            "y": -2,
            "z": 18,
            "elements": [
                "appliedenergistics2:controller@0"
            ]
        },
        {
            "x": -2,
            "y": -2,
            "z": 18,
            "elements": [
                "enderio:block_dark_iron_bars@0"
            ]
        },
        {
            "x": -1,
            "y": -2,
            "z": 18,
            "elements": [
                "enderio:block_dark_iron_bars@0"
            ]
        },
        {
            "x": 0,
            "y": -2,
            "z": 18,
            "elements": [
                "enderio:block_alloy@6"
            ]
        },
        {
            "x": 1,
            "y": -2,
            "z": 18,
            "elements": [
                "enderio:block_dark_iron_bars@0"
            ]
        },
        {
            "x": 2,
            "y": -2,
            "z": 18,
            "elements": [
                "enderio:block_dark_iron_bars@0"
            ]
        },
        {
            "x": 3,
            "y": -2,
            "z": 18,
            "elements": [
                "appliedenergistics2:controller@0"
            ]
        },
        {
            "x": 4,
            "y": -2,
            "z": 18,
            "elements": [
                "avaritia:block_resource@0"
            ]
        },
        {
            "x": 5,
            "y": -2,
            "z": 18,
            "elements": [
                "avaritia:block_resource@0"
            ]
        },
        {
            "x": -6,
            "y": 5,
            "z": 5,
            "elements": [
                "thermalfoundation:glass_alloy@7"
            ]
        },
        {
            "x": 6,
            "y": -2,
            "z": 18,
            "elements": [
                "modularmachinery:blockcasing@4"
            ]
        },
        {
            "x": -5,
            "y": 5,
            "z": 5,
            "elements": [
                "thermalfoundation:glass_alloy@7"
            ]
        },
        {
            "x": -2,
            "y": 5,
            "z": 5,
            "elements": [
                "appliedenergistics2:sky_stone_brick_slab@0"
            ]
        },
        {
            "x": -1,
            "y": 5,
            "z": 5,
            "elements": [
                "thermalfoundation:storage_alloy@6"
            ]
        },
        {
            "x": 0,
            "y": 5,
            "z": 5,
            "elements": [
                "avaritia:block_resource@0"
            ]
        },
        {
            "x": 1,
            "y": 5,
            "z": 5,
            "elements": [
                "thermalfoundation:storage_alloy@6"
            ]
        },
        {
            "x": -3,
            "y": -3,
            "z": 1,
            "elements": [
                "mekanism:plasticblock@7"
            ]
        },
        {
            "x": 2,
            "y": 5,
            "z": 5,
            "elements": [
                "appliedenergistics2:sky_stone_brick_slab@0"
            ]
        },
        {
            "x": -2,
            "y": -3,
            "z": 1,
            "elements": [
                "mekanism:reinforcedplasticblock@8"
            ]
        },
        {
            "x": -1,
            "y": -3,
            "z": 1,
            "elements": [
                "avaritia:block_resource@0"
            ]
        },
        {
            "x": 0,
            "y": -3,
            "z": 1,
            "elements": [
                "mekanism:glowplasticblock@8"
            ]
        },
        {
            "x": 5,
            "y": 5,
            "z": 5,
            "elements": [
                "thermalfoundation:glass_alloy@7"
            ]
        },
        {
            "x": 1,
            "y": -3,
            "z": 1,
            "elements": [
                "avaritia:block_resource@0"
            ]
        },
        {
            "x": 6,
            "y": 5,
            "z": 5,
            "elements": [
                "thermalfoundation:glass_alloy@7"
            ]
        },
        {
            "x": 2,
            "y": -3,
            "z": 1,
            "elements": [
                "mekanism:reinforcedplasticblock@8"
            ]
        },
        {
            "x": 3,
            "y": -3,
            "z": 1,
            "elements": [
                "mekanism:plasticblock@7"
            ]
        },
        {
            "x": -6,
            "y": -1,
            "z": 18,
            "elements": [
                "thermalfoundation:glass_alloy@7"
            ]
        },
        {
            "x": -3,
            "y": -1,
            "z": 18,
            "elements": [
                "minecraft:sea_lantern@0"
            ]
        },
        {
            "x": -2,
            "y": -1,
            "z": 18,
            "elements": [
                "enderio:block_dark_iron_bars@0"
            ]
        },
        {
            "x": -1,
            "y": -1,
            "z": 18,
            "elements": [
                "enderio:block_dark_iron_bars@0"
            ]
        },
        {
            "x": 0,
            "y": -1,
            "z": 18,
            "elements": [
                "enderio:block_alloy@6"
            ]
        },
        {
            "x": 1,
            "y": -1,
            "z": 18,
            "elements": [
                "enderio:block_dark_iron_bars@0"
            ]
        },
        {
            "x": 2,
            "y": -1,
            "z": 18,
            "elements": [
                "enderio:block_dark_iron_bars@0"
            ]
        },
        {
            "x": 6,
            "y": -1,
            "z": 18,
            "elements": [
                "modularmachinery:blockfluidinputhatch"
            ]
        },
        {
            "x": -5,
            "y": 6,
            "z": 5,
            "elements": [
                "thermalfoundation:glass_alloy@7"
            ]
        },
        {
            "x": -4,
            "y": 6,
            "z": 5,
            "elements": [
                "thermalfoundation:glass_alloy@7"
            ]
        },
        {
            "x": -4,
            "y": -2,
            "z": 1,
            "elements": [
                "thermalfoundation:glass_alloy@7"
            ]
        },
        {
            "x": 0,
            "y": 6,
            "z": 5,
            "elements": [
                "avaritia:block_resource@2"
            ]
        },
        {
            "x": -3,
            "y": -2,
            "z": 1,
            "elements": [
                "mekanism:plasticblock@7"
            ]
        },
        {
            "x": -2,
            "y": -2,
            "z": 1,
            "elements": [
                "mekanism:reinforcedplasticblock@8"
            ]
        },
        {
            "x": -1,
            "y": -2,
            "z": 1,
            "elements": [
                "appliedenergistics2:controller@0"
            ]
        },
        {
            "x": 4,
            "y": 6,
            "z": 5,
            "elements": [
                "thermalfoundation:glass_alloy@7"
            ]
        },
        {
            "x": 0,
            "y": -2,
            "z": 1,
            "elements": [
                "mekanism:glowplasticblock@8"
            ]
        },
        {
            "x": 1,
            "y": -2,
            "z": 1,
            "elements": [
                "appliedenergistics2:controller@0"
            ]
        },
        {
            "x": 5,
            "y": 6,
            "z": 5,
            "elements": [
                "thermalfoundation:glass_alloy@7"
            ]
        },
        {
            "x": 2,
            "y": -2,
            "z": 1,
            "elements": [
                "mekanism:reinforcedplasticblock@8"
            ]
        },
        {
            "x": 3,
            "y": -2,
            "z": 1,
            "elements": [
                "mekanism:plasticblock@7"
            ]
        },
        {
            "x": 4,
            "y": -2,
            "z": 1,
            "elements": [
                "thermalfoundation:glass_alloy@7"
            ]
        },
        {
            "x": -6,
            "y": 0,
            "z": 18,
            "elements": [
                "thermalfoundation:glass_alloy@7"
            ]
        },
        {
            "x": -3,
            "y": 0,
            "z": 18,
            "elements": [
                "appliedenergistics2:controller@0"
            ]
        },
        {
            "x": -2,
            "y": 0,
            "z": 18,
            "elements": [
                "thermalfoundation:fluid_cryotheum@0"
            ]
        },
        {
            "x": -1,
            "y": 0,
            "z": 18,
            "elements": [
                "thermalfoundation:fluid_cryotheum@0"
            ]
        },
        {
            "x": 0,
            "y": 0,
            "z": 18,
            "elements": [
                "enderio:block_dark_iron_bars@0"
            ]
        },
        {
            "x": 1,
            "y": 0,
            "z": 18,
            "elements": [
                "thermalfoundation:fluid_cryotheum@0"
            ]
        },
        {
            "x": 2,
            "y": 0,
            "z": 18,
            "elements": [
                "thermalfoundation:fluid_cryotheum@0"
            ]
        },
        {
            "x": 3,
            "y": 0,
            "z": 18,
            "elements": [
                "appliedenergistics2:controller@0"
            ]
        },
        {
            "x": 4,
            "y": 0,
            "z": 18,
            "elements": [
                "avaritia:block_resource@0"
            ]
        },
        {
            "x": 5,
            "y": 0,
            "z": 18,
            "elements": [
                "avaritia:block_resource@0"
            ]
        },
        {
            "x": 6,
            "y": 0,
            "z": 18,
            "elements": [
                "modularmachinery:blockcasing@4"
            ]
        },
        {
            "x": -4,
            "y": 7,
            "z": 5,
            "elements": [
