{   "registryname": "research3",
    "localizedname": "三阶科研基站",
    "requires_blueprint": false,
    "color": "000000",
    "failure-action": "still",
    "parts": [
        {
            "x": -1,
            "y": 0,
            "z": 0,
            "elements": [
                "minecraft:stone_slab@7"
            ]
        },
        {
            "x": 2,
            "y": 4,
            "z": 2,
            "elements": [
                "thermalfoundation:glass_alloy@7"
            ]
        },
        {
            "x": 1,
            "y": 2,
            "z": 1,
            "elements": [
                "enderio:block_dark_iron_bars@0"
            ]
        },
        {
            "x": 3,
            "y": 4,
            "z": 2,
            "elements": [
                "thermalfoundation:glass_alloy@7"
            ]
        },
        {
            "x": 1,
            "y": 0,
            "z": 0,
            "elements": [
                "minecraft:stone_slab@7"
            ]
        },
        {
            "x": 4,
            "y": 4,
            "z": 2,
            "elements": [
                "appliedenergistics2:smooth_sky_stone_block@0"
            ]
        },
        {
            "x": 6,
            "y": 2,
            "z": 1,
            "elements": [
                "appliedenergistics2:smooth_sky_stone_block@0"
            ]
        },
        {
            "x": -7,
            "y": 0,
            "z": 0,
            "elements": [
                "appliedenergistics2:smooth_sky_stone_block@0"
            ]
        },
        {
            "x": 7,
            "y": 2,
            "z": 1,
            "elements": [
                "appliedenergistics2:smooth_sky_stone_block@0"
            ]
        },
        {
            "x": 7,
            "y": 0,
            "z": 0,
            "elements": [
                "appliedenergistics2:smooth_sky_stone_block@0"
            ]
        },
        {
            "x": 7,
            "y": -1,
            "z": 0,
            "elements": [
                "mekanism:reinforcedplasticblock@8"
            ]
        },
        {
            "x": -7,
            "y": 1,
            "z": 0,
            "elements": [
                "thermalfoundation:glass_alloy@7"
            ]
        },
        {
            "x": -6,
            "y": 3,
            "z": 1,
            "elements": [
                "appliedenergistics2:smooth_sky_stone_block@0"
            ]
        },
        {
            "x": 6,
            "y": -1,
            "z": 0,
            "elements": [
                "minecraft:sea_lantern@0"
            ]
        },
        {
            "x": -5,
            "y": 3,
            "z": 1,
            "elements": [
                "appliedenergistics2:smooth_sky_stone_block@0"
            ]
        },
        {
            "x": 5,
            "y": -1,
            "z": 0,
            "elements": [
                "appliedenergistics2:chiseled_quartz_block@0"
            ]
        },
        {
            "x": 4,
            "y": -1,
            "z": 0,
            "elements": [
                "minecraft:quartz_block@1"
            ]
        },
        {
            "x": 3,
            "y": -1,
            "z": 0,
            "elements": [
                "appliedenergistics2:chiseled_quartz_block@0"
            ]
        },
        {
            "x": -2,
            "y": 3,
            "z": 1,
            "elements": [
                "appliedenergistics2:sky_stone_brick_stairs@0"
            ]
        },
        {
            "x": -1,
            "y": 5,
            "z": 2,
            "elements": [
                "appliedenergistics2:sky_stone_brick_stairs@3"
            ]
        },
        {
            "x": 2,
            "y": -1,
            "z": 0,
            "elements": [
                "appliedenergistics2:chiseled_quartz_block@0"
            ]
        },
        {
            "x": 0,
            "y": 5,
            "z": 2,
            "elements": [
                "appliedenergistics2:sky_stone_brick_stairs@3"
            ]
        },
        {
            "x": -1,
            "y": 3,
            "z": 1,
            "elements": [
                "enderio:block_alloy_endergy@1"
            ]
        },
        {
            "x": 1,
            "y": -1,
            "z": 0,
            "elements": [
                "minecraft:sea_lantern@0"
            ]
        },
        {
            "x": 0,
            "y": -1,
            "z": 0,
            "elements": [
                "minecraft:sea_lantern@0"
            ]
        },
        {
            "x": 1,
            "y": 5,
            "z": 2,
            "elements": [
                "appliedenergistics2:sky_stone_brick_stairs@3"
            ]
        },
        {
            "x": 0,
            "y": 3,
            "z": 1,
            "elements": [
                "enderio:block_alloy_endergy@1"
            ]
        },
        {
            "x": 0,
            "y": 1,
            "z": 0,
            "elements": [
                "enderio:block_dark_iron_bars@0"
            ]
        },
        {
            "x": 1,
            "y": 3,
            "z": 1,
            "elements": [
                "enderio:block_alloy_endergy@1"
            ]
        },
        {
            "x": -1,
            "y": -1,
            "z": 0,
            "elements": [
                "minecraft:sea_lantern@0"
            ]
        },
        {
            "x": -2,
            "y": -1,
            "z": 0,
            "elements": [
                "appliedenergistics2:chiseled_quartz_block@0"
            ]
        },
        {
            "x": 2,
            "y": 3,
            "z": 1,
            "elements": [
                "appliedenergistics2:sky_stone_brick_stairs@1"
            ]
        },
        {
            "x": -3,
            "y": -1,
            "z": 0,
            "elements": [
                "appliedenergistics2:chiseled_quartz_block@0"
            ]
        },
        {
            "x": -4,
            "y": -1,
            "z": 0,
            "elements": [
                "minecraft:quartz_block@1"
            ]
        },
        {
            "x": -5,
            "y": -1,
            "z": 0,
            "elements": [
                "appliedenergistics2:chiseled_quartz_block@0"
            ]
        },
        {
            "x": 5,
            "y": 3,
            "z": 1,
            "elements": [
                "appliedenergistics2:smooth_sky_stone_block@0"
            ]
        },
        {
            "x": 6,
            "y": 3,
            "z": 1,
            "elements": [
                "appliedenergistics2:smooth_sky_stone_block@0"
            ]
        },
        {
            "x": -6,
            "y": -1,
            "z": 0,
            "elements": [
                "minecraft:sea_lantern@0"
            ]
        },
        {
            "x": -7,
            "y": -1,
            "z": 0,
            "elements": [
                "mekanism:reinforcedplasticblock@8"
            ]
        },
        {
            "x": 7,
            "y": 1,
            "z": 0,
            "elements": [
                "thermalfoundation:glass_alloy@7"
            ]
        },
        {
            "x": -6,
            "y": 2,
            "z": 0,
            "elements": [
                "mekanism:reinforcedplasticblock@8"
            ]
        },
        {
            "x": -5,
            "y": 4,
            "z": 1,
            "elements": [
                "appliedenergistics2:smooth_sky_stone_block@0"
            ]
        },
        {
            "x": -4,
            "y": 4,
            "z": 1,
            "elements": [
                "appliedenergistics2:smooth_sky_stone_block@0"
            ]
        },
        {
            "x": -3,
            "y": 4,
            "z": 1,
            "elements": [
                "appliedenergistics2:smooth_sky_stone_block@0"
            ]
        },
        {
            "x": -1,
            "y": 8,
            "z": 3,
            "elements": [
                "mekanism:plasticfence@8"
            ]
        },
        {
            "x": 0,
            "y": 8,
            "z": 3,
            "elements": [
                "appliedenergistics2:smooth_sky_stone_block@0"
            ]
        },
        {
            "x": -2,
            "y": 4,
            "z": 1,
            "elements": [
                "appliedenergistics2:smooth_sky_stone_block@0"
            ]
        },
        {
            "x": 0,
            "y": 6,
            "z": 2,
            "elements": [
                "appliedenergistics2:sky_stone_brick_stairs@3"
            ]
        },
        {
            "x": 1,
            "y": 8,
            "z": 3,
            "elements": [
                "mekanism:plasticfence@8"
            ]
        },
        {
            "x": -1,
            "y": 4,
            "z": 1,
            "elements": [
                "appliedenergistics2:smooth_sky_stone_block@0"
            ]
        },
        {
            "x": 0,
            "y": 4,
            "z": 1,
            "elements": [
                "minecraft:beacon@0"
            ]
        },
        {
            "x": 1,
            "y": 4,
            "z": 1,
            "elements": [
                "appliedenergistics2:smooth_sky_stone_block@0"
            ]
        },
        {
            "x": 0,
            "y": 2,
            "z": 0,
            "elements": [
                "enderio:block_dark_iron_bars@0"
            ]
        },
        {
            "x": 2,
            "y": 4,
            "z": 1,
            "elements": [
                "appliedenergistics2:smooth_sky_stone_block@0"
            ]
        },
        {
            "x": 3,
            "y": 4,
            "z": 1,
            "elements": [
                "appliedenergistics2:smooth_sky_stone_block@0"
            ]
        },
        {
            "x": 4,
            "y": 4,
            "z": 1,
            "elements": [
                "appliedenergistics2:smooth_sky_stone_block@0"
            ]
        },
        {
            "x": 7,
            "y": 2,
            "z": 0,
            "elements": [
                "mekanism:reinforcedplasticblock@8"
            ]
        },
        {
            "x": -6,
            "y": 3,
            "z": 0,
            "elements": [
                "contenttweaker:zl_block@0"
            ]
        },
        {
            "x": -5,
            "y": 3,
            "z": 0,
            "elements": [
                "appliedenergistics2:smooth_sky_stone_block@0"
            ]
        },
        {
            "x": -3,
            "y": 5,
            "z": 1,
            "elements": [
                "appliedenergistics2:sky_stone_brick_slab@0"
            ]
        },
        {
            "x": 0,
            "y": 9,
            "z": 3,
            "elements": [
                "mekanism:plasticfence@8"
            ]
        },
        {
            "x": -2,
            "y": 5,
            "z": 1,
            "elements": [
                "appliedenergistics2:sky_stone_brick_slab@0"
            ]
        },
        {
            "x": -1,
            "y": 7,
            "z": 2,
            "elements": [
                "appliedenergistics2:sky_stone_brick_stairs@4"
            ]
        },
        {
            "x": 0,
            "y": 7,
            "z": 2,
            "elements": [
                "appliedenergistics2:sky_stone_brick_stairs@7"
            ]
        },
        {
            "x": -2,
            "y": 3,
            "z": 0,
            "elements": [
                "appliedenergistics2:sky_stone_brick_stairs@4"
            ]
        },
        {
            "x": -1,
            "y": 5,
            "z": 1,
            "elements": [
                "appliedenergistics2:sky_stone_brick_stairs@0"
            ]
        },
        {
            "x": 0,
            "y": 5,
            "z": 1,
            "elements": [
                "minecraft:stained_glass@3"
            ]
        },
        {
            "x": 1,
            "y": 7,
            "z": 2,
            "elements": [
                "appliedenergistics2:sky_stone_brick_stairs@7"
            ]
        },
        {
            "x": -1,
            "y": 3,
            "z": 0,
            "elements": [
                "enderio:block_alloy_endergy@1"
            ]
        },
        {
            "x": 1,
            "y": 5,
            "z": 1,
            "elements": [
                "appliedenergistics2:sky_stone_brick_stairs@1"
            ]
        },
        {
            "x": 0,
            "y": 3,
            "z": 0,
            "elements": [
                "enderio:block_alloy_endergy@1"
            ]
        },
        {
            "x": 1,
            "y": 3,
            "z": 0,
            "elements": [
                "enderio:block_alloy_endergy@1"
            ]
        },
        {
            "x": 2,
            "y": 5,
            "z": 1,
            "elements": [
                "appliedenergistics2:sky_stone_brick_slab@0"
            ]
        },
        {
            "x": 3,
            "y": 5,
            "z": 1,
            "elements": [
                "appliedenergistics2:sky_stone_brick_slab@0"
            ]
        },
        {
            "x": 2,
            "y": 3,
            "z": 0,
            "elements": [
                "appliedenergistics2:sky_stone_brick_stairs@5"
            ]
        },
        {
            "x": 5,
            "y": 3,
            "z": 0,
            "elements": [
                "appliedenergistics2:smooth_sky_stone_block@0"
            ]
        },
        {
            "x": 6,
            "y": 3,
            "z": 0,
            "elements": [
                "contenttweaker:zl_block@0"
            ]
        },
        {
            "x": -4,
            "y": 4,
            "z": 0,
            "elements": [
                "appliedenergistics2:smooth_sky_stone_block@0"
            ]
        },
        {
            "x": -2,
            "y": 8,
            "z": 2,
            "elements": [
                "mekanism:plasticfence@8"
            ]
        },
        {
            "x": 0,
            "y": 10,
            "z": 3,
            "elements": [
                "mekanism:plasticfence@8"
            ]
        },
        {
            "x": -3,
            "y": 4,
            "z": 0,
            "elements": [
                "thermalfoundation:glass_alloy@7"
            ]
        },
        {
            "x": -1,
            "y": 8,
            "z": 2,
            "elements": [
                "contenttweaker:zl_block@0"
            ]
        },
        {
            "x": -2,
            "y": 4,
            "z": 0,
            "elements": [
                "thermalfoundation:glass_alloy@7"
            ]
        },
        {
            "x": -1,
            "y": 6,
            "z": 1,
            "elements": [
                "appliedenergistics2:sky_stone_brick_stairs@0"
            ]
        },
        {
            "x": 1,
            "y": 8,
            "z": 2,
            "elements": [
                "contenttweaker:zl_block@0"
            ]
        },
        {
            "x": -1,
            "y": 4,
            "z": 0,
            "elements": [
                "modularmachinery:blockcasing@4"
            ]
        },
        {
            "x": 2,
            "y": 8,
            "z": 2,
            "elements": [
                "mekanism:plasticfence@8"
            ]
        },
        {
            "x": 1,
            "y": 6,
            "z": 1,
            "elements": [
                "appliedenergistics2:sky_stone_brick_stairs@1"
            ]
        },
        {
            "x": 0,
            "y": 4,
            "z": 0,
            "elements": [
                "appliedenergistics2:smooth_sky_stone_block@0"
            ]
        },
        {
            "x": 1,
            "y": 4,
            "z": 0,
            "elements": [
                "modularmachinery:blockcasing@4"
            ]
        },
        {
            "x": 2,
            "y": 4,
            "z": 0,
            "elements": [
                "thermalfoundation:glass_alloy@7"
            ]
        },
        {
            "x": 3,
            "y": 4,
            "z": 0,
            "elements": [
                "thermalfoundation:glass_alloy@7"
            ]
        },
        {
            "x": 4,
            "y": 4,
            "z": 0,
            "elements": [
                "appliedenergistics2:smooth_sky_stone_block@0"
            ]
        },
        {
            "x": 0,
            "y": 11,
            "z": 3,
            "elements": [
                "mekanism:plasticfence@8"
            ]
        },
        {
            "x": 0,
            "y": 9,
            "z": 2,
            "elements": [
                "minecraft:end_rod@2"
            ]
        },
        {
            "x": -1,
            "y": 7,
            "z": 1,
            "elements": [
                "appliedenergistics2:sky_stone_brick_stairs@4"
            ]
        },
        {
            "x": -1,
            "y": 5,
            "z": 0,
            "elements": [
                "appliedenergistics2:sky_stone_brick_stairs@2"
            ]
        },
        {
            "x": 0,
            "y": 5,
            "z": 0,
            "elements": [
                "appliedenergistics2:sky_stone_brick_stairs@2"
            ]
        },
        {
            "x": 1,
            "y": 7,
            "z": 1,
            "elements": [
                "appliedenergistics2:sky_stone_brick_stairs@5"
            ]
        },
        {
            "x": 1,
            "y": 5,
            "z": 0,
            "elements": [
                "appliedenergistics2:sky_stone_brick_stairs@2"
            ]
        },
        {
            "x": 0,
            "y": 12,
            "z": 3,
            "elements": [
                "minecraft:end_rod@1"
            ]
        },
        {
            "x": -2,
            "y": 8,
            "z": 1,
            "elements": [
                "appliedenergistics2:smooth_sky_stone_block@0"
            ]
        },
        {
            "x": 0,
            "y": 6,
            "z": 0,
            "elements": [
                "appliedenergistics2:sky_stone_brick_stairs@2"
            ]
        },
        {
            "x": 2,
            "y": 8,
            "z": 1,
            "elements": [
                "appliedenergistics2:smooth_sky_stone_block@0"
            ]
        },
        {
            "x": -2,
            "y": 9,
            "z": 1,
            "elements": [
                "mekanism:plasticfence@8"
            ]
        },
        {
            "x": 0,
            "y": 11,
            "z": 2,
            "elements": [
                "mekanism:plasticfence@8"
            ]
        },
        {
            "x": -1,
            "y": 9,
            "z": 1,
            "elements": [
                "minecraft:end_rod@5"
            ]
        },
        {
            "x": 0,
            "y": 9,
            "z": 1,
            "elements": [
                "thermalfoundation:glass_alloy@7"
            ]
        },
        {
            "x": -1,
            "y": 7,
            "z": 0,
            "elements": [
                "appliedenergistics2:sky_stone_brick_stairs@4"
            ]
        },
        {
            "x": 0,
            "y": 7,
            "z": 0,
            "elements": [
                "appliedenergistics2:sky_stone_brick_stairs@6"
            ]
        },
        {
            "x": 1,
            "y": 9,
            "z": 1,
            "elements": [
                "minecraft:end_rod@4"
            ]
        },
        {
            "x": 1,
            "y": 7,
            "z": 0,
            "elements": [
                "appliedenergistics2:sky_stone_brick_stairs@5"
            ]
        },
        {
            "x": 2,
            "y": 9,
            "z": 1,
            "elements": [
                "mekanism:plasticfence@8"
            ]
        },
        {
            "x": -2,
            "y": 10,
            "z": 1,
            "elements": [
                "mekanism:plasticfence@8"
            ]
        },
        {
            "x": 0,
            "y": 12,
            "z": 2,
            "elements": [
                "mekanism:plasticfence@8"
            ]
        },
        {
            "x": -2,
            "y": 8,
            "z": 0,
            "elements": [
                "mekanism:plasticfence@8"
            ]
        },
        {
            "x": -1,
            "y": 8,
            "z": 0,
            "elements": [
                "contenttweaker:zl_block@0"
            ]
        },
        {
            "x": 1,
            "y": 8,
            "z": 0,
            "elements": [
                "contenttweaker:zl_block@0"
            ]
        },
        {
            "x": 2,
            "y": 10,
            "z": 1,
            "elements": [
                "mekanism:plasticfence@8"
            ]
        },
        {
            "x": 2,
            "y": 8,
            "z": 0,
            "elements": [
                "mekanism:plasticfence@8"
            ]
        },
        {
            "x": -2,
            "y": 11,
            "z": 1,
            "elements": [
                "mekanism:plasticfence@8"
            ]
        },
        {
            "x": 0,
            "y": 13,
            "z": 2,
            "elements": [
                "mekanism:plasticfence@8"
            ]
        },
        {
            "x": -1,
            "y": 11,
            "z": 1,
            "elements": [
                "mekanism:plasticfence@8"
            ]
        },
        {
            "x": 0,
            "y": 9,
            "z": 0,
            "elements": [
                "minecraft:end_rod@3"
            ]
        },
        {
            "x": 1,
            "y": 11,
            "z": 1,
            "elements": [
                "mekanism:plasticfence@8"
            ]
        },
        {
            "x": 2,
            "y": 11,
            "z": 1,
            "elements": [
                "mekanism:plasticfence@8"
            ]
        },
        {
            "x": -2,
            "y": 12,
            "z": 1,
            "elements": [
                "minecraft:end_rod@1"
            ]
        },
        {
            "x": -1,
            "y": 12,
            "z": 1,
            "elements": [
                "mekanism:plasticfence@8"
            ]
        },
        {
            "x": 1,
            "y": 12,
            "z": 1,
            "elements": [
                "mekanism:plasticfence@8"
            ]
        },
        {
            "x": 2,
            "y": 12,
            "z": 1,
            "elements": [
                "minecraft:end_rod@1"
            ]
        },
        {
            "x": -1,
            "y": 13,
            "z": 1,
            "elements": [
                "mekanism:plasticfence@8"
            ]
        },
        {
            "x": 0,
            "y": 13,
            "z": 1,
            "elements": [
                "thermalfoundation:glass_alloy@7"
            ]
        },
        {
            "x": 1,
            "y": 13,
            "z": 1,
            "elements": [
                "mekanism:plasticfence@8"
            ]
        },
        {
            "x": 0,
            "y": 11,
            "z": 0,
            "elements": [
                "mekanism:plasticfence@8"
            ]
        },
        {
            "x": 0,
            "y": 12,
            "z": 0,
            "elements": [
                "mekanism:plasticfence@8"
            ]
        },
        {
            "x": 0,
            "y": 13,
            "z": 0,
            "elements": [
                "mekanism:plasticfence@8"
            ]
        },
        {
            "x": -1,
            "y": -1,
            "z": 8,
            "elements": [
                "mekanism:reinforcedplasticblock@8"
            ]
        },
        {
            "x": 0,
            "y": -1,
            "z": 8,
            "elements": [
                "mekanism:reinforcedplasticblock@8"
            ]
        },
        {
            "x": 1,
            "y": -1,
            "z": 8,
            "elements": [
                "mekanism:reinforcedplasticblock@8"
            ]
        },
        {
            "x": -1,
            "y": 0,
            "z": 8,
            "elements": [
                "appliedenergistics2:smooth_sky_stone_block@0"
            ]
        },
        {
            "x": 0,
            "y": 0,
            "z": 8,
            "elements": [
                "appliedenergistics2:smooth_sky_stone_block@0"
            ]
        },
        {
            "x": 1,
            "y": 0,
            "z": 8,
            "elements": [
                "appliedenergistics2:smooth_sky_stone_block@0"
            ]
        },
        {
            "x": -4,
            "y": -1,
            "z": 7,
            "elements": [
                "appliedenergistics2:smooth_sky_stone_block@0"
            ]
        },
        {
            "x": -3,
            "y": -1,
            "z": 7,
            "elements": [
                "appliedenergistics2:smooth_sky_stone_block@0"
            ]
        },
        {
            "x": -2,
            "y": -1,
            "z": 7,
            "elements": [
                "appliedenergistics2:smooth_sky_stone_block@0"
            ]
        },
        {
            "x": -1,
            "y": 1,
            "z": 8,
            "elements": [
                "thermalfoundation:glass_alloy@7"
            ]
        },
        {
            "x": 0,
            "y": 1,
            "z": 8,
            "elements": [
                "thermalfoundation:glass_alloy@7"
            ]
        },
        {
            "x": -1,
            "y": -1,
            "z": 7,
            "elements": [
                "minecraft:sea_lantern@0"
            ]
        },
        {
            "x": 0,
            "y": -1,
            "z": 7,
            "elements": [
                "mekanism:reinforcedplasticblock@8"
            ]
        },
        {
            "x": 1,
            "y": 1,
            "z": 8,
            "elements": [
                "thermalfoundation:glass_alloy@7"
            ]
        },
        {
            "x": 1,
            "y": -1,
            "z": 7,
            "elements": [
                "minecraft:sea_lantern@0"
            ]
        },
        {
            "x": 2,
            "y": -1,
            "z": 7,
            "elements": [
                "appliedenergistics2:smooth_sky_stone_block@0"
            ]
        },
        {
            "x": 3,
            "y": -1,
            "z": 7,
            "elements": [
                "appliedenergistics2:smooth_sky_stone_block@0"
            ]
        },
        {
            "x": 4,
            "y": -1,
            "z": 7,
            "elements": [
                "appliedenergistics2:smooth_sky_stone_block@0"
            ]
        },
        {
            "x": -4,
            "y": 0,
            "z": 7,
            "elements": [
                "appliedenergistics2:smooth_sky_stone_block@0"
            ]
        },
        {
            "x": -3,
            "y": 0,
            "z": 7,
            "elements": [
                "appliedenergistics2:smooth_sky_stone_block@0"
            ]
        },
        {
            "x": -2,
            "y": 0,
            "z": 7,
            "elements": [
                "appliedenergistics2:smooth_sky_stone_block@0"
            ]
        },
        {
            "x": -1,
            "y": 2,
            "z": 8,
            "elements": [
                "thermalfoundation:glass_alloy@7"
            ]
        },
        {
            "x": 0,
            "y": 2,
            "z": 8,
            "elements": [
                "thermalfoundation:glass_alloy@7"
            ]
        },
        {
            "x": 2,
            "y": 4,
            "z": -5,
            "elements": [
                "appliedenergistics2:sky_stone_brick_slab@0"
            ]
        },
        {
            "x": -1,
            "y": 0,
            "z": 7,
            "elements": [
                "modularmachinery:blockinputbus"
            ]
        },
        {
            "x": 0,
            "y": 0,
            "z": 7,
            "elements": [
                "modularmachinery:blockoutputbus"
            ]
        },
        {
            "x": 1,
            "y": 4,
            "z": -5,
            "elements": [
                "appliedenergistics2:sky_stone_brick_slab@0"
            ]
        },
        {
            "x": 1,
            "y": 2,
            "z": 8,
            "elements": [
                "thermalfoundation:glass_alloy@7"
            ]
        },
        {
            "x": 0,
            "y": 4,
            "z": -5,
            "elements": [
                "appliedenergistics2:smooth_sky_stone_block@0"
            ]
        },
        {
            "x": 1,
            "y": 0,
            "z": 7,
            "elements": [
                "modularmachinery:blockinputbus"
            ]
        },
        {
            "x": -1,
            "y": 4,
            "z": -5,
            "elements": [
                "appliedenergistics2:sky_stone_brick_slab@0"
            ]
        },
        {
            "x": 2,
            "y": 0,
            "z": 7,
            "elements": [
                "appliedenergistics2:smooth_sky_stone_block@0"
            ]
        },
        {
            "x": -2,
            "y": 4,
            "z": -5,
            "elements": [
                "appliedenergistics2:sky_stone_brick_slab@0"
            ]
        },
        {
            "x": 3,
            "y": 0,
            "z": 7,
            "elements": [
                "appliedenergistics2:smooth_sky_stone_block@0"
            ]
        },
        {
            "x": 4,
            "y": 0,
            "z": 7,
            "elements": [
                "appliedenergistics2:smooth_sky_stone_block@0"
            ]
        },
        {
            "x": 0,
            "y": 12,
            "z": -1,
            "elements": [
                "minecraft:end_rod@1"
            ]
        },
        {
            "x": -4,
            "y": 1,
            "z": 7,
            "elements": [
                "thermalfoundation:glass_alloy@7"
            ]
        },
        {
            "x": -5,
            "y": -1,
            "z": 6,
            "elements": [
                "appliedenergistics2:smooth_sky_stone_block@0"
            ]
        },
        {
            "x": -4,
            "y": -1,
            "z": 6,
            "elements": [
                "appliedenergistics2:chiseled_quartz_block@0"
            ]
        },
        {
            "x": -3,
            "y": 1,
            "z": 7,
            "elements": [
                "thermalfoundation:glass_alloy@7"
            ]
        },
        {
            "x": -3,
            "y": -1,
            "z": 6,
            "elements": [
                "appliedenergistics2:chiseled_quartz_block@0"
            ]
        },
        {
            "x": -2,
            "y": 1,
            "z": 7,
            "elements": [
                "appliedenergistics2:smooth_sky_stone_block@0"
            ]
        },
        {
            "x": -1,
            "y": 3,
            "z": 8,
            "elements": [
                "appliedenergistics2:sky_stone_brick_slab@0"
            ]
        },
        {
            "x": 3,
            "y": 3,
            "z": -5,
            "elements": [
                "appliedenergistics2:sky_stone_brick_stairs@1"
            ]
        },
        {
            "x": 1,
            "y": -1,
            "z": -7,
            "elements": [
                "appliedenergistics2:sky_stone_brick_slab@0"
            ]
        },
        {
            "x": 0,
            "y": -1,
            "z": -7,
            "elements": [
                "appliedenergistics2:sky_stone_brick_slab@0"
            ]
        },
        {
            "x": 0,
            "y": 3,
            "z": 8,
            "elements": [
                "appliedenergistics2:sky_stone_brick_slab@0"
            ]
        },
        {
            "x": -2,
            "y": -1,
            "z": 6,
            "elements": [
                "appliedenergistics2:chiseled_quartz_block@0"
            ]
        },
        {
            "x": 2,
            "y": 3,
            "z": -5,
            "elements": [
                "modularmachinery:blockcasing@4"
            ]
        },
        {
            "x": 1,
            "y": 3,
            "z": -5,
            "elements": [
                "modularmachinery:blockcasing@4"
            ]
        },
        {
            "x": 1,
            "y": 3,
            "z": 8,
            "elements": [
                "appliedenergistics2:sky_stone_brick_slab@0"
            ]
        },
        {
            "x": -1,
            "y": -1,
            "z": -7,
            "elements": [
                "appliedenergistics2:sky_stone_brick_slab@0"
            ]
        },
        {
            "x": -1,
            "y": -1,
            "z": 6,
            "elements": [
                "appliedenergistics2:chiseled_quartz_block@0"
            ]
        },
        {
            "x": 0,
            "y": -1,
            "z": 6,
            "elements": [
                "mekanism:reinforcedplasticblock@8"
            ]
        },
        {
            "x": 0,
            "y": 3,
            "z": -5,
            "elements": [
                "appliedenergistics2:sky_stone_brick_slab@8"
            ]
        },
        {
            "x": -1,
            "y": 3,
            "z": -5,
            "elements": [
                "modularmachinery:blockcasing@4"
            ]
        },
        {
            "x": 2,
            "y": 1,
            "z": 7,
            "elements": [
                "appliedenergistics2:smooth_sky_stone_block@0"
            ]
        },
        {
            "x": 1,
            "y": -1,
            "z": 6,
            "elements": [
                "appliedenergistics2:chiseled_quartz_block@0"
            ]
        },
        {
            "x": -2,
            "y": 3,
            "z": -5,
            "elements": [
                "modularmachinery:blockcasing@4"
            ]
        },
        {
            "x": 3,
            "y": 1,
            "z": 7,
            "elements": [
                "thermalfoundation:glass_alloy@7"
            ]
        },
        {
            "x": 2,
            "y": -1,
            "z": 6,
            "elements": [
                "appliedenergistics2:chiseled_quartz_block@0"
            ]
        },
        {
            "x": -3,
            "y": 3,
            "z": -5,
            "elements": [
                "appliedenergistics2:sky_stone_brick_stairs@0"
            ]
        },
        {
            "x": 4,
            "y": 1,
            "z": 7,
            "elements": [
                "thermalfoundation:glass_alloy@7"
            ]
        },
        {
            "x": 3,
            "y": -1,
            "z": 6,
            "elements": [
                "appliedenergistics2:chiseled_quartz_block@0"
            ]
        },
        {
            "x": 0,
            "y": 11,
            "z": -1,
            "elements": [
                "mekanism:plasticfence@8"
            ]
        },
        {
            "x": 4,
            "y": -1,
            "z": 6,
            "elements": [
                "appliedenergistics2:chiseled_quartz_block@0"
            ]
        },
        {
            "x": 5,
            "y": -1,
            "z": 6,
            "elements": [
                "appliedenergistics2:smooth_sky_stone_block@0"
            ]
        },
        {
            "x": -5,
            "y": 0,
            "z": 6,
            "elements": [
                "appliedenergistics2:smooth_sky_stone_block@0"
            ]
        },
        {
            "x": -4,
            "y": 2,
            "z": 7,
            "elements": [
                "mekanism:reinforcedplasticblock@8"
            ]
        },
        {
            "x": -3,
            "y": 2,
            "z": 7,
            "elements": [
                "mekanism:reinforcedplasticblock@8"
            ]
        },
        {
            "x": 4,
            "y": 2,
            "z": -5,
            "elements": [
                "mekanism:reinforcedplasticblock@8"
            ]
        },
        {
            "x": -3,
            "y": 0,
            "z": 6,
            "elements": [
                "modularmachinery:blockcasing@5"
            ]
        },
        {
            "x": -2,
            "y": 2,
            "z": 7,
            "elements": [
                "appliedenergistics2:smooth_sky_stone_block@0"
            ]
        },
        {
            "x": 3,
            "y": 2,
            "z": -5,
            "elements": [
                "appliedenergistics2:smooth_sky_stone_block@0"
            ]
        },
        {
            "x": -2,
            "y": 0,
            "z": 6,
            "elements": [
                "modularmachinery:blockcasing@5"
            ]
        },
        {
            "x": 2,
            "y": 2,
            "z": -5,
            "elements": [
                "modularmachinery:blockcasing@4"
            ]
        },
        {
            "x": 2,
            "y": 4,
            "z": -4,
            "elements": [
                "appliedenergistics2:smooth_sky_stone_block@0"
            ]
        },
        {
            "x": 1,
            "y": 2,
            "z": -5,
            "elements": [
                "appliedenergistics2:sky_stone_brick_stairs@4"
            ]
        },
        {
            "x": -1,
            "y": 0,
            "z": 6,
            "elements": [
                "minecraft:carpet@7"
            ]
        },
        {
            "x": 0,
            "y": 0,
            "z": 6,
            "elements": [
                "minecraft:carpet@7"
            ]
        },
        {
            "x": 1,
            "y": 4,
            "z": -4,
            "elements": [
                "thermalfoundation:glass_alloy@7"
            ]
        },
        {
            "x": 0,
            "y": 4,
            "z": -4,
            "elements": [
                "appliedenergistics2:smooth_sky_stone_block@0"
            ]
        },
        {
            "x": -1,
            "y": 2,
            "z": -5,
            "elements": [
                "appliedenergistics2:sky_stone_brick_stairs@5"
            ]
        },
        {
            "x": 2,
            "y": 2,
            "z": 7,
            "elements": [
                "appliedenergistics2:smooth_sky_stone_block@0"
            ]
        },
        {
            "x": 1,
            "y": 0,
            "z": 6,
            "elements": [
                "minecraft:carpet@7"
            ]
        },
        {
            "x": -2,
            "y": 2,
            "z": -5,
            "elements": [
                "modularmachinery:blockcasing@4"
            ]
        },
        {
            "x": -1,
            "y": 4,
            "z": -4,
            "elements": [
                "thermalfoundation:glass_alloy@7"
            ]
        },
        {
            "x": 3,
            "y": 2,
            "z": 7,
            "elements": [
                "mekanism:reinforcedplasticblock@8"
            ]
        },
        {
            "x": 2,
            "y": 0,
            "z": 6,
            "elements": [
                "modularmachinery:blockcasing@5"
            ]
        },
        {
            "x": -3,
            "y": 2,
            "z": -5,
            "elements": [
                "appliedenergistics2:smooth_sky_stone_block@0"
            ]
        },
        {
            "x": -2,
            "y": 4,
            "z": -4,
            "elements": [
                "appliedenergistics2:smooth_sky_stone_block@0"
            ]
        },
        {
            "x": 4,
            "y": 2,
            "z": 7,
            "elements": [
                "mekanism:reinforcedplasticblock@8"
            ]
        },
        {
            "x": 3,
            "y": 0,
            "z": 6,
            "elements": [
                "modularmachinery:blockcasing@5"
            ]
        },
        {
            "x": 0,
            "y": 10,
            "z": -1,
            "elements": [
                "mekanism:plasticfence@8"
            ]
        },
        {
            "x": -4,
            "y": 2,
            "z": -5,
            "elements": [
                "mekanism:reinforcedplasticblock@8"
            ]
        },
        {
            "x": 5,
            "y": 0,
            "z": 6,
            "elements": [
                "appliedenergistics2:smooth_sky_stone_block@0"
            ]
        },
        {
            "x": -6,
            "y": -1,
            "z": 5,
            "elements": [
                "appliedenergistics2:smooth_sky_stone_block@0"
            ]
        },
        {
            "x": -5,
            "y": 1,
            "z": 6,
            "elements": [
                "thermalfoundation:glass_alloy@7"
            ]
        },
        {
            "x": -5,
            "y": -1,
            "z": 5,
            "elements": [
                "appliedenergistics2:chiseled_quartz_block@0"
            ]
        },
        {
            "x": 4,
            "y": 1,
            "z": -5,
            "elements": [
                "thermalfoundation:glass_alloy@7"
            ]
        },
        {
            "x": -4,
            "y": -1,
            "z": 5,
            "elements": [
                "appliedenergistics2:smooth_sky_stone_block@0"
            ]
        },
        {
            "x": -2,
            "y": 3,
            "z": 7,
            "elements": [
                "appliedenergistics2:sky_stone_brick_slab@0"
            ]
        },
        {
            "x": 3,
            "y": 1,
            "z": -5,
            "elements": [
                "modularmachinery:blockcasing@5"
            ]
        },
        {
            "x": 2,
            "y": -1,
            "z": -6,
            "elements": [
                "appliedenergistics2:sky_stone_brick_slab@0"
            ]
        },
        {
            "x": -3,
            "y": -1,
            "z": 5,
            "elements": [
                "minecraft:quartz_block@1"
            ]
        },
        {
            "x": -2,
            "y": 1,
            "z": 6,
            "elements": [
                "modularmachinery:blockcasing@5"
            ]
        },
        {
            "x": -1,
            "y": 3,
            "z": 7,
            "elements": [
                "thermalfoundation:glass_alloy@7"
            ]
        },
        {
            "x": 2,
            "y": 1,
            "z": -5,
            "elements": [
                "modularmachinery:blockcasing@5"
            ]
        },
        {
            "x": 1,
            "y": -1,
            "z": -6,
            "elements": [
                "mekanism:reinforcedplasticblock@8"
            ]
        },
        {
            "x": 0,
            "y": -1,
            "z": -6,
            "elements": [
                "mekanism:reinforcedplasticblock@8"
            ]
        },
        {
            "x": 0,
            "y": 3,
            "z": 7,
            "elements": [
                "thermalfoundation:glass_alloy@7"
            ]
        },
        {
            "x": -2,
            "y": -1,
            "z": 5,
            "elements": [
                "minecraft:quartz_block@1"
            ]
        },
        {
            "x": 1,
            "y": 3,
            "z": 7,
            "elements": [
                "thermalfoundation:glass_alloy@7"
            ]
        },
        {
            "x": -1,
            "y": -1,
            "z": -6,
            "elements": [
                "mekanism:reinforcedplasticblock@8"
            ]
        },
        {
            "x": -1,
            "y": -1,
            "z": 5,
            "elements": [
                "minecraft:quartz_block@1"
            ]
        },
        {
            "x": 0,
            "y": -1,
            "z": 5,
            "elements": [
                "contenttweaker:zl_block@0"
            ]
        },
        {
            "x": -2,
            "y": -1,
            "z": -6,
            "elements": [
                "appliedenergistics2:sky_stone_brick_slab@0"
            ]
        },
        {
            "x": 2,
            "y": 3,
            "z": 7,
            "elements": [
                "appliedenergistics2:sky_stone_brick_slab@0"
            ]
        },
        {
            "x": -2,
            "y": 1,
            "z": -5,
            "elements": [
                "modularmachinery:blockcasing@5"
            ]
        },
        {
            "x": 1,
            "y": -1,
            "z": 5,
            "elements": [
                "minecraft:quartz_block@1"
            ]
        },
        {
            "x": -3,
            "y": 1,
            "z": -5,
            "elements": [
                "modularmachinery:blockcasing@5"
            ]
        },
        {
            "x": 2,
            "y": -1,
            "z": 5,
            "elements": [
                "minecraft:quartz_block@1"
            ]
        },
        {
            "x": 0,
            "y": 9,
            "z": -1,
            "elements": [
                "mekanism:plasticfence@8"
            ]
        },
        {
            "x": -4,
            "y": 1,
            "z": -5,
            "elements": [
                "thermalfoundation:glass_alloy@7"
            ]
        },
        {
            "x": 3,
            "y": -1,
            "z": 5,
            "elements": [
                "minecraft:quartz_block@1"
            ]
        },
        {
            "x": 5,
            "y": 1,
            "z": 6,
            "elements": [
                "thermalfoundation:glass_alloy@7"
            ]
        },
        {
            "x": 4,
            "y": -1,
            "z": 5,
            "elements": [
                "appliedenergistics2:smooth_sky_stone_block@0"
            ]
        },
        {
            "x": 5,
            "y": -1,
            "z": 5,
            "elements": [
                "appliedenergistics2:chiseled_quartz_block@0"
            ]
        },
        {
            "x": 6,
            "y": -1,
            "z": 5,
            "elements": [
                "appliedenergistics2:smooth_sky_stone_block@0"
            ]
        },
        {
            "x": -6,
            "y": 0,
            "z": 5,
            "elements": [
                "appliedenergistics2:smooth_sky_stone_block@0"
            ]
        },
        {
            "x": -5,
            "y": 2,
            "z": 6,
            "elements": [
                "mekanism:reinforcedplasticblock@8"
            ]
        },
        {
            "x": 5,
            "y": 2,
            "z": -4,
            "elements": [
                "mekanism:reinforcedplasticblock@8"
            ]
        },
        {
            "x": 4,
            "y": 0,
            "z": -5,
            "elements": [
                "appliedenergistics2:smooth_sky_stone_block@0"
            ]
        },
        {
            "x": 3,
            "y": 0,
            "z": -5,
            "elements": [
                "appliedenergistics2:smooth_sky_stone_block@0"
            ]
        },
        {
            "x": -3,
            "y": 0,
            "z": 5,
            "elements": [
                "modularmachinery:blockcasing@5"
            ]
        },
        {
            "x": -2,
            "y": 2,
            "z": 6,
            "elements": [
                "appliedenergistics2:smooth_sky_stone_block@0"
            ]
        },
        {
            "x": 4,
            "y": 4,
            "z": -3,
            "elements": [
                "mekanism:reinforcedplasticblock@8"
            ]
        },
        {
            "x": 2,
            "y": 0,
            "z": -5,
            "elements": [
                "appliedenergistics2:smooth_sky_stone_block@0"
            ]
        },
        {
            "x": -2,
            "y": 0,
            "z": 5,
            "elements": [
                "minecraft:carpet@7"
            ]
        },
        {
            "x": 3,
            "y": 4,
            "z": -3,
            "elements": [
                "appliedenergistics2:smooth_sky_stone_block@0"
            ]
        },
        {
            "x": 2,
            "y": 4,
            "z": -3,
            "elements": [
                "appliedenergistics2:smooth_sky_stone_block@0"
            ]
        },
        {
            "x": -1,
            "y": 0,
            "z": 5,
            "elements": [
                "minecraft:carpet@7"
            ]
        },
        {
            "x": 0,
            "y": 0,
            "z": 5,
            "elements": [
                "minecraft:carpet@7"
            ]
        },
        {
            "x": 1,
            "y": 4,
            "z": -3,
            "elements": [
                "thermalfoundation:glass_alloy@7"
            ]
        },
        {
            "x": 0,
            "y": 4,
            "z": -3,
            "elements": [
                "appliedenergistics2:smooth_sky_stone_block@0"
            ]
        },
        {
            "x": -2,
            "y": 0,
            "z": -5,
            "elements": [
                "appliedenergistics2:smooth_sky_stone_block@0"
            ]
        },
        {
            "x": 2,
            "y": 2,
            "z": 6,
            "elements": [
                "appliedenergistics2:smooth_sky_stone_block@0"
            ]
        },
        {
            "x": 1,
            "y": 0,
            "z": 5,
            "elements": [
                "minecraft:carpet@7"
            ]
        },
        {
            "x": 1,
            "y": 8,
            "z": -1,
            "elements": [
                "mekanism:plasticfence@8"
            ]
        },
        {
            "x": -3,
            "y": 0,
            "z": -5,
            "elements": [
                "appliedenergistics2:smooth_sky_stone_block@0"
            ]
        },
        {
            "x": -1,
            "y": 4,
            "z": -3,
            "elements": [
                "thermalfoundation:glass_alloy@7"
            ]
        },
        {
            "x": 2,
            "y": 0,
            "z": 5,
            "elements": [
                "minecraft:carpet@7"
            ]
        },
        {
            "x": 0,
            "y": 8,
            "z": -1,
            "elements": [
                "appliedenergistics2:smooth_sky_stone_block@0"
            ]
        },
        {
            "x": -4,
            "y": 0,
            "z": -5,
            "elements": [
                "appliedenergistics2:smooth_sky_stone_block@0"
            ]
        },
        {
            "x": -2,
            "y": 4,
            "z": -3,
            "elements": [
                "appliedenergistics2:smooth_sky_stone_block@0"
            ]
        },
        {
            "x": 3,
            "y": 0,
            "z": 5,
            "elements": [
                "modularmachinery:blockcasing@5"
            ]
        },
        {
            "x": -3,
            "y": 4,
            "z": -3,
            "elements": [
                "appliedenergistics2:smooth_sky_stone_block@0"
            ]
        },
        {
            "x": -1,
            "y": 8,
            "z": -1,
            "elements": [
                "mekanism:plasticfence@8"
            ]
        },
        {
            "x": 5,
            "y": 2,
            "z": 6,
            "elements": [
                "mekanism:reinforcedplasticblock@8"
            ]
        },
        {
            "x": -5,
            "y": 2,
            "z": -4,
            "elements": [
                "mekanism:reinforcedplasticblock@8"
            ]
        },
        {
            "x": -4,
            "y": 4,
            "z": -3,
            "elements": [
                "mekanism:reinforcedplasticblock@8"
            ]
        },
        {
            "x": 6,
            "y": 0,
            "z": 5,
            "elements": [
                "appliedenergistics2:smooth_sky_stone_block@0"
            ]
        },
        {
            "x": -6,
            "y": 1,
            "z": 5,
            "elements": [
                "thermalfoundation:glass_alloy@7"
            ]
        },
        {
            "x": -6,
            "y": -1,
            "z": 4,
            "elements": [
                "appliedenergistics2:smooth_sky_stone_block@0"
            ]
        },
        {
            "x": -4,
            "y": 3,
            "z": 6,
            "elements": [
                "mekanism:reinforcedplasticblock@8"
            ]
        },
        {
            "x": 5,
            "y": 1,
            "z": -4,
            "elements": [
                "thermalfoundation:glass_alloy@7"
            ]
        },
        {
            "x": 4,
            "y": -1,
            "z": -5,
            "elements": [
                "appliedenergistics2:smooth_sky_stone_block@0"
            ]
        },
        {
            "x": -5,
            "y": -1,
            "z": 4,
            "elements": [
                "appliedenergistics2:chiseled_quartz_block@0"
            ]
        },
        {
            "x": -3,
            "y": 3,
            "z": 6,
            "elements": [
                "appliedenergistics2:smooth_sky_stone_block@0"
            ]
        },
        {
            "x": 5,
            "y": 3,
            "z": -3,
            "elements": [
                "mekanism:reinforcedplasticblock@8"
            ]
        },
        {
            "x": 3,
            "y": -1,
            "z": -5,
            "elements": [
                "appliedenergistics2:smooth_sky_stone_block@0"
            ]
        },
        {
            "x": -4,
            "y": -1,
            "z": 4,
            "elements": [
                "minecraft:quartz_block@1"
            ]
        },
        {
            "x": -2,
            "y": 3,
            "z": 6,
            "elements": [
                "appliedenergistics2:smooth_sky_stone_block@0"
            ]
        },
        {
            "x": 2,
            "y": -1,
            "z": -5,
            "elements": [
                "appliedenergistics2:smooth_sky_stone_block@0"
            ]
        },
        {
            "x": -3,
            "y": -1,
            "z": 4,
            "elements": [
                "appliedenergistics2:smooth_sky_stone_block@0"
            ]
        },
        {
            "x": -1,
            "y": 3,
            "z": 6,
            "elements": [
                "appliedenergistics2:smooth_sky_stone_block@0"
            ]
        },
        {
            "x": 1,
            "y": -1,
            "z": -5,
            "elements": [
                "minecraft:sea_lantern@0"
            ]
        },
        {
            "x": 0,
            "y": 3,
            "z": 6,
            "elements": [
                "appliedenergistics2:smooth_sky_stone_block@0"
            ]
        },
        {
            "x": 0,
            "y": -1,
            "z": -5,
            "elements": [
                "mekanism:reinforcedplasticblock@8"
            ]
        },
        {
            "x": -2,
            "y": -1,
            "z": 4,
            "elements": [
                "appliedenergistics2:chiseled_quartz_block@0"
            ]
        },
        {
            "x": 1,
            "y": 3,
            "z": 6,
            "elements": [
                "appliedenergistics2:smooth_sky_stone_block@0"
            ]
        },
        {
            "x": -1,
            "y": -1,
            "z": -5,
            "elements": [
                "minecraft:sea_lantern@0"
            ]
        },
        {
            "x": -1,
            "y": -1,
            "z": 4,
            "elements": [
                "appliedenergistics2:chiseled_quartz_block@0"
            ]
        },
        {
            "x": 0,
            "y": -1,
            "z": 4,
            "elements": [
                "mekanism:reinforcedplasticblock@8"
            ]
        },
        {
            "x": -2,
            "y": -1,
            "z": -5,
            "elements": [
                "appliedenergistics2:smooth_sky_stone_block@0"
            ]
        },
        {
            "x": 2,
            "y": 3,
            "z": 6,
            "elements": [
                "appliedenergistics2:smooth_sky_stone_block@0"
            ]
        },
        {
            "x": 0,
            "y": 5,
            "z": -2,
            "elements": [
                "appliedenergistics2:sky_stone_brick_slab@0"
            ]
        },
        {
            "x": -3,
            "y": -1,
            "z": -5,
            "elements": [
                "appliedenergistics2:smooth_sky_stone_block@0"
            ]
        },
        {
            "x": 3,
            "y": 3,
            "z": 6,
            "elements": [
                "appliedenergistics2:smooth_sky_stone_block@0"
            ]
        },
        {
            "x": 1,
            "y": -1,
            "z": 4,
            "elements": [
                "appliedenergistics2:chiseled_quartz_block@0"
            ]
        },
        {
            "x": -4,
            "y": -1,
            "z": -5,
            "elements": [
                "appliedenergistics2:smooth_sky_stone_block@0"
            ]
        },
        {
            "x": 4,
            "y": 3,
            "z": 6,
            "elements": [
                "mekanism:reinforcedplasticblock@8"
            ]
        },
        {
            "x": 2,
            "y": -1,
            "z": 4,
            "elements": [
                "appliedenergistics2:chiseled_quartz_block@0"
            ]
        },
        {
            "x": 3,
            "y": -1,
            "z": 4,
            "elements": [
                "appliedenergistics2:smooth_sky_stone_block@0"
            ]
        },
        {
            "x": -5,
            "y": 1,
            "z": -4,
            "elements": [
                "thermalfoundation:glass_alloy@7"
            ]
        },
        {
            "x": 4,
            "y": -1,
            "z": 4,
            "elements": [
                "minecraft:quartz_block@1"
            ]
        },
        {
            "x": -5,
            "y": 3,
            "z": -3,
            "elements": [
                "mekanism:reinforcedplasticblock@8"
            ]
        },
        {
            "x": 6,
            "y": 1,
            "z": 5,
            "elements": [
                "thermalfoundation:glass_alloy@7"
            ]
        },
        {
            "x": 5,
            "y": -1,
            "z": 4,
            "elements": [
                "appliedenergistics2:chiseled_quartz_block@0"
            ]
        },
        {
            "x": 6,
            "y": -1,
            "z": 4,
            "elements": [
                "appliedenergistics2:smooth_sky_stone_block@0"
            ]
        },
        {
            "x": -6,
            "y": 2,
            "z": 5,
            "elements": [
                "mekanism:reinforcedplasticblock@8"
            ]
        },
        {
            "x": -6,
            "y": 0,
            "z": 4,
            "elements": [
                "appliedenergistics2:smooth_sky_stone_block@0"
            ]
        },
        {
            "x": 6,
            "y": 2,
            "z": -3,
            "elements": [
                "mekanism:reinforcedplasticblock@8"
            ]
        },
        {
            "x": 5,
            "y": 0,
            "z": -4,
            "elements": [
                "appliedenergistics2:smooth_sky_stone_block@0"
            ]
        },
        {
            "x": 3,
            "y": 4,
            "z": -2,
            "elements": [
                "appliedenergistics2:smooth_sky_stone_block@0"
            ]
        },
        {
            "x": 2,
            "y": 4,
            "z": -2,
            "elements": [
                "appliedenergistics2:smooth_sky_stone_block@0"
            ]
        },
        {
            "x": -1,
            "y": 0,
            "z": 4,
            "elements": [
                "minecraft:carpet@7"
            ]
        },
        {
            "x": 0,
            "y": 0,
            "z": 4,
            "elements": [
                "minecraft:carpet@7"
            ]
        },
        {
            "x": 1,
            "y": 4,
            "z": -2,
            "elements": [
                "thermalfoundation:glass_alloy@7"
            ]
        },
        {
            "x": 0,
            "y": 4,
            "z": -2,
            "elements": [
                "appliedenergistics2:smooth_sky_stone_block@0"
            ]
        },
        {
            "x": 1,
            "y": 0,
            "z": 4,
            "elements": [
                "minecraft:carpet@7"
            ]
        },
        {
            "x": -1,
            "y": 4,
            "z": -2,
            "elements": [
                "thermalfoundation:glass_alloy@7"
            ]
        },
        {
            "x": -2,
            "y": 4,
            "z": -2,
            "elements": [
                "appliedenergistics2:smooth_sky_stone_block@0"
            ]
        },
        {
            "x": -5,
            "y": 0,
            "z": -4,
            "elements": [
                "appliedenergistics2:smooth_sky_stone_block@0"
            ]
        },
        {
            "x": -3,
            "y": 4,
            "z": -2,
            "elements": [
                "appliedenergistics2:smooth_sky_stone_block@0"
            ]
        },
        {
            "x": 6,
            "y": 2,
            "z": 5,
            "elements": [
                "mekanism:reinforcedplasticblock@8"
            ]
        },
        {
            "x": -6,
            "y": 2,
            "z": -3,
            "elements": [
                "mekanism:reinforcedplasticblock@8"
            ]
        },
        {
            "x": 6,
            "y": 0,
            "z": 4,
            "elements": [
                "appliedenergistics2:smooth_sky_stone_block@0"
            ]
        },
        {
            "x": -6,
            "y": 1,
            "z": 4,
            "elements": [
                "thermalfoundation:glass_alloy@7"
            ]
        },
        {
            "x": -5,
            "y": 3,
            "z": 5,
            "elements": [
                "mekanism:reinforcedplasticblock@8"
            ]
        },
        {
            "x": 6,
            "y": 1,
            "z": -3,
            "elements": [
                "thermalfoundation:glass_alloy@7"
            ]
        },
        {
            "x": 5,
            "y": -1,
            "z": -4,
            "elements": [
                "appliedenergistics2:smooth_sky_stone_block@0"
            ]
        },
        {
            "x": -6,
            "y": -1,
            "z": 3,
            "elements": [
                "appliedenergistics2:smooth_sky_stone_block@0"
            ]
        },
        {
            "x": 4,
            "y": -1,
            "z": -4,
            "elements": [
                "appliedenergistics2:chiseled_quartz_block@0"
            ]
        },
        {
            "x": -5,
            "y": -1,
            "z": 3,
            "elements": [
                "appliedenergistics2:chiseled_quartz_block@0"
            ]
        },
        {
            "x": 5,
            "y": 3,
            "z": -2,
            "elements": [
                "appliedenergistics2:smooth_sky_stone_block@0"
            ]
        },
        {
            "x": 3,
            "y": -1,
            "z": -4,
            "elements": [
                "appliedenergistics2:chiseled_quartz_block@0"
            ]
        },
        {
            "x": -4,
            "y": -1,
            "z": 3,
            "elements": [
                "minecraft:quartz_block@1"
            ]
        },
        {
            "x": 2,
            "y": -1,
            "z": -4,
            "elements": [
                "appliedenergistics2:chiseled_quartz_block@0"
            ]
        },
        {
            "x": -3,
            "y": -1,
            "z": 3,
            "elements": [
                "appliedenergistics2:chiseled_quartz_block@0"
            ]
        },
        {
            "x": 1,
            "y": -1,
            "z": -4,
            "elements": [
                "appliedenergistics2:chiseled_quartz_block@0"
            ]
        },
        {
            "x": 0,
            "y": -1,
            "z": -4,
            "elements": [
                "mekanism:reinforcedplasticblock@8"
            ]
        },
        {
            "x": -2,
            "y": -1,
            "z": 3,
            "elements": [
                "appliedenergistics2:smooth_sky_stone_block@0"
            ]
        },
        {
            "x": -1,
            "y": -1,
            "z": -4,
            "elements": [
                "appliedenergistics2:chiseled_quartz_block@0"
            ]
        },
        {
            "x": -1,
            "y": -1,
            "z": 3,
            "elements": [
                "appliedenergistics2:chiseled_quartz_block@0"
            ]
        },
        {
            "x": 0,
            "y": -1,
            "z": 3,
            "elements": [
                "mekanism:reinforcedplasticblock@8"
            ]
        },
        {
            "x": -2,
            "y": -1,
            "z": -4,
            "elements": [
                "appliedenergistics2:chiseled_quartz_block@0"
            ]
        },
        {
            "x": 0,
            "y": 5,
            "z": -1,
            "elements": [
                "appliedenergistics2:sky_stone_brick_slab@0"
            ]
        },
        {
            "x": -3,
            "y": -1,
            "z": -4,
            "elements": [
                "appliedenergistics2:chiseled_quartz_block@0"
            ]
        },
        {
            "x": 1,
            "y": -1,
            "z": 3,
            "elements": [
                "appliedenergistics2:chiseled_quartz_block@0"
            ]
        },
        {
            "x": -4,
            "y": -1,
            "z": -4,
            "elements": [
                "appliedenergistics2:chiseled_quartz_block@0"
            ]
        },
        {
            "x": 2,
            "y": -1,
            "z": 3,
            "elements": [
                "appliedenergistics2:smooth_sky_stone_block@0"
            ]
        },
        {
            "x": -5,
            "y": -1,
            "z": -4,
            "elements": [
                "appliedenergistics2:smooth_sky_stone_block@0"
            ]
        },
        {
            "x": 5,
            "y": 3,
            "z": 5,
            "elements": [
                "mekanism:reinforcedplasticblock@8"
            ]
        },
        {
            "x": 3,
            "y": -1,
            "z": 3,
            "elements": [
                "appliedenergistics2:chiseled_quartz_block@0"
            ]
        },
        {
            "x": 4,
            "y": -1,
            "z": 3,
            "elements": [
                "minecraft:quartz_block@1"
            ]
        },
        {
            "x": -6,
            "y": 1,
            "z": -3,
            "elements": [
                "thermalfoundation:glass_alloy@7"
            ]
        },
        {
            "x": -5,
            "y": 3,
            "z": -2,
            "elements": [
                "appliedenergistics2:smooth_sky_stone_block@0"
            ]
        },
        {
            "x": 6,
            "y": 1,
            "z": 4,
            "elements": [
                "thermalfoundation:glass_alloy@7"
            ]
        },
        {
            "x": 5,
            "y": -1,
            "z": 3,
            "elements": [
                "appliedenergistics2:chiseled_quartz_block@0"
            ]
        },
        {
            "x": 6,
            "y": -1,
            "z": 3,
            "elements": [
                "appliedenergistics2:smooth_sky_stone_block@0"
            ]
        },
        {
            "x": -6,
            "y": 2,
            "z": 4,
            "elements": [
                "mekanism:reinforcedplasticblock@8"
            ]
        },
        {
            "x": 6,
            "y": 0,
            "z": -3,
            "elements": [
                "appliedenergistics2:smooth_sky_stone_block@0"
            ]
        },
        {
            "x": -6,
            "y": 0,
            "z": 3,
            "elements": [
                "appliedenergistics2:smooth_sky_stone_block@0"
            ]
        },
        {
            "x": -4,
            "y": 4,
            "z": 5,
            "elements": [
                "mekanism:reinforcedplasticblock@8"
            ]
        },
        {
            "x": 6,
            "y": 2,
            "z": -2,
            "elements": [
                "mekanism:reinforcedplasticblock@8"
            ]
        },
        {
            "x": -3,
            "y": 4,
            "z": 5,
            "elements": [
                "appliedenergistics2:smooth_sky_stone_block@0"
            ]
        },
        {
            "x": -2,
            "y": 4,
            "z": 5,
            "elements": [
                "appliedenergistics2:smooth_sky_stone_block@0"
            ]
        },
        {
            "x": -1,
            "y": 4,
            "z": 5,
            "elements": [
                "appliedenergistics2:smooth_sky_stone_block@0"
            ]
        },
        {
            "x": 4,
            "y": 4,
            "z": -1,
            "elements": [
                "appliedenergistics2:smooth_sky_stone_block@0"
            ]
        },
        {
            "x": 0,
            "y": 4,
            "z": 5,
            "elements": [
                "appliedenergistics2:smooth_sky_stone_block@0"
            ]
        },
        {
            "x": 3,
            "y": 4,
            "z": -1,
            "elements": [
                "appliedenergistics2:smooth_sky_stone_block@0"
            ]
        },
        {
            "x": 1,
            "y": 4,
            "z": 5,
            "elements": [
                "appliedenergistics2:smooth_sky_stone_block@0"
            ]
        },
        {
            "x": -1,
            "y": 0,
            "z": 3,
            "elements": [
                "minecraft:carpet@7"
            ]
        },
        {
            "x": 2,
            "y": 4,
            "z": -1,
            "elements": [
                "thermalfoundation:storage_alloy@6"
            ]
        },
        {
            "x": 0,
            "y": 0,
            "z": 3,
            "elements": [
                "minecraft:carpet@7"
            ]
        },
        {
            "x": 1,
            "y": 4,
            "z": -1,
            "elements": [
                "thermalfoundation:glass_alloy@7"
            ]
        },
        {
            "x": 2,
            "y": 4,
            "z": 5,
            "elements": [
                "appliedenergistics2:smooth_sky_stone_block@0"
            ]
        },
        {
            "x": 0,
            "y": 4,
            "z": -1,
            "elements": [
                "appliedenergistics2:smooth_sky_stone_block@0"
            ]
        },
        {
            "x": 3,
            "y": 4,
            "z": 5,
            "elements": [
                "appliedenergistics2:smooth_sky_stone_block@0"
            ]
        },
        {
            "x": 1,
            "y": 0,
            "z": 3,
            "elements": [
                "minecraft:carpet@7"
            ]
        },
        {
            "x": -1,
            "y": 4,
            "z": -1,
            "elements": [
                "thermalfoundation:glass_alloy@7"
            ]
        },
        {
            "x": 4,
            "y": 4,
            "z": 5,
            "elements": [
                "mekanism:reinforcedplasticblock@8"
            ]
        },
        {
            "x": -2,
            "y": 4,
            "z": -1,
            "elements": [
                "thermalfoundation:storage_alloy@6"
            ]
        },
        {
            "x": -3,
            "y": 4,
            "z": -1,
            "elements": [
                "appliedenergistics2:smooth_sky_stone_block@0"
            ]
        },
        {
            "x": -6,
            "y": 0,
            "z": -3,
            "elements": [
                "appliedenergistics2:smooth_sky_stone_block@0"
            ]
        },
        {
            "x": -4,
            "y": 4,
            "z": -1,
            "elements": [
                "appliedenergistics2:smooth_sky_stone_block@0"
            ]
        },
        {
            "x": 6,
            "y": 2,
            "z": 4,
            "elements": [
                "mekanism:reinforcedplasticblock@8"
            ]
        },
        {
            "x": -6,
            "y": 2,
            "z": -2,
            "elements": [
                "mekanism:reinforcedplasticblock@8"
            ]
        },
        {
            "x": 6,
            "y": 0,
            "z": 3,
            "elements": [
                "appliedenergistics2:smooth_sky_stone_block@0"
            ]
        },
        {
            "x": 6,
            "y": -1,
            "z": -3,
            "elements": [
                "appliedenergistics2:smooth_sky_stone_block@0"
            ]
        },
        {
            "x": -7,
            "y": -1,
            "z": 2,
            "elements": [
                "mekanism:reinforcedplasticblock@8"
            ]
        },
        {
            "x": -6,
            "y": 1,
            "z": 3,
            "elements": [
                "thermalfoundation:glass_alloy@7"
            ]
        },
        {
            "x": -5,
            "y": 3,
            "z": 4,
            "elements": [
                "appliedenergistics2:smooth_sky_stone_block@0"
            ]
        },
        {
            "x": 6,
            "y": 1,
            "z": -2,
            "elements": [
                "thermalfoundation:glass_alloy@7"
            ]
        },
        {
            "x": 5,
            "y": -1,
            "z": -3,
            "elements": [
                "appliedenergistics2:chiseled_quartz_block@0"
            ]
        },
        {
            "x": -6,
            "y": -1,
            "z": 2,
            "elements": [
                "minecraft:sea_lantern@0"
            ]
        },
        {
            "x": 4,
            "y": -1,
            "z": -3,
            "elements": [
                "appliedenergistics2:smooth_sky_stone_block@0"
            ]
        },
        {
            "x": -5,
            "y": -1,
            "z": 2,
            "elements": [
                "appliedenergistics2:chiseled_quartz_block@0"
            ]
        },
        {
            "x": 5,
            "y": 3,
            "z": -1,
            "elements": [
                "thermalfoundation:storage_alloy@6"
            ]
        },
        {
            "x": 3,
            "y": -1,
            "z": -3,
            "elements": [
                "minecraft:quartz_block@1"
            ]
        },
        {
            "x": -4,
            "y": -1,
            "z": 2,
            "elements": [
                "minecraft:quartz_block@1"
            ]
        },
        {
            "x": 2,
            "y": -1,
            "z": -3,
            "elements": [
                "minecraft:quartz_block@1"
            ]
        },
        {
            "x": -3,
            "y": -1,
            "z": 2,
            "elements": [
                "appliedenergistics2:chiseled_quartz_block@0"
            ]
        },
        {
            "x": 1,
            "y": -1,
            "z": -3,
            "elements": [
                "minecraft:quartz_block@1"
            ]
        },
        {
            "x": 0,
            "y": -1,
            "z": -3,
            "elements": [
                "contenttweaker:zl_block@0"
            ]
        },
        {
            "x": -2,
            "y": -1,
            "z": 2,
            "elements": [
                "appliedenergistics2:chiseled_quartz_block@0"
            ]
        },
        {
            "x": 1,
            "y": 3,
            "z": -1,
            "elements": [
                "appliedenergistics2:sky_stone_brick_stairs@6"
            ]
        },
        {
            "x": -1,
            "y": -1,
            "z": -3,
            "elements": [
                "minecraft:quartz_block@1"
            ]
        },
        {
            "x": -1,
            "y": -1,
            "z": 2,
            "elements": [
                "minecraft:sea_lantern@0"
            ]
        },
        {
            "x": 0,
            "y": -1,
            "z": 2,
            "elements": [
                "minecraft:sea_lantern@0"
            ]
        },
        {
            "x": 0,
            "y": 3,
            "z": -1,
            "elements": [
                "appliedenergistics2:sky_stone_brick_stairs@2"
            ]
        },
        {
            "x": -2,
            "y": -1,
            "z": -3,
            "elements": [
                "minecraft:quartz_block@1"
            ]
        },
        {
            "x": -3,
            "y": -1,
            "z": -3,
            "elements": [
                "minecraft:quartz_block@1"
            ]
        },
        {
            "x": -1,
            "y": 3,
            "z": -1,
            "elements": [
                "appliedenergistics2:sky_stone_brick_stairs@6"
            ]
        },
        {
            "x": 1,
            "y": -1,
            "z": 2,
            "elements": [
                "minecraft:sea_lantern@0"
            ]
        },
        {
            "x": -4,
            "y": -1,
            "z": -3,
            "elements": [
                "appliedenergistics2:smooth_sky_stone_block@0"
            ]
        },
        {
            "x": 2,
            "y": -1,
            "z": 2,
            "elements": [
                "appliedenergistics2:chiseled_quartz_block@0"
            ]
        },
        {
            "x": -5,
            "y": -1,
            "z": -3,
            "elements": [
                "appliedenergistics2:chiseled_quartz_block@0"
            ]
        },
        {
            "x": 5,
            "y": 3,
            "z": 4,
            "elements": [
                "appliedenergistics2:smooth_sky_stone_block@0"
            ]
        },
        {
            "x": 3,
            "y": -1,
            "z": 2,
            "elements": [
                "appliedenergistics2:chiseled_quartz_block@0"
            ]
        },
        {
            "x": -6,
            "y": -1,
            "z": -3,
            "elements": [
                "appliedenergistics2:smooth_sky_stone_block@0"
            ]
        },
        {
            "x": 4,
            "y": -1,
            "z": 2,
            "elements": [
                "minecraft:quartz_block@1"
            ]
        },
        {
            "x": -6,
            "y": 1,
            "z": -2,
            "elements": [
                "thermalfoundation:glass_alloy@7"
            ]
        },
        {
            "x": -5,
            "y": 3,
            "z": -1,
            "elements": [
                "thermalfoundation:storage_alloy@6"
            ]
        },
        {
            "x": 6,
            "y": 1,
            "z": 3,
            "elements": [
                "thermalfoundation:glass_alloy@7"
            ]
        },
        {
            "x": 5,
            "y": -1,
            "z": 2,
            "elements": [
                "appliedenergistics2:chiseled_quartz_block@0"
            ]
        },
        {
            "x": 6,
            "y": -1,
            "z": 2,
            "elements": [
                "minecraft:sea_lantern@0"
            ]
        },
        {
            "x": 7,
            "y": -1,
            "z": 2,
            "elements": [
                "mekanism:reinforcedplasticblock@8"
            ]
        },
        {
            "x": -7,
            "y": 0,
            "z": 2,
            "elements": [
                "appliedenergistics2:smooth_sky_stone_block@0"
            ]
        },
        {
            "x": -6,
            "y": 2,
            "z": 3,
            "elements": [
                "mekanism:reinforcedplasticblock@8"
            ]
        },
        {
            "x": 6,
            "y": 0,
            "z": -2,
            "elements": [
                "appliedenergistics2:smooth_sky_stone_block@0"
            ]
        },
        {
            "x": -4,
            "y": 4,
            "z": 4,
            "elements": [
                "appliedenergistics2:smooth_sky_stone_block@0"
            ]
        },
        {
            "x": 6,
            "y": 2,
            "z": -1,
            "elements": [
                "mekanism:reinforcedplasticblock@8"
            ]
        },
        {
            "x": -3,
            "y": 4,
            "z": 4,
            "elements": [
                "appliedenergistics2:smooth_sky_stone_block@0"
            ]
        },
        {
            "x": -2,
            "y": 4,
            "z": 4,
            "elements": [
                "appliedenergistics2:smooth_sky_stone_block@0"
            ]
        },
        {
            "x": -1,
            "y": 4,
            "z": 4,
            "elements": [
                "thermalfoundation:glass_alloy@7"
            ]
        },
        {
            "x": 0,
            "y": 4,
            "z": 4,
            "elements": [
                "appliedenergistics2:smooth_sky_stone_block@0"
            ]
        },
        {
            "x": 1,
            "y": 4,
            "z": 4,
            "elements": [
                "thermalfoundation:glass_alloy@7"
            ]
        },
        {
            "x": -1,
            "y": 0,
            "z": 2,
            "elements": [
                "minecraft:stone_slab@7"
            ]
        },
        {
            "x": 0,
            "y": 0,
            "z": 2,
            "elements": [
                "minecraft:stained_glass@0"
            ]
        },
        {
            "x": 2,
            "y": 4,
            "z": 4,
            "elements": [
                "appliedenergistics2:smooth_sky_stone_block@0"
            ]
        },
        {
            "x": 3,
            "y": 4,
            "z": 4,
            "elements": [
                "appliedenergistics2:smooth_sky_stone_block@0"
            ]
        },
        {
            "x": 1,
            "y": 0,
            "z": 2,
            "elements": [
                "minecraft:stone_slab@7"
            ]
        },
        {
            "x": 4,
            "y": 4,
            "z": 4,
            "elements": [
                "appliedenergistics2:smooth_sky_stone_block@0"
            ]
        },
        {
            "x": -6,
            "y": 0,
            "z": -2,
            "elements": [
                "appliedenergistics2:smooth_sky_stone_block@0"
            ]
        },
        {
            "x": 6,
            "y": 2,
            "z": 3,
            "elements": [
                "mekanism:reinforcedplasticblock@8"
            ]
        },
        {
            "x": -6,
            "y": 2,
            "z": -1,
            "elements": [
                "mekanism:reinforcedplasticblock@8"
            ]
        },
        {
            "x": 7,
            "y": 0,
            "z": 2,
            "elements": [
                "appliedenergistics2:smooth_sky_stone_block@0"
            ]
        },
        {
            "x": -7,
            "y": 1,
            "z": 2,
            "elements": [
                "thermalfoundation:glass_alloy@7"
            ]
        },
        {
            "x": 6,
            "y": -1,
            "z": -2,
            "elements": [
                "appliedenergistics2:smooth_sky_stone_block@0"
            ]
        },
        {
            "x": -7,
            "y": -1,
            "z": 1,
            "elements": [
                "mekanism:reinforcedplasticblock@8"
            ]
        },
        {
            "x": -5,
            "y": 3,
            "z": 3,
            "elements": [
                "thermalfoundation:storage_alloy@6"
            ]
        },
        {
            "x": 6,
            "y": 1,
            "z": -1,
            "elements": [
                "thermalfoundation:glass_alloy@7"
            ]
        },
        {
            "x": 5,
            "y": -1,
            "z": -2,
            "elements": [
                "appliedenergistics2:chiseled_quartz_block@0"
            ]
        },
        {
            "x": -6,
            "y": -1,
            "z": 1,
            "elements": [
                "modularmachinery:blockenergyinputhatch"
            ]
        },
        {
            "x": 4,
            "y": -1,
            "z": -2,
            "elements": [
                "minecraft:quartz_block@1"
            ]
        },
        {
            "x": -5,
            "y": -1,
            "z": 1,
            "elements": [
                "mekanism:reinforcedplasticblock@8"
            ]
        },
        {
            "x": 3,
            "y": -1,
            "z": -2,
            "elements": [
                "appliedenergistics2:smooth_sky_stone_block@0"
            ]
        },
        {
            "x": -4,
            "y": -1,
            "z": 1,
            "elements": [
                "contenttweaker:zl_block@0"
            ]
        },
        {
            "x": 2,
            "y": -1,
            "z": -2,
            "elements": [
                "appliedenergistics2:chiseled_quartz_block@0"
            ]
        },
        {
            "x": 0,
            "y": 5,
            "z": 4,
            "elements": [
                "appliedenergistics2:sky_stone_brick_slab@0"
            ]
        },
        {
            "x": -3,
            "y": -1,
            "z": 1,
            "elements": [
                "mekanism:reinforcedplasticblock@8"
            ]
        },
        {
            "x": -1,
            "y": 3,
            "z": 3,
            "elements": [
                "appliedenergistics2:sky_stone_brick_stairs@7"
            ]
        },
        {
            "x": 1,
            "y": -1,
            "z": -2,
            "elements": [
                "appliedenergistics2:chiseled_quartz_block@0"
            ]
        },
        {
            "x": 0,
            "y": -1,
            "z": -2,
            "elements": [
                "mekanism:reinforcedplasticblock@8"
            ]
        },
        {
            "x": 0,
            "y": 3,
            "z": 3,
            "elements": [
                "appliedenergistics2:sky_stone_brick_stairs@3"
            ]
        },
        {
            "x": -2,
            "y": -1,
            "z": 1,
            "elements": [
                "mekanism:reinforcedplasticblock@8"
            ]
        },
        {
            "x": 1,
            "y": 3,
            "z": 3,
            "elements": [
                "appliedenergistics2:sky_stone_brick_stairs@7"
            ]
        },
        {
            "x": 0,
            "y": 1,
            "z": 2,
            "elements": [
                "enderio:block_dark_iron_bars@0"
            ]
        },
        {
            "x": -1,
            "y": -1,
            "z": -2,
            "elements": [
                "appliedenergistics2:chiseled_quartz_block@0"
            ]
        },
        {
            "x": -1,
            "y": -1,
            "z": 1,
            "elements": [
                "minecraft:sea_lantern@0"
            ]
        },
        {
            "x": 0,
            "y": -1,
            "z": 1,
            "elements": [
                "contenttweaker:zl_block@0"
            ]
        },
        {
            "x": -2,
            "y": -1,
            "z": -2,
            "elements": [
                "appliedenergistics2:chiseled_quartz_block@0"
            ]
        },
        {
            "x": -3,
            "y": -1,
            "z": -2,
            "elements": [
                "appliedenergistics2:smooth_sky_stone_block@0"
            ]
        },
        {
            "x": 1,
            "y": -1,
            "z": 1,
            "elements": [
                "minecraft:sea_lantern@0"
            ]
        },
        {
            "x": -4,
            "y": -1,
            "z": -2,
            "elements": [
                "minecraft:quartz_block@1"
            ]
        },
        {
            "x": 2,
            "y": -1,
            "z": 1,
            "elements": [
                "mekanism:reinforcedplasticblock@8"
            ]
        },
        {
            "x": -5,
            "y": -1,
            "z": -2,
            "elements": [
                "appliedenergistics2:chiseled_quartz_block@0"
            ]
        },
        {
            "x": 5,
            "y": 3,
            "z": 3,
            "elements": [
                "thermalfoundation:storage_alloy@6"
            ]
        },
        {
            "x": 3,
            "y": -1,
            "z": 1,
            "elements": [
                "mekanism:reinforcedplasticblock@8"
            ]
        },
        {
            "x": -6,
            "y": -1,
            "z": -2,
            "elements": [
                "appliedenergistics2:smooth_sky_stone_block@0"
            ]
        },
        {
            "x": 4,
            "y": -1,
            "z": 1,
            "elements": [
                "contenttweaker:zl_block@0"
            ]
        },
        {
            "x": -6,
            "y": 1,
            "z": -1,
            "elements": [
                "thermalfoundation:glass_alloy@7"
            ]
        },
        {
            "x": 5,
            "y": -1,
            "z": 1,
            "elements": [
                "mekanism:reinforcedplasticblock@8"
            ]
        },
        {
            "x": 7,
            "y": 1,
            "z": 2,
            "elements": [
                "thermalfoundation:glass_alloy@7"
            ]
        },
        {
            "x": 6,
            "y": -1,
            "z": 1,
            "elements": [
                "modularmachinery:blockenergyinputhatch"
            ]
        },
        {
            "x": 7,
            "y": -1,
            "z": 1,
            "elements": [
                "mekanism:reinforcedplasticblock@8"
            ]
        },
        {
            "x": -7,
            "y": 0,
            "z": 1,
            "elements": [
                "appliedenergistics2:smooth_sky_stone_block@0"
            ]
        },
        {
            "x": -6,
            "y": 2,
            "z": 2,
            "elements": [
                "mekanism:reinforcedplasticblock@8"
            ]
        },
        {
            "x": 6,
            "y": 0,
            "z": -1,
            "elements": [
                "appliedenergistics2:smooth_sky_stone_block@0"
            ]
        },
        {
            "x": -4,
            "y": 4,
            "z": 3,
            "elements": [
                "appliedenergistics2:smooth_sky_stone_block@0"
            ]
        },
        {
            "x": -3,
            "y": 4,
            "z": 3,
            "elements": [
                "appliedenergistics2:smooth_sky_stone_block@0"
            ]
        },
        {
            "x": -2,
            "y": 4,
            "z": 3,
            "elements": [
                "thermalfoundation:storage_alloy@6"
            ]
        },
        {
            "x": -1,
            "y": 4,
            "z": 3,
            "elements": [
                "thermalfoundation:glass_alloy@7"
            ]
        },
        {
            "x": 0,
            "y": 4,
            "z": 3,
            "elements": [
                "appliedenergistics2:smooth_sky_stone_block@0"
            ]
        },
        {
            "x": 1,
            "y": 4,
            "z": 3,
            "elements": [
                "thermalfoundation:glass_alloy@7"
            ]
        },
        {
            "x": 0,
            "y": 2,
            "z": 2,
            "elements": [
                "enderio:block_dark_iron_bars@0"
            ]
        },
        {
            "x": -1,
            "y": 0,
            "z": 1,
            "elements": [
                "minecraft:stained_glass@0"
            ]
        },
        {
            "x": 0,
            "y": 0,
            "z": 1,
            "elements": [
                "environmentaltech:laser_lens_colored@15"
            ]
        },
        {
            "x": 2,
            "y": 4,
            "z": 3,
            "elements": [
                "thermalfoundation:storage_alloy@6"
            ]
        },
        {
            "x": 3,
            "y": 4,
            "z": 3,
            "elements": [
                "appliedenergistics2:smooth_sky_stone_block@0"
            ]
        },
        {
            "x": 1,
            "y": 0,
            "z": 1,
            "elements": [
                "minecraft:stained_glass@0"
            ]
        },
        {
            "x": 4,
            "y": 4,
            "z": 3,
            "elements": [
                "appliedenergistics2:smooth_sky_stone_block@0"
            ]
        },
        {
            "x": -6,
            "y": 0,
            "z": -1,
            "elements": [
                "appliedenergistics2:smooth_sky_stone_block@0"
            ]
        },
        {
            "x": 7,
            "y": 2,
            "z": 2,
            "elements": [
                "mekanism:reinforcedplasticblock@8"
            ]
        },
        {
            "x": 7,
            "y": 0,
            "z": 1,
            "elements": [
                "appliedenergistics2:smooth_sky_stone_block@0"
            ]
        },
        {
            "x": -7,
            "y": 1,
            "z": 1,
            "elements": [
                "appliedenergistics2:smooth_sky_stone_block@0"
            ]
        },
        {
            "x": -6,
            "y": 3,
            "z": 2,
            "elements": [
                "contenttweaker:zl_block@0"
            ]
        },
        {
            "x": 6,
            "y": -1,
            "z": -1,
            "elements": [
                "appliedenergistics2:smooth_sky_stone_block@0"
            ]
        },
        {
            "x": -5,
            "y": 3,
            "z": 2,
            "elements": [
                "appliedenergistics2:smooth_sky_stone_block@0"
            ]
        },
        {
            "x": 5,
            "y": -1,
            "z": -1,
            "elements": [
                "appliedenergistics2:chiseled_quartz_block@0"
            ]
        },
        {
            "x": 4,
            "y": -1,
            "z": -1,
            "elements": [
                "minecraft:quartz_block@1"
            ]
        },
        {
            "x": 3,
            "y": -1,
            "z": -1,
            "elements": [
                "appliedenergistics2:chiseled_quartz_block@0"
            ]
        },
        {
            "x": -2,
            "y": 3,
            "z": 2,
            "elements": [
                "appliedenergistics2:sky_stone_brick_stairs@4"
            ]
        },
        {
            "x": 2,
            "y": -1,
            "z": -1,
            "elements": [
                "appliedenergistics2:smooth_sky_stone_block@0"
            ]
        },
        {
            "x": 0,
            "y": 5,
            "z": 3,
            "elements": [
                "appliedenergistics2:sky_stone_brick_slab@0"
            ]
        },
        {
            "x": -1,
            "y": 3,
            "z": 2,
            "elements": [
                "enderio:block_alloy_endergy@1"
            ]
        },
        {
            "x": 1,
            "y": -1,
            "z": -1,
            "elements": [
                "appliedenergistics2:chiseled_quartz_block@0"
            ]
        },
        {
            "x": 0,
            "y": -1,
            "z": -1,
            "elements": [
                "mekanism:reinforcedplasticblock@8"
            ]
        },
        {
            "x": 0,
            "y": 3,
            "z": 2,
            "elements": [
                "enderio:block_alloy_endergy@1"
            ]
        },
        {
            "x": -1,
            "y": 1,
            "z": 1,
            "elements": [
                "enderio:block_dark_iron_bars@0"
            ]
        },
        {
            "x": 1,
            "y": 3,
            "z": 2,
            "elements": [
                "enderio:block_alloy_endergy@1"
            ]
        },
        {
            "x": 0,
            "y": 1,
            "z": 1,
            "elements": [
                "environmentaltech:laser_lens_colored@15"
            ]
        },
        {
            "x": -1,
            "y": -1,
            "z": -1,
            "elements": [
                "appliedenergistics2:chiseled_quartz_block@0"
            ]
        },
        {
            "x": -2,
            "y": -1,
            "z": -1,
            "elements": [
                "appliedenergistics2:smooth_sky_stone_block@0"
            ]
        },
        {
            "x": 2,
            "y": 3,
            "z": 2,
            "elements": [
                "appliedenergistics2:sky_stone_brick_stairs@5"
            ]
        },
        {
            "x": 1,
            "y": 1,
            "z": 1,
            "elements": [
                "enderio:block_dark_iron_bars@0"
            ]
        },
        {
            "x": -3,
            "y": -1,
            "z": -1,
            "elements": [
                "appliedenergistics2:chiseled_quartz_block@0"
            ]
        },
        {
            "x": -4,
            "y": -1,
            "z": -1,
            "elements": [
                "minecraft:quartz_block@1"
            ]
        },
        {
            "x": -5,
            "y": -1,
            "z": -1,
            "elements": [
                "appliedenergistics2:chiseled_quartz_block@0"
            ]
        },
        {
            "x": 5,
            "y": 3,
            "z": 2,
            "elements": [
                "appliedenergistics2:smooth_sky_stone_block@0"
            ]
        },
        {
            "x": -6,
            "y": -1,
            "z": -1,
            "elements": [
                "appliedenergistics2:smooth_sky_stone_block@0"
            ]
        },
        {
            "x": 6,
            "y": 3,
            "z": 2,
            "elements": [
                "contenttweaker:zl_block@0"
            ]
        },
        {
            "x": 7,
            "y": 1,
            "z": 1,
            "elements": [
                "appliedenergistics2:smooth_sky_stone_block@0"
            ]
        },
        {
            "x": -7,
            "y": 2,
            "z": 1,
            "elements": [
                "appliedenergistics2:smooth_sky_stone_block@0"
            ]
        },
        {
            "x": -6,
            "y": 2,
            "z": 1,
            "elements": [
                "appliedenergistics2:smooth_sky_stone_block@0"
            ]
        },
        {
            "x": -4,
            "y": 4,
            "z": 2,
            "elements": [
                "appliedenergistics2:smooth_sky_stone_block@0"
            ]
        },
        {
            "x": -3,
            "y": 4,
            "z": 2,
