{   "registryname": "earth_reactor",
    "localizedname": "地心反应堆",
    "requires-blueprint": false,
    "color": "FFFFFF",
    "parts": [
        {
            "x": 1,
            "y": -5,
            "z": 10,
            "elements": [
                "minecraft:stained_glass_pane@1"
            ]
        },
        {
            "x": -5,
            "y": 14,
            "z": 12,
            "elements": [
                "appliedenergistics2:smooth_sky_stone_stairs@7"
            ]
        },
        {
            "x": 1,
            "y": -5,
            "z": 4,
            "elements": [
                "minecraft:stained_glass_pane@0"
            ]
        },
        {
            "x": -4,
            "y": 42,
            "z": -1,
            "elements": [
                "minecraft:stained_glass_pane@14"
            ]
        },
        {
            "x": -4,
            "y": 42,
            "z": 0,
            "elements": [
                "minecraft:stained_glass_pane@14"
            ]
        },
        {
            "x": -5,
            "y": 14,
            "z": 11,
            "elements": [
                "appliedenergistics2:smooth_sky_stone_stairs@6"
            ]
        },
        {
            "x": 2,
            "y": 23,
            "z": -1,
            "elements": [
                "minecraft:concrete@0"
            ]
        },
        {
            "x": 1,
            "y": -5,
            "z": -5,
            "elements": [
                "minecraft:quartz_stairs@2"
            ]
        },
        {
            "x": 2,
            "y": 23,
            "z": 2,
            "elements": [
                "minecraft:end_rod@0"
            ]
        },
        {
            "x": 1,
            "y": -5,
            "z": -3,
            "elements": [
                "minecraft:concrete@0"
            ]
        },
        {
            "x": -2,
            "y": 44,
            "z": 16,
            "elements": [
                "minecraft:stained_glass_pane@14"
            ]
        },
        {
            "x": -4,
            "y": 42,
            "z": 9,
            "elements": [
                "minecraft:stained_glass_pane@14"
            ]
        },
        {
            "x": -4,
            "y": 42,
            "z": 10,
            "elements": [
                "minecraft:stained_glass_pane@14"
            ]
        },
        {
            "x": -2,
            "y": 44,
            "z": 15,
            "elements": [
                "minecraft:stained_glass_pane@14"
            ]
        },
        {
            "x": -4,
            "y": 42,
            "z": 11,
            "elements": [
                "minecraft:stained_glass_pane@14"
            ]
        },
        {
            "x": -2,
            "y": 44,
            "z": 13,
            "elements": [
                "minecraft:quartz_stairs@7"
            ]
        },
        {
            "x": -4,
            "y": 42,
            "z": 12,
            "elements": [
                "minecraft:stained_glass_pane@14"
            ]
        },
        {
            "x": -4,
            "y": 42,
            "z": 13,
            "elements": [
                "minecraft:stained_glass_pane@14"
            ]
        },
        {
            "x": -4,
            "y": 42,
            "z": 14,
            "elements": [
                "minecraft:stained_glass_pane@14"
            ]
        },
        {
            "x": -4,
            "y": 42,
            "z": 1,
            "elements": [
                "minecraft:concrete@0"
            ]
        },
        {
            "x": 3,
            "y": 51,
            "z": -1,
            "elements": [
                "embers:wall_ashen_stone@0"
            ]
        },
        {
            "x": -4,
            "y": 42,
            "z": 2,
            "elements": [
                "minecraft:concrete@0"
            ]
        },
        {
            "x": 3,
            "y": 51,
            "z": 0,
            "elements": [
                "minecraft:concrete@0"
            ]
        },
        {
            "x": -4,
            "y": 42,
            "z": 3,
            "elements": [
                "minecraft:concrete@0"
            ]
        },
        {
            "x": -4,
            "y": 42,
            "z": 4,
            "elements": [
                "minecraft:quartz_stairs@7"
            ]
        },
        {
            "x": -4,
            "y": 42,
            "z": 5,
            "elements": [
                "minecraft:quartz_stairs@4"
            ]
        },
        {
            "x": -4,
            "y": 42,
            "z": 6,
            "elements": [
                "minecraft:stained_glass_pane@14"
            ]
        },
        {
            "x": -4,
            "y": 42,
            "z": 7,
            "elements": [
                "minecraft:stained_glass_pane@14"
            ]
        },
        {
            "x": -4,
            "y": 42,
            "z": 8,
            "elements": [
                "minecraft:stained_glass_pane@14"
            ]
        },
        {
            "x": 3,
            "y": -3,
            "z": 14,
            "elements": [
                "minecraft:concrete@0"
            ]
        },
        {
            "x": 4,
            "y": 25,
            "z": 1,
            "elements": [
                "minecraft:concrete@0"
            ]
        },
        {
            "x": 3,
            "y": -3,
            "z": 8,
            "elements": [
                "minecraft:concrete@0"
            ]
        },
        {
            "x": 3,
            "y": -3,
            "z": 7,
            "elements": [
                "minecraft:concrete@0"
            ]
        },
        {
            "x": 4,
            "y": 25,
            "z": 6,
            "elements": [
                "minecraft:concrete@0"
            ]
        },
        {
            "x": 1,
            "y": -5,
            "z": 15,
            "elements": [
                "minecraft:concrete@0"
            ]
        },
        {
            "x": 1,
            "y": -5,
            "z": 16,
            "elements": [
                "embers:wall_ashen_stone@0"
            ]
        },
        {
            "x": 4,
            "y": 25,
            "z": 7,
            "elements": [
                "minecraft:concrete@0"
            ]
        },
        {
            "x": 4,
            "y": 25,
            "z": 8,
            "elements": [
                "minecraft:concrete@0"
            ]
        },
        {
            "x": 4,
            "y": 25,
            "z": 9,
            "elements": [
                "embers:wall_ashen_stone@0"
            ]
        },
        {
            "x": 4,
            "y": 25,
            "z": 2,
            "elements": [
                "minecraft:concrete@0"
            ]
        },
        {
            "x": 1,
            "y": -5,
            "z": 11,
            "elements": [
                "minecraft:stained_glass_pane@1"
            ]
        },
        {
            "x": 4,
            "y": 25,
            "z": 3,
            "elements": [
                "embers:wall_ashen_stone@0"
            ]
        },
        {
            "x": 1,
            "y": -5,
            "z": 12,
            "elements": [
                "minecraft:stained_glass_pane@1"
            ]
        },
        {
            "x": 4,
            "y": 25,
            "z": 4,
            "elements": [
                "minecraft:concrete@0"
            ]
        },
        {
            "x": 4,
            "y": 25,
            "z": 5,
            "elements": [
                "minecraft:concrete@0"
            ]
        },
        {
            "x": 1,
            "y": 49,
            "z": -3,
            "elements": [
                "minecraft:concrete@0"
            ]
        },
        {
            "x": -1,
            "y": 18,
            "z": 14,
            "elements": [
                "minecraft:end_rod@5"
            ]
        },
        {
            "x": 1,
            "y": 49,
            "z": -4,
            "elements": [
                "minecraft:concrete@0"
            ]
        },
        {
            "x": 1,
            "y": 49,
            "z": -5,
            "elements": [
                "appliedenergistics2:smooth_sky_stone_block@0"
            ]
        },
        {
            "x": -1,
            "y": 18,
            "z": -2,
            "elements": [
                "minecraft:concrete@0"
            ]
        },
        {
            "x": -1,
            "y": 18,
            "z": 3,
            "elements": [
                "minecraft:stone_slab@15"
            ]
        },
        {
            "x": -2,
            "y": 44,
            "z": 0,
            "elements": [
                "minecraft:concrete@0"
            ]
        },
        {
            "x": -2,
            "y": 44,
            "z": -1,
            "elements": [
                "minecraft:stone_slab@7"
            ]
        },
        {
            "x": -2,
            "y": 44,
            "z": -2,
            "elements": [
                "minecraft:stone_slab@15"
            ]
        },
        {
            "x": 2,
            "y": 48,
            "z": 16,
            "elements": [
                "minecraft:stained_glass_pane@14"
            ]
        },
        {
            "x": 2,
            "y": 48,
            "z": 15,
            "elements": [
                "minecraft:stained_glass_pane@14"
            ]
        },
        {
            "x": -2,
            "y": 19,
            "z": 13,
            "elements": [
                "appliedenergistics2:smooth_sky_stone_block@0"
            ]
        },
        {
            "x": -2,
            "y": 19,
            "z": 12,
            "elements": [
                "appliedenergistics2:smooth_sky_stone_block@0"
            ]
        },
        {
            "x": -2,
            "y": 19,
            "z": 11,
            "elements": [
                "appliedenergistics2:smooth_sky_stone_stairs@6"
            ]
        },
        {
            "x": -2,
            "y": 19,
            "z": 10,
            "elements": [
                "appliedenergistics2:smooth_sky_stone_slab@8"
            ]
        },
        {
            "x": 2,
            "y": 48,
            "z": 5,
            "elements": [
                "minecraft:concrete@0"
            ]
        },
        {
            "x": -2,
            "y": 19,
            "z": -1,
            "elements": [
                "minecraft:concrete@0"
            ]
        },
        {
            "x": -2,
            "y": 19,
            "z": -2,
            "elements": [
                "appliedenergistics2:smooth_sky_stone_block@0"
            ]
        },
        {
            "x": -2,
            "y": 44,
            "z": 5,
            "elements": [
                "minecraft:concrete@0"
            ]
        },
        {
            "x": 2,
            "y": 48,
            "z": 10,
            "elements": [
                "embers:wall_ashen_stone@0"
            ]
        },
        {
            "x": -2,
            "y": 44,
            "z": 12,
            "elements": [
                "minecraft:quartz_stairs@4"
            ]
        },
        {
            "x": -2,
            "y": 44,
            "z": 11,
            "elements": [
                "minecraft:stained_glass@0"
            ]
        },
        {
            "x": -2,
            "y": 44,
            "z": 10,
            "elements": [
                "minecraft:quartz_stairs@4"
            ]
        },
        {
            "x": 2,
            "y": 48,
            "z": 12,
            "elements": [
                "embers:wall_ashen_stone@0"
            ]
        },
        {
            "x": -2,
            "y": 19,
            "z": 2,
            "elements": [
                "appliedenergistics2:smooth_sky_stone_stairs@3"
            ]
        },
        {
            "x": -2,
            "y": 44,
            "z": 9,
            "elements": [
                "minecraft:quartz_stairs@4"
            ]
        },
        {
            "x": 2,
            "y": 48,
            "z": 11,
            "elements": [
                "minecraft:stained_glass@0"
            ]
        },
        {
            "x": 1,
            "y": 49,
            "z": 16,
            "elements": [
                "minecraft:stained_glass_pane@14"
            ]
        },
        {
            "x": 1,
            "y": 49,
            "z": 13,
            "elements": [
                "minecraft:quartz_stairs@7"
            ]
        },
        {
            "x": -5,
            "y": 14,
            "z": 1,
            "elements": [
                "appliedenergistics2:smooth_sky_stone_block@0"
            ]
        },
        {
            "x": 1,
            "y": 49,
            "z": 5,
            "elements": [
                "minecraft:concrete@0"
            ]
        },
        {
            "x": -2,
            "y": 19,
            "z": 14,
            "elements": [
                "appliedenergistics2:smooth_sky_stone_block@0"
            ]
        },
        {
            "x": 1,
            "y": 49,
            "z": 12,
            "elements": [
                "minecraft:concrete@7"
            ]
        },
        {
            "x": 1,
            "y": 49,
            "z": 10,
            "elements": [
                "minecraft:concrete@7"
            ]
        },
        {
            "x": 1,
            "y": 49,
            "z": 9,
            "elements": [
                "minecraft:quartz_stairs@6"
            ]
        },
        {
            "x": -4,
            "y": 17,
            "z": 2,
            "elements": [
                "minecraft:concrete@0"
            ]
        },
        {
            "x": -4,
            "y": 17,
            "z": 3,
            "elements": [
                "minecraft:concrete@0"
            ]
        },
        {
            "x": -4,
            "y": 17,
            "z": 4,
            "elements": [
                "embers:wall_ashen_stone@0"
            ]
        },
        {
            "x": -4,
            "y": 17,
            "z": 7,
            "elements": [
                "minecraft:concrete@0"
            ]
        },
        {
            "x": -5,
            "y": 39,
            "z": 3,
            "elements": [
                "appliedenergistics2:smooth_sky_stone_block@0"
            ]
        },
        {
            "x": -4,
            "y": 17,
            "z": 8,
            "elements": [
                "minecraft:concrete@0"
            ]
        },
        {
            "x": -5,
            "y": 39,
            "z": 2,
            "elements": [
                "appliedenergistics2:smooth_sky_stone_block@0"
            ]
        },
        {
            "x": -4,
            "y": 17,
            "z": 9,
            "elements": [
                "minecraft:concrete@0"
            ]
        },
        {
            "x": -4,
            "y": 17,
            "z": 10,
            "elements": [
                "minecraft:concrete@0"
            ]
        },
        {
            "x": -4,
            "y": 17,
            "z": 11,
            "elements": [
                "minecraft:concrete@0"
            ]
        },
        {
            "x": -4,
            "y": 17,
            "z": 12,
            "elements": [
                "minecraft:concrete@0"
            ]
        },
        {
            "x": -4,
            "y": 17,
            "z": 13,
            "elements": [
                "embers:wall_ashen_stone@0"
            ]
        },
        {
            "x": 4,
            "y": 50,
            "z": 5,
            "elements": [
                "minecraft:concrete@0"
            ]
        },
        {
            "x": 4,
            "y": 50,
            "z": 6,
            "elements": [
                "minecraft:stained_glass_pane@14"
            ]
        },
        {
            "x": 4,
            "y": 50,
            "z": 7,
            "elements": [
                "minecraft:stained_glass_pane@14"
            ]
        },
        {
            "x": 4,
            "y": 50,
            "z": 8,
            "elements": [
                "minecraft:stained_glass_pane@14"
            ]
        },
        {
            "x": 4,
            "y": 50,
            "z": 1,
            "elements": [
                "minecraft:concrete@0"
            ]
        },
        {
            "x": 4,
            "y": 50,
            "z": 2,
            "elements": [
                "minecraft:concrete@0"
            ]
        },
        {
            "x": 4,
            "y": 50,
            "z": 3,
            "elements": [
                "minecraft:concrete@0"
            ]
        },
        {
            "x": 4,
            "y": 50,
            "z": 4,
            "elements": [
                "minecraft:concrete@0"
            ]
        },
        {
            "x": 4,
            "y": 50,
            "z": 13,
            "elements": [
                "minecraft:stained_glass_pane@14"
            ]
        },
        {
            "x": 4,
            "y": 50,
            "z": 14,
            "elements": [
                "minecraft:stained_glass_pane@14"
            ]
        },
        {
            "x": 4,
            "y": 50,
            "z": 9,
            "elements": [
                "minecraft:stained_glass_pane@14"
            ]
        },
        {
            "x": 4,
            "y": 50,
            "z": 10,
            "elements": [
                "minecraft:stained_glass_pane@14"
            ]
        },
        {
            "x": 4,
            "y": 50,
            "z": 11,
            "elements": [
                "minecraft:stained_glass_pane@14"
            ]
        },
        {
            "x": 4,
            "y": 50,
            "z": 12,
            "elements": [
                "minecraft:stained_glass_pane@14"
            ]
        },
        {
            "x": 4,
            "y": 0,
            "z": 7,
            "elements": [
                "minecraft:concrete@0"
            ]
        },
        {
            "x": 4,
            "y": 0,
            "z": 8,
            "elements": [
                "minecraft:concrete@0"
            ]
        },
        {
            "x": 4,
            "y": 0,
            "z": 9,
            "elements": [
                "minecraft:concrete@0"
            ]
        },
        {
            "x": 4,
            "y": 0,
            "z": 10,
            "elements": [
                "minecraft:quartz_stairs@1"
            ]
        },
        {
            "x": 4,
            "y": 50,
            "z": -2,
            "elements": [
                "minecraft:concrete@0"
            ]
        },
        {
            "x": 4,
            "y": 50,
            "z": -1,
            "elements": [
                "minecraft:concrete@0"
            ]
        },
        {
            "x": 4,
            "y": 50,
            "z": 0,
            "elements": [
                "minecraft:concrete@0"
            ]
        },
        {
            "x": 4,
            "y": 0,
            "z": 11,
            "elements": [
                "minecraft:concrete@4"
            ]
        },
        {
            "x": 4,
            "y": 0,
            "z": 12,
            "elements": [
                "minecraft:quartz_stairs@1"
            ]
        },
        {
            "x": 4,
            "y": 0,
            "z": 13,
            "elements": [
                "minecraft:concrete@0"
            ]
        },
        {
            "x": 3,
            "y": 26,
            "z": 3,
            "elements": [
                "embers:wall_ashen_stone@0"
            ]
        },
        {
            "x": 3,
            "y": 26,
            "z": 0,
            "elements": [
                "minecraft:concrete@0"
            ]
        },
        {
            "x": 3,
            "y": 26,
            "z": -1,
            "elements": [
                "appliedenergistics2:smooth_sky_stone_block@0"
            ]
        },
        {
            "x": 5,
            "y": 28,
            "z": 2,
            "elements": [
                "appliedenergistics2:smooth_sky_stone_block@0"
            ]
        },
        {
            "x": 2,
            "y": 52,
            "z": -1,
            "elements": [
                "embers:wall_ashen_stone@0"
            ]
        },
        {
            "x": 2,
            "y": 52,
            "z": 0,
            "elements": [
                "embers:wall_ashen_stone@0"
            ]
        },
        {
            "x": -5,
            "y": 43,
            "z": 3,
            "elements": [
                "appliedenergistics2:smooth_sky_stone_block@0"
            ]
        },
        {
            "x": -3,
            "y": 16,
            "z": 0,
            "elements": [
                "minecraft:concrete@0"
            ]
        },
        {
            "x": -2,
            "y": 15,
            "z": 16,
            "elements": [
                "appliedenergistics2:smooth_sky_stone_block@0"
            ]
        },
        {
            "x": 3,
            "y": 51,
            "z": 5,
            "elements": [
                "minecraft:concrete@0"
            ]
        },
        {
            "x": -3,
            "y": 41,
            "z": 5,
            "elements": [
                "minecraft:concrete@0"
            ]
        },
        {
            "x": -3,
            "y": 41,
            "z": 6,
            "elements": [
                "astraladditions:block_marble_runed_wall@0"
            ]
        },
        {
            "x": 3,
            "y": 51,
            "z": 6,
            "elements": [
                "astraladditions:block_marble_runed_wall@0"
            ]
        },
        {
            "x": 3,
            "y": 51,
            "z": 1,
            "elements": [
                "minecraft:concrete@0"
            ]
        },
        {
            "x": -3,
            "y": 41,
            "z": 1,
            "elements": [
                "minecraft:concrete@0"
            ]
        },
        {
            "x": -3,
            "y": 41,
            "z": 15,
            "elements": [
                "minecraft:stained_glass_pane@14"
            ]
        },
        {
            "x": 3,
            "y": 51,
            "z": 15,
            "elements": [
                "minecraft:stained_glass_pane@14"
            ]
        },
        {
            "x": 3,
            "y": 51,
            "z": 14,
            "elements": [
                "minecraft:stained_glass_pane@14"
            ]
        },
        {
            "x": -3,
            "y": 41,
            "z": 14,
            "elements": [
                "minecraft:stained_glass_pane@14"
            ]
        },
        {
            "x": -3,
            "y": 16,
            "z": 2,
            "elements": [
                "appliedenergistics2:smooth_sky_stone_stairs@1"
            ]
        },
        {
            "x": -3,
            "y": 16,
            "z": 3,
            "elements": [
                "minecraft:quartz_stairs@1"
            ]
        },
        {
            "x": 2,
            "y": 52,
            "z": 9,
            "elements": [
                "minecraft:quartz_stairs@6"
            ]
        },
        {
            "x": 2,
            "y": 52,
            "z": 10,
            "elements": [
                "minecraft:quartz_stairs@5"
            ]
        },
        {
            "x": 2,
            "y": 52,
            "z": 11,
            "elements": [
                "minecraft:stained_glass@0"
            ]
        },
        {
            "x": 2,
            "y": 52,
            "z": 12,
            "elements": [
                "minecraft:quartz_stairs@5"
            ]
        },
        {
            "x": 2,
            "y": 52,
            "z": 13,
            "elements": [
                "minecraft:quartz_stairs@5"
            ]
        },
        {
            "x": 2,
            "y": 52,
            "z": 15,
            "elements": [
                "minecraft:stained_glass_pane@14"
            ]
        },
        {
            "x": 2,
            "y": 52,
            "z": 16,
            "elements": [
                "minecraft:stained_glass_pane@14"
            ]
        },
        {
            "x": -3,
            "y": 41,
            "z": -1,
            "elements": [
                "minecraft:stained_glass_pane@14"
            ]
        },
        {
            "x": 2,
            "y": 52,
            "z": 2,
            "elements": [
                "minecraft:concrete@0"
            ]
        },
        {
            "x": 2,
            "y": 52,
            "z": 3,
            "elements": [
                "minecraft:concrete@0"
            ]
        },
        {
            "x": 2,
            "y": 52,
            "z": 5,
            "elements": [
                "minecraft:concrete@0"
            ]
        },
        {
            "x": -4,
            "y": 17,
            "z": 1,
            "elements": [
                "minecraft:concrete@0"
            ]
        },
        {
            "x": 0,
            "y": 50,
            "z": 13,
            "elements": [
                "minecraft:stained_glass@0"
            ]
        },
        {
            "x": 0,
            "y": 17,
            "z": -2,
            "elements": [
                "minecraft:stained_glass@14"
            ]
        },
        {
            "x": 0,
            "y": 50,
            "z": 16,
            "elements": [
                "minecraft:stained_glass_pane@14"
            ]
        },
        {
            "x": 0,
            "y": 50,
            "z": 9,
            "elements": [
                "minecraft:stained_glass@0"
            ]
        },
        {
            "x": 0,
            "y": 50,
            "z": 11,
            "elements": [
                "environmentaltech:laser_core@0"
            ]
        },
        {
            "x": 0,
            "y": 17,
            "z": 11,
            "elements": [
                "environmentaltech:laser_core@0"
            ]
        },
        {
            "x": 0,
            "y": 50,
            "z": 5,
            "elements": [
                "minecraft:concrete@0"
            ]
        },
        {
            "x": 1,
            "y": 45,
            "z": 5,
            "elements": [
                "minecraft:concrete@0"
            ]
        },
        {
            "x": 1,
            "y": 45,
            "z": -3,
            "elements": [
                "minecraft:iron_trapdoor@3"
            ]
        },
        {
            "x": 1,
            "y": 45,
            "z": -4,
            "elements": [
                "minecraft:quartz_stairs@6"
            ]
        },
        {
            "x": -2,
            "y": 15,
            "z": -1,
            "elements": [
                "minecraft:concrete@0"
            ]
        },
        {
            "x": 3,
            "y": 1,
            "z": 8,
            "elements": [
                "minecraft:concrete@0"
            ]
        },
        {
            "x": 3,
            "y": 1,
            "z": 14,
            "elements": [
                "minecraft:concrete@0"
            ]
        },
        {
            "x": -4,
            "y": 46,
            "z": 4,
            "elements": [
                "minecraft:quartz_stairs@7"
            ]
        },
        {
            "x": -4,
            "y": 46,
            "z": 3,
            "elements": [
                "minecraft:concrete@0"
            ]
        },
        {
            "x": -4,
            "y": 46,
            "z": 2,
            "elements": [
                "minecraft:concrete@0"
            ]
        },
        {
            "x": -4,
            "y": 46,
            "z": 1,
            "elements": [
                "minecraft:concrete@0"
            ]
        },
        {
            "x": -4,
            "y": 46,
            "z": 0,
            "elements": [
                "minecraft:concrete@0"
            ]
        },
        {
            "x": -4,
            "y": 46,
            "z": -1,
            "elements": [
                "minecraft:concrete@0"
            ]
        },
        {
            "x": -4,
            "y": 46,
            "z": -2,
            "elements": [
                "minecraft:concrete@0"
            ]
        },
        {
            "x": -4,
            "y": 46,
            "z": 12,
            "elements": [
                "minecraft:stained_glass_pane@14"
            ]
        },
        {
            "x": -2,
            "y": -6,
            "z": -6,
            "elements": [
                "minecraft:concrete@0"
            ]
        },
        {
            "x": -4,
            "y": 46,
            "z": 11,
            "elements": [
                "minecraft:stained_glass_pane@14"
            ]
        },
        {
            "x": 5,
            "y": 24,
            "z": 5,
            "elements": [
                "appliedenergistics2:smooth_sky_stone_stairs@6"
            ]
        },
        {
            "x": -4,
            "y": 46,
            "z": 10,
            "elements": [
                "minecraft:stained_glass_pane@14"
            ]
        },
        {
            "x": -4,
            "y": 46,
            "z": 9,
            "elements": [
                "minecraft:stained_glass_pane@14"
            ]
        },
        {
            "x": -4,
            "y": 46,
            "z": 8,
            "elements": [
                "minecraft:stained_glass_pane@14"
            ]
        },
        {
            "x": -3,
            "y": 12,
            "z": 24,
            "elements": [
                "minecraft:iron_bars@0"
            ]
        },
        {
            "x": -3,
            "y": 12,
            "z": 25,
            "elements": [
                "minecraft:iron_bars@0"
            ]
        },
        {
            "x": -4,
            "y": 46,
            "z": 7,
            "elements": [
                "minecraft:stained_glass_pane@14"
            ]
        },
        {
            "x": 5,
            "y": 24,
            "z": 6,
            "elements": [
                "appliedenergistics2:smooth_sky_stone_stairs@7"
            ]
        },
        {
            "x": -4,
            "y": 46,
            "z": 6,
            "elements": [
                "minecraft:stained_glass_pane@14"
            ]
        },
        {
            "x": -2,
            "y": -6,
            "z": -4,
            "elements": [
                "minecraft:concrete@0"
            ]
        },
        {
            "x": -3,
            "y": 12,
            "z": 23,
            "elements": [
                "minecraft:iron_bars@0"
            ]
        },
        {
            "x": -2,
            "y": -6,
            "z": -5,
            "elements": [
                "minecraft:concrete@0"
            ]
        },
        {
            "x": -4,
            "y": 46,
            "z": 5,
            "elements": [
                "minecraft:quartz_stairs@4"
            ]
        },
        {
            "x": 5,
            "y": 24,
            "z": 1,
            "elements": [
                "appliedenergistics2:smooth_sky_stone_block@0"
            ]
        },
        {
            "x": -2,
            "y": -6,
            "z": 5,
            "elements": [
                "minecraft:quartz_stairs@0"
            ]
        },
        {
            "x": -2,
            "y": -6,
            "z": 4,
            "elements": [
                "minecraft:quartz_stairs@2"
            ]
        },
        {
            "x": -2,
            "y": -6,
            "z": 15,
            "elements": [
                "minecraft:concrete@0"
            ]
        },
        {
            "x": 3,
            "y": 55,
            "z": 15,
            "elements": [
                "minecraft:concrete@0"
            ]
        },
        {
            "x": 3,
            "y": 55,
            "z": 16,
            "elements": [
                "appliedenergistics2:smooth_sky_stone_slab@8"
            ]
        },
        {
            "x": 0,
            "y": 25,
            "z": 3,
            "elements": [
                "minecraft:stone_slab@15"
            ]
        },
        {
            "x": 0,
            "y": 25,
            "z": 2,
            "elements": [
                "minecraft:concrete@0"
            ]
        },
        {
            "x": 0,
            "y": 25,
            "z": -1,
            "elements": [
                "minecraft:concrete@0"
            ]
        },
        {
            "x": 0,
            "y": 42,
            "z": 16,
            "elements": [
                "minecraft:stained_glass_pane@14"
            ]
        },
        {
            "x": 0,
            "y": 25,
            "z": -2,
            "elements": [
                "minecraft:concrete@0"
            ]
        },
        {
            "x": 0,
            "y": 25,
            "z": 1,
            "elements": [
                "minecraft:concrete@0"
            ]
        },
        {
            "x": 0,
            "y": 25,
            "z": 0,
            "elements": [
                "minecraft:concrete@0"
            ]
        },
        {
            "x": 0,
            "y": 42,
            "z": 13,
            "elements": [
                "minecraft:stained_glass@0"
            ]
        },
        {
            "x": 0,
            "y": 25,
            "z": 11,
            "elements": [
                "environmentaltech:laser_core@0"
            ]
        },
        {
            "x": 0,
            "y": 50,
            "z": -2,
            "elements": [
                "minecraft:concrete@0"
            ]
        },
        {
            "x": 0,
            "y": 50,
            "z": -3,
            "elements": [
                "minecraft:concrete@0"
            ]
        },
        {
            "x": 0,
            "y": 50,
            "z": -1,
            "elements": [
                "minecraft:concrete@0"
            ]
        },
        {
            "x": 0,
            "y": 50,
            "z": -4,
            "elements": [
                "minecraft:concrete@0"
            ]
        },
        {
            "x": 3,
            "y": 55,
            "z": 5,
            "elements": [
                "minecraft:concrete@0"
            ]
        },
        {
            "x": -6,
            "y": 11,
            "z": 15,
            "elements": [
                "minecraft:concrete@0"
            ]
        },
        {
            "x": 2,
            "y": -2,
            "z": 0,
            "elements": [
                "minecraft:concrete@0"
            ]
        },
        {
            "x": 1,
            "y": 20,
            "z": -2,
            "elements": [
                "minecraft:concrete@0"
            ]
        },
        {
            "x": -6,
            "y": 11,
            "z": 14,
            "elements": [
                "minecraft:concrete@0"
            ]
        },
        {
            "x": 2,
            "y": -2,
            "z": -1,
            "elements": [
                "minecraft:concrete@0"
            ]
        },
        {
            "x": 2,
            "y": -2,
            "z": 2,
            "elements": [
                "minecraft:concrete@0"
            ]
        },
        {
            "x": -6,
            "y": 11,
            "z": 17,
            "elements": [
                "minecraft:stone_slab@15"
            ]
        },
        {
            "x": 2,
            "y": -2,
            "z": 1,
            "elements": [
                "minecraft:concrete@0"
            ]
        },
        {
            "x": -6,
            "y": 11,
            "z": 16,
            "elements": [
                "minecraft:quartz_stairs@7"
            ]
        },
        {
            "x": 2,
            "y": -2,
            "z": 4,
            "elements": [
                "appliedenergistics2:smooth_sky_stone_block@0"
            ]
        },
        {
            "x": -6,
            "y": 11,
            "z": 11,
            "elements": [
                "minecraft:concrete@0"
            ]
        },
        {
            "x": -6,
            "y": 11,
            "z": 10,
            "elements": [
                "minecraft:quartz_stairs@6"
            ]
        },
        {
            "x": 2,
            "y": -2,
            "z": 3,
            "elements": [
                "minecraft:concrete@0"
            ]
        },
        {
            "x": -6,
            "y": 11,
            "z": 13,
            "elements": [
                "minecraft:concrete@0"
            ]
        },
        {
            "x": 2,
            "y": -2,
            "z": 6,
            "elements": [
                "mekanism:glowplasticblock@7"
            ]
        },
        {
            "x": -6,
            "y": 11,
            "z": 12,
            "elements": [
                "minecraft:concrete@0"
            ]
        },
        {
            "x": 2,
            "y": -2,
            "z": 5,
            "elements": [
                "appliedenergistics2:smooth_sky_stone_block@0"
            ]
        },
        {
            "x": 1,
            "y": 20,
            "z": 2,
            "elements": [
                "appliedenergistics2:smooth_sky_stone_stairs@5"
            ]
        },
        {
            "x": 2,
            "y": -2,
            "z": -2,
            "elements": [
                "minecraft:concrete@0"
            ]
        },
        {
            "x": -1,
            "y": 47,
            "z": 9,
            "elements": [
                "minecraft:quartz_stairs@6"
            ]
        },
        {
            "x": -1,
            "y": 47,
            "z": 10,
            "elements": [
                "minecraft:concrete@7"
            ]
        },
        {
            "x": 2,
            "y": 48,
            "z": -3,
            "elements": [
                "minecraft:stained_glass_pane@0"
            ]
        },
        {
            "x": -1,
            "y": 47,
            "z": 11,
            "elements": [
                "minecraft:stained_glass@14"
            ]
        },
        {
            "x": -1,
            "y": 47,
            "z": 12,
            "elements": [
                "minecraft:concrete@7"
            ]
        },
        {
            "x": -1,
            "y": 47,
            "z": 13,
            "elements": [
                "minecraft:quartz_stairs@7"
            ]
        },
        {
            "x": -1,
            "y": 47,
            "z": 16,
            "elements": [
                "minecraft:stained_glass_pane@14"
            ]
        },
        {
            "x": 2,
            "y": 48,
            "z": -4,
            "elements": [
                "minecraft:stained_glass_pane@0"
            ]
        },
        {
            "x": 2,
            "y": -2,
            "z": 15,
            "elements": [
                "minecraft:concrete@0"
            ]
        },
        {
            "x": -4,
            "y": 46,
            "z": 14,
            "elements": [
                "minecraft:stained_glass_pane@14"
            ]
        },
        {
            "x": -4,
            "y": 46,
            "z": 13,
            "elements": [
                "minecraft:stained_glass_pane@14"
            ]
        },
        {
            "x": 2,
            "y": -2,
            "z": 8,
            "elements": [
                "appliedenergistics2:smooth_sky_stone_block@0"
            ]
        },
        {
            "x": 2,
            "y": -2,
            "z": 7,
            "elements": [
                "mekanism:glowplasticblock@7"
            ]
        },
        {
            "x": -3,
            "y": 49,
            "z": -3,
            "elements": [
                "minecraft:concrete@0"
            ]
        },
        {
            "x": -3,
            "y": 49,
            "z": -4,
            "elements": [
                "appliedenergistics2:smooth_sky_stone_block@0"
            ]
        },
        {
            "x": -3,
            "y": 49,
            "z": 5,
            "elements": [
                "minecraft:concrete@0"
            ]
        },
        {
            "x": 4,
            "y": 21,
            "z": 11,
            "elements": [
                "embers:wall_ashen_stone@0"
            ]
        },
        {
            "x": -3,
            "y": 49,
            "z": 6,
            "elements": [
                "astraladditions:block_marble_runed_wall@0"
            ]
        },
        {
            "x": 4,
            "y": 21,
            "z": 10,
            "elements": [
                "minecraft:concrete@0"
            ]
        },
        {
            "x": 4,
            "y": 21,
            "z": 7,
            "elements": [
                "minecraft:concrete@0"
            ]
        },
        {
            "x": 4,
            "y": 21,
            "z": 6,
            "elements": [
                "minecraft:concrete@0"
            ]
        },
        {
            "x": 4,
            "y": 21,
            "z": 9,
            "elements": [
                "minecraft:concrete@0"
            ]
        },
        {
            "x": 4,
            "y": 21,
            "z": 8,
            "elements": [
                "minecraft:concrete@0"
            ]
        },
        {
            "x": 4,
            "y": -4,
            "z": 12,
            "elements": [
                "minecraft:concrete@0"
            ]
        },
        {
            "x": 4,
            "y": 21,
            "z": 3,
            "elements": [
                "embers:wall_ashen_stone@0"
            ]
        },
        {
            "x": 4,
            "y": -4,
            "z": 11,
            "elements": [
                "minecraft:concrete@0"
            ]
        },
        {
            "x": 4,
            "y": 21,
            "z": 2,
            "elements": [
                "minecraft:concrete@0"
            ]
        },
        {
            "x": -1,
            "y": -3,
            "z": -3,
            "elements": [
                "minecraft:quartz_stairs@2"
            ]
        },
        {
            "x": 4,
            "y": 21,
            "z": 5,
            "elements": [
                "minecraft:concrete@0"
            ]
        },
        {
            "x": 4,
            "y": -4,
            "z": 13,
            "elements": [
                "minecraft:concrete@0"
            ]
        },
        {
            "x": -1,
            "y": -3,
            "z": -1,
            "elements": [
                "minecraft:concrete@0"
            ]
        },
        {
            "x": 4,
            "y": -4,
            "z": 8,
            "elements": [
                "minecraft:concrete@0"
            ]
        },
        {
            "x": 4,
            "y": -4,
            "z": 7,
            "elements": [
                "minecraft:end_rod@0"
            ]
        },
        {
            "x": 4,
            "y": 21,
            "z": 1,
            "elements": [
                "minecraft:concrete@0"
            ]
        },
        {
            "x": 4,
            "y": -4,
            "z": 10,
            "elements": [
                "minecraft:concrete@0"
            ]
        },
        {
            "x": 4,
            "y": -4,
            "z": 9,
            "elements": [
                "minecraft:concrete@0"
            ]
        },
        {
            "x": -1,
            "y": -3,
            "z": 4,
            "elements": [
                "minecraft:stained_glass_pane@0"
            ]
        },
        {
            "x": -1,
            "y": -3,
            "z": 10,
            "elements": [
                "minecraft:concrete@4"
            ]
        },
        {
            "x": -4,
            "y": 9,
            "z": 11,
            "elements": [
                "minecraft:concrete@0"
            ]
        },
        {
            "x": -1,
            "y": -3,
            "z": 11,
            "elements": [
                "minecraft:concrete@4"
            ]
        },
        {
            "x": 4,
            "y": 58,
            "z": 12,
            "elements": [
                "minecraft:concrete@0"
            ]
        },
        {
            "x": -1,
            "y": 22,
            "z": 2,
            "elements": [
                "embers:wall_ashen_stone@0"
            ]
        },
        {
            "x": 4,
            "y": 58,
            "z": 11,
            "elements": [
                "minecraft:concrete@0"
            ]
        },
        {
            "x": -4,
            "y": 9,
            "z": 10,
            "elements": [
                "minecraft:concrete@0"
            ]
        },
        {
            "x": -1,
            "y": -3,
            "z": 12,
            "elements": [
                "minecraft:concrete@4"
            ]
        },
        {
            "x": 4,
            "y": 58,
            "z": 10,
            "elements": [
                "minecraft:concrete@0"
            ]
        },
        {
            "x": -4,
            "y": 9,
            "z": 13,
            "elements": [
                "minecraft:concrete@0"
            ]
        },
        {
            "x": -4,
            "y": 9,
            "z": 12,
            "elements": [
                "minecraft:concrete@0"
            ]
        },
        {
            "x": 4,
            "y": 58,
            "z": 9,
            "elements": [
                "minecraft:concrete@0"
            ]
        },
        {
            "x": -1,
            "y": 47,
            "z": -4,
            "elements": [
                "minecraft:stained_glass_pane@0"
            ]
        },
        {
            "x": -1,
            "y": -3,
            "z": 15,
            "elements": [
                "minecraft:concrete@0"
            ]
        },
        {
            "x": -4,
            "y": 9,
            "z": 15,
            "elements": [
                "appliedenergistics2:smooth_sky_stone_block@0"
            ]
        },
        {
            "x": -1,
            "y": -3,
            "z": 16,
            "elements": [
                "minecraft:quartz_stairs@3"
            ]
        },
        {
            "x": -4,
            "y": 9,
            "z": 14,
            "elements": [
                "minecraft:concrete@0"
            ]
        },
        {
            "x": 4,
            "y": 58,
            "z": 14,
            "elements": [
                "minecraft:concrete@0"
            ]
        },
        {
            "x": -4,
            "y": 9,
            "z": 16,
            "elements": [
                "minecraft:concrete@0"
            ]
        },
        {
            "x": 4,
            "y": 58,
            "z": 13,
            "elements": [
                "minecraft:concrete@0"
            ]
        },
        {
            "x": 1,
            "y": 45,
            "z": 16,
            "elements": [
                "minecraft:stained_glass_pane@14"
            ]
        },
        {
            "x": -1,
            "y": 47,
            "z": 5,
            "elements": [
                "minecraft:concrete@0"
            ]
        },
        {
            "x": -1,
            "y": 22,
            "z": -2,
            "elements": [
                "minecraft:concrete@0"
            ]
        },
        {
            "x": 1,
            "y": 45,
            "z": 10,
            "elements": [
                "embers:wall_ashen_stone@0"
            ]
        },
        {
            "x": 1,
            "y": 45,
            "z": 12,
            "elements": [
                "embers:wall_ashen_stone@0"
            ]
        },
        {
            "x": -6,
            "y": 11,
            "z": 9,
            "elements": [
                "minecraft:stone_slab@15"
            ]
        },
        {
            "x": 4,
            "y": 58,
            "z": 8,
            "elements": [
                "minecraft:concrete@0"
            ]
        },
        {
            "x": -2,
            "y": 11,
            "z": 18,
            "elements": [
                "minecraft:concrete@0"
            ]
        },
        {
            "x": -2,
            "y": -2,
            "z": -2,
            "elements": [
                "minecraft:concrete@0"
            ]
        },
        {
            "x": 2,
            "y": 56,
            "z": 6,
            "elements": [
                "minecraft:concrete@0"
            ]
        },
        {
            "x": -2,
            "y": 11,
            "z": 19,
            "elements": [
                "minecraft:concrete@0"
            ]
        },
        {
            "x": -2,
            "y": 11,
            "z": 20,
            "elements": [
                "minecraft:concrete@0"
            ]
        },
        {
            "x": -2,
            "y": 11,
            "z": 21,
            "elements": [
                "minecraft:concrete@0"
            ]
        },
        {
            "x": -2,
            "y": -2,
            "z": 1,
            "elements": [
                "minecraft:concrete@0"
            ]
        },
        {
            "x": -1,
            "y": 39,
            "z": 5,
            "elements": [
                "minecraft:concrete@0"
            ]
        },
        {
            "x": -2,
            "y": -2,
            "z": 2,
            "elements": [
                "minecraft:concrete@0"
            ]
        },
        {
            "x": 2,
            "y": 56,
            "z": 11,
            "elements": [
                "minecraft:stained_glass@0"
            ]
        },
        {
            "x": -2,
            "y": -2,
            "z": -1,
            "elements": [
                "minecraft:concrete@0"
            ]
        },
        {
            "x": -2,
            "y": 11,
            "z": 17,
            "elements": [
                "minecraft:concrete@0"
            ]
        },
        {
            "x": -2,
            "y": -2,
            "z": 0,
            "elements": [
                "minecraft:concrete@0"
            ]
        },
        {
            "x": -1,
            "y": 39,
            "z": 10,
            "elements": [
                "minecraft:concrete@7"
            ]
        },
        {
            "x": -2,
            "y": -2,
            "z": 5,
            "elements": [
                "appliedenergistics2:smooth_sky_stone_block@0"
            ]
        },
        {
            "x": -1,
            "y": 39,
            "z": 9,
            "elements": [
                "minecraft:quartz_stairs@6"
            ]
        },
        {
            "x": -2,
            "y": -2,
            "z": 6,
            "elements": [
                "mekanism:glowplasticblock@7"
            ]
        },
        {
            "x": -1,
            "y": 39,
            "z": 12,
            "elements": [
                "minecraft:concrete@7"
            ]
        },
        {
            "x": -2,
            "y": -2,
            "z": 3,
            "elements": [
                "minecraft:concrete@0"
            ]
        },
        {
            "x": -2,
            "y": -2,
            "z": 4,
            "elements": [
                "appliedenergistics2:smooth_sky_stone_block@0"
            ]
        },
        {
            "x": -1,
            "y": 39,
            "z": 13,
            "elements": [
                "minecraft:quartz_stairs@7"
            ]
        },
        {
            "x": -1,
            "y": 39,
            "z": 16,
            "elements": [
                "minecraft:stained_glass_pane@14"
            ]
        },
        {
            "x": -2,
            "y": -2,
            "z": 7,
            "elements": [
                "mekanism:glowplasticblock@7"
            ]
        },
        {
            "x": -2,
            "y": -2,
            "z": 8,
            "elements": [
                "appliedenergistics2:smooth_sky_stone_block@0"
            ]
        },
        {
            "x": 0,
            "y": 0,
            "z": 15,
            "elements": [
                "minecraft:concrete@4"
            ]
        },
        {
            "x": -2,
            "y": 11,
            "z": 26,
            "elements": [
                "minecraft:quartz_stairs@7"
            ]
        },
        {
            "x": 0,
            "y": 0,
            "z": 11,
            "elements": [
                "environmentaltech:laser_core@0"
            ]
        },
        {
            "x": -2,
            "y": 11,
            "z": 27,
            "elements": [
                "minecraft:stone_slab@15"
            ]
        },
        {
            "x": 2,
            "y": 56,
            "z": 15,
            "elements": [
                "minecraft:stained_glass_pane@1"
            ]
        },
        {
            "x": 2,
            "y": 56,
            "z": 16,
            "elements": [
                "minecraft:stained_glass_pane@1"
            ]
        },
        {
            "x": -2,
            "y": 11,
            "z": 22,
            "elements": [
                "minecraft:concrete@0"
            ]
        },
        {
            "x": -1,
            "y": 39,
            "z": -2,
            "elements": [
                "minecraft:quartz_stairs@2"
            ]
        },
        {
            "x": -2,
            "y": 11,
            "z": 23,
            "elements": [
                "minecraft:concrete@0"
            ]
        },
        {
            "x": -4,
            "y": 9,
            "z": 9,
            "elements": [
                "minecraft:concrete@0"
            ]
        },
        {
            "x": -2,
            "y": 11,
            "z": 24,
            "elements": [
                "minecraft:concrete@0"
            ]
        },
        {
            "x": -1,
            "y": 39,
            "z": 0,
            "elements": [
                "minecraft:concrete@0"
            ]
        },
        {
            "x": -2,
            "y": 11,
            "z": 25,
            "elements": [
                "minecraft:concrete@0"
            ]
        },
        {
            "x": -1,
            "y": 39,
            "z": -1,
            "elements": [
                "minecraft:concrete@0"
            ]
        },
        {
            "x": 1,
            "y": 41,
            "z": 16,
            "elements": [
                "minecraft:stained_glass_pane@14"
            ]
        },
        {
            "x": 1,
            "y": 41,
            "z": 10,
            "elements": [
                "embers:wall_ashen_stone@0"
            ]
        },
        {
            "x": 1,
            "y": 41,
            "z": 12,
            "elements": [
                "embers:wall_ashen_stone@0"
            ]
        },
        {
            "x": 1,
            "y": 41,
            "z": 5,
            "elements": [
                "minecraft:concrete@0"
            ]
        },
        {
            "x": 0,
            "y": 0,
            "z": 2,
            "elements": [
                "nuclearcraft:heat_exchanger_wall@0"
            ]
        },
        {
            "x": 1,
            "y": 41,
            "z": 1,
            "elements": [
                "appliedenergistics2:smooth_sky_stone_block@0"
            ]
        },
        {
            "x": 1,
            "y": 41,
            "z": 0,
            "elements": [
                "minecraft:end_rod@4"
            ]
        },
        {
            "x": 0,
            "y": 13,
            "z": 3,
            "elements": [
                "minecraft:concrete@4"
            ]
        },
        {
            "x": 0,
            "y": 13,
            "z": 2,
            "elements": [
                "minecraft:stone_slab@7"
            ]
        },
        {
            "x": 4,
            "y": 46,
            "z": 2,
            "elements": [
                "minecraft:concrete@0"
            ]
        },
        {
            "x": 4,
            "y": 46,
            "z": 1,
            "elements": [
                "minecraft:concrete@0"
            ]
        },
        {
            "x": 4,
            "y": 46,
            "z": 4,
            "elements": [
                "minecraft:quartz_stairs@7"
            ]
        },
        {
            "x": -2,
            "y": 11,
            "z": -3,
            "elements": [
                "minecraft:concrete@0"
            ]
        },
        {
            "x": 4,
            "y": 46,
            "z": 3,
            "elements": [
                "minecraft:concrete@0"
            ]
        },
        {
            "x": 4,
            "y": 46,
            "z": -2,
            "elements": [
                "minecraft:concrete@0"
            ]
        },
        {
            "x": 4,
            "y": 46,
            "z": 0,
            "elements": [
                "minecraft:concrete@0"
            ]
        },
        {
            "x": 0,
            "y": 13,
            "z": 11,
            "elements": [
                "environmentaltech:laser_core@0"
            ]
        },
        {
            "x": 4,
            "y": 46,
            "z": -1,
            "elements": [
                "minecraft:concrete@0"
            ]
        },
        {
            "x": 4,
            "y": 46,
            "z": 10,
            "elements": [
                "minecraft:stained_glass_pane@14"
            ]
        },
        {
            "x": 4,
            "y": 46,
            "z": 9,
            "elements": [
                "minecraft:stained_glass_pane@14"
            ]
        },
        {
            "x": 4,
            "y": 46,
            "z": 12,
            "elements": [
                "minecraft:stained_glass_pane@14"
            ]
        },
        {
            "x": -4,
            "y": 21,
            "z": 11,
            "elements": [
                "embers:wall_ashen_stone@0"
            ]
        },
        {
            "x": 4,
            "y": 46,
            "z": 11,
            "elements": [
                "minecraft:stained_glass_pane@14"
            ]
        },
        {
            "x": -4,
            "y": 21,
            "z": 10,
            "elements": [
                "minecraft:concrete@0"
            ]
        },
        {
            "x": 4,
            "y": 46,
            "z": 6,
            "elements": [
                "minecraft:stained_glass_pane@14"
            ]
        },
        {
            "x": -4,
            "y": 21,
            "z": 9,
            "elements": [
                "minecraft:concrete@0"
            ]
        },
        {
            "x": -4,
            "y": 21,
            "z": 8,
            "elements": [
                "minecraft:concrete@0"
            ]
        },
        {
            "x": 4,
            "y": 46,
            "z": 5,
            "elements": [
                "minecraft:quartz_stairs@5"
            ]
        },
        {
            "x": 4,
            "y": 46,
            "z": 8,
            "elements": [
                "minecraft:stained_glass_pane@14"
            ]
        },
        {
            "x": -4,
            "y": 21,
            "z": 7,
            "elements": [
                "minecraft:concrete@0"
            ]
        },
        {
            "x": -4,
            "y": 21,
            "z": 6,
            "elements": [
                "minecraft:concrete@0"
            ]
        },
        {
            "x": 4,
            "y": 46,
            "z": 7,
            "elements": [
                "minecraft:stained_glass_pane@14"
            ]
        },
        {
            "x": -4,
            "y": 21,
            "z": 5,
            "elements": [
                "minecraft:concrete@0"
            ]
        },
        {
            "x": 0,
            "y": 13,
            "z": 0,
            "elements": [
                "minecraft:stone_slab@7"
            ]
        },
        {
            "x": -4,
            "y": 21,
            "z": 3,
            "elements": [
                "embers:wall_ashen_stone@0"
            ]
        },
        {
            "x": 0,
            "y": 13,
            "z": -1,
            "elements": [
                "minecraft:concrete@4"
            ]
        },
        {
            "x": -4,
            "y": 21,
            "z": 2,
            "elements": [
                "minecraft:concrete@0"
            ]
        },
        {
            "x": 0,
            "y": 13,
            "z": -3,
            "elements": [
                "minecraft:stained_glass@14"
            ]
        },
        {
            "x": -4,
            "y": 21,
            "z": 1,
            "elements": [
                "minecraft:concrete@0"
            ]
        },
        {
            "x": 4,
            "y": 46,
            "z": 14,
            "elements": [
                "minecraft:stained_glass_pane@14"
            ]
        },
        {
            "x": 4,
            "y": 46,
            "z": 13,
            "elements": [
                "minecraft:stained_glass_pane@14"
            ]
        },
        {
            "x": 2,
            "y": 31,
            "z": -2,
            "elements": [
                "embers:wall_ashen_stone@0"
            ]
        },
        {
            "x": 2,
            "y": 31,
            "z": -1,
            "elements": [
                "minecraft:concrete@0"
            ]
        },
        {
            "x": 2,
            "y": 31,
            "z": 4,
            "elements": [
                "appliedenergistics2:smooth_sky_stone_stairs@3"
            ]
        },
        {
            "x": -4,
            "y": -4,
            "z": 13,
            "elements": [
                "minecraft:concrete@0"
            ]
        },
        {
            "x": -4,
            "y": -4,
            "z": 12,
            "elements": [
                "minecraft:concrete@0"
            ]
        },
        {
            "x": -1,
            "y": 26,
            "z": 3,
            "elements": [
                "minecraft:quartz_stairs@3"
            ]
        },
        {
            "x": -4,
            "y": -4,
            "z": 11,
            "elements": [
                "minecraft:concrete@0"
            ]
        },
        {
            "x": -4,
            "y": -4,
            "z": 10,
            "elements": [
                "minecraft:concrete@0"
            ]
        },
        {
            "x": -4,
            "y": -4,
            "z": 9,
            "elements": [
                "minecraft:concrete@0"
            ]
        },
        {
            "x": -1,
            "y": 26,
            "z": -1,
            "elements": [
                "minecraft:concrete@0"
            ]
        },
        {
            "x": -4,
            "y": -4,
            "z": 8,
            "elements": [
                "minecraft:concrete@0"
            ]
        },
        {
            "x": -4,
            "y": -4,
            "z": 7,
            "elements": [
                "minecraft:end_rod@0"
            ]
        },
        {
            "x": -1,
            "y": 26,
            "z": -2,
            "elements": [
                "minecraft:quartz_stairs@6"
            ]
        },
        {
            "x": 1,
            "y": 53,
            "z": 12,
            "elements": [
                "minecraft:concrete@7"
            ]
        },
        {
            "x": 1,
            "y": 53,
            "z": 11,
            "elements": [
                "minecraft:stained_glass@14"
            ]
        },
        {
            "x": 1,
            "y": 53,
            "z": 10,
            "elements": [
                "minecraft:concrete@7"
            ]
        },
        {
            "x": -3,
            "y": -5,
            "z": 6,
            "elements": [
                "minecraft:stained_glass_pane@0"
            ]
        },
        {
            "x": 1,
            "y": 53,
            "z": 9,
            "elements": [
                "embers:wall_ashen_stone@0"
            ]
        },
        {
            "x": -3,
            "y": -5,
            "z": 5,
            "elements": [
                "minecraft:stained_glass_pane@0"
            ]
        },
        {
            "x": 1,
            "y": 53,
            "z": 16,
            "elements": [
                "minecraft:concrete@0"
            ]
        },
        {
            "x": -1,
            "y": 14,
            "z": 16,
            "elements": [
                "minecraft:end_rod@5"
            ]
        },
        {
            "x": 1,
            "y": 53,
            "z": 13,
            "elements": [
                "embers:wall_ashen_stone@0"
            ]
        },
        {
            "x": 1,
            "y": 53,
            "z": 4,
            "elements": [
                "minecraft:concrete@0"
            ]
        },
        {
            "x": -3,
            "y": -5,
            "z": 14,
            "elements": [
                "minecraft:concrete@0"
            ]
        },
        {
            "x": -1,
            "y": 14,
            "z": 4,
            "elements": [
                "minecraft:concrete@0"
            ]
        },
        {
            "x": -3,
            "y": -5,
            "z": 8,
            "elements": [
                "minecraft:concrete@0"
            ]
        },
        {
            "x": -3,
            "y": -5,
            "z": 7,
            "elements": [
                "minecraft:concrete@0"
            ]
        },
        {
            "x": 1,
            "y": 53,
            "z": 5,
            "elements": [
                "minecraft:concrete@0"
            ]
        },
        {
            "x": 0,
            "y": 42,
            "z": 12,
            "elements": [
                "minecraft:stained_glass@14"
            ]
        },
        {
            "x": 0,
            "y": 42,
            "z": 11,
            "elements": [
                "environmentaltech:laser_core@0"
            ]
        },
        {
            "x": 0,
            "y": 42,
            "z": 10,
            "elements": [
                "minecraft:stained_glass@14"
            ]
        },
        {
            "x": 0,
            "y": 42,
            "z": 9,
            "elements": [
                "minecraft:stained_glass@0"
            ]
        },
        {
            "x": 1,
            "y": 3,
            "z": 15,
            "elements": [
                "minecraft:concrete@0"
            ]
        },
        {
            "x": 0,
            "y": 42,
            "z": 5,
            "elements": [
                "minecraft:concrete@0"
            ]
        },
        {
            "x": 1,
            "y": 3,
            "z": 3,
            "elements": [
                "minecraft:stained_glass@1"
            ]
        },
        {
            "x": 0,
            "y": 42,
            "z": 1,
            "elements": [
                "appliedenergistics2:smooth_sky_stone_block@0"
            ]
        },
        {
            "x": -1,
            "y": 51,
            "z": 0,
            "elements": [
                "minecraft:concrete@0"
            ]
        },
        {
            "x": -1,
            "y": 51,
            "z": 1,
            "elements": [
                "minecraft:concrete@0"
            ]
        },
        {
            "x": -1,
            "y": 51,
            "z": 5,
            "elements": [
                "minecraft:concrete@0"
            ]
        },
        {
            "x": 0,
            "y": 38,
            "z": 16,
            "elements": [
                "appliedenergistics2:smooth_sky_stone_block@0"
            ]
        },
        {
            "x": 0,
            "y": 38,
            "z": 13,
            "elements": [
                "minecraft:stained_glass@0"
            ]
        },
        {
            "x": 1,
            "y": 16,
            "z": 15,
            "elements": [
                "minecraft:end_rod@4"
            ]
        },
        {
            "x": -1,
            "y": 51,
            "z": 10,
            "elements": [
                "embers:wall_ashen_stone@0"
            ]
        },
        {
            "x": 0,
            "y": 38,
            "z": 11,
            "elements": [
                "environmentaltech:laser_core@0"
            ]
        },
        {
            "x": 1,
            "y": 3,
            "z": -1,
            "elements": [
                "minecraft:stained_glass@1"
            ]
        },
        {
            "x": -1,
            "y": 51,
            "z": 12,
            "elements": [
                "embers:wall_ashen_stone@0"
            ]
        },
        {
            "x": 0,
            "y": 38,
            "z": 9,
            "elements": [
                "minecraft:stained_glass@0"
            ]
        },
        {
            "x": -1,
            "y": 51,
            "z": 16,
            "elements": [
                "minecraft:stained_glass_pane@14"
            ]
        },
        {
            "x": 0,
            "y": 38,
            "z": 5,
            "elements": [
                "minecraft:concrete@0"
            ]
        },
        {
            "x": 0,
            "y": 38,
            "z": -1,
            "elements": [
                "minecraft:concrete@0"
            ]
        },
        {
            "x": -1,
            "y": 14,
            "z": -3,
            "elements": [
                "minecraft:concrete@0"
            ]
        },
        {
            "x": 0,
            "y": 38,
            "z": -2,
            "elements": [
                "minecraft:concrete@0"
            ]
        },
        {
            "x": 1,
            "y": 16,
            "z": -2,
            "elements": [
                "minecraft:concrete@0"
            ]
        },
        {
            "x": -1,
            "y": 14,
            "z": -2,
            "elements": [
                "minecraft:concrete@0"
            ]
        },
        {
            "x": 5,
            "y": 49,
            "z": -1,
            "elements": [
                "appliedenergistics2:smooth_sky_stone_block@0"
            ]
        },
        {
            "x": 5,
            "y": 49,
            "z": 0,
            "elements": [
                "appliedenergistics2:smooth_sky_stone_block@0"
            ]
        },
        {
            "x": 5,
            "y": 49,
            "z": -2,
            "elements": [
                "appliedenergistics2:smooth_sky_stone_block@0"
            ]
        },
        {
            "x": 5,
            "y": 49,
            "z": 3,
            "elements": [
                "appliedenergistics2:smooth_sky_stone_block@0"
            ]
        },
        {
            "x": 5,
            "y": 49,
            "z": 1,
            "elements": [
                "appliedenergistics2:smooth_sky_stone_block@0"
            ]
        },
        {
            "x": 5,
            "y": 49,
            "z": 2,
            "elements": [
                "appliedenergistics2:smooth_sky_stone_block@0"
            ]
        },
        {
            "x": 0,
            "y": 54,
            "z": 13,
            "elements": [
                "minecraft:stained_glass@0"
            ]
        },
        {
            "x": 0,
            "y": 54,
            "z": 16,
            "elements": [
                "minecraft:end_rod@1"
            ]
        },
        {
            "x": 0,
            "y": 54,
            "z": 15,
            "elements": [
                "minecraft:concrete@4"
            ]
        },
        {
            "x": 0,
            "y": 54,
            "z": 9,
            "elements": [
                "minecraft:stained_glass@0"
            ]
        },
        {
            "x": 0,
            "y": 54,
            "z": 11,
            "elements": [
                "environmentaltech:laser_core@0"
            ]
        },
        {
            "x": 0,
            "y": 54,
            "z": 5,
            "elements": [
                "minecraft:concrete@0"
            ]
        },
        {
            "x": 0,
            "y": 29,
            "z": 3,
            "elements": [
                "minecraft:sea_lantern@0"
            ]
        },
        {
            "x": 0,
            "y": 29,
            "z": 4,
            "elements": [
                "minecraft:stained_glass@1"
            ]
        },
        {
            "x": 0,
            "y": 29,
            "z": 11,
            "elements": [
                "environmentaltech:laser_core@0"
            ]
        },
        {
            "x": -5,
            "y": 18,
            "z": 1,
            "elements": [
                "appliedenergistics2:smooth_sky_stone_block@0"
            ]
        },
        {
            "x": 1,
            "y": 28,
            "z": -2,
            "elements": [
                "minecraft:stained_glass_pane@14"
            ]
        },
        {
            "x": 1,
            "y": 28,
            "z": -1,
            "elements": [
                "minecraft:concrete@0"
            ]
        },
        {
            "x": 1,
            "y": 28,
            "z": 3,
            "elements": [
                "minecraft:quartz_stairs@3"
            ]
        },
        {
            "x": 0,
            "y": 29,
            "z": -1,
            "elements": [
                "minecraft:concrete@0"
            ]
        },
        {
            "x": 0,
            "y": 29,
            "z": -2,
            "elements": [
                "minecraft:concrete@0"
            ]
        },
        {
            "x": 3,
            "y": 34,
            "z": 5,
            "elements": [
                "embers:wall_ashen_stone@0"
            ]
        },
        {
            "x": 2,
            "y": 6,
            "z": 15,
            "elements": [
                "minecraft:stained_glass_pane@1"
            ]
        },
        {
            "x": 3,
            "y": 34,
            "z": 0,
            "elements": [
                "minecraft:concrete@0"
            ]
        },
        {
            "x": -3,
            "y": 33,
            "z": 0,
            "elements": [
                "minecraft:concrete@0"
            ]
        },
        {
            "x": 0,
            "y": 4,
            "z": -1,
            "elements": [
                "minecraft:stained_glass_pane@15"
            ]
        },
        {
            "x": -2,
            "y": 48,
            "z": -4,
            "elements": [
                "minecraft:stained_glass_pane@0"
            ]
        },
        {
            "x": 0,
            "y": 4,
            "z": 1,
            "elements": [
                "embers:wall_ashen_stone@0"
            ]
        },
        {
            "x": 3,
            "y": 47,
            "z": 6,
            "elements": [
                "astraladditions:block_marble_runed_wall@0"
            ]
        },
        {
            "x": -2,
            "y": 48,
            "z": -3,
            "elements": [
                "minecraft:stained_glass_pane@0"
            ]
        },
        {
            "x": 3,
            "y": 47,
            "z": 5,
            "elements": [
                "minecraft:concrete@0"
            ]
        },
        {
            "x": 2,
            "y": 6,
            "z": 14,
            "elements": [
                "minecraft:stained_glass_pane@1"
            ]
        },
        {
            "x": 2,
            "y": 6,
            "z": -1,
            "elements": [
                "minecraft:concrete@0"
            ]
        },
        {
            "x": -3,
            "y": 33,
            "z": 5,
            "elements": [
                "embers:wall_ashen_stone@0"
            ]
        },
        {
            "x": 2,
            "y": 6,
            "z": 4,
            "elements": [
                "minecraft:concrete@0"
            ]
        },
        {
            "x": 3,
            "y": 47,
            "z": 15,
            "elements": [
                "minecraft:stained_glass_pane@14"
            ]
        },
        {
            "x": -2,
            "y": 48,
            "z": 5,
            "elements": [
                "minecraft:concrete@0"
            ]
        },
        {
            "x": 3,
            "y": 47,
            "z": 14,
            "elements": [
                "minecraft:stained_glass_pane@14"
            ]
        },
        {
            "x": -2,
            "y": 48,
            "z": 11,
            "elements": [
                "minecraft:stained_glass@0"
            ]
        },
        {
            "x": 2,
            "y": 19,
            "z": 12,
            "elements": [
                "appliedenergistics2:smooth_sky_stone_block@0"
            ]
        },
        {
            "x": 2,
            "y": 19,
            "z": 13,
            "elements": [
                "appliedenergistics2:smooth_sky_stone_block@0"
            ]
        },
        {
            "x": -2,
            "y": 48,
            "z": 12,
            "elements": [
                "embers:wall_ashen_stone@0"
            ]
        },
        {
            "x": 2,
            "y": 19,
            "z": 10,
            "elements": [
                "appliedenergistics2:smooth_sky_stone_slab@8"
            ]
        },
        {
            "x": -2,
            "y": 48,
            "z": 10,
            "elements": [
                "embers:wall_ashen_stone@0"
            ]
        },
        {
            "x": 2,
            "y": 19,
            "z": 11,
            "elements": [
                "appliedenergistics2:smooth_sky_stone_stairs@6"
            ]
        },
        {
            "x": -2,
            "y": 48,
            "z": 15,
            "elements": [
                "minecraft:stained_glass_pane@14"
            ]
        },
        {
            "x": -2,
            "y": 48,
            "z": 16,
            "elements": [
                "minecraft:stained_glass_pane@14"
            ]
        },
        {
            "x": 2,
            "y": 6,
            "z": -3,
            "elements": [
                "embers:wall_ashen_stone@0"
            ]
        },
        {
            "x": 2,
            "y": 19,
            "z": 14,
            "elements": [
                "appliedenergistics2:smooth_sky_stone_block@0"
            ]
        },
        {
            "x": 3,
            "y": 47,
            "z": -2,
            "elements": [
                "minecraft:stained_glass_pane@0"
            ]
        },
        {
            "x": 3,
            "y": 47,
            "z": -3,
            "elements": [
                "minecraft:stained_glass_pane@0"
            ]
        },
        {
            "x": 2,
            "y": 19,
            "z": -2,
            "elements": [
                "appliedenergistics2:smooth_sky_stone_block@0"
            ]
        },
        {
            "x": 2,
            "y": 19,
            "z": -1,
            "elements": [
                "minecraft:concrete@0"
            ]
        },
        {
            "x": 2,
            "y": 19,
            "z": 2,
            "elements": [
                "appliedenergistics2:smooth_sky_stone_stairs@3"
            ]
        },
        {
            "x": 2,
            "y": -6,
            "z": -6,
            "elements": [
                "minecraft:concrete@0"
            ]
        },
        {
            "x": 2,
            "y": -6,
            "z": 4,
            "elements": [
                "minecraft:quartz_stairs@1"
            ]
        },
        {
            "x": 2,
            "y": -6,
            "z": 5,
            "elements": [
                "minecraft:quartz_stairs@2"
            ]
        },
        {
            "x": 2,
            "y": -6,
            "z": -4,
            "elements": [
                "minecraft:concrete@0"
            ]
        },
        {
            "x": 2,
            "y": -6,
            "z": -5,
            "elements": [
                "minecraft:concrete@0"
            ]
        },
        {
            "x": -1,
            "y": 1,
            "z": 15,
            "elements": [
                "minecraft:concrete@0"
            ]
        },
        {
            "x": -3,
            "y": 20,
            "z": 2,
            "elements": [
                "appliedenergistics2:smooth_sky_stone_stairs@1"
            ]
        },
        {
            "x": -3,
            "y": 20,
            "z": 0,
            "elements": [
                "minecraft:concrete@0"
            ]
        },
        {
            "x": 3,
            "y": 9,
            "z": 16,
            "elements": [
                "appliedenergistics2:smooth_sky_stone_block@0"
            ]
        },
        {
            "x": 4,
            "y": 37,
            "z": 1,
            "elements": [
                "minecraft:concrete@0"
            ]
        },
        {
            "x": 3,
            "y": 9,
            "z": 15,
            "elements": [
                "minecraft:concrete@0"
            ]
        },
        {
            "x": -2,
            "y": 36,
            "z": 11,
            "elements": [
                "appliedenergistics2:smooth_sky_stone_slab@8"
            ]
        },
        {
            "x": 4,
            "y": 37,
            "z": 4,
            "elements": [
                "minecraft:quartz_stairs@3"
            ]
        },
        {
            "x": -2,
            "y": 36,
            "z": 5,
            "elements": [
                "minecraft:concrete@0"
            ]
        },
        {
            "x": 4,
            "y": 37,
            "z": 5,
            "elements": [
                "minecraft:quartz_stairs@1"
            ]
        },
        {
            "x": 4,
            "y": 37,
            "z": 2,
            "elements": [
                "minecraft:concrete@0"
            ]
        },
        {
            "x": 4,
            "y": 37,
            "z": 3,
            "elements": [
                "minecraft:concrete@0"
            ]
        },
        {
            "x": -3,
            "y": 8,
            "z": 15,
            "elements": [
                "minecraft:concrete@0"
            ]
        },
        {
            "x": 3,
            "y": 59,
            "z": 8,
            "elements": [
                "minecraft:concrete@0"
            ]
        },
        {
            "x": 3,
            "y": 59,
            "z": 14,
            "elements": [
                "minecraft:concrete@0"
            ]
        },
        {
            "x": 3,
            "y": 59,
            "z": 13,
            "elements": [
                "minecraft:concrete@0"
            ]
        },
        {
            "x": 3,
            "y": 59,
            "z": 15,
            "elements": [
                "minecraft:concrete@0"
            ]
        },
        {
            "x": -3,
            "y": 45,
            "z": -2,
            "elements": [
                "minecraft:quartz_stairs@6"
            ]
        },
        {
            "x": 3,
            "y": 59,
            "z": 10,
            "elements": [
                "minecraft:concrete@0"
            ]
        },
        {
            "x": -1,
            "y": 1,
            "z": 2,
            "elements": [
                "nuclearcraft:heat_exchanger_wall@0"
            ]
        },
        {
            "x": -1,
            "y": 1,
            "z": 1,
            "elements": [
                "nuclearcraft:heat_exchanger_wall@0"
            ]
        },
        {
            "x": -3,
            "y": 45,
            "z": -3,
            "elements": [
                "minecraft:quartz_stairs@4"
            ]
        },
        {
            "x": 3,
            "y": 59,
            "z": 9,
            "elements": [
                "minecraft:concrete@0"
            ]
        },
        {
            "x": 3,
            "y": 59,
            "z": 12,
            "elements": [
                "minecraft:concrete@0"
            ]
        },
        {
            "x": -1,
            "y": 1,
            "z": 0,
            "elements": [
                "nuclearcraft:heat_exchanger_wall@0"
            ]
        },
        {
            "x": 3,
            "y": 9,
            "z": -3,
            "elements": [
                "embers:wall_ashen_stone@0"
            ]
        },
        {
            "x": 3,
            "y": 59,
            "z": 11,
            "elements": [
                "minecraft:concrete@0"
            ]
        },
        {
            "x": 3,
            "y": 9,
            "z": 8,
            "elements": [
                "appliedenergistics2:smooth_sky_stone_block@0"
            ]
        },
        {
            "x": 2,
            "y": 44,
            "z": 11,
            "elements": [
                "minecraft:stained_glass@0"
            ]
        },
        {
            "x": 3,
            "y": 9,
            "z": 7,
            "elements": [
                "appliedenergistics2:smooth_sky_stone_block@0"
            ]
        },
        {
            "x": 2,
            "y": 44,
            "z": 12,
            "elements": [
                "minecraft:quartz_stairs@5"
            ]
        },
        {
            "x": 2,
            "y": 44,
            "z": 9,
            "elements": [
                "minecraft:quartz_stairs@6"
            ]
        },
        {
            "x": 2,
            "y": 44,
            "z": 10,
            "elements": [
                "minecraft:quartz_stairs@5"
            ]
        },
        {
            "x": 3,
            "y": 9,
            "z": 4,
            "elements": [
                "appliedenergistics2:smooth_sky_stone_block@0"
            ]
        },
        {
            "x": -3,
            "y": 45,
            "z": 6,
            "elements": [
                "astraladditions:block_marble_runed_wall@0"
            ]
        },
        {
            "x": 2,
            "y": 44,
            "z": 15,
            "elements": [
                "minecraft:stained_glass_pane@14"
            ]
        },
        {
            "x": -2,
            "y": 36,
            "z": -2,
            "elements": [
                "embers:wall_ashen_stone@0"
            ]
        },
        {
            "x": 2,
            "y": 44,
            "z": 16,
            "elements": [
                "minecraft:stained_glass_pane@14"
            ]
        },
        {
            "x": -3,
            "y": 45,
            "z": 5,
            "elements": [
                "minecraft:concrete@0"
            ]
        },
        {
            "x": 2,
            "y": 44,
            "z": 13,
            "elements": [
                "minecraft:quartz_stairs@5"
            ]
        },
        {
            "x": 3,
            "y": 9,
            "z": 6,
            "elements": [
                "appliedenergistics2:smooth_sky_stone_block@0"
            ]
        },
        {
            "x": -2,
            "y": 36,
            "z": -1,
            "elements": [
                "minecraft:concrete@0"
            ]
        },
        {
            "x": 3,
            "y": 9,
            "z": 5,
            "elements": [
                "appliedenergistics2:smooth_sky_stone_block@0"
            ]
        },
        {
            "x": 3,
            "y": 22,
            "z": 2,
            "elements": [
                "appliedenergistics2:smooth_sky_stone_stairs@0"
            ]
        },
        {
            "x": -3,
            "y": 45,
            "z": 14,
            "elements": [
                "minecraft:stained_glass_pane@14"
            ]
        },
        {
            "x": 3,
            "y": 22,
            "z": 0,
            "elements": [
                "minecraft:concrete@0"
            ]
        },
        {
            "x": 2,
            "y": 44,
            "z": 5,
            "elements": [
                "minecraft:concrete@0"
            ]
        },
        {
            "x": -3,
            "y": 45,
            "z": 15,
            "elements": [
                "minecraft:stained_glass_pane@14"
            ]
        },
        {
            "x": 2,
            "y": 44,
            "z": -1,
            "elements": [
                "minecraft:stone_slab@7"
            ]
        },
        {
            "x": 2,
            "y": 44,
            "z": 0,
            "elements": [
                "minecraft:concrete@0"
            ]
        },
        {
            "x": 2,
            "y": -6,
            "z": 15,
            "elements": [
                "minecraft:concrete@0"
            ]
        },
        {
            "x": 2,
            "y": 44,
            "z": -2,
            "elements": [
                "minecraft:stone_slab@15"
            ]
        },
        {
            "x": -3,
            "y": 8,
            "z": 9,
            "elements": [
                "appliedenergistics2:smooth_sky_stone_block@0"
            ]
        },
        {
            "x": -3,
            "y": 8,
            "z": 8,
            "elements": [
                "appliedenergistics2:smooth_sky_stone_block@0"
            ]
        },
        {
            "x": -3,
            "y": 8,
            "z": 7,
            "elements": [
                "appliedenergistics2:smooth_sky_stone_block@0"
            ]
        },
        {
            "x": -3,
            "y": 8,
            "z": 6,
            "elements": [
                "appliedenergistics2:smooth_sky_stone_block@0"
            ]
        },
        {
            "x": -3,
            "y": 8,
            "z": 5,
            "elements": [
                "appliedenergistics2:smooth_sky_stone_block@0"
            ]
        },
        {
            "x": -3,
            "y": 8,
            "z": 4,
            "elements": [
                "appliedenergistics2:smooth_sky_stone_block@0"
            ]
        },
        {
            "x": -7,
            "y": 12,
            "z": 15,
            "elements": [
                "minecraft:iron_bars@0"
            ]
        },
        {
            "x": -7,
            "y": 12,
            "z": 14,
            "elements": [
                "minecraft:iron_bars@0"
            ]
        },
        {
            "x": -7,
            "y": 12,
            "z": 13,
            "elements": [
                "minecraft:iron_bars@0"
            ]
        },
        {
            "x": -7,
            "y": 12,
            "z": 12,
            "elements": [
                "minecraft:iron_bars@0"
            ]
        },
        {
            "x": -7,
            "y": 12,
            "z": 11,
            "elements": [
                "minecraft:iron_bars@0"
            ]
        },
        {
            "x": 3,
            "y": -3,
            "z": 6,
            "elements": [
                "minecraft:stained_glass_pane@0"
            ]
        },
        {
            "x": 3,
            "y": -3,
            "z": 5,
            "elements": [
                "minecraft:stained_glass_pane@0"
            ]
        },
        {
            "x": -2,
            "y": 23,
            "z": 2,
            "elements": [
                "minecraft:end_rod@0"
            ]
        },
        {
            "x": -2,
            "y": -2,
            "z": 15,
            "elements": [
                "minecraft:concrete@0"
            ]
        },
        {
            "x": -3,
            "y": 58,
            "z": 15,
            "elements": [
                "minecraft:concrete@0"
            ]
        },
        {
            "x": -3,
            "y": 58,
            "z": 14,
            "elements": [
                "minecraft:concrete@0"
            ]
        },
        {
            "x": -3,
            "y": 58,
            "z": 8,
            "elements": [
                "minecraft:concrete@0"
            ]
        },
        {
            "x": -2,
            "y": 23,
            "z": -1,
            "elements": [
                "minecraft:concrete@0"
            ]
        },
        {
            "x": -4,
            "y": 55,
            "z": 14,
            "elements": [
                "minecraft:concrete@0"
            ]
        },
        {
            "x": -4,
            "y": 55,
            "z": 15,
            "elements": [
                "appliedenergistics2:smooth_sky_stone_slab@8"
            ]
        },
        {
            "x": -4,
            "y": 55,
            "z": 12,
            "elements": [
                "minecraft:concrete@0"
            ]
        },
        {
            "x": -4,
            "y": 55,
            "z": 13,
            "elements": [
                "minecraft:concrete@0"
            ]
        },
        {
            "x": -2,
            "y": 31,
            "z": 4,
            "elements": [
                "appliedenergistics2:smooth_sky_stone_stairs@3"
            ]
        },
        {
            "x": -3,
            "y": 3,
            "z": 14,
            "elements": [
                "minecraft:concrete@0"
            ]
        },
        {
            "x": -2,
            "y": 31,
            "z": -1,
            "elements": [
                "minecraft:concrete@0"
            ]
        },
        {
            "x": -2,
            "y": 31,
            "z": -2,
            "elements": [
                "embers:wall_ashen_stone@0"
            ]
        },
        {
            "x": -3,
            "y": 3,
            "z": 8,
            "elements": [
                "minecraft:concrete@0"
            ]
        },
        {
            "x": -5,
            "y": 27,
            "z": 2,
            "elements": [
                "appliedenergistics2:smooth_sky_stone_block@0"
            ]
        },
        {
            "x": -4,
            "y": 29,
            "z": 4,
            "elements": [
                "minecraft:concrete@0"
            ]
        },
        {
            "x": -4,
            "y": 29,
            "z": 5,
            "elements": [
                "minecraft:concrete@0"
            ]
        },
        {
            "x": -4,
            "y": 29,
            "z": 2,
            "elements": [
                "minecraft:concrete@0"
            ]
        },
        {
            "x": -4,
            "y": 29,
            "z": 3,
            "elements": [
                "minecraft:concrete@0"
            ]
        },
        {
            "x": -4,
            "y": 29,
            "z": 0,
            "elements": [
                "appliedenergistics2:smooth_sky_stone_block@0"
            ]
        },
        {
            "x": -4,
            "y": 29,
            "z": 1,
            "elements": [
                "minecraft:concrete@0"
            ]
        },
        {
            "x": -1,
            "y": 59,
            "z": 15,
            "elements": [
                "minecraft:concrete@0"
            ]
        },
        {
            "x": -1,
            "y": 59,
            "z": 16,
            "elements": [
                "minecraft:concrete@0"
            ]
        },
        {
            "x": -1,
            "y": 59,
            "z": 13,
            "elements": [
                "minecraft:quartz_stairs@7"
            ]
        },
        {
            "x": -1,
            "y": 59,
            "z": 14,
            "elements": [
                "minecraft:concrete@0"
            ]
        },
        {
            "x": -1,
            "y": 59,
            "z": 12,
            "elements": [
                "minecraft:concrete@7"
            ]
        },
        {
            "x": -1,
            "y": 59,
            "z": 9,
            "elements": [
                "minecraft:quartz_stairs@6"
            ]
        },
        {
            "x": -1,
            "y": 59,
            "z": 10,
            "elements": [
                "minecraft:concrete@7"
            ]
        },
        {
            "x": -1,
            "y": 59,
            "z": 8,
            "elements": [
                "minecraft:concrete@0"
            ]
        },
        {
            "x": 1,
            "y": 61,
            "z": 10,
            "elements": [
                "appliedenergistics2:smooth_sky_stone_stairs@1"
            ]
        },
        {
            "x": 1,
            "y": 61,
            "z": 12,
            "elements": [
                "appliedenergistics2:smooth_sky_stone_stairs@3"
            ]
        },
        {
            "x": 1,
            "y": 61,
            "z": 11,
            "elements": [
                "appliedenergistics2:smooth_sky_stone_stairs@1"
            ]
        },
        {
            "x": -4,
            "y": 29,
            "z": 6,
            "elements": [
                "minecraft:concrete@0"
            ]
        },
        {
            "x": -4,
            "y": 29,
            "z": 7,
            "elements": [
                "embers:wall_ashen_stone@0"
            ]
        },
        {
            "x": -3,
            "y": 29,
            "z": 0,
            "elements": [
                "minecraft:concrete@0"
            ]
        },
        {
            "x": -3,
            "y": 29,
            "z": 4,
            "elements": [
                "embers:wall_ashen_stone@0"
            ]
        },
        {
            "x": 0,
            "y": 59,
            "z": 13,
            "elements": [
                "minecraft:stained_glass@0"
            ]
        },
        {
            "x": 0,
            "y": 33,
            "z": 4,
            "elements": [
                "minecraft:sea_lantern@0"
            ]
        },
        {
            "x": 0,
            "y": 59,
            "z": 14,
            "elements": [
                "minecraft:concrete@0"
            ]
        },
        {
            "x": 0,
            "y": 59,
            "z": 15,
            "elements": [
                "minecraft:concrete@0"
            ]
        },
        {
            "x": 0,
            "y": 33,
            "z": 5,
            "elements": [
                "minecraft:stained_glass@1"
            ]
        },
        {
            "x": 0,
            "y": 33,
            "z": -2,
            "elements": [
                "minecraft:concrete@0"
            ]
        },
        {
            "x": 0,
            "y": 59,
            "z": 16,
            "elements": [
                "minecraft:concrete@0"
            ]
        },
        {
            "x": 0,
            "y": 33,
            "z": -1,
            "elements": [
                "minecraft:concrete@0"
            ]
        },
        {
            "x": -3,
            "y": 57,
            "z": 7,
            "elements": [
                "minecraft:concrete@0"
            ]
        },
        {
            "x": 0,
            "y": 33,
            "z": 11,
            "elements": [
                "environmentaltech:laser_core@0"
            ]
        },
        {
            "x": 5,
            "y": 41,
            "z": 3,
            "elements": [
                "appliedenergistics2:smooth_sky_stone_block@0"
            ]
        },
        {
            "x": 0,
            "y": 59,
            "z": 8,
            "elements": [
                "minecraft:concrete@0"
            ]
        },
        {
            "x": 0,
            "y": 59,
            "z": 9,
            "elements": [
