{   "registryname": "chicken",
    "localizedname": "机你太美",
    "requires-blueprint": false,
    "color": "e66c47",
    "parts": [
        {
            "x": -4,
            "y": 2,
            "z": 4,
            "elements": [
                "minecraft:wool@0"
            ]
        },
        {
            "x": -4,
            "y": 2,
            "z": -3,
            "elements": [
                "minecraft:wool@0"
            ]
        },
        {
            "x": -4,
            "y": 2,
            "z": -5,
            "elements": [
                "minecraft:concrete@0"
            ]
        },
        {
            "x": -4,
            "y": 2,
            "z": -4,
            "elements": [
                "minecraft:concrete@0"
            ]
        },
        {
            "x": -4,
            "y": 2,
            "z": -6,
            "elements": [
                "minecraft:wool@14"
            ]
        },
        {
            "x": -5,
            "y": 1,
            "z": 4,
            "elements": [
                "minecraft:wool@0"
            ]
        },
        {
            "x": -5,
            "y": 1,
            "z": -4,
            "elements": [
                "minecraft:iron_bars@0"
            ]
        },
        {
            "x": -5,
            "y": 1,
            "z": -3,
            "elements": [
                "minecraft:wool@15"
            ]
        },
        {
            "x": -6,
            "y": -1,
            "z": -3,
            "elements": [
                "minecraft:wool@0"
            ]
        },
        {
            "x": -6,
            "y": -1,
            "z": 5,
            "elements": [
                "minecraft:wool@8"
            ]
        },
        {
            "x": -6,
            "y": -1,
            "z": 4,
            "elements": [
                "minecraft:wool@8"
            ]
        },
        {
            "x": -5,
            "y": 0,
            "z": -3,
            "elements": [
                "minecraft:wool@15"
            ]
        },
        {
            "x": -7,
            "y": -1,
            "z": 4,
            "elements": [
                "minecraft:wool@8"
            ]
        },
        {
            "x": -7,
            "y": -1,
            "z": 3,
            "elements": [
                "minecraft:wool@8"
            ]
        },
        {
            "x": -7,
            "y": -1,
            "z": 5,
            "elements": [
                "minecraft:wool@8"
            ]
        },
        {
            "x": -7,
            "y": -1,
            "z": 0,
            "elements": [
                "minecraft:wool@15"
            ]
        },
        {
            "x": -7,
            "y": -1,
            "z": -1,
            "elements": [
                "minecraft:wool@15"
            ]
        },
        {
            "x": -7,
            "y": -1,
            "z": 2,
            "elements": [
                "minecraft:wool@8"
            ]
        },
        {
            "x": -7,
            "y": -1,
            "z": 1,
            "elements": [
                "minecraft:wool@15"
            ]
        },
        {
            "x": -7,
            "y": -1,
            "z": -2,
            "elements": [
                "minecraft:wool@15"
            ]
        },
        {
            "x": -7,
            "y": -1,
            "z": -3,
            "elements": [
                "minecraft:wool@15"
            ]
        },
        {
            "x": -3,
            "y": 3,
            "z": -5,
            "elements": [
                "minecraft:wool@0"
            ]
        },
        {
            "x": -3,
            "y": 3,
            "z": -4,
            "elements": [
                "minecraft:wool@0"
            ]
        },
        {
            "x": -3,
            "y": 3,
            "z": -2,
            "elements": [
                "minecraft:wool@0"
            ]
        },
        {
            "x": -2,
            "y": 5,
            "z": -4,
            "elements": [
                "minecraft:stained_hardened_clay@8"
            ]
        },
        {
            "x": -7,
            "y": -3,
            "z": 1,
            "elements": [
                "minecraft:wool@8"
            ]
        },
        {
            "x": -7,
            "y": -3,
            "z": 2,
            "elements": [
                "minecraft:wool@8"
            ]
        },
        {
            "x": -3,
            "y": 3,
            "z": 3,
            "elements": [
                "minecraft:wool@0"
            ]
        },
        {
            "x": -3,
            "y": 3,
            "z": 4,
            "elements": [
                "minecraft:wool@15"
            ]
        },
        {
            "x": -3,
            "y": 3,
            "z": -1,
            "elements": [
                "minecraft:wool@0"
            ]
        },
        {
            "x": -3,
            "y": 3,
            "z": 0,
            "elements": [
                "minecraft:wool@0"
            ]
        },
        {
            "x": -3,
            "y": 3,
            "z": 1,
            "elements": [
                "minecraft:wool@0"
            ]
        },
        {
            "x": -3,
            "y": 3,
            "z": 2,
            "elements": [
                "minecraft:wool@0"
            ]
        },
        {
            "x": -6,
            "y": 1,
            "z": -3,
            "elements": [
                "minecraft:wool@0"
            ]
        },
        {
            "x": -5,
            "y": 0,
            "z": 4,
            "elements": [
                "minecraft:wool@8"
            ]
        },
        {
            "x": -2,
            "y": -7,
            "z": -1,
            "elements": [
                "minecraft:wool@4"
            ]
        },
        {
            "x": -2,
            "y": 3,
            "z": -3,
            "elements": [
                "minecraft:wool@15"
            ]
        },
        {
            "x": -2,
            "y": -7,
            "z": 0,
            "elements": [
                "minecraft:concrete@4"
            ]
        },
        {
            "x": -4,
            "y": 4,
            "z": -3,
            "elements": [
                "minecraft:concrete@0"
            ]
        },
        {
            "x": -5,
            "y": -1,
            "z": -3,
            "elements": [
                "minecraft:wool@15"
            ]
        },
        {
            "x": -4,
            "y": 4,
            "z": -7,
            "elements": [
                "minecraft:concrete@4"
            ]
        },
        {
            "x": -5,
            "y": -1,
            "z": 4,
            "elements": [
                "minecraft:wool@8"
            ]
        },
        {
            "x": -2,
            "y": 3,
            "z": 4,
            "elements": [
                "minecraft:wool@15"
            ]
        },
        {
            "x": -5,
            "y": 2,
            "z": 4,
            "elements": [
                "minecraft:wool@0"
            ]
        },
        {
            "x": -4,
            "y": 1,
            "z": -4,
            "elements": [
                "minecraft:iron_bars@0"
            ]
        },
        {
            "x": -4,
            "y": 1,
            "z": -3,
            "elements": [
                "minecraft:wool@15"
            ]
        },
        {
            "x": -3,
            "y": 1,
            "z": 5,
            "elements": [
                "minecraft:wool@15"
            ]
        },
        {
            "x": -4,
            "y": 1,
            "z": 4,
            "elements": [
                "minecraft:wool@0"
            ]
        },
        {
            "x": -3,
            "y": 1,
            "z": 4,
            "elements": [
                "minecraft:wool@15"
            ]
        },
        {
            "x": -3,
            "y": 1,
            "z": -3,
            "elements": [
                "minecraft:wool@0"
            ]
        },
        {
            "x": -5,
            "y": 2,
            "z": -6,
            "elements": [
                "minecraft:wool@14"
            ]
        },
        {
            "x": -5,
            "y": 2,
            "z": -5,
            "elements": [
                "minecraft:concrete@0"
            ]
        },
        {
            "x": -5,
            "y": 2,
            "z": -4,
            "elements": [
                "minecraft:concrete@0"
            ]
        },
        {
            "x": -5,
            "y": 2,
            "z": -3,
            "elements": [
                "minecraft:wool@0"
            ]
        },
        {
            "x": -6,
            "y": -3,
            "z": 2,
            "elements": [
                "minecraft:wool@8"
            ]
        },
        {
            "x": -6,
            "y": -3,
            "z": 1,
            "elements": [
                "minecraft:wool@8"
            ]
        },
        {
            "x": -6,
            "y": -3,
            "z": 0,
            "elements": [
                "minecraft:wool@8"
            ]
        },
        {
            "x": 2,
            "y": -1,
            "z": 3,
            "elements": [
                "minecraft:concrete@0"
            ]
        },
        {
            "x": -3,
            "y": 4,
            "z": -3,
            "elements": [
                "minecraft:concrete@0"
            ]
        },
        {
            "x": 2,
            "y": -1,
            "z": 2,
            "elements": [
                "minecraft:wool@0"
            ]
        },
        {
            "x": -3,
            "y": 4,
            "z": -4,
            "elements": [
                "minecraft:wool@0"
            ]
        },
        {
            "x": -3,
            "y": 4,
            "z": -5,
            "elements": [
                "minecraft:wool@0"
            ]
        },
        {
            "x": -3,
            "y": 4,
            "z": -6,
            "elements": [
                "minecraft:concrete@4"
            ]
        },
        {
            "x": -3,
            "y": 4,
            "z": -7,
            "elements": [
                "minecraft:concrete@4"
            ]
        },
        {
            "x": 2,
            "y": -1,
            "z": 1,
            "elements": [
                "minecraft:wool@0"
            ]
        },
        {
            "x": 2,
            "y": -1,
            "z": 0,
            "elements": [
                "minecraft:concrete@0"
            ]
        },
        {
            "x": -6,
            "y": 0,
            "z": -3,
            "elements": [
                "minecraft:wool@0"
            ]
        },
        {
            "x": -7,
            "y": -2,
            "z": -2,
            "elements": [
                "minecraft:wool@15"
            ]
        },
        {
            "x": -6,
            "y": 0,
            "z": 4,
            "elements": [
                "minecraft:wool@8"
            ]
        },
        {
            "x": -7,
            "y": -2,
            "z": -1,
            "elements": [
                "minecraft:wool@15"
            ]
        },
        {
            "x": -7,
            "y": -2,
            "z": -3,
            "elements": [
                "minecraft:wool@15"
            ]
        },
        {
            "x": -7,
            "y": -2,
            "z": 2,
            "elements": [
                "minecraft:wool@8"
            ]
        },
        {
            "x": -2,
            "y": 6,
            "z": -4,
            "elements": [
                "minecraft:stained_hardened_clay@8"
            ]
        },
        {
            "x": -7,
            "y": -2,
            "z": 3,
            "elements": [
                "minecraft:wool@8"
            ]
        },
        {
            "x": -7,
            "y": -2,
            "z": 0,
            "elements": [
                "minecraft:wool@15"
            ]
        },
        {
            "x": -6,
            "y": 0,
            "z": 5,
            "elements": [
                "minecraft:wool@8"
            ]
        },
        {
            "x": -2,
            "y": 6,
            "z": -3,
            "elements": [
                "minecraft:stained_hardened_clay@8"
            ]
        },
        {
            "x": -7,
            "y": -2,
            "z": 1,
            "elements": [
                "minecraft:wool@8"
            ]
        },
        {
            "x": -7,
            "y": -2,
            "z": 4,
            "elements": [
                "minecraft:wool@8"
            ]
        },
        {
            "x": -7,
            "y": 1,
            "z": 2,
            "elements": [
                "minecraft:wool@15"
            ]
        },
        {
            "x": -7,
            "y": 1,
            "z": 1,
            "elements": [
                "minecraft:wool@15"
            ]
        },
        {
            "x": -7,
            "y": 1,
            "z": 4,
            "elements": [
                "minecraft:wool@15"
            ]
        },
        {
            "x": -7,
            "y": 1,
            "z": 3,
            "elements": [
                "minecraft:wool@15"
            ]
        },
        {
            "x": -7,
            "y": 1,
            "z": -2,
            "elements": [
                "minecraft:wool@15"
            ]
        },
        {
            "x": -7,
            "y": 1,
            "z": -3,
            "elements": [
                "minecraft:wool@15"
            ]
        },
        {
            "x": -7,
            "y": 1,
            "z": 0,
            "elements": [
                "minecraft:wool@15"
            ]
        },
        {
            "x": -7,
            "y": 1,
            "z": -1,
            "elements": [
                "minecraft:wool@15"
            ]
        },
        {
            "x": -7,
            "y": 1,
            "z": 5,
            "elements": [
                "minecraft:wool@15"
            ]
        },
        {
            "x": -2,
            "y": 8,
            "z": -6,
            "elements": [
                "minecraft:wool@8"
            ]
        },
        {
            "x": -2,
            "y": 8,
            "z": -5,
            "elements": [
                "minecraft:wool@8"
            ]
        },
        {
            "x": -3,
            "y": 0,
            "z": 4,
            "elements": [
                "minecraft:wool@8"
            ]
        },
        {
            "x": -3,
            "y": 0,
            "z": 5,
            "elements": [
                "minecraft:wool@8"
            ]
        },
        {
            "x": -2,
            "y": 8,
            "z": -4,
            "elements": [
                "minecraft:wool@8"
            ]
        },
        {
            "x": -2,
            "y": 8,
            "z": -3,
            "elements": [
                "minecraft:wool@8"
            ]
        },
        {
            "x": -2,
            "y": 8,
            "z": -2,
            "elements": [
                "minecraft:wool@8"
            ]
        },
        {
            "x": -2,
            "y": 1,
            "z": 4,
            "elements": [
                "minecraft:wool@15"
            ]
        },
        {
            "x": -2,
            "y": 1,
            "z": 5,
            "elements": [
                "minecraft:wool@15"
            ]
        },
        {
            "x": -2,
            "y": 1,
            "z": 2,
            "elements": [
                "minecraft:wool@15"
            ]
        },
        {
            "x": -2,
            "y": 1,
            "z": 3,
            "elements": [
                "minecraft:wool@15"
            ]
        },
        {
            "x": -2,
            "y": 1,
            "z": 0,
            "elements": [
                "minecraft:wool@15"
            ]
        },
        {
            "x": -2,
            "y": 1,
            "z": 1,
            "elements": [
                "minecraft:wool@15"
            ]
        },
        {
            "x": -7,
            "y": 2,
            "z": -3,
            "elements": [
                "minecraft:wool@15"
            ]
        },
        {
            "x": -7,
            "y": 2,
            "z": -1,
            "elements": [
                "minecraft:wool@15"
            ]
        },
        {
            "x": -3,
            "y": 0,
            "z": -3,
            "elements": [
                "minecraft:wool@0"
            ]
        },
        {
            "x": -7,
            "y": 2,
            "z": -2,
            "elements": [
                "minecraft:wool@15"
            ]
        },
        {
            "x": -7,
            "y": 2,
            "z": 1,
            "elements": [
                "minecraft:wool@15"
            ]
        },
        {
            "x": -3,
            "y": -7,
            "z": 1,
            "elements": [
                "minecraft:stained_hardened_clay@4"
            ]
        },
        {
            "x": -7,
            "y": 2,
            "z": 0,
            "elements": [
                "minecraft:wool@15"
            ]
        },
        {
            "x": -7,
            "y": 2,
            "z": 3,
            "elements": [
                "minecraft:wool@15"
            ]
        },
        {
            "x": -7,
            "y": 2,
            "z": 2,
            "elements": [
                "minecraft:wool@15"
            ]
        },
        {
            "x": -7,
            "y": 2,
            "z": 4,
            "elements": [
                "minecraft:wool@15"
            ]
        },
        {
            "x": -2,
            "y": 1,
            "z": -2,
            "elements": [
                "minecraft:wool@15"
            ]
        },
        {
            "x": -1,
            "y": 3,
            "z": 3,
            "elements": [
                "minecraft:wool@15"
            ]
        },
        {
            "x": -2,
            "y": 1,
            "z": -1,
            "elements": [
                "minecraft:wool@15"
            ]
        },
        {
            "x": -1,
            "y": 3,
            "z": 2,
            "elements": [
                "minecraft:wool@15"
            ]
        },
        {
            "x": -2,
            "y": 1,
            "z": -3,
            "elements": [
                "minecraft:wool@15"
            ]
        },
        {
            "x": -1,
            "y": 3,
            "z": 1,
            "elements": [
                "minecraft:wool@15"
            ]
        },
        {
            "x": -1,
            "y": 3,
            "z": 0,
            "elements": [
                "minecraft:wool@15"
            ]
        },
        {
            "x": -1,
            "y": 3,
            "z": -1,
            "elements": [
                "minecraft:wool@15"
            ]
        },
        {
            "x": -1,
            "y": 3,
            "z": -2,
            "elements": [
                "minecraft:wool@15"
            ]
        },
        {
            "x": -3,
            "y": -6,
            "z": 1,
            "elements": [
                "minecraft:stained_hardened_clay@4"
            ]
        },
        {
            "x": -4,
            "y": -2,
            "z": 4,
            "elements": [
                "modularmachinery:blockoutputbus"
            ]
        },
        {
            "x": -4,
            "y": -2,
            "z": 3,
            "elements": [
                "minecraft:wool@8"
            ]
        },
        {
            "x": -4,
            "y": -2,
            "z": 2,
            "elements": [
                "minecraft:wool@8"
            ]
        },
        {
            "x": -4,
            "y": -2,
            "z": 1,
            "elements": [
                "minecraft:wool@8"
            ]
        },
        {
            "x": -4,
            "y": -2,
            "z": 0,
            "elements": [
                "minecraft:wool@15"
            ]
        },
        {
            "x": -4,
            "y": -2,
            "z": -1,
            "elements": [
                "minecraft:wool@15"
            ]
        },
        {
            "x": -4,
            "y": -2,
            "z": -2,
            "elements": [
                "minecraft:wool@15"
            ]
        },
        {
            "x": -4,
            "y": -2,
            "z": -3,
            "elements": [
                "minecraft:wool@15"
            ]
        },
        {
            "x": -3,
            "y": 6,
            "z": -5,
            "elements": [
                "minecraft:wool@15"
            ]
        },
        {
            "x": -2,
            "y": 7,
            "z": -2,
            "elements": [
                "minecraft:wool@8"
            ]
        },
        {
            "x": -2,
            "y": 7,
            "z": -5,
            "elements": [
                "minecraft:stained_hardened_clay@8"
            ]
        },
        {
            "x": -2,
            "y": 7,
            "z": -6,
            "elements": [
                "minecraft:stained_hardened_clay@8"
            ]
        },
        {
            "x": -2,
            "y": 7,
            "z": -3,
            "elements": [
                "minecraft:wool@8"
            ]
        },
        {
            "x": -2,
            "y": 7,
            "z": -4,
            "elements": [
                "minecraft:wool@8"
            ]
        },
        {
            "x": -7,
            "y": 8,
            "z": -6,
            "elements": [
                "minecraft:wool@8"
            ]
        },
        {
            "x": -7,
            "y": 8,
            "z": -5,
            "elements": [
                "minecraft:wool@8"
            ]
        },
        {
            "x": -7,
            "y": 8,
            "z": -4,
            "elements": [
                "minecraft:wool@8"
            ]
        },
        {
            "x": -7,
            "y": 8,
            "z": -3,
            "elements": [
                "minecraft:wool@8"
            ]
        },
        {
            "x": -6,
            "y": 4,
            "z": -5,
            "elements": [
                "minecraft:wool@0"
            ]
        },
        {
            "x": -6,
            "y": 4,
            "z": -4,
            "elements": [
                "minecraft:wool@0"
            ]
        },
        {
            "x": -6,
            "y": 4,
            "z": -7,
            "elements": [
                "minecraft:concrete@4"
            ]
        },
        {
            "x": -6,
            "y": 4,
            "z": -6,
            "elements": [
                "minecraft:concrete@4"
            ]
        },
        {
            "x": -3,
            "y": 6,
            "z": -2,
            "elements": [
                "minecraft:stained_hardened_clay@8"
            ]
        },
        {
            "x": -3,
            "y": 6,
            "z": -3,
            "elements": [
                "minecraft:wool@0"
            ]
        },
        {
            "x": -6,
            "y": 4,
            "z": -3,
            "elements": [
                "minecraft:concrete@0"
            ]
        },
        {
            "x": -2,
            "y": 2,
            "z": -2,
            "elements": [
                "minecraft:wool@15"
            ]
        },
        {
            "x": -3,
            "y": 6,
            "z": -4,
            "elements": [
                "minecraft:wool@0"
            ]
        },
        {
            "x": -2,
            "y": 2,
            "z": -3,
            "elements": [
                "minecraft:wool@15"
            ]
        },
        {
            "x": -7,
            "y": 8,
            "z": -2,
            "elements": [
                "minecraft:wool@8"
            ]
        },
        {
            "x": -2,
            "y": 2,
            "z": 0,
            "elements": [
                "minecraft:wool@15"
            ]
        },
        {
            "x": -2,
            "y": 2,
            "z": -1,
            "elements": [
                "minecraft:wool@15"
            ]
        },
        {
            "x": -2,
            "y": 2,
            "z": 2,
            "elements": [
                "minecraft:wool@15"
            ]
        },
        {
            "x": -2,
            "y": 2,
            "z": 1,
            "elements": [
                "minecraft:wool@15"
            ]
        },
        {
            "x": -2,
            "y": 2,
            "z": 4,
            "elements": [
                "minecraft:wool@15"
            ]
        },
        {
            "x": -2,
            "y": 2,
            "z": 3,
            "elements": [
                "minecraft:wool@15"
            ]
        },
        {
            "x": -3,
            "y": 5,
            "z": -3,
            "elements": [
                "minecraft:wool@0"
            ]
        },
        {
            "x": -6,
            "y": -2,
            "z": -2,
            "elements": [
                "minecraft:wool@0"
            ]
        },
        {
            "x": -6,
            "y": -2,
            "z": -3,
            "elements": [
                "minecraft:wool@0"
            ]
        },
        {
            "x": -3,
            "y": 5,
            "z": -4,
            "elements": [
                "minecraft:wool@0"
            ]
        },
        {
            "x": -3,
            "y": 5,
            "z": -5,
            "elements": [
                "minecraft:wool@0"
            ]
        },
        {
            "x": -3,
            "y": 5,
            "z": -6,
            "elements": [
                "minecraft:wool@4"
            ]
        },
        {
            "x": -3,
            "y": 5,
            "z": -7,
            "elements": [
                "minecraft:concrete@4"
            ]
        },
        {
            "x": -4,
            "y": -3,
            "z": 1,
            "elements": [
                "minecraft:wool@8"
            ]
        },
        {
            "x": -6,
            "y": -2,
            "z": 2,
            "elements": [
                "minecraft:wool@8"
            ]
        },
        {
            "x": -6,
            "y": -2,
            "z": 1,
            "elements": [
                "minecraft:wool@8"
            ]
        },
        {
            "x": -4,
            "y": -3,
            "z": 0,
            "elements": [
                "minecraft:wool@8"
            ]
        },
        {
            "x": -7,
            "y": -3,
            "z": 0,
            "elements": [
                "minecraft:wool@8"
            ]
        },
        {
            "x": -6,
            "y": -2,
            "z": 0,
            "elements": [
                "minecraft:wool@0"
            ]
        },
        {
            "x": -6,
            "y": -2,
            "z": -1,
            "elements": [
                "minecraft:wool@0"
            ]
        },
        {
            "x": -6,
            "y": -2,
            "z": 4,
            "elements": [
                "minecraft:wool@8"
            ]
        },
        {
            "x": -6,
            "y": -2,
            "z": 3,
            "elements": [
                "minecraft:wool@8"
            ]
        },
        {
            "x": -4,
            "y": -3,
            "z": 2,
            "elements": [
                "minecraft:wool@8"
            ]
        },
        {
            "x": 0,
            "y": -1,
            "z": 0,
            "elements": [
                "minecraft:wool@1"
            ]
        },
        {
            "x": 0,
            "y": -1,
            "z": 3,
            "elements": [
                "minecraft:wool@1"
            ]
        },
        {
            "x": -7,
            "y": 3,
            "z": 4,
            "elements": [
                "minecraft:wool@15"
            ]
        },
        {
            "x": -7,
            "y": 3,
            "z": -3,
            "elements": [
                "minecraft:wool@15"
            ]
        },
        {
            "x": -4,
            "y": 3,
            "z": -6,
            "elements": [
                "minecraft:wool@14"
            ]
        },
        {
            "x": -4,
            "y": 3,
            "z": -2,
            "elements": [
                "minecraft:wool@15"
            ]
        },
        {
            "x": -4,
            "y": 3,
            "z": -1,
            "elements": [
                "minecraft:wool@15"
            ]
        },
        {
            "x": -7,
            "y": 9,
            "z": -5,
            "elements": [
                "minecraft:wool@8"
            ]
        },
        {
            "x": -7,
            "y": 9,
            "z": -4,
            "elements": [
                "minecraft:wool@8"
            ]
        },
        {
            "x": -3,
            "y": -7,
            "z": 0,
            "elements": [
                "minecraft:stained_hardened_clay@4"
            ]
        },
        {
            "x": -6,
            "y": 5,
            "z": -4,
            "elements": [
                "minecraft:wool@0"
            ]
        },
        {
            "x": -6,
            "y": 5,
            "z": -3,
            "elements": [
                "minecraft:wool@0"
            ]
        },
        {
            "x": -3,
            "y": -7,
            "z": -1,
            "elements": [
                "minecraft:stained_hardened_clay@4"
            ]
        },
        {
            "x": -6,
            "y": 5,
            "z": -6,
            "elements": [
                "minecraft:wool@4"
            ]
        },
        {
            "x": -6,
            "y": 5,
            "z": -5,
            "elements": [
                "minecraft:wool@0"
            ]
        },
        {
            "x": -6,
            "y": 5,
            "z": -7,
            "elements": [
                "minecraft:concrete@4"
            ]
        },
        {
            "x": -3,
            "y": -1,
            "z": -3,
            "elements": [
                "minecraft:wool@0"
            ]
        },
        {
            "x": -5,
            "y": 7,
            "z": -5,
            "elements": [
                "minecraft:wool@0"
            ]
        },
        {
            "x": -4,
            "y": 3,
            "z": 2,
            "elements": [
                "minecraft:wool@15"
            ]
        },
        {
            "x": -4,
            "y": 3,
            "z": 3,
            "elements": [
                "minecraft:wool@15"
            ]
        },
        {
            "x": -5,
            "y": 7,
            "z": -1,
            "elements": [
                "minecraft:wool@8"
            ]
        },
        {
            "x": -4,
            "y": 3,
            "z": 0,
            "elements": [
                "minecraft:wool@15"
            ]
        },
        {
            "x": -4,
            "y": 3,
            "z": 1,
            "elements": [
                "minecraft:wool@15"
            ]
        },
        {
            "x": -3,
            "y": -1,
            "z": 4,
            "elements": [
                "minecraft:wool@8"
            ]
        },
        {
            "x": -3,
            "y": -1,
            "z": 5,
            "elements": [
                "minecraft:wool@8"
            ]
        },
        {
            "x": -4,
            "y": 3,
            "z": 4,
            "elements": [
                "minecraft:wool@0"
            ]
        },
        {
            "x": -2,
            "y": -2,
            "z": -3,
            "elements": [
                "minecraft:wool@15"
            ]
        },
        {
            "x": -2,
            "y": -2,
            "z": -2,
            "elements": [
                "minecraft:wool@15"
            ]
        },
        {
            "x": -6,
            "y": -7,
            "z": -1,
            "elements": [
                "minecraft:stained_hardened_clay@4"
            ]
        },
        {
            "x": -6,
            "y": -7,
            "z": 0,
            "elements": [
                "minecraft:stained_hardened_clay@4"
            ]
        },
        {
            "x": -2,
            "y": -2,
            "z": 1,
            "elements": [
                "minecraft:wool@8"
            ]
        },
        {
            "x": -6,
            "y": -7,
            "z": 1,
            "elements": [
                "minecraft:stained_hardened_clay@4"
            ]
        },
        {
            "x": -2,
            "y": -2,
            "z": 2,
            "elements": [
                "minecraft:wool@8"
            ]
        },
        {
            "x": -2,
            "y": -2,
            "z": -1,
            "elements": [
                "minecraft:wool@15"
            ]
        },
        {
            "x": -7,
            "y": 5,
            "z": -4,
            "elements": [
                "minecraft:stained_hardened_clay@8"
            ]
        },
        {
            "x": -2,
            "y": -2,
            "z": 0,
            "elements": [
                "minecraft:wool@15"
            ]
        },
        {
            "x": -2,
            "y": -2,
            "z": 3,
            "elements": [
                "minecraft:wool@8"
            ]
        },
        {
            "x": -2,
            "y": -2,
            "z": 4,
            "elements": [
                "minecraft:wool@8"
            ]
        },
        {
            "x": -4,
            "y": 9,
            "z": -5,
            "elements": [
                "minecraft:wool@8"
            ]
        },
        {
            "x": -4,
            "y": 9,
            "z": -6,
            "elements": [
                "minecraft:wool@8"
            ]
        },
        {
            "x": -1,
            "y": -1,
            "z": 3,
            "elements": [
                "minecraft:wool@1"
            ]
        },
        {
            "x": -4,
            "y": 9,
            "z": -3,
            "elements": [
                "minecraft:wool@8"
            ]
        },
        {
            "x": -4,
            "y": 9,
            "z": -4,
            "elements": [
                "minecraft:wool@8"
            ]
        },
        {
            "x": -4,
            "y": 9,
            "z": -2,
            "elements": [
                "minecraft:wool@8"
            ]
        },
        {
            "x": -1,
            "y": -1,
            "z": 0,
            "elements": [
                "minecraft:wool@1"
            ]
        },
        {
            "x": 0,
            "y": 0,
            "z": 3,
            "elements": [
                "minecraft:wool@1"
            ]
        },
        {
            "x": -3,
            "y": -3,
            "z": 1,
            "elements": [
                "minecraft:wool@8"
            ]
        },
        {
            "x": -3,
            "y": -3,
            "z": 2,
            "elements": [
                "minecraft:wool@8"
            ]
        },
        {
            "x": -3,
            "y": -3,
            "z": 0,
            "elements": [
                "minecraft:wool@8"
            ]
        },
        {
            "x": -6,
            "y": 6,
            "z": -3,
            "elements": [
                "minecraft:wool@0"
            ]
        },
        {
            "x": -6,
            "y": 6,
            "z": -2,
            "elements": [
                "minecraft:stained_hardened_clay@8"
            ]
        },
        {
            "x": -6,
            "y": 6,
            "z": -5,
            "elements": [
                "minecraft:wool@15"
            ]
        },
        {
            "x": -6,
            "y": 6,
            "z": -4,
            "elements": [
                "minecraft:wool@0"
            ]
        },
        {
            "x": -6,
            "y": 7,
            "z": -2,
            "elements": [
                "minecraft:wool@8"
            ]
        },
        {
            "x": -6,
            "y": 7,
            "z": -1,
            "elements": [
                "minecraft:wool@8"
            ]
        },
        {
            "x": -8,
            "y": 3,
            "z": -1,
            "elements": [
                "minecraft:wool@15"
            ]
        },
        {
            "x": 1,
            "y": 1,
            "z": 0,
            "elements": [
                "minecraft:wool@15"
            ]
        },
        {
            "x": -8,
            "y": 3,
            "z": -2,
            "elements": [
                "minecraft:wool@15"
            ]
        },
        {
            "x": 1,
            "y": 1,
            "z": -1,
            "elements": [
                "minecraft:wool@15"
            ]
        },
        {
            "x": -8,
            "y": 3,
            "z": 3,
            "elements": [
                "minecraft:wool@15"
            ]
        },
        {
            "x": 1,
            "y": 1,
            "z": 4,
            "elements": [
                "minecraft:wool@15"
            ]
        },
        {
            "x": -8,
            "y": 3,
            "z": 2,
            "elements": [
                "minecraft:wool@15"
            ]
        },
        {
            "x": 1,
            "y": 1,
            "z": 3,
            "elements": [
                "minecraft:wool@15"
            ]
        },
        {
            "x": 1,
            "y": 1,
            "z": 2,
            "elements": [
                "minecraft:wool@15"
            ]
        },
        {
            "x": -8,
            "y": 3,
            "z": 1,
            "elements": [
                "minecraft:wool@15"
            ]
        },
        {
            "x": 1,
            "y": 1,
            "z": 1,
            "elements": [
                "minecraft:wool@15"
            ]
        },
        {
            "x": -8,
            "y": 3,
            "z": 0,
            "elements": [
                "minecraft:wool@15"
            ]
        },
        {
            "x": -3,
            "y": 9,
            "z": -4,
            "elements": [
                "minecraft:wool@8"
            ]
        },
        {
            "x": -3,
            "y": 9,
            "z": -5,
            "elements": [
                "minecraft:wool@8"
            ]
        },
        {
            "x": -3,
            "y": 9,
            "z": -6,
            "elements": [
                "minecraft:wool@8"
            ]
        },
        {
            "x": -3,
            "y": 9,
            "z": -3,
            "elements": [
                "minecraft:wool@8"
            ]
        },
        {
            "x": -5,
            "y": 8,
            "z": -1,
            "elements": [
                "minecraft:wool@8"
            ]
        },
        {
            "x": -6,
            "y": 7,
            "z": -5,
            "elements": [
                "minecraft:wool@0"
            ]
        },
        {
            "x": -10,
            "y": 0,
            "z": 1,
            "elements": [
                "minecraft:wool@15"
            ]
        },
        {
            "x": -10,
            "y": 0,
            "z": 2,
            "elements": [
                "minecraft:wool@15"
            ]
        },
        {
            "x": -9,
            "y": 2,
            "z": 2,
            "elements": [
                "minecraft:wool@15"
            ]
        },
        {
            "x": -10,
            "y": 0,
            "z": -1,
            "elements": [
                "minecraft:wool@15"
            ]
        },
        {
            "x": -10,
            "y": 0,
            "z": 0,
            "elements": [
                "minecraft:wool@15"
            ]
        },
        {
            "x": -1,
            "y": -2,
            "z": 1,
            "elements": [
                "minecraft:wool@1"
            ]
        },
        {
            "x": -9,
            "y": 2,
            "z": 0,
            "elements": [
                "minecraft:wool@15"
            ]
        },
        {
            "x": -5,
            "y": 8,
            "z": -5,
            "elements": [
                "minecraft:stained_hardened_clay@8"
            ]
        },
        {
            "x": -9,
            "y": 2,
            "z": 1,
            "elements": [
                "minecraft:wool@15"
            ]
        },
        {
            "x": -9,
            "y": 2,
            "z": -1,
            "elements": [
                "minecraft:wool@15"
            ]
        },
        {
            "x": -2,
            "y": -1,
            "z": 4,
            "elements": [
                "minecraft:wool@8"
            ]
        },
        {
            "x": -2,
            "y": -1,
            "z": 5,
            "elements": [
                "minecraft:wool@8"
            ]
        },
        {
            "x": -2,
            "y": -1,
            "z": 2,
            "elements": [
                "minecraft:wool@8"
            ]
        },
        {
            "x": -2,
            "y": -1,
            "z": 3,
            "elements": [
                "minecraft:wool@8"
            ]
        },
        {
            "x": -2,
            "y": -1,
            "z": 0,
            "elements": [
                "minecraft:wool@15"
            ]
        },
        {
            "x": -2,
            "y": -1,
            "z": 1,
            "elements": [
                "minecraft:wool@15"
            ]
        },
        {
            "x": -2,
            "y": -1,
            "z": -2,
            "elements": [
                "minecraft:wool@15"
            ]
        },
        {
            "x": -2,
            "y": -1,
            "z": -1,
            "elements": [
                "minecraft:wool@15"
            ]
        },
        {
            "x": -2,
            "y": -1,
            "z": -3,
            "elements": [
                "minecraft:wool@15"
            ]
        },
        {
            "x": -1,
            "y": -2,
            "z": 2,
            "elements": [
                "minecraft:wool@1"
            ]
        },
        {
            "x": -8,
            "y": 2,
            "z": 3,
            "elements": [
                "minecraft:wool@15"
            ]
        },
        {
            "x": -8,
            "y": 2,
            "z": 2,
            "elements": [
                "minecraft:wool@15"
            ]
        },
        {
            "x": 1,
            "y": 0,
            "z": 2,
            "elements": [
                "minecraft:wool@1"
            ]
        },
        {
            "x": -8,
            "y": 2,
            "z": 1,
            "elements": [
                "minecraft:wool@15"
            ]
        },
        {
            "x": -8,
            "y": 2,
            "z": 0,
            "elements": [
                "minecraft:wool@15"
            ]
        },
        {
            "x": 1,
            "y": 0,
            "z": 1,
            "elements": [
                "minecraft:wool@1"
            ]
        },
        {
            "x": -8,
            "y": 2,
            "z": -1,
            "elements": [
                "minecraft:wool@15"
            ]
        },
        {
            "x": -8,
            "y": 2,
            "z": -2,
            "elements": [
                "minecraft:wool@15"
            ]
        },
        {
            "x": -3,
            "y": -5,
            "z": 1,
            "elements": [
                "minecraft:wool@4"
            ]
        },
        {
            "x": -5,
            "y": 6,
            "z": -5,
            "elements": [
                "minecraft:wool@0"
            ]
        },
        {
            "x": -4,
            "y": 7,
            "z": -1,
            "elements": [
                "minecraft:wool@8"
            ]
        },
        {
            "x": -5,
            "y": 6,
            "z": -2,
            "elements": [
                "minecraft:wool@8"
            ]
        },
        {
            "x": -5,
            "y": 6,
            "z": -1,
            "elements": [
                "minecraft:wool@8"
            ]
        },
        {
            "x": -3,
            "y": -2,
            "z": 4,
            "elements": [
                "minecraft:wool@8"
            ]
        },
        {
            "x": -2,
            "y": 0,
            "z": 3,
            "elements": [
                "minecraft:wool@15"
            ]
        },
        {
            "x": -3,
            "y": -2,
            "z": -3,
            "elements": [
                "minecraft:wool@0"
            ]
        },
        {
            "x": -2,
            "y": 0,
            "z": 4,
            "elements": [
                "minecraft:wool@8"
            ]
        },
        {
            "x": -3,
            "y": -2,
            "z": -2,
            "elements": [
                "minecraft:wool@0"
            ]
        },
        {
            "x": -2,
            "y": 0,
            "z": 1,
            "elements": [
                "minecraft:wool@15"
            ]
        },
        {
            "x": -2,
            "y": 0,
            "z": 2,
            "elements": [
                "minecraft:wool@15"
            ]
        },
        {
            "x": -3,
            "y": -2,
            "z": -1,
            "elements": [
                "minecraft:wool@0"
            ]
        },
        {
            "x": -3,
            "y": -2,
            "z": 0,
            "elements": [
                "minecraft:wool@0"
            ]
        },
        {
            "x": -3,
            "y": -2,
            "z": 1,
            "elements": [
                "minecraft:wool@8"
            ]
        },
        {
            "x": -2,
            "y": 0,
            "z": 5,
            "elements": [
                "minecraft:wool@8"
            ]
        },
        {
            "x": -3,
            "y": -2,
            "z": 2,
            "elements": [
                "minecraft:wool@8"
            ]
        },
        {
            "x": -3,
            "y": -2,
            "z": 3,
            "elements": [
                "minecraft:wool@8"
            ]
        },
        {
            "x": -7,
            "y": 7,
            "z": -5,
            "elements": [
                "minecraft:wool@8"
            ]
        },
        {
            "x": -7,
            "y": 7,
            "z": -4,
            "elements": [
                "minecraft:wool@8"
            ]
        },
        {
            "x": -7,
            "y": 7,
            "z": -3,
            "elements": [
                "minecraft:wool@8"
            ]
        },
        {
            "x": -7,
            "y": 7,
            "z": -2,
            "elements": [
                "minecraft:wool@8"
            ]
        },
        {
            "x": -2,
            "y": 0,
            "z": -1,
            "elements": [
                "minecraft:wool@15"
            ]
        },
        {
            "x": -2,
            "y": 0,
            "z": 0,
            "elements": [
                "minecraft:wool@15"
            ]
        },
        {
            "x": -2,
            "y": 0,
            "z": -3,
            "elements": [
                "minecraft:wool@15"
            ]
        },
        {
            "x": -7,
            "y": 7,
            "z": -6,
            "elements": [
                "minecraft:stained_hardened_clay@8"
            ]
        },
        {
            "x": -2,
            "y": 0,
            "z": -2,
            "elements": [
                "minecraft:wool@15"
            ]
        },
        {
            "x": -2,
            "y": -3,
            "z": 2,
            "elements": [
                "minecraft:wool@8"
            ]
        },
        {
            "x": -2,
            "y": -3,
            "z": 0,
            "elements": [
                "minecraft:wool@8"
            ]
        },
        {
            "x": -2,
            "y": -3,
            "z": 1,
            "elements": [
                "minecraft:wool@8"
            ]
        },
        {
            "x": -5,
            "y": 9,
            "z": -2,
            "elements": [
                "minecraft:wool@8"
            ]
        },
        {
            "x": -5,
            "y": 9,
            "z": -3,
            "elements": [
                "minecraft:wool@8"
            ]
        },
        {
            "x": -5,
            "y": 9,
            "z": -4,
            "elements": [
                "minecraft:wool@8"
            ]
        },
        {
            "x": -5,
            "y": 9,
            "z": -5,
            "elements": [
                "minecraft:wool@8"
            ]
        },
        {
            "x": -9,
            "y": 0,
            "z": -2,
            "elements": [
                "minecraft:wool@15"
            ]
        },
        {
            "x": -4,
            "y": 8,
            "z": -6,
            "elements": [
                "minecraft:stained_hardened_clay@8"
            ]
        },
        {
            "x": -4,
            "y": 8,
            "z": -1,
            "elements": [
                "minecraft:wool@8"
            ]
        },
        {
            "x": 0,
            "y": -2,
            "z": 2,
            "elements": [
                "minecraft:wool@1"
            ]
        },
        {
            "x": -9,
            "y": 0,
            "z": 3,
            "elements": [
                "minecraft:wool@15"
            ]
        },
        {
            "x": 0,
            "y": -2,
            "z": 1,
            "elements": [
                "minecraft:wool@1"
            ]
        },
        {
            "x": -1,
            "y": 2,
            "z": 1,
            "elements": [
                "minecraft:wool@15"
            ]
        },
        {
            "x": -1,
            "y": 2,
            "z": 0,
            "elements": [
                "minecraft:wool@15"
            ]
        },
        {
            "x": -1,
            "y": 2,
            "z": -1,
            "elements": [
                "minecraft:wool@15"
            ]
        },
        {
            "x": -1,
            "y": 2,
            "z": -2,
            "elements": [
                "minecraft:wool@15"
            ]
        },
        {
            "x": -1,
            "y": 2,
            "z": 4,
            "elements": [
                "minecraft:wool@15"
            ]
        },
        {
            "x": -1,
            "y": 2,
            "z": 3,
            "elements": [
                "minecraft:wool@15"
            ]
        },
        {
            "x": -1,
            "y": 2,
            "z": 2,
            "elements": [
                "minecraft:wool@15"
            ]
        },
        {
            "x": -2,
            "y": 9,
            "z": -4,
            "elements": [
                "minecraft:wool@8"
            ]
        },
        {
            "x": -6,
            "y": -6,
            "z": 1,
            "elements": [
                "minecraft:stained_hardened_clay@4"
            ]
        },
        {
            "x": -2,
            "y": 9,
            "z": -5,
            "elements": [
                "minecraft:wool@8"
            ]
        },
        {
            "x": 0,
            "y": 1,
            "z": -1,
            "elements": [
                "minecraft:wool@15"
            ]
        },
        {
            "x": 0,
            "y": 1,
            "z": 0,
            "elements": [
                "minecraft:wool@15"
            ]
        },
        {
            "x": 0,
            "y": 1,
            "z": 3,
            "elements": [
                "minecraft:wool@15"
            ]
        },
        {
            "x": 0,
            "y": 1,
            "z": 4,
            "elements": [
                "minecraft:wool@15"
            ]
        },
        {
            "x": -10,
            "y": -2,
            "z": -1,
            "elements": [
                "minecraft:concrete@0"
            ]
        },
        {
            "x": -6,
            "y": 3,
            "z": 0,
            "elements": [
                "minecraft:wool@0"
            ]
        },
        {
            "x": -6,
            "y": 3,
            "z": 1,
            "elements": [
                "minecraft:wool@0"
            ]
        },
        {
            "x": -10,
            "y": -2,
            "z": 0,
            "elements": [
                "minecraft:wool@0"
            ]
        },
        {
            "x": -6,
            "y": 3,
            "z": -2,
            "elements": [
                "minecraft:wool@0"
            ]
        },
        {
            "x": -10,
            "y": -2,
            "z": 1,
            "elements": [
                "minecraft:wool@0"
            ]
        },
        {
            "x": -10,
            "y": -2,
            "z": 2,
            "elements": [
                "minecraft:concrete@0"
            ]
        },
        {
            "x": -6,
            "y": 3,
            "z": -1,
            "elements": [
                "minecraft:wool@0"
            ]
        },
        {
            "x": -6,
            "y": 3,
            "z": -4,
            "elements": [
                "minecraft:wool@0"
            ]
        },
        {
            "x": -6,
            "y": 3,
            "z": -5,
            "elements": [
                "minecraft:wool@0"
            ]
        },
        {
            "x": -4,
            "y": -1,
            "z": -3,
            "elements": [
                "minecraft:wool@15"
            ]
        },
        {
            "x": -6,
            "y": -4,
            "z": 1,
            "elements": [
                "minecraft:wool@8"
            ]
        },
        {
            "x": -6,
            "y": 3,
            "z": 4,
            "elements": [
                "minecraft:wool@15"
            ]
        },
        {
            "x": -6,
            "y": 3,
            "z": 2,
            "elements": [
                "minecraft:wool@0"
            ]
        },
        {
            "x": -6,
            "y": 3,
            "z": 3,
            "elements": [
                "minecraft:wool@0"
            ]
        },
        {
            "x": -3,
            "y": 7,
            "z": -2,
            "elements": [
                "minecraft:wool@8"
            ]
        },
        {
            "x": -3,
            "y": 7,
            "z": -5,
            "elements": [
                "minecraft:wool@0"
            ]
        },
        {
            "x": -3,
            "y": 7,
            "z": -1,
            "elements": [
                "minecraft:wool@8"
            ]
        },
        {
            "x": -5,
            "y": -2,
            "z": -3,
            "elements": [
                "minecraft:wool@15"
            ]
        },
        {
            "x": -4,
            "y": 5,
            "z": -2,
            "elements": [
                "minecraft:stained_hardened_clay@8"
            ]
        },
        {
            "x": -5,
            "y": -2,
            "z": 3,
            "elements": [
                "minecraft:wool@8"
            ]
        },
        {
            "x": -5,
            "y": -2,
            "z": 2,
            "elements": [
                "minecraft:wool@8"
            ]
        },
        {
            "x": -5,
            "y": -2,
            "z": 4,
            "elements": [
                "modularmachinery:blockoutputbus"
            ]
        },
        {
            "x": -5,
            "y": -2,
            "z": -1,
            "elements": [
                "minecraft:wool@15"
            ]
        },
        {
            "x": -5,
            "y": -2,
            "z": -2,
            "elements": [
                "minecraft:wool@15"
            ]
        },
        {
            "x": -6,
            "y": 9,
            "z": -4,
            "elements": [
                "minecraft:wool@8"
            ]
        },
        {
            "x": -5,
            "y": -2,
            "z": 1,
            "elements": [
                "minecraft:wool@8"
            ]
        },
        {
            "x": -5,
            "y": -2,
            "z": 0,
            "elements": [
                "minecraft:wool@15"
            ]
        },
        {
            "x": -6,
            "y": 9,
            "z": -3,
            "elements": [
                "minecraft:wool@8"
            ]
        },
        {
            "x": 1,
            "y": -1,
            "z": 2,
            "elements": [
                "minecraft:wool@1"
            ]
        },
        {
            "x": 1,
            "y": -1,
            "z": 1,
            "elements": [
                "minecraft:wool@1"
            ]
        },
        {
            "x": -4,
            "y": 5,
            "z": -7,
            "elements": [
                "minecraft:wool@4"
            ]
        },
        {
            "x": -4,
            "y": 5,
            "z": -3,
            "elements": [
                "minecraft:stained_hardened_clay@8"
            ]
        },
        {
            "x": -4,
            "y": 5,
            "z": -6,
            "elements": [
                "minecraft:wool@4"
            ]
        },
        {
            "x": -5,
            "y": 5,
            "z": -7,
            "elements": [
                "minecraft:wool@4"
            ]
        },
        {
            "x": -5,
            "y": 5,
            "z": -6,
            "elements": [
                "minecraft:wool@4"
            ]
        },
        {
            "x": -5,
            "y": 5,
            "z": -3,
            "elements": [
                "minecraft:stained_hardened_clay@8"
            ]
        },
        {
            "x": -5,
            "y": 5,
            "z": -2,
            "elements": [
                "minecraft:stained_hardened_clay@8"
            ]
        },
        {
            "x": -6,
            "y": 9,
            "z": -6,
            "elements": [
                "minecraft:wool@8"
            ]
        },
        {
            "x": -6,
            "y": 9,
            "z": -5,
            "elements": [
                "minecraft:wool@8"
            ]
        },
        {
            "x": -5,
            "y": 3,
            "z": -6,
            "elements": [
                "minecraft:wool@14"
            ]
        },
        {
            "x": -5,
            "y": 3,
            "z": -2,
            "elements": [
                "minecraft:wool@15"
            ]
        },
        {
            "x": -5,
            "y": 3,
            "z": -1,
            "elements": [
                "minecraft:wool@15"
            ]
        },
        {
            "x": -5,
            "y": 3,
            "z": 0,
            "elements": [
                "minecraft:wool@15"
            ]
        },
        {
            "x": -5,
            "y": 3,
            "z": 1,
            "elements": [
                "minecraft:wool@15"
            ]
        },
        {
            "x": -5,
            "y": -3,
            "z": 0,
            "elements": [
                "minecraft:wool@8"
            ]
        },
        {
            "x": -5,
            "y": 3,
            "z": 2,
            "elements": [
                "minecraft:wool@15"
            ]
        },
        {
            "x": -5,
            "y": 3,
            "z": 3,
            "elements": [
                "minecraft:wool@15"
            ]
        },
        {
            "x": -5,
            "y": -3,
            "z": 2,
            "elements": [
                "minecraft:wool@8"
            ]
        },
        {
            "x": -4,
            "y": -1,
            "z": 4,
            "elements": [
                "minecraft:wool@8"
            ]
        },
        {
            "x": -5,
            "y": 3,
            "z": 4,
            "elements": [
                "minecraft:wool@0"
            ]
        },
        {
            "x": -5,
            "y": -3,
            "z": 1,
            "elements": [
                "minecraft:wool@8"
            ]
        },
        {
            "x": -4,
            "y": 7,
            "z": -5,
            "elements": [
                "minecraft:wool@0"
            ]
        },
        {
            "x": 2,
            "y": 0,
            "z": 0,
            "elements": [
                "minecraft:wool@0"
            ]
        },
        {
            "x": 2,
            "y": 0,
            "z": -1,
            "elements": [
                "minecraft:concrete@0"
            ]
        },
        {
            "x": 2,
            "y": 0,
            "z": 2,
            "elements": [
                "minecraft:concrete@0"
            ]
        },
        {
            "x": 2,
            "y": 0,
            "z": 1,
            "elements": [
                "minecraft:wool@0"
            ]
        },
        {
            "x": 2,
            "y": 0,
            "z": 4,
            "elements": [
                "minecraft:wool@15"
            ]
        },
        {
            "x": 2,
            "y": 0,
            "z": 3,
            "elements": [
                "minecraft:wool@15"
            ]
        },
        {
            "x": -7,
            "y": 0,
            "z": -1,
            "elements": [
                "minecraft:wool@15"
            ]
        },
        {
            "x": -7,
            "y": 0,
            "z": -2,
            "elements": [
                "minecraft:wool@15"
            ]
        },
        {
            "x": -7,
            "y": 0,
            "z": 1,
            "elements": [
                "minecraft:wool@15"
            ]
        },
        {
            "x": -7,
            "y": 0,
            "z": 0,
            "elements": [
                "minecraft:wool@15"
            ]
        },
        {
            "x": -7,
            "y": 0,
            "z": 3,
            "elements": [
                "minecraft:wool@15"
            ]
        },
        {
            "x": -7,
            "y": 0,
            "z": 2,
            "elements": [
                "minecraft:wool@15"
            ]
        },
        {
            "x": -7,
            "y": 0,
            "z": 5,
            "elements": [
                "minecraft:wool@8"
            ]
        },
        {
            "x": -6,
            "y": 8,
            "z": -6,
            "elements": [
                "minecraft:stained_hardened_clay@8"
            ]
        },
        {
            "x": -7,
            "y": 0,
            "z": 4,
            "elements": [
                "minecraft:wool@8"
            ]
        },
        {
            "x": -6,
            "y": 8,
            "z": -1,
            "elements": [
                "minecraft:wool@8"
            ]
        },
        {
            "x": -6,
            "y": 8,
            "z": -2,
            "elements": [
                "minecraft:wool@8"
            ]
        },
        {
            "x": -9,
            "y": 1,
            "z": -2,
            "elements": [
                "minecraft:wool@15"
            ]
        },
        {
            "x": -6,
            "y": 1,
            "z": 5,
            "elements": [
                "minecraft:wool@15"
            ]
        },
        {
            "x": -7,
            "y": 0,
            "z": -3,
            "elements": [
                "minecraft:wool@15"
            ]
        },
        {
            "x": -6,
            "y": 1,
            "z": 4,
            "elements": [
                "minecraft:wool@15"
            ]
        },
        {
            "x": -9,
            "y": 1,
            "z": 1,
            "elements": [
                "minecraft:wool@15"
            ]
        },
        {
            "x": -9,
            "y": 1,
            "z": 2,
            "elements": [
                "minecraft:wool@15"
            ]
        },
        {
            "x": -9,
            "y": 1,
            "z": -1,
            "elements": [
                "minecraft:wool@15"
            ]
        },
        {
            "x": -1,
            "y": 1,
            "z": 3,
            "elements": [
                "minecraft:wool@1"
            ]
        },
        {
            "x": -9,
            "y": 1,
            "z": 0,
            "elements": [
                "minecraft:wool@15"
            ]
        },
        {
            "x": -3,
            "y": 2,
            "z": -5,
            "elements": [
                "minecraft:concrete@0"
            ]
        },
        {
            "x": -3,
            "y": 2,
            "z": -4,
            "elements": [
                "minecraft:wool@0"
            ]
        },
        {
            "x": -3,
            "y": 2,
            "z": -3,
            "elements": [
                "minecraft:wool@0"
            ]
        },
        {
            "x": -9,
            "y": 1,
            "z": 3,
            "elements": [
                "minecraft:wool@15"
            ]
        },
        {
            "x": -1,
            "y": 1,
            "z": 0,
            "elements": [
                "minecraft:wool@1"
            ]
        },
        {
            "x": 0,
            "y": 2,
            "z": 2,
            "elements": [
                "minecraft:wool@15"
            ]
        },
        {
            "x": 0,
            "y": 2,
            "z": 1,
            "elements": [
                "minecraft:wool@15"
            ]
        },
        {
            "x": 0,
            "y": 2,
            "z": 4,
            "elements": [
                "minecraft:wool@15"
            ]
        },
        {
            "x": 0,
            "y": 2,
            "z": 3,
            "elements": [
                "minecraft:wool@15"
            ]
        },
        {
            "x": 0,
            "y": 2,
            "z": 0,
            "elements": [
                "minecraft:wool@15"
            ]
        },
        {
            "x": 0,
            "y": 2,
            "z": -1,
            "elements": [
                "minecraft:wool@15"
            ]
        },
        {
            "x": -7,
            "y": -7,
            "z": -1,
            "elements": [
                "minecraft:wool@4"
            ]
        },
        {
            "x": -7,
            "y": -7,
            "z": 0,
            "elements": [
                "minecraft:concrete@4"
            ]
        },
        {
            "x": -6,
            "y": -5,
            "z": 1,
            "elements": [
                "minecraft:wool@4"
            ]
        },
        {
            "x": -3,
            "y": 8,
            "z": -1,
            "elements": [
                "minecraft:wool@8"
            ]
        },
        {
            "x": -3,
            "y": 8,
            "z": -2,
            "elements": [
                "minecraft:wool@8"
            ]
        },
        {
            "x": -3,
            "y": 8,
            "z": -6,
            "elements": [
                "minecraft:stained_hardened_clay@8"
            ]
        },
        {
            "x": -1,
            "y": 0,
            "z": 3,
            "elements": [
                "minecraft:wool@1"
            ]
        },
        {
            "x": -6,
            "y": 2,
            "z": 4,
            "elements": [
                "minecraft:wool@15"
            ]
        },
        {
            "x": -1,
            "y": 0,
            "z": 0,
            "elements": [
                "minecraft:wool@1"
            ]
        },
        {
            "x": -6,
            "y": 2,
            "z": -3,
            "elements": [
                "minecraft:wool@0"
            ]
        },
        {
            "x": -3,
            "y": -4,
            "z": 1,
            "elements": [
                "minecraft:wool@8"
            ]
        },
        {
            "x": -6,
            "y": 2,
            "z": -4,
            "elements": [
                "minecraft:wool@0"
            ]
        },
        {
            "x": -7,
            "y": 6,
            "z": -5,
            "elements": [
                "minecraft:stained_hardened_clay@8"
            ]
        },
        {
            "x": -6,
            "y": 2,
            "z": -5,
            "elements": [
                "minecraft:concrete@0"
            ]
        },
        {
            "x": -7,
            "y": 6,
            "z": -4,
            "elements": [
                "minecraft:wool@8"
            ]
        },
        {
            "x": -7,
            "y": 6,
            "z": -3,
            "elements": [
                "minecraft:stained_hardened_clay@8"
            ]
        },
        {
            "x": -4,
            "y": 6,
            "z": -2,
            "elements": [
                "minecraft:wool@8"
            ]
        },
        {
            "x": -4,
            "y": 6,
            "z": -1,
            "elements": [
                "minecraft:wool@8"
            ]
        },
        {
            "x": -4,
            "y": 6,
            "z": -5,
            "elements": [
                "minecraft:wool@0"
            ]
        },
        {
            "x": -4,
            "y": 0,
            "z": -3,
            "elements": [
                "minecraft:wool@15"
            ]
        },
        {
            "x": -3,
            "y": 2,
            "z": 4,
            "elements": [
                "minecraft:wool@15"
            ]
        },
        {
            "x": -4,
            "y": 0,
            "z": 4,
            "elements": [
                "minecraft:wool@8"
            ]
        },
        {
            "x": -5,
            "y": 4,
            "z": -3,
            "elements": [
                "minecraft:concrete@0"
            ]
        },
        {
            "x": -10,
            "y": -1,
            "z": -2,
            "elements": [
                "minecraft:concrete@0"
            ]
        },
        {
            "x": -5,
            "y": 4,
            "z": -7,
            "elements": [
                "minecraft:concrete@4"
            ]
        },
        {
            "x": -10,
            "y": -1,
            "z": -1,
            "elements": [
                "minecraft:wool@0"
            ]
        },
        {
            "x": -10,
            "y": -1,
            "z": 0,
            "elements": [
                "minecraft:wool@0"
            ]
        },
        {
            "x": -10,
            "y": -1,
            "z": 1,
            "elements": [
                "minecraft:concrete@0"
            ]
        },
        {
            "x": -10,
            "y": -1,
            "z": 2,
            "elements": [
                "minecraft:wool@15"
            ]
        },
        {
            "x": -10,
            "y": -1,
            "z": 3,
            "elements": [
                "minecraft:wool@15"
            ]
        }
    ]}