{   "registryname": "workshop",
    "localizedname": "集成式处理车间",
    "requires-blueprint": false,
    "color": "FFFFFF",
    "parts": [
        {
            "x": -13,
            "y": 4,
            "z": 4,
            "elements": [
                "modularmachinery:blockcasing@0"
            ]
        },
        {
            "x": -13,
            "y": 4,
            "z": 5,
            "elements": [
                "minecraft:end_rod@5"
            ]
        },
        {
            "x": -13,
            "y": 4,
            "z": 2,
            "elements": [
                "modularmachinery:blockcasing@0"
            ]
        },
        {
            "x": -13,
            "y": 4,
            "z": 3,
            "elements": [
                "modularmachinery:blockcasing@0"
            ]
        },
        {
            "x": -14,
            "y": 3,
            "z": -7,
            "elements": [
                "minecraft:concrete@7"
            ]
        },
        {
            "x": -13,
            "y": 4,
            "z": 0,
            "elements": [
                "modularmachinery:blockcasing@1"
            ]
        },
        {
            "x": -13,
            "y": 4,
            "z": 1,
            "elements": [
                "modularmachinery:blockcasing@1"
            ]
        },
        {
            "x": -13,
            "y": 4,
            "z": -2,
            "elements": [
                "modularmachinery:blockcasing@0"
            ]
        },
        {
            "x": -13,
            "y": 4,
            "z": -1,
            "elements": [
                "modularmachinery:blockcasing@1"
            ]
        },
        {
            "x": -13,
            "y": 4,
            "z": -4,
            "elements": [
                "modularmachinery:blockcasing@0"
            ]
        },
        {
            "x": -13,
            "y": 4,
            "z": -3,
            "elements": [
                "modularmachinery:blockcasing@0"
            ]
        },
        {
            "x": -13,
            "y": 4,
            "z": -5,
            "elements": [
                "minecraft:end_rod@5"
            ]
        },
        {
            "x": -12,
            "y": 5,
            "z": -3,
            "elements": [
                "appliedenergistics2:smooth_sky_stone_slab@0"
            ]
        },
        {
            "x": 3,
            "y": -3,
            "z": 7,
            "elements": [
                "appliedenergistics2:smooth_sky_stone_block@0"
            ]
        },
        {
            "x": -12,
            "y": 5,
            "z": 2,
            "elements": [
                "minecraft:concrete@7"
            ]
        },
        {
            "x": -12,
            "y": 5,
            "z": 3,
            "elements": [
                "appliedenergistics2:smooth_sky_stone_slab@0"
            ]
        },
        {
            "x": -12,
            "y": 5,
            "z": -2,
            "elements": [
                "minecraft:concrete@7"
            ]
        },
        {
            "x": -14,
            "y": 3,
            "z": 5,
            "elements": [
                "modularmachinery:blockcasing@0"
            ]
        },
        {
            "x": -16,
            "y": 1,
            "z": -6,
            "elements": [
                "modularmachinery:blockcasing@0"
            ]
        },
        {
            "x": -16,
            "y": 1,
            "z": -5,
            "elements": [
                "modularmachinery:blockcasing@0"
            ]
        },
        {
            "x": -14,
            "y": 3,
            "z": 7,
            "elements": [
                "minecraft:concrete@7"
            ]
        },
        {
            "x": -14,
            "y": 3,
            "z": 6,
            "elements": [
                "minecraft:concrete@7"
            ]
        },
        {
            "x": 9,
            "y": 5,
            "z": -2,
            "elements": [
                "minecraft:concrete@7"
            ]
        },
        {
            "x": 9,
            "y": 5,
            "z": 0,
            "elements": [
                "minecraft:concrete@7"
            ]
        },
        {
            "x": -14,
            "y": 3,
            "z": -5,
            "elements": [
                "modularmachinery:blockcasing@0"
            ]
        },
        {
            "x": 9,
            "y": 5,
            "z": 2,
            "elements": [
                "minecraft:concrete@7"
            ]
        },
        {
            "x": -14,
            "y": 3,
            "z": -6,
            "elements": [
                "minecraft:concrete@7"
            ]
        },
        {
            "x": 4,
            "y": 0,
            "z": -7,
            "elements": [
                "modularmachinery:blockcasing@3"
            ]
        },
        {
            "x": -16,
            "y": -1,
            "z": 6,
            "elements": [
                "modularmachinery:blockcasing@0"
            ]
        },
        {
            "x": -16,
            "y": -1,
            "z": -6,
            "elements": [
                "modularmachinery:blockcasing@0"
            ]
        },
        {
            "x": 7,
            "y": 1,
            "z": -5,
            "elements": [
                "modularmachinery:blockcasing@0"
            ]
        },
        {
            "x": 3,
            "y": -1,
            "z": 7,
            "elements": [
                "modularmachinery:blockcasing@0"
            ]
        },
        {
            "x": 3,
            "y": -1,
            "z": -7,
            "elements": [
                "modularmachinery:blockcasing@0"
            ]
        },
        {
            "x": 4,
            "y": 0,
            "z": 7,
            "elements": [
                "modularmachinery:blockcasing@3"
            ]
        },
        {
            "x": -13,
            "y": 6,
            "z": 0,
            "elements": [
                "minecraft:concrete@7"
            ]
        },
        {
            "x": 6,
            "y": 2,
            "z": 6,
            "elements": [
                "quark:snow_bricks_stairs@3"
            ]
        },
        {
            "x": 6,
            "y": 2,
            "z": 5,
            "elements": [
                "modularmachinery:blockcasing@0"
            ]
        },
        {
            "x": -16,
            "y": 3,
            "z": 1,
            "elements": [
                "modularmachinery:blockcasing@1"
            ]
        },
        {
            "x": -19,
            "y": -4,
            "z": -5,
            "elements": [
                "minecraft:concrete@4"
            ]
        },
        {
            "x": -16,
            "y": 3,
            "z": 0,
            "elements": [
                "modularmachinery:blockcasing@1"
            ]
        },
        {
            "x": -19,
            "y": -4,
            "z": -6,
            "elements": [
                "minecraft:concrete@4"
            ]
        },
        {
            "x": -16,
            "y": 3,
            "z": 3,
            "elements": [
                "modularmachinery:blockcasing@1"
            ]
        },
        {
            "x": -19,
            "y": -4,
            "z": -3,
            "elements": [
                "minecraft:concrete@4"
            ]
        },
        {
            "x": -19,
            "y": -4,
            "z": -4,
            "elements": [
                "minecraft:concrete@4"
            ]
        },
        {
            "x": -16,
            "y": 3,
            "z": 2,
            "elements": [
                "modularmachinery:blockcasing@1"
            ]
        },
        {
            "x": -19,
            "y": -4,
            "z": -9,
            "elements": [
                "minecraft:concrete@4"
            ]
        },
        {
            "x": -16,
            "y": 3,
            "z": -3,
            "elements": [
                "modularmachinery:blockcasing@1"
            ]
        },
        {
            "x": -16,
            "y": 3,
            "z": -4,
            "elements": [
                "modularmachinery:blockcasing@0"
            ]
        },
        {
            "x": -16,
            "y": 3,
            "z": -1,
            "elements": [
                "modularmachinery:blockcasing@1"
            ]
        },
        {
            "x": -19,
            "y": -4,
            "z": -7,
            "elements": [
                "minecraft:concrete@4"
            ]
        },
        {
            "x": -19,
            "y": -4,
            "z": -8,
            "elements": [
                "minecraft:concrete@4"
            ]
        },
        {
            "x": -16,
            "y": 3,
            "z": -2,
            "elements": [
                "modularmachinery:blockcasing@1"
            ]
        },
        {
            "x": -19,
            "y": -4,
            "z": 3,
            "elements": [
                "minecraft:concrete@4"
            ]
        },
        {
            "x": -19,
            "y": -4,
            "z": 2,
            "elements": [
                "minecraft:concrete@4"
            ]
        },
        {
            "x": -19,
            "y": -4,
            "z": 5,
            "elements": [
                "minecraft:concrete@4"
            ]
        },
        {
            "x": -19,
            "y": -4,
            "z": 4,
            "elements": [
                "minecraft:concrete@4"
            ]
        },
        {
            "x": -19,
            "y": -4,
            "z": -1,
            "elements": [
                "minecraft:concrete@4"
            ]
        },
        {
            "x": 5,
            "y": 3,
            "z": -4,
            "elements": [
                "thermalfoundation:glass_alloy@7"
            ]
        },
        {
            "x": -19,
            "y": -4,
            "z": -2,
            "elements": [
                "minecraft:concrete@4"
            ]
        },
        {
            "x": -16,
            "y": 3,
            "z": 4,
            "elements": [
                "modularmachinery:blockcasing@0"
            ]
        },
        {
            "x": 2,
            "y": -4,
            "z": -8,
            "elements": [
                "minecraft:concrete@7"
            ]
        },
        {
            "x": -19,
            "y": -4,
            "z": 1,
            "elements": [
                "minecraft:concrete@4"
            ]
        },
        {
            "x": 5,
            "y": 3,
            "z": -2,
            "elements": [
                "thermalfoundation:glass_alloy@7"
            ]
        },
        {
            "x": -19,
            "y": -4,
            "z": 0,
            "elements": [
                "minecraft:concrete@4"
            ]
        },
        {
            "x": 2,
            "y": -4,
            "z": -9,
            "elements": [
                "minecraft:concrete@4"
            ]
        },
        {
            "x": 5,
            "y": 3,
            "z": -3,
            "elements": [
                "thermalfoundation:glass_alloy@7"
            ]
        },
        {
            "x": -15,
            "y": 2,
            "z": -1,
            "elements": [
                "minecraft:stained_glass_pane@15"
            ]
        },
        {
            "x": 2,
            "y": -4,
            "z": -6,
            "elements": [
                "minecraft:concrete@7"
            ]
        },
        {
            "x": -15,
            "y": 2,
            "z": -2,
            "elements": [
                "minecraft:stained_glass_pane@15"
            ]
        },
        {
            "x": 2,
            "y": -4,
            "z": -7,
            "elements": [
                "minecraft:concrete@7"
            ]
        },
        {
            "x": 2,
            "y": -4,
            "z": -4,
            "elements": [
                "minecraft:concrete@7"
            ]
        },
        {
            "x": -15,
            "y": 2,
            "z": -3,
            "elements": [
                "minecraft:stained_glass_pane@15"
            ]
        },
        {
            "x": 12,
            "y": 6,
            "z": 0,
            "elements": [
                "minecraft:concrete@7"
            ]
        },
        {
            "x": -15,
            "y": 2,
            "z": -4,
            "elements": [
                "minecraft:concrete@7"
            ]
        },
        {
            "x": 2,
            "y": -4,
            "z": -5,
            "elements": [
                "minecraft:concrete@7"
            ]
        },
        {
            "x": 2,
            "y": -4,
            "z": -2,
            "elements": [
                "minecraft:concrete@7"
            ]
        },
        {
            "x": -19,
            "y": -4,
            "z": 7,
            "elements": [
                "minecraft:concrete@4"
            ]
        },
        {
            "x": -15,
            "y": 2,
            "z": 3,
            "elements": [
                "minecraft:stained_glass_pane@15"
            ]
        },
        {
            "x": 2,
            "y": -4,
            "z": -3,
            "elements": [
                "minecraft:concrete@7"
            ]
        },
        {
            "x": -15,
            "y": 2,
            "z": 2,
            "elements": [
                "minecraft:stained_glass_pane@15"
            ]
        },
        {
            "x": -19,
            "y": -4,
            "z": 6,
            "elements": [
                "minecraft:concrete@4"
            ]
        },
        {
            "x": -19,
            "y": -4,
            "z": 9,
            "elements": [
                "minecraft:concrete@4"
            ]
        },
        {
            "x": 2,
            "y": -4,
            "z": 0,
            "elements": [
                "minecraft:concrete@7"
            ]
        },
        {
            "x": -15,
            "y": 2,
            "z": 1,
            "elements": [
                "minecraft:stained_glass_pane@15"
            ]
        },
        {
            "x": -15,
            "y": 2,
            "z": 0,
            "elements": [
                "minecraft:stained_glass_pane@15"
            ]
        },
        {
            "x": 2,
            "y": -4,
            "z": -1,
            "elements": [
                "minecraft:concrete@7"
            ]
        },
        {
            "x": -19,
            "y": -4,
            "z": 8,
            "elements": [
                "minecraft:concrete@4"
            ]
        },
        {
            "x": 2,
            "y": -4,
            "z": 2,
            "elements": [
                "minecraft:concrete@7"
            ]
        },
        {
            "x": -15,
            "y": 2,
            "z": 7,
            "elements": [
                "quark:snow_bricks_stairs@3"
            ]
        },
        {
            "x": 2,
            "y": -4,
            "z": 1,
            "elements": [
                "minecraft:concrete@7"
            ]
        },
        {
            "x": -15,
            "y": 2,
            "z": 6,
            "elements": [
                "modularmachinery:blockcasing@0"
            ]
        },
        {
            "x": 2,
            "y": -4,
            "z": 4,
            "elements": [
                "minecraft:concrete@7"
            ]
        },
        {
            "x": -15,
            "y": 2,
            "z": 5,
            "elements": [
                "modularmachinery:blockcasing@0"
            ]
        },
        {
            "x": 2,
            "y": -4,
            "z": 3,
            "elements": [
                "minecraft:concrete@7"
            ]
        },
        {
            "x": -15,
            "y": 2,
            "z": 4,
            "elements": [
                "minecraft:concrete@7"
            ]
        },
        {
            "x": -14,
            "y": 1,
            "z": -7,
            "elements": [
                "modularmachinery:blockcasing@0"
            ]
        },
        {
            "x": 2,
            "y": -4,
            "z": 6,
            "elements": [
                "minecraft:concrete@7"
            ]
        },
        {
            "x": -14,
            "y": 1,
            "z": -8,
            "elements": [
                "appliedenergistics2:smooth_sky_stone_stairs@6"
            ]
        },
        {
            "x": 2,
            "y": -4,
            "z": 5,
            "elements": [
                "minecraft:concrete@7"
            ]
        },
        {
            "x": 2,
            "y": -4,
            "z": 8,
            "elements": [
                "minecraft:concrete@7"
            ]
        },
        {
            "x": 2,
            "y": -4,
            "z": 7,
            "elements": [
                "minecraft:concrete@7"
            ]
        },
        {
            "x": 2,
            "y": -4,
            "z": 9,
            "elements": [
                "minecraft:concrete@4"
            ]
        },
        {
            "x": 6,
            "y": 2,
            "z": -5,
            "elements": [
                "modularmachinery:blockcasing@0"
            ]
        },
        {
            "x": -9,
            "y": 6,
            "z": 0,
            "elements": [
                "minecraft:concrete@7"
            ]
        },
        {
            "x": 6,
            "y": 2,
            "z": -6,
            "elements": [
                "quark:snow_bricks_stairs@2"
            ]
        },
        {
            "x": -14,
            "y": 1,
            "z": 7,
            "elements": [
                "modularmachinery:blockcasing@0"
            ]
        },
        {
            "x": 7,
            "y": 1,
            "z": 5,
            "elements": [
                "modularmachinery:blockcasing@0"
            ]
        },
        {
            "x": -15,
            "y": 2,
            "z": -5,
            "elements": [
                "minecraft:concrete@7"
            ]
        },
        {
            "x": -15,
            "y": 2,
            "z": -6,
            "elements": [
                "modularmachinery:blockcasing@0"
            ]
        },
        {
            "x": -14,
            "y": 1,
            "z": 8,
            "elements": [
                "appliedenergistics2:smooth_sky_stone_stairs@7"
            ]
        },
        {
            "x": -15,
            "y": 2,
            "z": -7,
            "elements": [
                "quark:snow_bricks_stairs@2"
            ]
        },
        {
            "x": 3,
            "y": 1,
            "z": -7,
            "elements": [
                "quark:snow_bricks_stairs@2"
            ]
        },
        {
            "x": 3,
            "y": 1,
            "z": -6,
            "elements": [
                "modularmachinery:blockcasing@0"
            ]
        },
        {
            "x": 4,
            "y": 2,
            "z": 5,
            "elements": [
                "thermalfoundation:glass_alloy@7"
            ]
        },
        {
            "x": 4,
            "y": 2,
            "z": -5,
            "elements": [
                "thermalfoundation:glass_alloy@7"
            ]
        },
        {
            "x": -14,
            "y": -1,
            "z": 7,
            "elements": [
                "modularmachinery:blockcasing@0"
            ]
        },
        {
            "x": 5,
            "y": 3,
            "z": 0,
            "elements": [
                "thermalfoundation:glass_alloy@7"
            ]
        },
        {
            "x": 5,
            "y": 3,
            "z": -1,
            "elements": [
                "thermalfoundation:glass_alloy@7"
            ]
        },
        {
            "x": 5,
            "y": 3,
            "z": 2,
            "elements": [
                "thermalfoundation:glass_alloy@7"
            ]
        },
        {
            "x": 5,
            "y": 3,
            "z": 1,
            "elements": [
                "thermalfoundation:glass_alloy@7"
            ]
        },
        {
            "x": -14,
            "y": -1,
            "z": 8,
            "elements": [
                "appliedenergistics2:smooth_sky_stone_stairs@7"
            ]
        },
        {
            "x": 5,
            "y": 3,
            "z": 4,
            "elements": [
                "thermalfoundation:glass_alloy@7"
            ]
        },
        {
            "x": 5,
            "y": 3,
            "z": 3,
            "elements": [
                "thermalfoundation:glass_alloy@7"
            ]
        },
        {
            "x": 3,
            "y": 1,
            "z": 7,
            "elements": [
                "quark:snow_bricks_stairs@3"
            ]
        },
        {
            "x": 3,
            "y": 1,
            "z": 6,
            "elements": [
                "modularmachinery:blockcasing@0"
            ]
        },
        {
            "x": -15,
            "y": 4,
            "z": 5,
            "elements": [
                "quark:snow_bricks_stairs@3"
            ]
        },
        {
            "x": -15,
            "y": 4,
            "z": 4,
            "elements": [
                "modularmachinery:blockcasing@0"
            ]
        },
        {
            "x": -15,
            "y": 4,
            "z": 3,
            "elements": [
                "modularmachinery:blockcasing@0"
            ]
        },
        {
            "x": -15,
            "y": 4,
            "z": 2,
            "elements": [
                "modularmachinery:blockcasing@0"
            ]
        },
        {
            "x": -15,
            "y": 4,
            "z": -3,
            "elements": [
                "modularmachinery:blockcasing@0"
            ]
        },
        {
            "x": -15,
            "y": 4,
            "z": -4,
            "elements": [
                "modularmachinery:blockcasing@0"
            ]
        },
        {
            "x": -15,
            "y": 4,
            "z": -5,
            "elements": [
                "quark:snow_bricks_stairs@2"
            ]
        },
        {
            "x": -15,
            "y": 4,
            "z": 1,
            "elements": [
                "modularmachinery:blockcasing@0"
            ]
        },
        {
            "x": -15,
            "y": 4,
            "z": 0,
            "elements": [
                "modularmachinery:blockcasing@0"
            ]
        },
        {
            "x": -15,
            "y": 4,
            "z": -1,
            "elements": [
                "modularmachinery:blockcasing@0"
            ]
        },
        {
            "x": -15,
            "y": 4,
            "z": -2,
            "elements": [
                "modularmachinery:blockcasing@0"
            ]
        },
        {
            "x": 10,
            "y": 2,
            "z": 1,
            "elements": [
                "minecraft:concrete@7"
            ]
        },
        {
            "x": 10,
            "y": 4,
            "z": 5,
            "elements": [
                "quark:snow_bricks_stairs@3"
            ]
        },
        {
            "x": -12,
            "y": 3,
            "z": 5,
            "elements": [
                "modularmachinery:blockcasing@0"
            ]
        },
        {
            "x": 10,
            "y": 2,
            "z": 2,
            "elements": [
                "minecraft:concrete@7"
            ]
        },
        {
            "x": -14,
            "y": -1,
            "z": -7,
            "elements": [
                "modularmachinery:blockcasing@0"
            ]
        },
        {
            "x": 10,
            "y": 2,
            "z": -1,
            "elements": [
                "minecraft:concrete@7"
            ]
        },
        {
            "x": 10,
            "y": 2,
            "z": 0,
            "elements": [
                "minecraft:concrete@7"
            ]
        },
        {
            "x": -14,
            "y": -1,
            "z": -8,
            "elements": [
                "appliedenergistics2:smooth_sky_stone_stairs@6"
            ]
        },
        {
            "x": 10,
            "y": 2,
            "z": -3,
            "elements": [
                "minecraft:concrete@7"
            ]
        },
        {
            "x": 10,
            "y": 4,
            "z": 2,
            "elements": [
                "modularmachinery:blockcasing@0"
            ]
        },
        {
            "x": 10,
            "y": 2,
            "z": -2,
            "elements": [
                "minecraft:concrete@7"
            ]
        },
        {
            "x": 10,
            "y": 4,
            "z": 1,
            "elements": [
                "modularmachinery:blockcasing@0"
            ]
        },
        {
            "x": 10,
            "y": 2,
            "z": -5,
            "elements": [
                "minecraft:concrete@7"
            ]
        },
        {
            "x": 10,
            "y": 4,
            "z": 4,
            "elements": [
                "modularmachinery:blockcasing@0"
            ]
        },
        {
            "x": 10,
            "y": 2,
            "z": -4,
            "elements": [
                "minecraft:concrete@7"
            ]
        },
        {
            "x": 10,
            "y": 4,
            "z": 3,
            "elements": [
                "modularmachinery:blockcasing@0"
            ]
        },
        {
            "x": 10,
            "y": 4,
            "z": -2,
            "elements": [
                "modularmachinery:blockcasing@0"
            ]
        },
        {
            "x": 10,
            "y": 4,
            "z": -3,
            "elements": [
                "modularmachinery:blockcasing@0"
            ]
        },
        {
            "x": 10,
            "y": 2,
            "z": 7,
            "elements": [
                "quark:snow_bricks_stairs@3"
            ]
        },
        {
            "x": 10,
            "y": 4,
            "z": 0,
            "elements": [
                "modularmachinery:blockcasing@0"
            ]
        },
        {
            "x": 10,
            "y": 4,
            "z": -1,
            "elements": [
                "modularmachinery:blockcasing@0"
            ]
        },
        {
            "x": 10,
            "y": 2,
            "z": 5,
            "elements": [
                "minecraft:concrete@7"
            ]
        },
        {
            "x": 10,
            "y": 2,
            "z": 6,
            "elements": [
                "modularmachinery:blockcasing@0"
            ]
        },
        {
            "x": 10,
            "y": 4,
            "z": -4,
            "elements": [
                "modularmachinery:blockcasing@0"
            ]
        },
        {
            "x": 10,
            "y": 2,
            "z": 3,
            "elements": [
                "minecraft:concrete@7"
            ]
        },
        {
            "x": -12,
            "y": 3,
            "z": -5,
            "elements": [
                "modularmachinery:blockcasing@0"
            ]
        },
        {
            "x": 10,
            "y": 4,
            "z": -5,
            "elements": [
                "quark:snow_bricks_stairs@2"
            ]
        },
        {
            "x": 10,
            "y": 2,
            "z": 4,
            "elements": [
                "minecraft:concrete@7"
            ]
        },
        {
            "x": -2,
            "y": -4,
            "z": -9,
            "elements": [
                "minecraft:concrete@4"
            ]
        },
        {
            "x": -2,
            "y": -4,
            "z": -8,
            "elements": [
                "minecraft:concrete@7"
            ]
        },
        {
            "x": -14,
            "y": 5,
            "z": -5,
            "elements": [
                "appliedenergistics2:smooth_sky_stone_slab@0"
            ]
        },
        {
            "x": -14,
            "y": 5,
            "z": -3,
            "elements": [
                "appliedenergistics2:smooth_sky_stone_slab@0"
            ]
        },
        {
            "x": -2,
            "y": -4,
            "z": -5,
            "elements": [
                "minecraft:concrete@7"
            ]
        },
        {
            "x": -2,
            "y": -4,
            "z": -4,
            "elements": [
                "minecraft:concrete@7"
            ]
        },
        {
            "x": -14,
            "y": 5,
            "z": -4,
            "elements": [
                "appliedenergistics2:smooth_sky_stone_slab@0"
            ]
        },
        {
            "x": -2,
            "y": -4,
            "z": -7,
            "elements": [
                "minecraft:concrete@7"
            ]
        },
        {
            "x": -14,
            "y": 5,
            "z": -2,
            "elements": [
                "minecraft:concrete@7"
            ]
        },
        {
            "x": -2,
            "y": -4,
            "z": -6,
            "elements": [
                "minecraft:concrete@7"
            ]
        },
        {
            "x": -15,
            "y": -2,
            "z": -2,
            "elements": [
                "minecraft:concrete@7"
            ]
        },
        {
            "x": -14,
            "y": 5,
            "z": 3,
            "elements": [
                "appliedenergistics2:smooth_sky_stone_slab@0"
            ]
        },
        {
            "x": -14,
            "y": 5,
            "z": 2,
            "elements": [
                "minecraft:concrete@7"
            ]
        },
        {
            "x": -14,
            "y": 5,
            "z": 5,
            "elements": [
                "appliedenergistics2:smooth_sky_stone_slab@0"
            ]
        },
        {
            "x": -14,
            "y": 5,
            "z": 4,
            "elements": [
                "appliedenergistics2:smooth_sky_stone_slab@0"
            ]
        },
        {
            "x": -15,
            "y": -2,
            "z": -7,
            "elements": [
                "modularmachinery:blockcasing@0"
            ]
        },
        {
            "x": -15,
            "y": -2,
            "z": -6,
            "elements": [
                "minecraft:concrete@7"
            ]
        },
        {
            "x": -15,
            "y": -2,
            "z": 6,
            "elements": [
                "minecraft:concrete@7"
            ]
        },
        {
            "x": -15,
            "y": -2,
            "z": 7,
            "elements": [
                "modularmachinery:blockcasing@0"
            ]
        },
        {
            "x": -15,
            "y": -2,
            "z": 2,
            "elements": [
                "minecraft:concrete@7"
            ]
        },
        {
            "x": 6,
            "y": 0,
            "z": 7,
            "elements": [
                "modularmachinery:blockcasing@0"
            ]
        },
        {
            "x": 14,
            "y": 6,
            "z": 0,
            "elements": [
                "minecraft:concrete@7"
            ]
        },
        {
            "x": -13,
            "y": 2,
            "z": -6,
            "elements": [
                "modularmachinery:blockcasing@0"
            ]
        },
        {
            "x": -13,
            "y": 2,
            "z": 7,
            "elements": [
                "minecraft:end_rod@5"
            ]
        },
        {
            "x": -13,
            "y": 2,
            "z": 6,
            "elements": [
                "modularmachinery:blockcasing@0"
            ]
        },
        {
            "x": -9,
            "y": 4,
            "z": 0,
            "elements": [
                "minecraft:concrete@7"
            ]
        },
        {
            "x": -9,
            "y": 4,
            "z": 2,
            "elements": [
                "minecraft:concrete@7"
            ]
        },
        {
            "x": -9,
            "y": 4,
            "z": -2,
            "elements": [
                "minecraft:concrete@7"
            ]
        },
        {
            "x": 6,
            "y": 0,
            "z": -7,
            "elements": [
                "modularmachinery:blockcasing@0"
            ]
        },
        {
            "x": -16,
            "y": 1,
            "z": 6,
            "elements": [
                "modularmachinery:blockcasing@0"
            ]
        },
        {
            "x": 9,
            "y": 1,
            "z": 5,
            "elements": [
                "modularmachinery:blockcasing@0"
            ]
        },
        {
            "x": -16,
            "y": 1,
            "z": 5,
            "elements": [
                "modularmachinery:blockcasing@0"
            ]
        },
        {
            "x": 11,
            "y": 5,
            "z": -2,
            "elements": [
                "minecraft:concrete@7"
            ]
        },
        {
            "x": 4,
            "y": -4,
            "z": 8,
            "elements": [
                "minecraft:concrete@7"
            ]
        },
        {
            "x": -11,
            "y": 6,
            "z": 0,
            "elements": [
                "minecraft:concrete@7"
            ]
        },
        {
            "x": 4,
            "y": -4,
            "z": 7,
            "elements": [
                "minecraft:concrete@7"
            ]
        },
        {
            "x": 11,
            "y": 5,
            "z": -3,
            "elements": [
                "appliedenergistics2:smooth_sky_stone_slab@0"
            ]
        },
        {
            "x": 11,
            "y": 5,
            "z": -4,
            "elements": [
                "appliedenergistics2:smooth_sky_stone_slab@0"
            ]
        },
        {
            "x": 11,
            "y": 5,
            "z": -5,
            "elements": [
                "appliedenergistics2:smooth_sky_stone_slab@0"
            ]
        },
        {
            "x": 4,
            "y": -4,
            "z": 9,
            "elements": [
                "minecraft:concrete@4"
            ]
        },
        {
            "x": 11,
            "y": 5,
            "z": 2,
            "elements": [
                "minecraft:concrete@7"
            ]
        },
        {
            "x": -13,
            "y": 2,
            "z": -7,
            "elements": [
                "minecraft:end_rod@5"
            ]
        },
        {
            "x": 11,
            "y": 5,
            "z": 5,
            "elements": [
                "appliedenergistics2:smooth_sky_stone_slab@0"
            ]
        },
        {
            "x": 11,
            "y": 5,
            "z": 4,
            "elements": [
                "appliedenergistics2:smooth_sky_stone_slab@0"
            ]
        },
        {
            "x": 9,
            "y": 1,
            "z": -5,
            "elements": [
                "modularmachinery:blockcasing@0"
            ]
        },
        {
            "x": 11,
            "y": 5,
            "z": 3,
            "elements": [
                "appliedenergistics2:smooth_sky_stone_slab@0"
            ]
        },
        {
            "x": 4,
            "y": -4,
            "z": -4,
            "elements": [
                "minecraft:concrete@7"
            ]
        },
        {
            "x": 4,
            "y": -4,
            "z": -5,
            "elements": [
                "minecraft:concrete@7"
            ]
        },
        {
            "x": 4,
            "y": -4,
            "z": -2,
            "elements": [
                "modularmachinery:blockcasing@0"
            ]
        },
        {
            "x": 4,
            "y": -4,
            "z": -3,
            "elements": [
                "minecraft:concrete@7"
            ]
        },
        {
            "x": 4,
            "y": -4,
            "z": -8,
            "elements": [
                "minecraft:concrete@7"
            ]
        },
        {
            "x": 4,
            "y": -4,
            "z": -9,
            "elements": [
                "minecraft:concrete@4"
            ]
        },
        {
            "x": 4,
            "y": -4,
            "z": -6,
            "elements": [
                "minecraft:concrete@7"
            ]
        },
        {
            "x": 4,
            "y": -4,
            "z": -7,
            "elements": [
                "minecraft:concrete@7"
            ]
        },
        {
            "x": 4,
            "y": -4,
            "z": 4,
            "elements": [
                "minecraft:concrete@7"
            ]
        },
        {
            "x": 4,
            "y": -4,
            "z": 3,
            "elements": [
                "minecraft:concrete@7"
            ]
        },
        {
            "x": 4,
            "y": -4,
            "z": 6,
            "elements": [
                "minecraft:concrete@7"
            ]
        },
        {
            "x": 4,
            "y": -4,
            "z": 5,
            "elements": [
                "minecraft:concrete@7"
            ]
        },
        {
            "x": 4,
            "y": -4,
            "z": 0,
            "elements": [
                "minecraft:concrete@7"
            ]
        },
        {
            "x": 4,
            "y": -4,
            "z": -1,
            "elements": [
                "minecraft:concrete@7"
            ]
        },
        {
            "x": 4,
            "y": -4,
            "z": 2,
            "elements": [
                "modularmachinery:blockcasing@0"
            ]
        },
        {
            "x": 4,
            "y": -4,
            "z": 1,
            "elements": [
                "minecraft:concrete@7"
            ]
        },
        {
            "x": 11,
            "y": 1,
            "z": 7,
            "elements": [
                "modularmachinery:blockcasing@0"
            ]
        },
        {
            "x": 11,
            "y": 1,
            "z": 8,
            "elements": [
                "appliedenergistics2:smooth_sky_stone_stairs@7"
            ]
        },
        {
            "x": -11,
            "y": 0,
            "z": 8,
            "elements": [
                "appliedenergistics2:smooth_sky_stone_stairs@3"
            ]
        },
        {
            "x": -11,
            "y": 0,
            "z": 7,
            "elements": [
                "modularmachinery:blockcasing@0"
            ]
        },
        {
            "x": -3,
            "y": -3,
            "z": -7,
            "elements": [
                "appliedenergistics2:smooth_sky_stone_block@0"
            ]
        },
        {
            "x": 0,
            "y": 0,
            "z": 7,
            "elements": [
                "modularmachinery:blockcasing@5"
            ]
        },
        {
            "x": 9,
            "y": -1,
            "z": -6,
            "elements": [
                "modularmachinery:blockcasing@0"
            ]
        },
        {
            "x": -12,
            "y": -1,
            "z": 7,
            "elements": [
                "modularmachinery:blockcasing@0"
            ]
        },
        {
            "x": -3,
            "y": -3,
            "z": 7,
            "elements": [
                "appliedenergistics2:smooth_sky_stone_block@0"
            ]
        },
        {
            "x": 0,
            "y": 0,
            "z": -7,
            "elements": [
                "modularmachinery:blockcasing@5"
            ]
        },
        {
            "x": -12,
            "y": -1,
            "z": -7,
            "elements": [
                "modularmachinery:blockcasing@0"
            ]
        },
        {
            "x": 11,
            "y": 1,
            "z": -8,
            "elements": [
                "appliedenergistics2:smooth_sky_stone_stairs@6"
            ]
        },
        {
            "x": 11,
            "y": 1,
            "z": -7,
            "elements": [
                "modularmachinery:blockcasing@0"
            ]
        },
        {
            "x": -14,
            "y": -3,
            "z": 2,
            "elements": [
                "appliedenergistics2:smooth_sky_stone_block@0"
            ]
        },
        {
            "x": -14,
            "y": -3,
            "z": 3,
            "elements": [
                "appliedenergistics2:smooth_sky_stone_block@0"
            ]
        },
        {
            "x": -14,
            "y": -3,
            "z": 6,
            "elements": [
                "appliedenergistics2:smooth_sky_stone_block@0"
            ]
        },
        {
            "x": -14,
            "y": -3,
            "z": 7,
            "elements": [
                "appliedenergistics2:smooth_sky_stone_block@0"
            ]
        },
        {
            "x": 8,
            "y": -2,
            "z": 7,
            "elements": [
                "appliedenergistics2:smooth_sky_stone_stairs@7"
            ]
        },
        {
            "x": -14,
            "y": -3,
            "z": 4,
            "elements": [
                "appliedenergistics2:smooth_sky_stone_block@0"
            ]
        },
        {
            "x": 8,
            "y": -2,
            "z": 6,
            "elements": [
                "minecraft:concrete@7"
            ]
        },
        {
            "x": -14,
            "y": -3,
            "z": 5,
            "elements": [
                "appliedenergistics2:smooth_sky_stone_block@0"
            ]
        },
        {
            "x": -14,
            "y": -3,
            "z": 8,
            "elements": [
                "appliedenergistics2:smooth_sky_stone_block@0"
            ]
        },
        {
            "x": -14,
            "y": -3,
            "z": -6,
            "elements": [
                "appliedenergistics2:smooth_sky_stone_block@0"
            ]
        },
        {
            "x": 8,
            "y": -4,
            "z": 6,
            "elements": [
                "minecraft:concrete@7"
            ]
        },
        {
            "x": -14,
            "y": -3,
            "z": -5,
            "elements": [
                "appliedenergistics2:smooth_sky_stone_block@0"
            ]
        },
        {
            "x": 8,
            "y": -4,
            "z": 5,
            "elements": [
                "minecraft:concrete@7"
            ]
        },
        {
            "x": 8,
            "y": -4,
            "z": 4,
            "elements": [
                "minecraft:concrete@7"
            ]
        },
        {
            "x": -14,
            "y": -3,
            "z": -8,
            "elements": [
                "appliedenergistics2:smooth_sky_stone_block@0"
            ]
        },
        {
            "x": 8,
            "y": -2,
            "z": -6,
            "elements": [
                "minecraft:concrete@7"
            ]
        },
        {
            "x": -14,
            "y": -3,
            "z": -7,
            "elements": [
                "appliedenergistics2:smooth_sky_stone_block@0"
            ]
        },
        {
            "x": 8,
            "y": -4,
            "z": 3,
            "elements": [
                "minecraft:concrete@7"
            ]
        },
        {
            "x": 8,
            "y": -2,
            "z": -7,
            "elements": [
                "appliedenergistics2:smooth_sky_stone_stairs@6"
            ]
        },
        {
            "x": -14,
            "y": -3,
            "z": -2,
            "elements": [
                "appliedenergistics2:smooth_sky_stone_block@0"
            ]
        },
        {
            "x": 8,
            "y": -4,
            "z": 9,
            "elements": [
                "minecraft:concrete@4"
            ]
        },
        {
            "x": -14,
            "y": -3,
            "z": -4,
            "elements": [
                "appliedenergistics2:smooth_sky_stone_block@0"
            ]
        },
        {
            "x": 8,
            "y": -4,
            "z": 8,
            "elements": [
                "minecraft:concrete@7"
            ]
        },
        {
            "x": -13,
            "y": -2,
            "z": 7,
            "elements": [
                "modularmachinery:blockcasing@0"
            ]
        },
        {
            "x": -14,
            "y": -3,
            "z": -3,
            "elements": [
                "appliedenergistics2:smooth_sky_stone_block@0"
            ]
        },
        {
            "x": 8,
            "y": -4,
            "z": 7,
            "elements": [
                "minecraft:concrete@7"
            ]
        },
        {
            "x": -4,
            "y": -4,
            "z": -2,
            "elements": [
                "modularmachinery:blockcasing@0"
            ]
        },
        {
            "x": -4,
            "y": -4,
            "z": -3,
            "elements": [
                "minecraft:concrete@7"
            ]
        },
        {
            "x": -4,
            "y": -4,
            "z": -4,
            "elements": [
                "minecraft:concrete@7"
            ]
        },
        {
            "x": -4,
            "y": -4,
            "z": -5,
            "elements": [
                "minecraft:concrete@7"
            ]
        },
        {
            "x": -4,
            "y": -4,
            "z": -6,
            "elements": [
                "minecraft:concrete@7"
            ]
        },
        {
            "x": -13,
            "y": -2,
            "z": -7,
            "elements": [
                "modularmachinery:blockcasing@0"
            ]
        },
        {
            "x": -4,
            "y": -4,
            "z": -7,
            "elements": [
                "minecraft:concrete@7"
            ]
        },
        {
            "x": -4,
            "y": -4,
            "z": -8,
            "elements": [
                "minecraft:concrete@7"
            ]
        },
        {
            "x": -4,
            "y": -4,
            "z": -9,
            "elements": [
                "minecraft:concrete@4"
            ]
        },
        {
            "x": -4,
            "y": -4,
            "z": 6,
            "elements": [
                "minecraft:concrete@7"
            ]
        },
        {
            "x": -4,
            "y": -4,
            "z": 5,
            "elements": [
                "minecraft:concrete@7"
            ]
        },
        {
            "x": -4,
            "y": -4,
            "z": 4,
            "elements": [
                "minecraft:concrete@7"
            ]
        },
        {
            "x": -4,
            "y": -4,
            "z": 3,
            "elements": [
                "minecraft:concrete@7"
            ]
        },
        {
            "x": -4,
            "y": -4,
            "z": 2,
            "elements": [
                "modularmachinery:blockcasing@0"
            ]
        },
        {
            "x": 12,
            "y": 2,
            "z": 6,
            "elements": [
                "modularmachinery:blockcasing@0"
            ]
        },
        {
            "x": -4,
            "y": -4,
            "z": 1,
            "elements": [
                "minecraft:concrete@7"
            ]
        },
        {
            "x": -4,
            "y": -4,
            "z": 0,
            "elements": [
                "minecraft:concrete@7"
            ]
        },
        {
            "x": 12,
            "y": 2,
            "z": 7,
            "elements": [
                "minecraft:end_rod@5"
            ]
        },
        {
            "x": -4,
            "y": -4,
            "z": -1,
            "elements": [
                "minecraft:concrete@7"
            ]
        },
        {
            "x": 12,
            "y": 2,
            "z": -6,
            "elements": [
                "modularmachinery:blockcasing@0"
            ]
        },
        {
            "x": 12,
            "y": 2,
            "z": -7,
            "elements": [
                "minecraft:end_rod@5"
            ]
        },
        {
            "x": -4,
            "y": -4,
            "z": 9,
            "elements": [
                "minecraft:concrete@4"
            ]
        },
        {
            "x": -4,
            "y": -4,
            "z": 8,
            "elements": [
                "minecraft:concrete@7"
            ]
        },
        {
            "x": -4,
            "y": -4,
            "z": 7,
            "elements": [
                "minecraft:concrete@7"
            ]
        },
        {
            "x": 19,
            "y": -4,
            "z": 6,
            "elements": [
                "minecraft:concrete@4"
            ]
        },
        {
            "x": 10,
            "y": -2,
            "z": 6,
            "elements": [
                "minecraft:concrete@7"
            ]
        },
        {
            "x": 19,
            "y": -4,
            "z": 7,
            "elements": [
                "minecraft:concrete@4"
            ]
        },
        {
            "x": 19,
            "y": -4,
            "z": 4,
            "elements": [
                "minecraft:concrete@4"
            ]
        },
        {
            "x": 19,
            "y": -4,
            "z": 5,
            "elements": [
                "minecraft:concrete@4"
            ]
        },
        {
            "x": 19,
            "y": -4,
            "z": 2,
            "elements": [
                "minecraft:concrete@4"
            ]
        },
        {
            "x": -10,
            "y": 3,
            "z": -6,
            "elements": [
                "quark:snow_bricks_stairs@2"
            ]
        },
        {
            "x": -10,
            "y": 3,
            "z": -5,
            "elements": [
                "modularmachinery:blockcasing@0"
            ]
        },
        {
            "x": 19,
            "y": -4,
            "z": 3,
            "elements": [
                "minecraft:concrete@4"
            ]
        },
        {
            "x": 19,
            "y": -4,
            "z": 0,
            "elements": [
                "minecraft:concrete@4"
            ]
        },
        {
            "x": -10,
            "y": 3,
            "z": -4,
            "elements": [
                "minecraft:concrete@7"
            ]
        },
        {
            "x": 19,
            "y": -4,
            "z": 1,
            "elements": [
                "minecraft:concrete@4"
            ]
        },
        {
            "x": -10,
            "y": 3,
            "z": -3,
            "elements": [
                "minecraft:concrete@7"
            ]
        },
        {
            "x": -10,
            "y": 3,
            "z": -2,
            "elements": [
                "minecraft:concrete@7"
            ]
        },
        {
            "x": -10,
            "y": 3,
            "z": -1,
            "elements": [
                "minecraft:concrete@7"
            ]
        },
        {
            "x": -10,
            "y": 3,
            "z": 0,
            "elements": [
                "minecraft:concrete@7"
            ]
        },
        {
            "x": -10,
            "y": 3,
            "z": 1,
            "elements": [
                "minecraft:concrete@7"
            ]
        },
        {
            "x": -10,
            "y": 3,
            "z": 2,
            "elements": [
                "minecraft:concrete@7"
            ]
        },
        {
            "x": -10,
            "y": 3,
            "z": 3,
            "elements": [
                "minecraft:concrete@7"
            ]
        },
        {
            "x": -10,
            "y": 3,
            "z": 4,
            "elements": [
                "minecraft:concrete@7"
            ]
        },
        {
            "x": 10,
            "y": -2,
            "z": 7,
            "elements": [
                "modularmachinery:blockcasing@0"
            ]
        },
        {
            "x": 19,
            "y": -4,
            "z": 8,
            "elements": [
                "minecraft:concrete@4"
            ]
        },
        {
            "x": 19,
            "y": -4,
            "z": 9,
            "elements": [
                "minecraft:concrete@4"
            ]
        },
        {
            "x": -10,
            "y": 3,
            "z": 5,
            "elements": [
                "modularmachinery:blockcasing@0"
            ]
        },
        {
            "x": -10,
            "y": 3,
            "z": 6,
            "elements": [
                "quark:snow_bricks_stairs@3"
            ]
        },
        {
            "x": -2,
            "y": -4,
            "z": 7,
            "elements": [
                "minecraft:concrete@7"
            ]
        },
        {
            "x": 19,
            "y": -4,
            "z": -9,
            "elements": [
                "minecraft:concrete@4"
            ]
        },
        {
            "x": -2,
            "y": -4,
            "z": 8,
            "elements": [
                "minecraft:concrete@7"
            ]
        },
        {
            "x": -2,
            "y": -4,
            "z": 5,
            "elements": [
                "minecraft:concrete@7"
            ]
        },
        {
            "x": -2,
            "y": -4,
            "z": 6,
            "elements": [
                "minecraft:concrete@7"
            ]
        },
        {
            "x": -2,
            "y": -4,
            "z": 9,
            "elements": [
                "minecraft:concrete@4"
            ]
        },
        {
            "x": 19,
            "y": -4,
            "z": -2,
            "elements": [
                "minecraft:concrete@4"
            ]
        },
        {
            "x": -2,
            "y": -4,
            "z": -1,
            "elements": [
                "minecraft:concrete@7"
            ]
        },
        {
            "x": -2,
            "y": -4,
            "z": 0,
            "elements": [
                "minecraft:concrete@7"
            ]
        },
        {
            "x": 19,
            "y": -4,
            "z": -1,
            "elements": [
                "minecraft:concrete@4"
            ]
        },
        {
            "x": 19,
            "y": -4,
            "z": -4,
            "elements": [
                "minecraft:concrete@4"
            ]
        },
        {
            "x": 1,
            "y": 3,
            "z": 3,
            "elements": [
                "modularmachinery:blockcasing@0"
            ]
        },
        {
            "x": -2,
            "y": -4,
            "z": -3,
            "elements": [
                "minecraft:concrete@7"
            ]
        },
        {
            "x": -2,
            "y": -4,
            "z": -2,
            "elements": [
                "minecraft:concrete@7"
            ]
        },
        {
            "x": 1,
            "y": 3,
            "z": 4,
            "elements": [
                "modularmachinery:blockcasing@0"
            ]
        },
        {
            "x": 19,
            "y": -4,
            "z": -3,
            "elements": [
                "minecraft:concrete@4"
            ]
        },
        {
            "x": -2,
            "y": -4,
            "z": 3,
            "elements": [
                "minecraft:concrete@7"
            ]
        },
        {
            "x": 19,
            "y": -4,
            "z": -6,
            "elements": [
                "minecraft:concrete@4"
            ]
        },
        {
            "x": -2,
            "y": -4,
            "z": 4,
            "elements": [
                "minecraft:concrete@7"
            ]
        },
        {
            "x": 19,
            "y": -4,
            "z": -5,
            "elements": [
                "minecraft:concrete@4"
            ]
        },
        {
            "x": 19,
            "y": -4,
            "z": -8,
            "elements": [
                "minecraft:concrete@4"
            ]
        },
        {
            "x": -2,
            "y": -4,
            "z": 1,
            "elements": [
                "minecraft:concrete@7"
            ]
        },
        {
            "x": -2,
            "y": -4,
            "z": 2,
            "elements": [
                "minecraft:concrete@7"
            ]
        },
        {
            "x": 19,
            "y": -4,
            "z": -7,
            "elements": [
                "minecraft:concrete@4"
            ]
        },
        {
            "x": 1,
            "y": 3,
            "z": -3,
            "elements": [
                "modularmachinery:blockcasing@0"
            ]
        },
        {
            "x": 1,
            "y": 3,
            "z": -2,
            "elements": [
                "minecraft:iron_trapdoor@2"
            ]
        },
        {
            "x": 1,
            "y": 3,
            "z": -4,
            "elements": [
                "modularmachinery:blockcasing@0"
            ]
        },
        {
            "x": -2,
            "y": 0,
            "z": 7,
            "elements": [
                "modularmachinery:blockcasing@0"
            ]
        },
        {
            "x": 1,
            "y": 3,
            "z": 1,
            "elements": [
                "minecraft:iron_trapdoor@2"
            ]
        },
        {
            "x": -11,
            "y": 2,
            "z": 6,
            "elements": [
                "modularmachinery:blockcasing@0"
            ]
        },
        {
            "x": 1,
            "y": 3,
            "z": 2,
            "elements": [
                "minecraft:iron_trapdoor@0"
            ]
        },
        {
            "x": -11,
            "y": 2,
            "z": 7,
            "elements": [
                "minecraft:concrete@7"
            ]
        },
        {
            "x": 1,
            "y": 3,
            "z": -1,
            "elements": [
                "minecraft:iron_trapdoor@2"
            ]
        },
        {
            "x": 1,
            "y": 3,
            "z": 0,
            "elements": [
                "nuclearcraft:turbine_rotor_blade_sic_sic_cmc@3"
            ]
        },
        {
            "x": -11,
            "y": 2,
            "z": -6,
            "elements": [
                "modularmachinery:blockcasing@0"
            ]
        },
        {
            "x": 10,
            "y": 2,
            "z": -7,
            "elements": [
                "quark:snow_bricks_stairs@2"
            ]
        },
        {
            "x": -15,
            "y": -4,
            "z": 6,
            "elements": [
                "minecraft:concrete@7"
            ]
        },
        {
            "x": 10,
            "y": 2,
            "z": -6,
            "elements": [
                "modularmachinery:blockcasing@0"
            ]
        },
        {
            "x": -15,
            "y": -4,
            "z": 7,
            "elements": [
                "minecraft:concrete@7"
            ]
        },
        {
            "x": -15,
            "y": -4,
            "z": 8,
            "elements": [
                "minecraft:concrete@7"
            ]
        },
        {
            "x": -2,
            "y": 0,
            "z": -7,
            "elements": [
                "modularmachinery:blockcasing@0"
            ]
        },
        {
            "x": -11,
            "y": 2,
            "z": -8,
            "elements": [
                "minecraft:concrete@7"
            ]
        },
        {
            "x": -15,
            "y": -4,
            "z": 9,
            "elements": [
                "minecraft:concrete@4"
            ]
        },
        {
            "x": -11,
            "y": 2,
            "z": -7,
            "elements": [
                "minecraft:concrete@7"
            ]
        },
        {
            "x": -15,
            "y": -4,
            "z": 2,
            "elements": [
                "minecraft:concrete@7"
            ]
        },
        {
            "x": -15,
            "y": -4,
            "z": 3,
            "elements": [
                "minecraft:concrete@7"
            ]
        },
        {
            "x": -15,
            "y": -4,
            "z": 4,
            "elements": [
                "minecraft:concrete@7"
            ]
        },
        {
            "x": -15,
            "y": -4,
            "z": 5,
            "elements": [
                "minecraft:concrete@7"
            ]
        },
        {
            "x": 10,
            "y": -2,
            "z": -7,
            "elements": [
                "modularmachinery:blockcasing@0"
            ]
        },
        {
            "x": 10,
            "y": -2,
            "z": -6,
            "elements": [
                "minecraft:concrete@7"
            ]
        },
        {
            "x": -13,
            "y": 0,
            "z": -7,
            "elements": [
                "modularmachinery:blockcasing@0"
            ]
        },
        {
            "x": -15,
            "y": -4,
            "z": -2,
            "elements": [
                "minecraft:concrete@7"
            ]
        },
        {
            "x": -15,
            "y": -4,
            "z": -1,
            "elements": [
                "minecraft:concrete@7"
            ]
        },
        {
            "x": -15,
            "y": -4,
            "z": 0,
            "elements": [
                "minecraft:concrete@7"
            ]
        },
        {
            "x": -15,
            "y": -4,
            "z": 1,
            "elements": [
                "minecraft:concrete@7"
            ]
        },
        {
            "x": -13,
            "y": 0,
            "z": 7,
            "elements": [
                "modularmachinery:blockcasing@0"
            ]
        },
        {
            "x": -15,
            "y": -4,
            "z": -6,
            "elements": [
                "minecraft:concrete@7"
            ]
        },
        {
            "x": -15,
            "y": -4,
            "z": -5,
            "elements": [
                "minecraft:concrete@7"
            ]
        },
        {
            "x": -15,
            "y": -4,
            "z": -4,
            "elements": [
                "minecraft:concrete@7"
            ]
        },
        {
            "x": -15,
            "y": -4,
            "z": -3,
            "elements": [
                "minecraft:concrete@7"
            ]
        },
        {
            "x": -15,
            "y": -4,
            "z": -9,
            "elements": [
                "minecraft:concrete@4"
            ]
        },
        {
            "x": -15,
            "y": -4,
            "z": -8,
            "elements": [
                "minecraft:concrete@7"
            ]
        },
        {
            "x": -15,
            "y": -4,
            "z": -7,
            "elements": [
                "minecraft:concrete@7"
            ]
        },
        {
            "x": 9,
            "y": -1,
            "z": 6,
            "elements": [
                "modularmachinery:blockcasing@0"
            ]
        },
        {
            "x": 13,
            "y": 5,
            "z": 3,
            "elements": [
                "appliedenergistics2:smooth_sky_stone_slab@0"
            ]
        },
        {
            "x": 13,
            "y": 5,
            "z": 2,
            "elements": [
                "minecraft:concrete@7"
            ]
        },
        {
            "x": 13,
            "y": 5,
            "z": -3,
            "elements": [
                "appliedenergistics2:smooth_sky_stone_slab@0"
            ]
        },
        {
            "x": 13,
            "y": 5,
            "z": -2,
            "elements": [
                "minecraft:concrete@7"
            ]
        },
        {
            "x": -6,
            "y": 3,
            "z": 0,
            "elements": [
                "modularmachinery:blockcasing@0"
            ]
        },
        {
            "x": -6,
            "y": 3,
            "z": 1,
            "elements": [
                "modularmachinery:blockcasing@0"
            ]
        },
        {
            "x": -6,
            "y": 3,
            "z": -2,
            "elements": [
                "modularmachinery:blockcasing@0"
            ]
        },
        {
            "x": -6,
            "y": 3,
            "z": -1,
            "elements": [
                "modularmachinery:blockcasing@0"
            ]
        },
        {
            "x": -6,
            "y": 3,
            "z": -4,
            "elements": [
                "modularmachinery:blockcasing@0"
            ]
        },
        {
            "x": -6,
            "y": 3,
            "z": -3,
            "elements": [
                "modularmachinery:blockcasing@0"
            ]
        },
        {
            "x": -6,
            "y": 3,
            "z": -5,
            "elements": [
                "quark:snow_bricks_stairs@2"
            ]
        },
        {
            "x": -6,
            "y": 3,
            "z": 4,
            "elements": [
                "modularmachinery:blockcasing@0"
            ]
        },
        {
            "x": -6,
            "y": 3,
            "z": 5,
            "elements": [
                "quark:snow_bricks_stairs@3"
            ]
        },
        {
            "x": -6,
            "y": 3,
            "z": 2,
            "elements": [
                "modularmachinery:blockcasing@0"
            ]
        },
        {
            "x": -6,
            "y": 3,
            "z": 3,
            "elements": [
                "modularmachinery:blockcasing@0"
            ]
        },
        {
            "x": -10,
            "y": 5,
            "z": 2,
            "elements": [
                "minecraft:concrete@7"
            ]
        },
        {
            "x": -10,
            "y": 5,
            "z": -2,
            "elements": [
                "minecraft:concrete@7"
            ]
        },
        {
            "x": -11,
            "y": 4,
            "z": 6,
            "elements": [
                "minecraft:concrete@7"
            ]
        },
        {
            "x": 6,
            "y": 4,
            "z": -4,
            "elements": [
                "quark:snow_bricks_stairs@2"
            ]
        },
        {
            "x": 6,
            "y": 4,
            "z": 4,
            "elements": [
                "quark:snow_bricks_stairs@3"
            ]
        },
        {
            "x": 6,
            "y": 4,
            "z": 3,
            "elements": [
                "minecraft:concrete@7"
            ]
        },
        {
            "x": 6,
            "y": 4,
            "z": 2,
            "elements": [
                "minecraft:concrete@7"
            ]
        },
        {
            "x": 6,
            "y": 4,
            "z": 1,
            "elements": [
                "minecraft:concrete@7"
            ]
        },
        {
            "x": -11,
            "y": 4,
            "z": -4,
            "elements": [
                "modularmachinery:blockcasing@0"
            ]
        },
        {
            "x": 6,
            "y": 4,
            "z": 0,
            "elements": [
                "minecraft:concrete@7"
            ]
        },
        {
            "x": -11,
            "y": 4,
            "z": -3,
            "elements": [
                "modularmachinery:blockcasing@0"
            ]
        },
        {
            "x": 6,
            "y": 4,
            "z": -1,
            "elements": [
                "minecraft:concrete@7"
            ]
        },
        {
            "x": -11,
            "y": 4,
            "z": -6,
            "elements": [
                "minecraft:concrete@7"
            ]
        },
        {
            "x": 6,
            "y": 4,
            "z": -2,
            "elements": [
                "minecraft:concrete@7"
            ]
        },
        {
            "x": 6,
            "y": 4,
            "z": -3,
            "elements": [
                "minecraft:concrete@7"
            ]
        },
        {
            "x": -11,
            "y": 4,
            "z": -5,
            "elements": [
                "minecraft:concrete@7"
            ]
        },
        {
            "x": -11,
            "y": 4,
            "z": 0,
            "elements": [
                "modularmachinery:blockcasing@1"
            ]
        },
        {
            "x": -11,
            "y": 4,
            "z": 1,
            "elements": [
                "modularmachinery:blockcasing@1"
            ]
        },
        {
            "x": -11,
            "y": 4,
            "z": -2,
            "elements": [
                "modularmachinery:blockcasing@0"
            ]
        },
        {
            "x": -11,
            "y": 2,
            "z": 8,
            "elements": [
                "minecraft:concrete@7"
            ]
        },
        {
            "x": -11,
            "y": 4,
            "z": -1,
            "elements": [
                "modularmachinery:blockcasing@1"
            ]
        },
        {
            "x": -15,
            "y": 6,
            "z": 0,
            "elements": [
                "minecraft:concrete@7"
            ]
        },
        {
            "x": -11,
            "y": 4,
            "z": 4,
            "elements": [
                "modularmachinery:blockcasing@0"
            ]
        },
        {
            "x": -11,
            "y": 4,
            "z": 5,
            "elements": [
                "minecraft:concrete@7"
            ]
        },
        {
            "x": -11,
            "y": 4,
            "z": 2,
            "elements": [
                "modularmachinery:blockcasing@0"
            ]
        },
        {
            "x": -11,
            "y": 4,
            "z": 3,
            "elements": [
                "modularmachinery:blockcasing@0"
            ]
        },
        {
            "x": 11,
            "y": 3,
            "z": 7,
            "elements": [
                "minecraft:concrete@7"
            ]
        },
        {
            "x": 11,
            "y": 3,
            "z": 6,
            "elements": [
                "minecraft:concrete@7"
            ]
        },
        {
            "x": 11,
            "y": 3,
            "z": 5,
            "elements": [
                "modularmachinery:blockcasing@0"
            ]
        },
        {
            "x": 11,
            "y": 3,
            "z": -5,
            "elements": [
                "modularmachinery:blockcasing@0"
            ]
        },
        {
            "x": 11,
            "y": 3,
            "z": -6,
            "elements": [
                "minecraft:concrete@7"
            ]
        },
        {
            "x": 11,
            "y": 3,
            "z": -7,
            "elements": [
                "minecraft:concrete@7"
            ]
        },
        {
            "x": 12,
            "y": 4,
            "z": -4,
            "elements": [
                "modularmachinery:blockcasing@0"
            ]
        },
        {
            "x": 12,
            "y": 4,
            "z": -5,
            "elements": [
                "minecraft:end_rod@5"
            ]
        },
        {
            "x": 0,
            "y": 2,
            "z": 5,
            "elements": [
                "modularmachinery:blockcasing@0"
            ]
        },
        {
            "x": 12,
            "y": 4,
            "z": -2,
            "elements": [
                "modularmachinery:blockcasing@0"
            ]
        },
        {
            "x": 12,
            "y": 4,
            "z": -3,
            "elements": [
                "modularmachinery:blockcasing@0"
            ]
        },
        {
            "x": 9,
            "y": -3,
            "z": -6,
            "elements": [
                "appliedenergistics2:smooth_sky_stone_block@0"
            ]
        },
        {
            "x": 12,
            "y": 4,
            "z": 0,
            "elements": [
                "modularmachinery:blockcasing@1"
            ]
        },
        {
            "x": 12,
            "y": 4,
            "z": -1,
            "elements": [
                "modularmachinery:blockcasing@1"
            ]
        },
        {
            "x": 9,
            "y": -3,
            "z": -4,
            "elements": [
                "appliedenergistics2:smooth_sky_stone_stairs@0"
            ]
        },
        {
            "x": 12,
            "y": 4,
            "z": 2,
            "elements": [
                "modularmachinery:blockcasing@0"
            ]
        },
        {
            "x": 9,
            "y": -3,
            "z": -5,
            "elements": [
                "appliedenergistics2:smooth_sky_stone_stairs@0"
            ]
        },
        {
            "x": 12,
            "y": 4,
            "z": 1,
            "elements": [
                "modularmachinery:blockcasing@1"
            ]
        },
        {
            "x": 9,
            "y": -3,
            "z": -2,
            "elements": [
                "appliedenergistics2:smooth_sky_stone_stairs@0"
            ]
        },
        {
            "x": 12,
            "y": 4,
            "z": 4,
            "elements": [
                "modularmachinery:blockcasing@0"
            ]
        },
        {
            "x": -6,
            "y": 1,
            "z": 7,
            "elements": [
                "quark:snow_bricks_stairs@3"
            ]
        },
        {
            "x": 9,
            "y": -3,
            "z": -3,
            "elements": [
                "appliedenergistics2:smooth_sky_stone_stairs@0"
            ]
        },
        {
            "x": -7,
            "y": 0,
            "z": -6,
            "elements": [
                "modularmachinery:blockcasing@0"
            ]
        },
        {
            "x": -6,
            "y": 1,
            "z": 6,
            "elements": [
                "modularmachinery:blockcasing@0"
            ]
        },
        {
            "x": 12,
            "y": 4,
            "z": 3,
            "elements": [
                "modularmachinery:blockcasing@0"
            ]
        },
        {
            "x": 12,
            "y": 4,
            "z": 5,
            "elements": [
                "minecraft:end_rod@5"
            ]
        },
        {
            "x": -1,
            "y": 1,
            "z": 6,
            "elements": [
                "modularmachinery:blockcasing@0"
            ]
        },
        {
            "x": 9,
            "y": -3,
            "z": 2,
            "elements": [
                "appliedenergistics2:smooth_sky_stone_stairs@0"
            ]
        },
        {
            "x": 15,
            "y": -2,
            "z": -7,
            "elements": [
                "modularmachinery:blockcasing@0"
            ]
        },
        {
            "x": 9,
            "y": -3,
            "z": 4,
            "elements": [
                "appliedenergistics2:smooth_sky_stone_stairs@0"
            ]
        },
        {
            "x": 9,
            "y": -3,
            "z": 3,
            "elements": [
                "appliedenergistics2:smooth_sky_stone_stairs@0"
            ]
        },
        {
            "x": 0,
            "y": 2,
            "z": -5,
            "elements": [
                "modularmachinery:blockcasing@0"
            ]
        },
        {
            "x": 9,
            "y": -3,
            "z": 6,
            "elements": [
                "appliedenergistics2:smooth_sky_stone_block@0"
            ]
        },
        {
            "x": -16,
            "y": 5,
            "z": 2,
            "elements": [
                "minecraft:concrete@7"
            ]
        },
        {
            "x": 9,
            "y": -3,
            "z": 5,
            "elements": [
                "appliedenergistics2:smooth_sky_stone_stairs@0"
            ]
        },
        {
            "x": -1,
            "y": 1,
            "z": 0,
            "elements": [
                "appliedenergistics2:smooth_sky_stone_stairs@0"
            ]
        },
        {
            "x": -16,
            "y": 5,
            "z": -2,
            "elements": [
                "minecraft:concrete@7"
            ]
        },
        {
            "x": -7,
            "y": 0,
            "z": 6,
            "elements": [
                "modularmachinery:blockcasing@0"
            ]
        },
        {
            "x": 15,
            "y": -2,
            "z": -2,
            "elements": [
                "minecraft:concrete@7"
            ]
        },
        {
            "x": -16,
            "y": 5,
            "z": 0,
            "elements": [
                "minecraft:concrete@7"
            ]
        },
        {
            "x": -1,
            "y": 1,
            "z": -6,
            "elements": [
                "modularmachinery:blockcasing@0"
            ]
        },
        {
            "x": 0,
            "y": 2,
            "z": 0,
            "elements": [
                "quark:iron_rod@0"
            ]
        },
        {
            "x": 15,
            "y": -2,
            "z": -6,
            "elements": [
                "minecraft:concrete@7"
            ]
        },
        {
            "x": 8,
            "y": -4,
            "z": -2,
            "elements": [
                "minecraft:concrete@7"
            ]
        },
        {
            "x": 8,
            "y": -4,
            "z": -3,
            "elements": [
                "minecraft:concrete@7"
            ]
        },
        {
            "x": 8,
            "y": -4,
            "z": -4,
            "elements": [
                "minecraft:concrete@7"
            ]
        },
        {
            "x": 15,
            "y": -2,
            "z": 7,
            "elements": [
                "modularmachinery:blockcasing@0"
            ]
        },
        {
            "x": 15,
            "y": -2,
            "z": 6,
            "elements": [
                "minecraft:concrete@7"
            ]
        },
        {
            "x": 8,
            "y": -4,
            "z": -5,
            "elements": [
                "minecraft:concrete@7"
            ]
        },
        {
            "x": 8,
            "y": -4,
            "z": 2,
            "elements": [
                "minecraft:concrete@7"
            ]
        },
        {
            "x": 8,
            "y": -4,
            "z": 1,
            "elements": [
                "minecraft:concrete@7"
            ]
        },
        {
            "x": 8,
            "y": -4,
            "z": 0,
            "elements": [
                "minecraft:concrete@7"
            ]
        },
        {
            "x": 15,
            "y": -2,
            "z": 2,
            "elements": [
                "minecraft:concrete@7"
            ]
        },
        {
            "x": 8,
            "y": -4,
            "z": -1,
            "elements": [
                "minecraft:concrete@7"
            ]
        },
        {
            "x": 8,
            "y": -4,
            "z": -6,
            "elements": [
                "minecraft:concrete@7"
            ]
        },
        {
            "x": 8,
            "y": -4,
            "z": -7,
            "elements": [
                "minecraft:concrete@7"
            ]
        },
        {
            "x": 8,
            "y": -4,
            "z": -8,
            "elements": [
                "minecraft:concrete@7"
            ]
        },
        {
            "x": 8,
            "y": -4,
            "z": -9,
            "elements": [
                "minecraft:concrete@4"
            ]
        },
        {
            "x": 5,
            "y": 1,
            "z": -6,
            "elements": [
                "thermalfoundation:glass_alloy@7"
            ]
        },
        {
            "x": 3,
            "y": -3,
            "z": -7,
            "elements": [
                "appliedenergistics2:smooth_sky_stone_block@0"
            ]
        },
        {
            "x": -12,
            "y": 1,
            "z": 7,
            "elements": [
                "modularmachinery:blockcasing@0"
            ]
        },
        {
            "x": 5,
            "y": 1,
            "z": 6,
            "elements": [
                "thermalfoundation:glass_alloy@7"
            ]
        },
        {
            "x": 10,
            "y": 0,
            "z": 7,
            "elements": [
                "modularmachinery:blockcasing@0"
            ]
        },
        {
            "x": 10,
            "y": 0,
            "z": 6,
            "elements": [
                "minecraft:concrete@7"
            ]
        },
        {
            "x": -12,
            "y": 1,
            "z": -7,
            "elements": [
                "modularmachinery:blockcasing@0"
            ]
        },
        {
            "x": 10,
            "y": 0,
            "z": -7,
            "elements": [
                "modularmachinery:blockcasing@0"
            ]
        },
        {
            "x": 10,
            "y": 0,
            "z": -6,
            "elements": [
                "minecraft:concrete@7"
            ]
        },
        {
            "x": 14,
            "y": -2,
            "z": 8,
            "elements": [
                "appliedenergistics2:smooth_sky_stone_stairs@3"
            ]
        },
        {
            "x": -8,
            "y": -3,
            "z": 6,
            "elements": [
                "appliedenergistics2:smooth_sky_stone_block@0"
            ]
        },
        {
            "x": 14,
            "y": -2,
            "z": 7,
            "elements": [
                "modularmachinery:blockcasing@0"
            ]
        },
        {
            "x": -5,
            "y": 1,
            "z": -6,
            "elements": [
                "thermalfoundation:glass_alloy@7"
            ]
        },
        {
            "x": -9,
            "y": -4,
            "z": -6,
            "elements": [
                "minecraft:concrete@7"
            ]
        },
        {
            "x": -9,
            "y": -4,
            "z": -5,
            "elements": [
                "minecraft:concrete@7"
            ]
        },
        {
            "x": -9,
            "y": -4,
            "z": -8,
            "elements": [
                "minecraft:concrete@7"
            ]
        },
        {
            "x": -9,
            "y": -4,
            "z": -7,
            "elements": [
                "minecraft:concrete@7"
            ]
        },
        {
            "x": -8,
            "y": -3,
            "z": -6,
            "elements": [
                "appliedenergistics2:smooth_sky_stone_block@0"
            ]
        },
        {
            "x": -9,
            "y": -4,
            "z": -9,
            "elements": [
                "minecraft:concrete@4"
            ]
        },
        {
            "x": -9,
            "y": -4,
            "z": 2,
            "elements": [
                "minecraft:concrete@7"
            ]
        },
        {
            "x": -9,
            "y": -4,
            "z": 3,
            "elements": [
                "minecraft:concrete@7"
            ]
        },
        {
            "x": -9,
            "y": -4,
            "z": 0,
            "elements": [
                "minecraft:concrete@7"
            ]
        },
        {
            "x": -5,
            "y": 1,
            "z": 6,
            "elements": [
                "thermalfoundation:glass_alloy@7"
            ]
        },
        {
            "x": -9,
            "y": -4,
            "z": 1,
            "elements": [
                "minecraft:concrete@7"
            ]
        },
        {
            "x": -9,
            "y": -4,
            "z": -2,
            "elements": [
                "minecraft:concrete@7"
            ]
        },
        {
            "x": -9,
            "y": -4,
            "z": -1,
            "elements": [
                "minecraft:concrete@7"
            ]
        },
        {
            "x": -9,
            "y": -4,
            "z": -4,
            "elements": [
                "minecraft:concrete@7"
            ]
        },
        {
            "x": -9,
            "y": -4,
            "z": -3,
            "elements": [
                "minecraft:concrete@7"
            ]
        },
        {
            "x": 12,
            "y": -4,
            "z": -7,
            "elements": [
                "minecraft:concrete@7"
            ]
        },
        {
            "x": 12,
            "y": -4,
            "z": -6,
            "elements": [
                "minecraft:concrete@7"
            ]
        },
        {
            "x": 12,
            "y": -4,
            "z": -9,
            "elements": [
                "minecraft:concrete@4"
            ]
        },
        {
            "x": -9,
            "y": -4,
            "z": 8,
            "elements": [
                "minecraft:concrete@7"
            ]
        },
        {
            "x": 12,
            "y": -4,
            "z": -8,
            "elements": [
                "minecraft:concrete@7"
            ]
        },
        {
            "x": -9,
            "y": -4,
            "z": 9,
            "elements": [
                "minecraft:concrete@4"
            ]
        },
        {
            "x": 12,
            "y": -4,
            "z": -3,
            "elements": [
                "minecraft:concrete@7"
            ]
        },
        {
            "x": -9,
            "y": -4,
            "z": 6,
            "elements": [
                "minecraft:concrete@7"
            ]
        },
        {
            "x": 12,
            "y": -4,
            "z": -2,
            "elements": [
                "minecraft:concrete@7"
            ]
        },
        {
            "x": -9,
            "y": -4,
            "z": 7,
            "elements": [
                "minecraft:concrete@7"
            ]
        },
        {
            "x": -9,
            "y": -4,
            "z": 4,
            "elements": [
                "minecraft:concrete@7"
            ]
        },
        {
            "x": 12,
            "y": -4,
            "z": -5,
            "elements": [
                "minecraft:concrete@7"
            ]
        },
        {
            "x": 12,
            "y": -4,
            "z": -4,
            "elements": [
                "minecraft:concrete@7"
            ]
        },
        {
            "x": -9,
            "y": -4,
            "z": 5,
            "elements": [
                "minecraft:concrete@7"
            ]
        },
        {
            "x": 12,
            "y": -4,
            "z": 1,
            "elements": [
                "minecraft:concrete@7"
            ]
        },
        {
            "x": 12,
            "y": -4,
            "z": 2,
            "elements": [
                "minecraft:concrete@7"
            ]
        },
        {
            "x": 12,
            "y": -4,
            "z": -1,
            "elements": [
                "minecraft:concrete@7"
            ]
        },
        {
            "x": 12,
            "y": -4,
            "z": 0,
            "elements": [
                "minecraft:sea_lantern@0"
            ]
        },
        {
            "x": 12,
            "y": -4,
            "z": 5,
            "elements": [
                "minecraft:concrete@7"
            ]
        },
        {
            "x": 12,
            "y": -4,
            "z": 6,
            "elements": [
                "minecraft:concrete@7"
            ]
        },
        {
            "x": -6,
            "y": -1,
            "z": 7,
            "elements": [
                "modularmachinery:blockcasing@0"
            ]
        },
        {
            "x": 12,
            "y": -4,
            "z": 3,
            "elements": [
                "minecraft:concrete@7"
            ]
        },
        {
            "x": 12,
            "y": -4,
            "z": 4,
            "elements": [
                "minecraft:concrete@7"
            ]
        },
        {
            "x": 12,
            "y": -4,
            "z": 9,
            "elements": [
                "minecraft:concrete@4"
            ]
        },
        {
            "x": 12,
            "y": -4,
            "z": 7,
            "elements": [
                "minecraft:concrete@7"
            ]
        },
        {
            "x": 12,
            "y": -4,
            "z": 8,
            "elements": [
                "minecraft:concrete@7"
            ]
        },
        {
            "x": -6,
            "y": -1,
            "z": -7,
            "elements": [
                "modularmachinery:blockcasing@0"
            ]
        },
        {
            "x": 13,
            "y": -4,
            "z": 6,
            "elements": [
                "minecraft:concrete@7"
            ]
        },
        {
            "x": 13,
            "y": -4,
            "z": 7,
            "elements": [
                "minecraft:concrete@7"
            ]
        },
        {
            "x": 13,
            "y": -4,
            "z": 8,
            "elements": [
                "minecraft:concrete@7"
            ]
        },
        {
            "x": 13,
            "y": -4,
            "z": 9,
            "elements": [
                "minecraft:concrete@4"
            ]
        },
        {
            "x": -8,
            "y": -2,
            "z": -7,
            "elements": [
                "appliedenergistics2:smooth_sky_stone_stairs@6"
            ]
        },
        {
            "x": -8,
            "y": -2,
            "z": -6,
            "elements": [
                "minecraft:concrete@7"
            ]
        },
        {
            "x": -7,
            "y": -1,
            "z": 6,
            "elements": [
                "modularmachinery:blockcasing@0"
            ]
        },
        {
            "x": -7,
            "y": -1,
            "z": -6,
            "elements": [
                "modularmachinery:blockcasing@0"
            ]
        },
        {
            "x": -3,
            "y": 3,
            "z": -5,
            "elements": [
                "quark:snow_bricks_stairs@2"
            ]
        },
        {
            "x": -3,
            "y": 3,
            "z": -4,
            "elements": [
                "modularmachinery:blockcasing@0"
            ]
        },
        {
            "x": -3,
            "y": 3,
            "z": -3,
            "elements": [
                "modularmachinery:blockcasing@0"
            ]
        },
        {
            "x": -7,
            "y": -3,
            "z": 6,
            "elements": [
                "appliedenergistics2:smooth_sky_stone_block@0"
            ]
        },
        {
            "x": -3,
            "y": 3,
            "z": -2,
            "elements": [
                "modularmachinery:blockcasing@0"
            ]
        },
        {
            "x": 13,
            "y": -2,
            "z": 7,
            "elements": [
                "modularmachinery:blockcasing@0"
            ]
        },
        {
            "x": -3,
            "y": 3,
            "z": 3,
            "elements": [
                "modularmachinery:blockcasing@0"
            ]
        },
        {
            "x": -3,
            "y": 3,
            "z": 4,
            "elements": [
                "modularmachinery:blockcasing@0"
            ]
        },
        {
            "x": -3,
            "y": 3,
            "z": 5,
            "elements": [
                "quark:snow_bricks_stairs@3"
            ]
        },
        {
            "x": -3,
            "y": 3,
            "z": -1,
            "elements": [
                "modularmachinery:blockcasing@0"
            ]
        },
        {
            "x": -3,
            "y": 3,
            "z": 0,
            "elements": [
                "modularmachinery:blockcasing@0"
            ]
        },
        {
            "x": -3,
            "y": 3,
            "z": 1,
            "elements": [
                "modularmachinery:blockcasing@0"
            ]
        },
        {
            "x": -3,
            "y": 3,
            "z": 2,
            "elements": [
                "modularmachinery:blockcasing@0"
            ]
        },
        {
            "x": 13,
            "y": -2,
            "z": -7,
            "elements": [
                "modularmachinery:blockcasing@0"
            ]
        },
        {
            "x": -6,
            "y": 1,
            "z": -6,
            "elements": [
                "modularmachinery:blockcasing@0"
            ]
        },
        {
            "x": -6,
            "y": 1,
            "z": -7,
            "elements": [
                "quark:snow_bricks_stairs@2"
            ]
        },
        {
            "x": -8,
            "y": -2,
            "z": 6,
            "elements": [
                "minecraft:concrete@7"
            ]
        },
        {
            "x": -8,
            "y": -2,
            "z": 7,
            "elements": [
                "appliedenergistics2:smooth_sky_stone_stairs@7"
            ]
        },
        {
            "x": -2,
            "y": 3,
            "z": -3,
            "elements": [
                "modularmachinery:blockcasing@0"
            ]
        },
        {
            "x": -2,
            "y": 3,
            "z": -4,
            "elements": [
                "modularmachinery:blockcasing@0"
            ]
        },
        {
            "x": 16,
            "y": -1,
            "z": -6,
            "elements": [
                "modularmachinery:blockcasing@0"
            ]
        },
        {
            "x": 16,
            "y": 2,
            "z": 5,
            "elements": [
                "modularmachinery:blockcasing@0"
            ]
        },
        {
            "x": -2,
            "y": 3,
            "z": 3,
            "elements": [
                "modularmachinery:blockcasing@0"
            ]
        },
        {
            "x": -2,
            "y": 3,
            "z": 2,
            "elements": [
                "minecraft:iron_trapdoor@0"
            ]
        },
        {
            "x": 16,
            "y": -1,
            "z": 6,
            "elements": [
                "modularmachinery:blockcasing@0"
            ]
        },
        {
            "x": -2,
            "y": 3,
            "z": 4,
            "elements": [
                "modularmachinery:blockcasing@0"
            ]
        },
        {
            "x": -2,
            "y": 3,
            "z": -1,
            "elements": [
                "minecraft:iron_trapdoor@3"
            ]
        },
        {
            "x": -2,
            "y": 3,
            "z": -2,
            "elements": [
                "minecraft:iron_trapdoor@3"
            ]
        },
        {
            "x": -2,
            "y": 3,
            "z": 1,
            "elements": [
                "minecraft:iron_trapdoor@0"
            ]
        },
        {
            "x": -2,
            "y": 3,
            "z": 0,
            "elements": [
                "nuclearcraft:turbine_rotor_blade_sic_sic_cmc@3"
            ]
        },
        {
            "x": 16,
            "y": 2,
            "z": -5,
            "elements": [
                "modularmachinery:blockcasing@0"
            ]
        },
        {
            "x": 16,
            "y": 2,
            "z": -4,
            "elements": [
                "modularmachinery:blockcasing@0"
            ]
        },
        {
            "x": -4,
            "y": 1,
            "z": -6,
            "elements": [
                "thermalfoundation:glass_alloy@7"
            ]
        },
        {
            "x": 16,
            "y": 2,
            "z": 4,
            "elements": [
                "modularmachinery:blockcasing@0"
            ]
        },
        {
            "x": -3,
            "y": 1,
            "z": 6,
            "elements": [
                "modularmachinery:blockcasing@0"
            ]
        },
        {
            "x": -3,
            "y": 1,
            "z": 7,
            "elements": [
                "quark:snow_bricks_stairs@3"
            ]
        },
        {
            "x": -4,
            "y": 1,
            "z": 6,
            "elements": [
                "thermalfoundation:glass_alloy@7"
            ]
        },
        {
            "x": -3,
            "y": 1,
            "z": -7,
            "elements": [
                "quark:snow_bricks_stairs@2"
            ]
        },
        {
            "x": -3,
            "y": 1,
            "z": -6,
            "elements": [
                "modularmachinery:blockcasing@0"
            ]
        },
        {
            "x": 13,
            "y": -4,
            "z": 2,
            "elements": [
                "minecraft:concrete@7"
            ]
        },
        {
            "x": -6,
            "y": -3,
            "z": 7,
            "elements": [
                "appliedenergistics2:smooth_sky_stone_block@0"
            ]
        },
        {
            "x": 13,
            "y": -4,
            "z": 3,
            "elements": [
                "minecraft:concrete@7"
            ]
        },
        {
            "x": 13,
            "y": -4,
            "z": 4,
            "elements": [
                "minecraft:concrete@7"
            ]
        },
        {
            "x": 13,
            "y": -4,
            "z": 5,
            "elements": [
                "minecraft:concrete@7"
            ]
        },
        {
            "x": 13,
            "y": -4,
            "z": -2,
            "elements": [
                "minecraft:concrete@7"
            ]
        },
        {
            "x": 15,
            "y": -3,
            "z": -6,
            "elements": [
                "appliedenergistics2:smooth_sky_stone_block@0"
            ]
        },
        {
            "x": 15,
            "y": -3,
            "z": -7,
            "elements": [
                "appliedenergistics2:smooth_sky_stone_block@0"
            ]
        },
        {
            "x": 13,
            "y": -4,
            "z": -1,
            "elements": [
                "minecraft:concrete@7"
            ]
        },
        {
            "x": 13,
            "y": -4,
            "z": 0,
            "elements": [
                "minecraft:concrete@7"
            ]
        },
        {
            "x": 13,
            "y": -4,
            "z": 1,
            "elements": [
                "minecraft:concrete@7"
            ]
        },
        {
            "x": 15,
            "y": 0,
            "z": 7,
            "elements": [
                "modularmachinery:blockcasing@0"
            ]
        },
        {
            "x": 13,
            "y": -4,
            "z": -6,
            "elements": [
                "minecraft:concrete@7"
            ]
        },
        {
            "x": 15,
            "y": 0,
            "z": 6,
            "elements": [
                "minecraft:concrete@7"
            ]
        },
