{   "registryname": "star_tower",
    "localizedname": "穹域共振仪",
    "requires-blueprint": false,
    "color": "FFFFFF",
    "parts": [
        {
            "x": -1,
            "y": 0,
            "z": 0,
            "elements": [
                "quark:snow_bricks_stairs@0"
            ]
        },
        {
            "x": 7,
            "y": 12,
            "z": 6,
            "elements": [
                "quark:stone_diorite_bricks_wall@0"
            ]
        },
        {
            "x": 1,
            "y": 0,
            "z": 0,
            "elements": [
                "quark:snow_bricks_stairs@1"
            ]
        },
        {
            "x": -3,
            "y": 17,
            "z": 8,
            "elements": [
                "appliedenergistics2:smooth_sky_stone_slab@0"
            ]
        },
        {
            "x": 3,
            "y": 17,
            "z": 8,
            "elements": [
                "appliedenergistics2:smooth_sky_stone_slab@0"
            ]
        },
        {
            "x": -1,
            "y": 5,
            "z": 2,
            "elements": [
                "quark:stone_diorite_bricks_wall@0"
            ]
        },
        {
            "x": 2,
            "y": -1,
            "z": 0,
            "elements": [
                "quark:polished_stone@0"
            ]
        },
        {
            "x": 1,
            "y": -1,
            "z": 0,
            "elements": [
                "minecraft:stonebrick@0"
            ]
        },
        {
            "x": 0,
            "y": 5,
            "z": 2,
            "elements": [
                "minecraft:stained_glass@11"
            ]
        },
        {
            "x": 0,
            "y": -1,
            "z": 0,
            "elements": [
                "minecraft:stonebrick@0"
            ]
        },
        {
            "x": 1,
            "y": 5,
            "z": 2,
            "elements": [
                "quark:stone_diorite_bricks_wall@0"
            ]
        },
        {
            "x": -1,
            "y": -1,
            "z": 0,
            "elements": [
                "minecraft:stonebrick@0"
            ]
        },
        {
            "x": -2,
            "y": -1,
            "z": 0,
            "elements": [
                "quark:polished_stone@0"
            ]
        },
        {
            "x": -7,
            "y": -1,
            "z": 15,
            "elements": [
                "quark:polished_stone@0"
            ]
        },
        {
            "x": -6,
            "y": -1,
            "z": 15,
            "elements": [
                "quark:polished_stone@0"
            ]
        },
        {
            "x": -5,
            "y": -1,
            "z": 15,
            "elements": [
                "quark:polished_stone@0"
            ]
        },
        {
            "x": -4,
            "y": -1,
            "z": 15,
            "elements": [
                "quark:polished_stone@0"
            ]
        },
        {
            "x": -3,
            "y": -1,
            "z": 15,
            "elements": [
                "quark:polished_stone@0"
            ]
        },
        {
            "x": -2,
            "y": -1,
            "z": 15,
            "elements": [
                "quark:polished_stone@0"
            ]
        },
        {
            "x": -1,
            "y": -1,
            "z": 15,
            "elements": [
                "minecraft:stonebrick@0"
            ]
        },
        {
            "x": 0,
            "y": -1,
            "z": 15,
            "elements": [
                "minecraft:stonebrick@0"
            ]
        },
        {
            "x": 1,
            "y": -1,
            "z": 15,
            "elements": [
                "minecraft:stonebrick@0"
            ]
        },
        {
            "x": 2,
            "y": -1,
            "z": 15,
            "elements": [
                "quark:polished_stone@0"
            ]
        },
        {
            "x": 3,
            "y": -1,
            "z": 15,
            "elements": [
                "quark:polished_stone@0"
            ]
        },
        {
            "x": 4,
            "y": -1,
            "z": 15,
            "elements": [
                "quark:polished_stone@0"
            ]
        },
        {
            "x": 5,
            "y": -1,
            "z": 15,
            "elements": [
                "quark:polished_stone@0"
            ]
        },
        {
            "x": 6,
            "y": -1,
            "z": 15,
            "elements": [
                "quark:polished_stone@0"
            ]
        },
        {
            "x": 7,
            "y": -1,
            "z": 15,
            "elements": [
                "quark:polished_stone@0"
            ]
        },
        {
            "x": -1,
            "y": 6,
            "z": 2,
            "elements": [
                "minecraft:stained_glass_pane@11"
            ]
        },
        {
            "x": 0,
            "y": 6,
            "z": 2,
            "elements": [
                "minecraft:stained_glass@11"
            ]
        },
        {
            "x": 1,
            "y": 6,
            "z": 2,
            "elements": [
                "minecraft:stained_glass_pane@11"
            ]
        },
        {
            "x": -2,
            "y": 0,
            "z": 15,
            "elements": [
                "quark:stone_diorite_wall@0"
            ]
        },
        {
            "x": -1,
            "y": 0,
            "z": 15,
            "elements": [
                "minecraft:concrete@0"
            ]
        },
        {
            "x": 0,
            "y": 0,
            "z": 15,
            "elements": [
                "minecraft:concrete@0"
            ]
        },
        {
            "x": 1,
            "y": 0,
            "z": 15,
            "elements": [
                "minecraft:concrete@0"
            ]
        },
        {
            "x": 2,
            "y": 0,
            "z": 15,
            "elements": [
                "quark:stone_diorite_wall@0"
            ]
        },
        {
            "x": -3,
            "y": 19,
            "z": 8,
            "elements": [
                "appliedenergistics2:smooth_sky_stone_slab@0"
            ]
        },
        {
            "x": -1,
            "y": 15,
            "z": 6,
            "elements": [
                "quark:snow_bricks_slab@0"
            ]
        },
        {
            "x": 3,
            "y": 19,
            "z": 8,
            "elements": [
                "appliedenergistics2:smooth_sky_stone_slab@0"
            ]
        },
        {
            "x": 1,
            "y": 15,
            "z": 6,
            "elements": [
                "quark:snow_bricks_slab@0"
            ]
        },
        {
            "x": -1,
            "y": 7,
            "z": 2,
            "elements": [
                "minecraft:stained_glass_pane@11"
            ]
        },
        {
            "x": 0,
            "y": 7,
            "z": 2,
            "elements": [
                "minecraft:stained_glass@11"
            ]
        },
        {
            "x": 1,
            "y": 7,
            "z": 2,
            "elements": [
                "minecraft:stained_glass_pane@11"
            ]
        },
        {
            "x": -1,
            "y": 1,
            "z": 15,
            "elements": [
                "quark:snow_bricks_stairs@0"
            ]
        },
        {
            "x": 0,
            "y": 1,
            "z": 15,
            "elements": [
                "appliedenergistics2:smooth_sky_stone_stairs@3"
            ]
        },
        {
            "x": 1,
            "y": 1,
            "z": 15,
            "elements": [
                "quark:snow_bricks_stairs@1"
            ]
        },
        {
            "x": -1,
            "y": 20,
            "z": 8,
            "elements": [
                "quark:snow_bricks_stairs@0"
            ]
        },
        {
            "x": 0,
            "y": 20,
            "z": 8,
            "elements": [
                "minecraft:stained_glass@1"
            ]
        },
        {
            "x": 1,
            "y": 20,
            "z": 8,
            "elements": [
                "quark:snow_bricks_stairs@1"
            ]
        },
        {
            "x": -1,
            "y": 8,
            "z": 2,
            "elements": [
                "quark:snow_bricks_stairs@3"
            ]
        },
        {
            "x": 0,
            "y": 8,
            "z": 2,
            "elements": [
                "quark:acacia_trapdoor@1"
            ]
        },
        {
            "x": 1,
            "y": 8,
            "z": 2,
            "elements": [
                "quark:snow_bricks_stairs@3"
            ]
        },
        {
            "x": -2,
            "y": 17,
            "z": 6,
            "elements": [
                "quark:snow_bricks_slab@0"
            ]
        },
        {
            "x": 2,
            "y": 17,
            "z": 6,
            "elements": [
                "quark:snow_bricks_slab@0"
            ]
        },
        {
            "x": -7,
            "y": -1,
            "z": 13,
            "elements": [
                "quark:polished_stone@0"
            ]
        },
        {
            "x": -6,
            "y": -1,
            "z": 13,
            "elements": [
                "minecraft:stonebrick@0"
            ]
        },
        {
            "x": -5,
            "y": -1,
            "z": 13,
            "elements": [
                "minecraft:stonebrick@0"
            ]
        },
        {
            "x": -4,
            "y": -1,
            "z": 13,
            "elements": [
                "minecraft:stonebrick@0"
            ]
        },
        {
            "x": -3,
            "y": -1,
            "z": 13,
            "elements": [
                "quark:polished_stone@0"
            ]
        },
        {
            "x": -2,
            "y": -1,
            "z": 13,
            "elements": [
                "minecraft:stonebrick@0"
            ]
        },
        {
            "x": -1,
            "y": -1,
            "z": 13,
            "elements": [
                "minecraft:stonebrick@0"
            ]
        },
        {
            "x": 0,
            "y": -1,
            "z": 13,
            "elements": [
                "minecraft:stonebrick@0"
            ]
        },
        {
            "x": 1,
            "y": -1,
            "z": 13,
            "elements": [
                "minecraft:stonebrick@0"
            ]
        },
        {
            "x": 2,
            "y": -1,
            "z": 13,
            "elements": [
                "minecraft:stonebrick@0"
            ]
        },
        {
            "x": 3,
            "y": -1,
            "z": 13,
            "elements": [
                "quark:polished_stone@0"
            ]
        },
        {
            "x": 4,
            "y": -1,
            "z": 13,
            "elements": [
                "minecraft:stonebrick@0"
            ]
        },
        {
            "x": 5,
            "y": -1,
            "z": 13,
            "elements": [
                "minecraft:stonebrick@0"
            ]
        },
        {
            "x": 6,
            "y": -1,
            "z": 13,
            "elements": [
                "minecraft:stonebrick@0"
            ]
        },
        {
            "x": 7,
            "y": -1,
            "z": 13,
            "elements": [
                "quark:polished_stone@0"
            ]
        },
        {
            "x": -6,
            "y": 0,
            "z": 13,
            "elements": [
                "quark:snow_bricks_stairs@0"
            ]
        },
        {
            "x": -5,
            "y": 0,
            "z": 13,
            "elements": [
                "minecraft:concrete@0"
            ]
        },
        {
            "x": -4,
            "y": 0,
            "z": 13,
            "elements": [
                "minecraft:concrete@0"
            ]
        },
        {
            "x": -3,
            "y": 0,
            "z": 13,
            "elements": [
                "quark:red_sandstone_wall@0"
            ]
        },
        {
            "x": -2,
            "y": 0,
            "z": 13,
            "elements": [
                "minecraft:concrete@0"
            ]
        },
        {
            "x": -1,
            "y": 0,
            "z": 13,
            "elements": [
                "minecraft:concrete@0"
            ]
        },
        {
            "x": 0,
            "y": 0,
            "z": 13,
            "elements": [
                "minecraft:concrete@0"
            ]
        },
        {
            "x": 1,
            "y": 0,
            "z": 13,
            "elements": [
                "minecraft:concrete@0"
            ]
        },
        {
            "x": 2,
            "y": 0,
            "z": 13,
            "elements": [
                "minecraft:concrete@0"
            ]
        },
        {
            "x": 3,
            "y": 0,
            "z": 13,
            "elements": [
                "quark:red_sandstone_wall@0"
            ]
        },
        {
            "x": -2,
            "y": 19,
            "z": 6,
            "elements": [
                "quark:snow_bricks_slab@0"
            ]
        },
        {
            "x": 4,
            "y": 0,
            "z": 13,
            "elements": [
                "minecraft:concrete@0"
            ]
        },
        {
            "x": 5,
            "y": 0,
            "z": 13,
            "elements": [
                "minecraft:concrete@0"
            ]
        },
        {
            "x": 6,
            "y": 0,
            "z": 13,
            "elements": [
                "quark:snow_bricks_stairs@1"
            ]
        },
        {
            "x": 2,
            "y": 19,
            "z": 6,
            "elements": [
                "quark:snow_bricks_slab@0"
            ]
        },
        {
            "x": -5,
            "y": 1,
            "z": 13,
            "elements": [
                "quark:snow_bricks_stairs@0"
            ]
        },
        {
            "x": -4,
            "y": 1,
            "z": 13,
            "elements": [
                "quark:snow_bricks_stairs@3"
            ]
        },
        {
            "x": -2,
            "y": 1,
            "z": 13,
            "elements": [
                "quark:snow_bricks_stairs@0"
            ]
        },
        {
            "x": -1,
            "y": 1,
            "z": 13,
            "elements": [
                "minecraft:concrete@0"
            ]
        },
        {
            "x": 0,
            "y": 1,
            "z": 13,
            "elements": [
                "minecraft:concrete@0"
            ]
        },
        {
            "x": 1,
            "y": 1,
            "z": 13,
            "elements": [
                "minecraft:concrete@0"
            ]
        },
        {
            "x": 2,
            "y": 1,
            "z": 13,
            "elements": [
                "quark:snow_bricks_stairs@1"
            ]
        },
        {
            "x": 4,
            "y": 1,
            "z": 13,
            "elements": [
                "quark:snow_bricks_stairs@3"
            ]
        },
        {
            "x": 5,
            "y": 1,
            "z": 13,
            "elements": [
                "quark:snow_bricks_stairs@3"
            ]
        },
        {
            "x": -1,
            "y": 12,
            "z": 2,
            "elements": [
                "quark:snow_bricks_stairs@7"
            ]
        },
        {
            "x": 0,
            "y": 12,
            "z": 2,
            "elements": [
                "quark:acacia_trapdoor@9"
            ]
        },
        {
            "x": 1,
            "y": 12,
            "z": 2,
            "elements": [
                "quark:snow_bricks_stairs@7"
            ]
        },
        {
            "x": -1,
            "y": 2,
            "z": 13,
            "elements": [
                "quark:snow_bricks_stairs@0"
            ]
        },
        {
            "x": 0,
            "y": 2,
            "z": 13,
            "elements": [
                "minecraft:concrete@0"
            ]
        },
        {
            "x": 1,
            "y": 2,
            "z": 13,
            "elements": [
                "quark:snow_bricks_stairs@1"
            ]
        },
        {
            "x": -1,
            "y": 13,
            "z": 2,
            "elements": [
                "minecraft:stained_glass_pane@11"
            ]
        },
        {
            "x": 0,
            "y": 13,
            "z": 2,
            "elements": [
                "minecraft:stained_glass@11"
            ]
        },
        {
            "x": -1,
            "y": 9,
            "z": 0,
            "elements": [
                "appliedenergistics2:smooth_sky_stone_stairs@6"
            ]
        },
        {
            "x": 1,
            "y": 13,
            "z": 2,
            "elements": [
                "minecraft:stained_glass_pane@11"
            ]
        },
        {
            "x": 0,
            "y": 9,
            "z": 0,
            "elements": [
                "quark:snow_bricks_stairs@6"
            ]
        },
        {
            "x": 1,
            "y": 9,
            "z": 0,
            "elements": [
                "appliedenergistics2:smooth_sky_stone_stairs@6"
            ]
        },
        {
            "x": -7,
            "y": -1,
            "z": 11,
            "elements": [
                "quark:polished_stone@0"
            ]
        },
        {
            "x": -6,
            "y": -1,
            "z": 11,
            "elements": [
                "quark:polished_stone@0"
            ]
        },
        {
            "x": -5,
            "y": -1,
            "z": 11,
            "elements": [
                "quark:polished_stone@0"
            ]
        },
        {
            "x": -1,
            "y": 7,
            "z": 15,
            "elements": [
                "minecraft:end_rod@0"
            ]
        },
        {
            "x": -4,
            "y": -1,
            "z": 11,
            "elements": [
                "minecraft:stonebrick@0"
            ]
        },
        {
            "x": -3,
            "y": -1,
            "z": 11,
            "elements": [
                "minecraft:stonebrick@0"
            ]
        },
        {
            "x": 1,
            "y": 7,
            "z": 15,
            "elements": [
                "minecraft:end_rod@0"
            ]
        },
        {
            "x": 0,
            "y": 3,
            "z": 13,
            "elements": [
                "appliedenergistics2:smooth_sky_stone_slab@0"
            ]
        },
        {
            "x": -2,
            "y": -1,
            "z": 11,
            "elements": [
                "minecraft:stonebrick@0"
            ]
        },
        {
            "x": -1,
            "y": -1,
            "z": 11,
            "elements": [
                "minecraft:concrete@7"
            ]
        },
        {
            "x": 0,
            "y": -1,
            "z": 11,
            "elements": [
                "minecraft:concrete@7"
            ]
        },
        {
            "x": 1,
            "y": -1,
            "z": 11,
            "elements": [
                "minecraft:concrete@7"
            ]
        },
        {
            "x": 2,
            "y": -1,
            "z": 11,
            "elements": [
                "minecraft:stonebrick@0"
            ]
        },
        {
            "x": 3,
            "y": -1,
            "z": 11,
            "elements": [
                "minecraft:stonebrick@0"
            ]
        },
        {
            "x": 4,
            "y": -1,
            "z": 11,
            "elements": [
                "minecraft:stonebrick@0"
            ]
        },
        {
            "x": 5,
            "y": -1,
            "z": 11,
            "elements": [
                "quark:polished_stone@0"
            ]
        },
        {
            "x": 6,
            "y": -1,
            "z": 11,
            "elements": [
                "quark:polished_stone@0"
            ]
        },
        {
            "x": -1,
            "y": 14,
            "z": 2,
            "elements": [
                "minecraft:stained_glass_pane@11"
            ]
        },
        {
            "x": 7,
            "y": -1,
            "z": 11,
            "elements": [
                "quark:polished_stone@0"
            ]
        },
        {
            "x": 0,
            "y": 14,
            "z": 2,
            "elements": [
                "minecraft:stained_glass@11"
            ]
        },
        {
            "x": -1,
            "y": 10,
            "z": 0,
            "elements": [
                "quark:red_sandstone_wall@0"
            ]
        },
        {
            "x": 1,
            "y": 14,
            "z": 2,
            "elements": [
                "minecraft:stained_glass_pane@11"
            ]
        },
        {
            "x": 0,
            "y": 10,
            "z": 0,
            "elements": [
                "minecraft:concrete@11"
            ]
        },
        {
            "x": 1,
            "y": 10,
            "z": 0,
            "elements": [
                "quark:red_sandstone_wall@0"
            ]
        },
        {
            "x": -2,
            "y": 8,
            "z": 15,
            "elements": [
                "quark:stone_diorite_bricks_wall@0"
            ]
        },
        {
            "x": -5,
            "y": 0,
            "z": 11,
            "elements": [
                "quark:red_sandstone_wall@0"
            ]
        },
        {
            "x": -1,
            "y": 8,
            "z": 15,
            "elements": [
                "minecraft:stained_glass@11"
            ]
        },
        {
            "x": 0,
            "y": 8,
            "z": 15,
            "elements": [
                "minecraft:stained_glass@11"
            ]
        },
        {
            "x": -4,
            "y": 0,
            "z": 11,
            "elements": [
                "minecraft:concrete@0"
            ]
        },
        {
            "x": 1,
            "y": 8,
            "z": 15,
            "elements": [
                "minecraft:stained_glass@11"
            ]
        },
        {
            "x": 2,
            "y": 8,
            "z": 15,
            "elements": [
                "quark:stone_diorite_bricks_wall@0"
            ]
        },
        {
            "x": -2,
            "y": 0,
            "z": 11,
            "elements": [
                "minecraft:sea_lantern@0"
            ]
        },
        {
            "x": -1,
            "y": 0,
            "z": 11,
            "elements": [
                "minecraft:stained_glass@11"
            ]
        },
        {
            "x": 0,
            "y": 0,
            "z": 11,
            "elements": [
                "minecraft:stained_glass@11"
            ]
        },
        {
            "x": 1,
            "y": 0,
            "z": 11,
            "elements": [
                "minecraft:stained_glass@11"
            ]
        },
        {
            "x": 2,
            "y": 0,
            "z": 11,
            "elements": [
                "minecraft:sea_lantern@0"
            ]
        },
        {
            "x": 4,
            "y": 0,
            "z": 11,
            "elements": [
                "minecraft:concrete@0"
            ]
        },
        {
            "x": 5,
            "y": 0,
            "z": 11,
            "elements": [
                "quark:red_sandstone_wall@0"
            ]
        },
        {
            "x": -1,
            "y": 15,
            "z": 2,
            "elements": [
                "quark:stone_diorite_bricks_wall@0"
            ]
        },
        {
            "x": 0,
            "y": 15,
            "z": 2,
            "elements": [
                "minecraft:stained_glass@11"
            ]
        },
        {
            "x": -1,
            "y": 11,
            "z": 0,
            "elements": [
                "appliedenergistics2:smooth_sky_stone_stairs@2"
            ]
        },
        {
            "x": 1,
            "y": 15,
            "z": 2,
            "elements": [
                "quark:stone_diorite_bricks_wall@0"
            ]
        },
        {
            "x": 0,
            "y": 11,
            "z": 0,
            "elements": [
                "quark:snow_bricks_stairs@2"
            ]
        },
        {
            "x": 1,
            "y": 11,
            "z": 0,
            "elements": [
                "appliedenergistics2:smooth_sky_stone_stairs@2"
            ]
        },
        {
            "x": -2,
            "y": 9,
            "z": 15,
            "elements": [
                "quark:stone_diorite_bricks_wall@0"
            ]
        },
        {
            "x": -1,
            "y": 9,
            "z": 15,
            "elements": [
                "minecraft:stained_glass@11"
            ]
        },
        {
            "x": 0,
            "y": 9,
            "z": 15,
            "elements": [
                "minecraft:stained_glass@11"
            ]
        },
        {
            "x": -4,
            "y": 1,
            "z": 11,
            "elements": [
                "appliedenergistics2:smooth_sky_stone_stairs@0"
            ]
        },
        {
            "x": -3,
            "y": 1,
            "z": 11,
            "elements": [
                "quark:snow_bricks_stairs@2"
            ]
        },
        {
            "x": 1,
            "y": 9,
            "z": 15,
            "elements": [
                "minecraft:stained_glass@11"
            ]
        },
        {
            "x": 2,
            "y": 9,
            "z": 15,
            "elements": [
                "quark:stone_diorite_bricks_wall@0"
            ]
        },
        {
            "x": -2,
            "y": 1,
            "z": 11,
            "elements": [
                "quark:snow_bricks_stairs@2"
            ]
        },
        {
            "x": 2,
            "y": 1,
            "z": 11,
            "elements": [
                "quark:snow_bricks_stairs@2"
            ]
        },
        {
            "x": 3,
            "y": 1,
            "z": 11,
            "elements": [
                "quark:snow_bricks_stairs@0"
            ]
        },
        {
            "x": 4,
            "y": 1,
            "z": 11,
            "elements": [
                "appliedenergistics2:smooth_sky_stone_stairs@1"
            ]
        },
        {
            "x": -1,
            "y": 16,
            "z": 2,
            "elements": [
                "quark:stone_diorite_bricks_wall@0"
            ]
        },
        {
            "x": 0,
            "y": 16,
            "z": 2,
            "elements": [
                "minecraft:stained_glass@11"
            ]
        },
        {
            "x": 1,
            "y": 16,
            "z": 2,
            "elements": [
                "quark:stone_diorite_bricks_wall@0"
            ]
        },
        {
            "x": -1,
            "y": 10,
            "z": 15,
            "elements": [
                "quark:stone_diorite_bricks_wall@0"
            ]
        },
        {
            "x": 0,
            "y": 10,
            "z": 15,
            "elements": [
                "quark:acacia_trapdoor@4"
            ]
        },
        {
            "x": -3,
            "y": 2,
            "z": 11,
            "elements": [
                "minecraft:stained_glass_pane@11"
            ]
        },
        {
            "x": 1,
            "y": 10,
            "z": 15,
            "elements": [
                "quark:stone_diorite_bricks_wall@0"
            ]
        },
        {
            "x": -2,
            "y": 2,
            "z": 11,
            "elements": [
                "minecraft:stained_glass_pane@11"
            ]
        },
        {
            "x": -1,
            "y": -2,
            "z": 9,
            "elements": [
                "minecraft:emerald_block@0"
            ]
        },
        {
            "x": 0,
            "y": -2,
            "z": 9,
            "elements": [
                "minecraft:emerald_block@0"
            ]
        },
        {
            "x": 2,
            "y": 2,
            "z": 11,
            "elements": [
                "minecraft:stained_glass_pane@11"
            ]
        },
        {
            "x": 3,
            "y": 2,
            "z": 11,
            "elements": [
                "minecraft:stained_glass_pane@11"
            ]
        },
        {
            "x": 1,
            "y": -2,
            "z": 9,
            "elements": [
                "minecraft:emerald_block@0"
            ]
        },
        {
            "x": -10,
            "y": -1,
            "z": 9,
            "elements": [
                "quark:polished_stone@0"
            ]
        },
        {
            "x": -9,
            "y": -1,
            "z": 9,
            "elements": [
                "minecraft:stonebrick@0"
            ]
        },
        {
            "x": -8,
            "y": -1,
            "z": 9,
            "elements": [
                "minecraft:stonebrick@0"
            ]
        },
        {
            "x": -2,
            "y": 11,
            "z": 15,
            "elements": [
                "quark:stone_diorite_bricks_wall@0"
            ]
        },
        {
            "x": -1,
            "y": 11,
            "z": 15,
            "elements": [
                "minecraft:stained_glass@11"
            ]
        },
        {
            "x": -7,
            "y": -1,
            "z": 9,
            "elements": [
                "minecraft:stonebrick@0"
            ]
        },
        {
            "x": 0,
            "y": 11,
            "z": 15,
            "elements": [
                "minecraft:stained_glass@11"
            ]
        },
        {
            "x": -6,
            "y": -1,
            "z": 9,
            "elements": [
                "minecraft:stonebrick@0"
            ]
        },
        {
            "x": -5,
            "y": -1,
            "z": 9,
            "elements": [
                "minecraft:stonebrick@0"
            ]
        },
        {
            "x": 1,
            "y": 11,
            "z": 15,
            "elements": [
                "minecraft:stained_glass@11"
            ]
        },
        {
            "x": 2,
            "y": 11,
            "z": 15,
            "elements": [
                "quark:stone_diorite_bricks_wall@0"
            ]
        },
        {
            "x": -4,
            "y": -1,
            "z": 9,
            "elements": [
                "minecraft:stonebrick@0"
            ]
        },
        {
            "x": -3,
            "y": -1,
            "z": 9,
            "elements": [
                "minecraft:concrete@7"
            ]
        },
        {
            "x": -2,
            "y": -1,
            "z": 9,
            "elements": [
                "minecraft:concrete@7"
            ]
        },
        {
            "x": -1,
            "y": -1,
            "z": 9,
            "elements": [
                "minecraft:concrete@7"
            ]
        },
        {
            "x": 0,
            "y": -1,
            "z": 9,
            "elements": [
                "minecraft:concrete@7"
            ]
        },
        {
            "x": 1,
            "y": -1,
            "z": 9,
            "elements": [
                "minecraft:concrete@7"
            ]
        },
        {
            "x": 2,
            "y": -1,
            "z": 9,
            "elements": [
                "minecraft:concrete@7"
            ]
        },
        {
            "x": 3,
            "y": -1,
            "z": 9,
            "elements": [
                "minecraft:concrete@7"
            ]
        },
        {
            "x": 4,
            "y": -1,
            "z": 9,
            "elements": [
                "minecraft:stonebrick@0"
            ]
        },
        {
            "x": 5,
            "y": -1,
            "z": 9,
            "elements": [
                "minecraft:stonebrick@0"
            ]
        },
        {
            "x": 6,
            "y": -1,
            "z": 9,
            "elements": [
                "minecraft:stonebrick@0"
            ]
        },
        {
            "x": 7,
            "y": -1,
            "z": 9,
            "elements": [
                "minecraft:stonebrick@0"
            ]
        },
        {
            "x": 8,
            "y": -1,
            "z": 9,
            "elements": [
                "minecraft:stonebrick@0"
            ]
        },
        {
            "x": 9,
            "y": -1,
            "z": 9,
            "elements": [
                "minecraft:stonebrick@0"
            ]
        },
        {
            "x": 10,
            "y": -1,
            "z": 9,
            "elements": [
                "quark:polished_stone@0"
            ]
        },
        {
            "x": -9,
            "y": 0,
            "z": 9,
            "elements": [
                "quark:snow_bricks_stairs@3"
            ]
        },
        {
            "x": -8,
            "y": 0,
            "z": 9,
            "elements": [
                "quark:snow_bricks_stairs@3"
            ]
        },
        {
            "x": -2,
            "y": 12,
            "z": 15,
            "elements": [
                "quark:stone_diorite_bricks_wall@0"
            ]
        },
        {
            "x": -1,
            "y": 12,
            "z": 15,
            "elements": [
                "minecraft:stained_glass@11"
            ]
        },
        {
            "x": -7,
            "y": 0,
            "z": 9,
            "elements": [
                "minecraft:concrete@0"
            ]
        },
        {
            "x": 0,
            "y": 12,
            "z": 15,
            "elements": [
                "minecraft:stained_glass@11"
            ]
        },
        {
            "x": -6,
            "y": 0,
            "z": 9,
            "elements": [
                "minecraft:concrete@0"
            ]
        },
        {
            "x": -5,
            "y": 0,
            "z": 9,
            "elements": [
                "minecraft:concrete@0"
            ]
        },
        {
            "x": 1,
            "y": 12,
            "z": 15,
            "elements": [
                "minecraft:stained_glass@11"
            ]
        },
        {
            "x": 2,
            "y": 12,
            "z": 15,
            "elements": [
                "quark:stone_diorite_bricks_wall@0"
            ]
        },
        {
            "x": -4,
            "y": 0,
            "z": 9,
            "elements": [
                "minecraft:sea_lantern@0"
            ]
        },
        {
            "x": -3,
            "y": 0,
            "z": 9,
            "elements": [
                "minecraft:stained_glass@11"
            ]
        },
        {
            "x": -2,
            "y": 0,
            "z": 9,
            "elements": [
                "minecraft:stained_glass@11"
            ]
        },
        {
            "x": -1,
            "y": 0,
            "z": 9,
            "elements": [
                "minecraft:stained_glass@11"
            ]
        },
        {
            "x": 0,
            "y": 0,
            "z": 9,
            "elements": [
                "minecraft:stained_glass@11"
            ]
        },
        {
            "x": 1,
            "y": 0,
            "z": 9,
            "elements": [
                "minecraft:stained_glass@11"
            ]
        },
        {
            "x": 2,
            "y": 0,
            "z": 9,
            "elements": [
                "minecraft:stained_glass@11"
            ]
        },
        {
            "x": 3,
            "y": 0,
            "z": 9,
            "elements": [
                "minecraft:stained_glass@11"
            ]
        },
        {
            "x": 4,
            "y": 0,
            "z": 9,
            "elements": [
                "minecraft:sea_lantern@0"
            ]
        },
        {
            "x": 5,
            "y": 0,
            "z": 9,
            "elements": [
                "minecraft:concrete@0"
            ]
        },
        {
            "x": 6,
            "y": 0,
            "z": 9,
            "elements": [
                "minecraft:concrete@0"
            ]
        },
        {
            "x": 7,
            "y": 0,
            "z": 9,
            "elements": [
                "minecraft:concrete@0"
            ]
        },
        {
            "x": 8,
            "y": 0,
            "z": 9,
            "elements": [
                "quark:snow_bricks_stairs@3"
            ]
        },
        {
            "x": 9,
            "y": 0,
            "z": 9,
            "elements": [
                "quark:snow_bricks_stairs@3"
            ]
        },
        {
            "x": -1,
            "y": 13,
            "z": 15,
            "elements": [
                "minecraft:end_rod@1"
            ]
        },
        {
            "x": -7,
            "y": 1,
            "z": 9,
            "elements": [
                "quark:snow_bricks_stairs@3"
            ]
        },
        {
            "x": -6,
            "y": 1,
            "z": 9,
            "elements": [
                "minecraft:concrete@0"
            ]
        },
        {
            "x": 1,
            "y": 13,
            "z": 15,
            "elements": [
                "minecraft:end_rod@1"
            ]
        },
        {
            "x": -5,
            "y": 1,
            "z": 9,
            "elements": [
                "minecraft:concrete@0"
            ]
        },
        {
            "x": -4,
            "y": 1,
            "z": 9,
            "elements": [
                "quark:snow_bricks_stairs@1"
            ]
        },
        {
            "x": -1,
            "y": 5,
            "z": 11,
            "elements": [
                "quark:snow_bricks_slab@0"
            ]
        },
        {
            "x": 0,
            "y": 5,
            "z": 11,
            "elements": [
                "appliedenergistics2:smooth_sky_stone_slab@0"
            ]
        },
        {
            "x": 1,
            "y": 5,
            "z": 11,
            "elements": [
                "quark:snow_bricks_slab@0"
            ]
        },
        {
            "x": 4,
            "y": 1,
            "z": 9,
            "elements": [
                "quark:snow_bricks_stairs@0"
            ]
        },
        {
            "x": 5,
            "y": 1,
            "z": 9,
            "elements": [
                "minecraft:concrete@0"
            ]
        },
        {
            "x": 6,
            "y": 1,
            "z": 9,
            "elements": [
                "minecraft:concrete@0"
            ]
        },
        {
            "x": 7,
            "y": 1,
            "z": 9,
            "elements": [
                "quark:snow_bricks_stairs@3"
            ]
        },
        {
            "x": -6,
            "y": 2,
            "z": 9,
            "elements": [
                "quark:snow_bricks_stairs@0"
            ]
        },
        {
            "x": -5,
            "y": 2,
            "z": 9,
            "elements": [
                "quark:snow_bricks_stairs@3"
            ]
        },
        {
            "x": -4,
            "y": 2,
            "z": 9,
            "elements": [
                "minecraft:stained_glass_pane@11"
            ]
        },
        {
            "x": -1,
            "y": -2,
            "z": 7,
            "elements": [
                "minecraft:emerald_block@0"
            ]
        },
        {
            "x": 0,
            "y": -2,
            "z": 7,
            "elements": [
                "minecraft:emerald_block@0"
            ]
        },
        {
            "x": 1,
            "y": -2,
            "z": 7,
            "elements": [
                "minecraft:emerald_block@0"
            ]
        },
        {
            "x": 4,
            "y": 2,
            "z": 9,
            "elements": [
                "minecraft:stained_glass_pane@11"
            ]
        },
        {
            "x": 5,
            "y": 2,
            "z": 9,
            "elements": [
                "quark:snow_bricks_stairs@3"
            ]
        },
        {
            "x": 6,
            "y": 2,
            "z": 9,
            "elements": [
                "quark:snow_bricks_stairs@3"
            ]
        },
        {
            "x": -10,
            "y": -1,
            "z": 7,
            "elements": [
                "quark:polished_stone@0"
            ]
        },
        {
            "x": -9,
            "y": -1,
            "z": 7,
            "elements": [
                "minecraft:stonebrick@0"
            ]
        },
        {
            "x": -8,
            "y": -1,
            "z": 7,
            "elements": [
                "minecraft:stonebrick@0"
            ]
        },
        {
            "x": -7,
            "y": -1,
            "z": 7,
            "elements": [
                "minecraft:stonebrick@0"
            ]
        },
        {
            "x": -6,
            "y": -1,
            "z": 7,
            "elements": [
                "minecraft:stonebrick@0"
            ]
        },
        {
            "x": -5,
            "y": -1,
            "z": 7,
            "elements": [
                "minecraft:stonebrick@0"
            ]
        },
        {
            "x": -1,
            "y": 7,
            "z": 11,
            "elements": [
                "quark:snow_bricks_slab@0"
            ]
        },
        {
            "x": 0,
            "y": 7,
            "z": 11,
            "elements": [
                "appliedenergistics2:smooth_sky_stone_slab@0"
            ]
        },
        {
            "x": -4,
            "y": -1,
            "z": 7,
            "elements": [
                "minecraft:stonebrick@0"
            ]
        },
        {
            "x": -3,
            "y": -1,
            "z": 7,
            "elements": [
                "minecraft:concrete@7"
            ]
        },
        {
            "x": 1,
            "y": 7,
            "z": 11,
            "elements": [
                "quark:snow_bricks_slab@0"
            ]
        },
        {
            "x": -2,
            "y": -1,
            "z": 7,
            "elements": [
                "minecraft:concrete@7"
            ]
        },
        {
            "x": -1,
            "y": -1,
            "z": 7,
            "elements": [
                "minecraft:concrete@7"
            ]
        },
        {
            "x": 0,
            "y": -1,
            "z": 7,
            "elements": [
                "minecraft:concrete@7"
            ]
        },
        {
            "x": 1,
            "y": -1,
            "z": 7,
            "elements": [
                "minecraft:concrete@7"
            ]
        },
        {
            "x": 2,
            "y": -1,
            "z": 7,
            "elements": [
                "minecraft:concrete@7"
            ]
        },
        {
            "x": 3,
            "y": -1,
            "z": 7,
            "elements": [
                "minecraft:concrete@7"
            ]
        },
        {
            "x": 4,
            "y": -1,
            "z": 7,
            "elements": [
                "minecraft:stonebrick@0"
            ]
        },
        {
            "x": 5,
            "y": -1,
            "z": 7,
            "elements": [
                "minecraft:stonebrick@0"
            ]
        },
        {
            "x": 6,
            "y": -1,
            "z": 7,
            "elements": [
                "minecraft:stonebrick@0"
            ]
        },
        {
            "x": 7,
            "y": -1,
            "z": 7,
            "elements": [
                "minecraft:stonebrick@0"
            ]
        },
        {
            "x": 8,
            "y": -1,
            "z": 7,
            "elements": [
                "minecraft:stonebrick@0"
            ]
        },
        {
            "x": 9,
            "y": -1,
            "z": 7,
            "elements": [
                "minecraft:stonebrick@0"
            ]
        },
        {
            "x": 10,
            "y": -1,
            "z": 7,
            "elements": [
                "quark:polished_stone@0"
            ]
        },
        {
            "x": -9,
            "y": 0,
            "z": 7,
            "elements": [
                "quark:snow_bricks_stairs@2"
            ]
        },
        {
            "x": -8,
            "y": 0,
            "z": 7,
            "elements": [
                "quark:snow_bricks_stairs@2"
            ]
        },
        {
            "x": -6,
            "y": 4,
            "z": 9,
            "elements": [
                "quark:stone_diorite_bricks_wall@0"
            ]
        },
        {
            "x": -7,
            "y": 0,
            "z": 7,
            "elements": [
                "minecraft:concrete@0"
            ]
        },
        {
            "x": -6,
            "y": 0,
            "z": 7,
            "elements": [
                "minecraft:concrete@0"
            ]
        },
        {
            "x": -5,
            "y": 0,
            "z": 7,
            "elements": [
                "minecraft:concrete@0"
            ]
        },
        {
            "x": -4,
            "y": 0,
            "z": 7,
            "elements": [
                "minecraft:sea_lantern@0"
            ]
        },
        {
            "x": -3,
            "y": 0,
            "z": 7,
            "elements": [
                "minecraft:stained_glass@11"
            ]
        },
        {
            "x": -2,
            "y": 0,
            "z": 7,
            "elements": [
                "minecraft:stained_glass@11"
            ]
        },
        {
            "x": -1,
            "y": 0,
            "z": 7,
            "elements": [
                "minecraft:stained_glass@11"
            ]
        },
        {
            "x": 0,
            "y": 0,
            "z": 7,
            "elements": [
                "minecraft:stained_glass@11"
            ]
        },
        {
            "x": 1,
            "y": 0,
            "z": 7,
            "elements": [
                "minecraft:stained_glass@11"
            ]
        },
        {
            "x": 2,
            "y": 0,
            "z": 7,
            "elements": [
                "minecraft:stained_glass@11"
            ]
        },
        {
            "x": 3,
            "y": 0,
            "z": 7,
            "elements": [
                "minecraft:stained_glass@11"
            ]
        },
        {
            "x": 6,
            "y": 4,
            "z": 9,
            "elements": [
                "quark:stone_diorite_bricks_wall@0"
            ]
        },
        {
            "x": 4,
            "y": 0,
            "z": 7,
            "elements": [
                "minecraft:sea_lantern@0"
            ]
        },
        {
            "x": 5,
            "y": 0,
            "z": 7,
            "elements": [
                "minecraft:concrete@0"
            ]
        },
        {
            "x": 6,
            "y": 0,
            "z": 7,
            "elements": [
                "minecraft:concrete@0"
            ]
        },
        {
            "x": 7,
            "y": 0,
            "z": 7,
            "elements": [
                "minecraft:concrete@0"
            ]
        },
        {
            "x": 8,
            "y": 0,
            "z": 7,
            "elements": [
                "quark:snow_bricks_stairs@2"
            ]
        },
        {
            "x": 9,
            "y": 0,
            "z": 7,
            "elements": [
                "quark:snow_bricks_stairs@2"
            ]
        },
        {
            "x": -6,
            "y": 5,
            "z": 9,
            "elements": [
                "quark:stone_diorite_bricks_wall@0"
            ]
        },
        {
            "x": -7,
            "y": 1,
            "z": 7,
            "elements": [
                "quark:snow_bricks_stairs@2"
            ]
        },
        {
            "x": -6,
            "y": 1,
            "z": 7,
            "elements": [
                "minecraft:concrete@0"
            ]
        },
        {
            "x": -3,
            "y": 5,
            "z": 9,
            "elements": [
                "quark:snow_bricks_slab@0"
            ]
        },
        {
            "x": -5,
            "y": 1,
            "z": 7,
            "elements": [
                "minecraft:concrete@0"
            ]
        },
        {
            "x": -4,
            "y": 1,
            "z": 7,
            "elements": [
                "quark:snow_bricks_stairs@1"
            ]
        },
        {
            "x": 3,
            "y": 5,
            "z": 9,
            "elements": [
                "quark:snow_bricks_slab@0"
            ]
        },
        {
            "x": 6,
            "y": 5,
            "z": 9,
            "elements": [
                "quark:stone_diorite_bricks_wall@0"
            ]
        },
        {
            "x": 4,
            "y": 1,
            "z": 7,
            "elements": [
                "quark:snow_bricks_stairs@0"
            ]
        },
        {
            "x": 5,
            "y": 1,
            "z": 7,
            "elements": [
                "minecraft:concrete@0"
            ]
        },
        {
            "x": 6,
            "y": 1,
            "z": 7,
            "elements": [
                "minecraft:concrete@0"
            ]
        },
        {
            "x": 7,
            "y": 1,
            "z": 7,
            "elements": [
                "quark:snow_bricks_stairs@2"
            ]
        },
        {
            "x": -6,
            "y": 6,
            "z": 9,
            "elements": [
                "minecraft:stained_glass_pane@11"
            ]
        },
        {
            "x": -6,
            "y": 2,
            "z": 7,
            "elements": [
                "quark:snow_bricks_stairs@2"
            ]
        },
        {
            "x": -5,
            "y": 2,
            "z": 7,
            "elements": [
                "quark:snow_bricks_stairs@2"
            ]
        },
        {
            "x": -4,
            "y": 2,
            "z": 7,
            "elements": [
                "minecraft:stained_glass_pane@11"
            ]
        },
        {
            "x": 6,
            "y": 6,
            "z": 9,
            "elements": [
                "minecraft:stained_glass_pane@11"
            ]
        },
        {
            "x": 4,
            "y": 2,
            "z": 7,
            "elements": [
                "minecraft:stained_glass_pane@11"
            ]
        },
        {
            "x": 5,
            "y": 2,
            "z": 7,
            "elements": [
                "quark:snow_bricks_stairs@2"
            ]
        },
        {
            "x": 6,
            "y": 2,
            "z": 7,
            "elements": [
                "quark:snow_bricks_stairs@2"
            ]
        },
        {
            "x": -7,
            "y": 7,
            "z": 9,
            "elements": [
                "minecraft:end_rod@0"
            ]
        },
        {
            "x": -6,
            "y": 7,
            "z": 9,
            "elements": [
                "minecraft:stained_glass_pane@11"
            ]
        },
        {
            "x": -7,
            "y": -1,
            "z": 5,
            "elements": [
                "quark:polished_stone@0"
            ]
        },
        {
            "x": -3,
            "y": 7,
            "z": 9,
            "elements": [
                "quark:snow_bricks_slab@0"
            ]
        },
        {
            "x": -6,
            "y": -1,
            "z": 5,
            "elements": [
                "quark:polished_stone@0"
            ]
        },
        {
            "x": -5,
            "y": -1,
            "z": 5,
            "elements": [
                "quark:polished_stone@0"
            ]
        },
        {
            "x": -4,
            "y": -1,
            "z": 5,
            "elements": [
                "minecraft:stonebrick@0"
            ]
        },
        {
            "x": -3,
            "y": -1,
            "z": 5,
            "elements": [
                "minecraft:stonebrick@0"
            ]
        },
        {
            "x": -2,
            "y": -1,
            "z": 5,
            "elements": [
                "minecraft:stonebrick@0"
            ]
        },
        {
            "x": -1,
            "y": -1,
            "z": 5,
            "elements": [
                "minecraft:concrete@7"
            ]
        },
        {
            "x": 3,
            "y": 7,
            "z": 9,
            "elements": [
                "quark:snow_bricks_slab@0"
            ]
        },
        {
            "x": 0,
            "y": -1,
            "z": 5,
            "elements": [
                "minecraft:concrete@7"
            ]
        },
        {
            "x": 1,
            "y": -1,
            "z": 5,
            "elements": [
                "minecraft:concrete@7"
            ]
        },
        {
            "x": 6,
            "y": 7,
            "z": 9,
            "elements": [
                "minecraft:stained_glass_pane@11"
            ]
        },
        {
            "x": 2,
            "y": -1,
            "z": 5,
            "elements": [
                "minecraft:stonebrick@0"
            ]
        },
        {
            "x": 7,
            "y": 7,
            "z": 9,
            "elements": [
                "minecraft:end_rod@0"
            ]
        },
        {
            "x": 3,
            "y": -1,
            "z": 5,
            "elements": [
                "minecraft:stonebrick@0"
            ]
        },
        {
            "x": 4,
            "y": -1,
            "z": 5,
            "elements": [
                "minecraft:stonebrick@0"
            ]
        },
        {
            "x": 5,
            "y": -1,
            "z": 5,
            "elements": [
                "quark:polished_stone@0"
            ]
        },
        {
            "x": 6,
            "y": -1,
            "z": 5,
            "elements": [
                "quark:polished_stone@0"
            ]
        },
        {
            "x": 7,
            "y": -1,
            "z": 5,
            "elements": [
                "quark:polished_stone@0"
            ]
        },
        {
            "x": -7,
            "y": 8,
            "z": 9,
            "elements": [
                "minecraft:stained_glass@11"
            ]
        },
        {
            "x": -6,
            "y": 8,
            "z": 9,
            "elements": [
                "quark:snow_bricks_stairs@1"
            ]
        },
        {
            "x": -6,
            "y": 4,
            "z": 7,
            "elements": [
                "quark:stone_diorite_bricks_wall@0"
            ]
        },
        {
            "x": -2,
            "y": 8,
            "z": 9,
            "elements": [
                "quark:snow_bricks_slab@8"
            ]
        },
        {
            "x": -5,
            "y": 0,
            "z": 5,
            "elements": [
                "quark:red_sandstone_wall@0"
            ]
        },
        {
            "x": -1,
            "y": 8,
            "z": 9,
            "elements": [
                "quark:snow_bricks_slab@8"
            ]
        },
        {
            "x": 0,
            "y": 8,
            "z": 9,
            "elements": [
                "appliedenergistics2:smooth_sky_stone_slab@8"
            ]
        },
        {
            "x": -4,
            "y": 0,
            "z": 5,
            "elements": [
                "minecraft:concrete@0"
            ]
        },
        {
            "x": 1,
            "y": 8,
            "z": 9,
            "elements": [
                "quark:snow_bricks_slab@8"
            ]
        },
        {
            "x": 2,
            "y": 8,
            "z": 9,
            "elements": [
                "quark:snow_bricks_slab@8"
            ]
        },
        {
            "x": -2,
            "y": 0,
            "z": 5,
            "elements": [
                "minecraft:sea_lantern@0"
            ]
        },
        {
            "x": -1,
            "y": 0,
            "z": 5,
            "elements": [
                "minecraft:stained_glass@11"
            ]
        },
        {
            "x": 0,
            "y": 0,
            "z": 5,
            "elements": [
                "minecraft:stained_glass@11"
            ]
        },
        {
            "x": 1,
            "y": 0,
            "z": 5,
            "elements": [
                "minecraft:stained_glass@11"
            ]
        },
        {
            "x": 6,
            "y": 8,
            "z": 9,
            "elements": [
                "quark:snow_bricks_stairs@0"
            ]
        },
        {
            "x": 2,
            "y": 0,
            "z": 5,
            "elements": [
                "minecraft:sea_lantern@0"
            ]
        },
        {
            "x": 7,
            "y": 8,
            "z": 9,
            "elements": [
                "minecraft:stained_glass@11"
            ]
        },
        {
            "x": 6,
            "y": 4,
            "z": 7,
            "elements": [
                "quark:stone_diorite_bricks_wall@0"
            ]
        },
        {
            "x": 4,
            "y": 0,
            "z": 5,
            "elements": [
                "minecraft:concrete@0"
            ]
        },
        {
            "x": 5,
            "y": 0,
            "z": 5,
            "elements": [
                "quark:red_sandstone_wall@0"
            ]
        },
        {
            "x": -8,
            "y": 9,
            "z": 9,
            "elements": [
                "appliedenergistics2:smooth_sky_stone_stairs@4"
            ]
        },
        {
            "x": -7,
            "y": 9,
            "z": 9,
            "elements": [
                "minecraft:stained_glass@11"
            ]
        },
        {
            "x": -6,
            "y": 5,
            "z": 7,
            "elements": [
                "quark:stone_diorite_bricks_wall@0"
            ]
        },
        {
            "x": -1,
            "y": 9,
            "z": 9,
            "elements": [
                "quark:stone_diorite_bricks_wall@0"
            ]
        },
        {
            "x": -3,
            "y": 5,
            "z": 7,
            "elements": [
                "quark:snow_bricks_slab@0"
            ]
        },
        {
            "x": 0,
            "y": 9,
            "z": 9,
            "elements": [
                "quark:snow_bricks_stairs@3"
            ]
        },
        {
            "x": -4,
            "y": 1,
            "z": 5,
            "elements": [
                "appliedenergistics2:smooth_sky_stone_stairs@0"
            ]
        },
        {
            "x": -3,
            "y": 1,
            "z": 5,
            "elements": [
                "quark:snow_bricks_stairs@1"
            ]
        },
        {
            "x": 1,
            "y": 9,
            "z": 9,
            "elements": [
                "quark:stone_diorite_bricks_wall@0"
            ]
        },
        {
            "x": -2,
            "y": 1,
            "z": 5,
            "elements": [
                "quark:snow_bricks_stairs@3"
            ]
        },
        {
            "x": 3,
            "y": 5,
            "z": 7,
            "elements": [
                "quark:snow_bricks_slab@0"
            ]
        },
        {
            "x": 2,
            "y": 1,
            "z": 5,
            "elements": [
                "quark:snow_bricks_stairs@3"
            ]
        },
        {
            "x": 7,
            "y": 9,
            "z": 9,
            "elements": [
                "minecraft:stained_glass@11"
            ]
        },
        {
            "x": 3,
            "y": 1,
            "z": 5,
            "elements": [
                "quark:snow_bricks_stairs@0"
            ]
        },
        {
            "x": 8,
            "y": 9,
            "z": 9,
            "elements": [
                "appliedenergistics2:smooth_sky_stone_stairs@5"
            ]
        },
        {
            "x": 6,
            "y": 5,
            "z": 7,
            "elements": [
                "quark:stone_diorite_bricks_wall@0"
            ]
        },
        {
            "x": 4,
            "y": 1,
            "z": 5,
            "elements": [
                "appliedenergistics2:smooth_sky_stone_stairs@1"
            ]
        },
        {
            "x": -8,
            "y": 10,
            "z": 9,
            "elements": [
                "quark:red_sandstone_wall@0"
            ]
        },
        {
            "x": -7,
            "y": 10,
            "z": 9,
            "elements": [
                "quark:stone_diorite_bricks_wall@0"
            ]
        },
        {
            "x": -6,
            "y": 6,
            "z": 7,
            "elements": [
                "minecraft:stained_glass_pane@11"
            ]
        },
        {
            "x": -1,
            "y": 10,
            "z": 9,
            "elements": [
                "quark:stone_diorite_bricks_wall@0"
            ]
        },
        {
            "x": -3,
            "y": 2,
            "z": 5,
            "elements": [
                "minecraft:stained_glass_pane@11"
            ]
        },
        {
            "x": 1,
            "y": 10,
            "z": 9,
            "elements": [
                "quark:stone_diorite_bricks_wall@0"
            ]
        },
        {
            "x": -2,
            "y": 2,
            "z": 5,
            "elements": [
                "minecraft:stained_glass_pane@11"
            ]
        },
        {
            "x": 2,
            "y": 2,
            "z": 5,
            "elements": [
                "minecraft:stained_glass_pane@11"
            ]
        },
        {
            "x": 7,
            "y": 10,
            "z": 9,
            "elements": [
                "quark:stone_diorite_bricks_wall@0"
            ]
        },
        {
            "x": 3,
            "y": 2,
            "z": 5,
            "elements": [
                "minecraft:stained_glass_pane@11"
            ]
        },
        {
            "x": 8,
            "y": 10,
            "z": 9,
            "elements": [
                "quark:red_sandstone_wall@0"
            ]
        },
        {
            "x": 6,
            "y": 6,
            "z": 7,
            "elements": [
                "minecraft:stained_glass_pane@11"
            ]
        },
        {
            "x": -8,
            "y": 11,
            "z": 9,
            "elements": [
                "appliedenergistics2:smooth_sky_stone_stairs@0"
            ]
        },
        {
            "x": -7,
            "y": 11,
            "z": 9,
            "elements": [
                "minecraft:stained_glass@11"
            ]
        },
        {
            "x": -7,
            "y": 7,
            "z": 7,
            "elements": [
                "minecraft:end_rod@0"
            ]
        },
        {
            "x": -6,
            "y": 7,
            "z": 7,
            "elements": [
                "minecraft:stained_glass_pane@11"
            ]
        },
        {
            "x": -7,
            "y": -1,
            "z": 3,
            "elements": [
                "quark:polished_stone@0"
            ]
        },
        {
            "x": -3,
            "y": 7,
            "z": 7,
            "elements": [
                "quark:snow_bricks_slab@0"
            ]
        },
        {
            "x": -1,
            "y": 11,
            "z": 9,
            "elements": [
                "quark:stone_diorite_bricks_wall@0"
            ]
        },
        {
            "x": -6,
            "y": -1,
            "z": 3,
            "elements": [
                "minecraft:stonebrick@0"
            ]
        },
        {
            "x": -5,
            "y": -1,
            "z": 3,
            "elements": [
                "minecraft:stonebrick@0"
            ]
        },
        {
            "x": 1,
            "y": 11,
            "z": 9,
            "elements": [
                "quark:stone_diorite_bricks_wall@0"
            ]
        },
        {
            "x": -4,
            "y": -1,
            "z": 3,
            "elements": [
                "minecraft:stonebrick@0"
            ]
        },
        {
            "x": -3,
            "y": -1,
            "z": 3,
            "elements": [
                "quark:polished_stone@0"
            ]
        },
        {
            "x": -2,
            "y": -1,
            "z": 3,
            "elements": [
                "minecraft:stonebrick@0"
            ]
        },
        {
            "x": -1,
            "y": -1,
            "z": 3,
            "elements": [
                "minecraft:stonebrick@0"
            ]
        },
        {
            "x": 3,
            "y": 7,
            "z": 7,
            "elements": [
                "quark:snow_bricks_slab@0"
            ]
        },
        {
            "x": 0,
            "y": -1,
            "z": 3,
            "elements": [
                "minecraft:stonebrick@0"
            ]
        },
        {
            "x": 7,
            "y": 11,
            "z": 9,
            "elements": [
                "minecraft:stained_glass@11"
            ]
        },
        {
            "x": 1,
            "y": -1,
            "z": 3,
            "elements": [
                "minecraft:stonebrick@0"
            ]
        },
        {
            "x": 8,
            "y": 11,
            "z": 9,
            "elements": [
                "appliedenergistics2:smooth_sky_stone_stairs@1"
            ]
        },
        {
            "x": 6,
            "y": 7,
            "z": 7,
            "elements": [
                "minecraft:stained_glass_pane@11"
            ]
        },
        {
            "x": 2,
            "y": -1,
            "z": 3,
            "elements": [
                "minecraft:stonebrick@0"
            ]
        },
        {
            "x": 7,
            "y": 7,
            "z": 7,
            "elements": [
                "minecraft:end_rod@0"
            ]
        },
        {
            "x": 3,
            "y": -1,
            "z": 3,
            "elements": [
                "quark:polished_stone@0"
            ]
        },
        {
            "x": 4,
            "y": -1,
            "z": 3,
            "elements": [
                "minecraft:stonebrick@0"
            ]
        },
        {
            "x": 5,
            "y": -1,
            "z": 3,
            "elements": [
                "minecraft:stonebrick@0"
            ]
        },
        {
            "x": 6,
            "y": -1,
            "z": 3,
            "elements": [
                "minecraft:stonebrick@0"
            ]
        },
        {
            "x": 7,
            "y": -1,
            "z": 3,
            "elements": [
                "quark:polished_stone@0"
            ]
        },
        {
            "x": -7,
            "y": 12,
            "z": 9,
            "elements": [
                "minecraft:stained_glass@11"
            ]
        },
        {
            "x": -6,
            "y": 12,
            "z": 9,
            "elements": [
                "quark:snow_bricks_stairs@5"
            ]
        },
        {
            "x": -7,
            "y": 8,
            "z": 7,
            "elements": [
                "minecraft:stained_glass@11"
            ]
        },
        {
            "x": -6,
            "y": 8,
            "z": 7,
            "elements": [
                "quark:snow_bricks_stairs@1"
            ]
        },
        {
            "x": -1,
            "y": 12,
            "z": 9,
            "elements": [
                "quark:stone_diorite_bricks_wall@0"
            ]
        },
        {
            "x": -6,
            "y": 0,
            "z": 3,
            "elements": [
                "quark:snow_bricks_stairs@0"
            ]
        },
        {
            "x": -2,
            "y": 8,
            "z": 7,
            "elements": [
                "quark:snow_bricks_slab@8"
            ]
        },
        {
            "x": -1,
            "y": 8,
            "z": 7,
            "elements": [
                "quark:snow_bricks_slab@8"
            ]
        },
        {
            "x": -5,
            "y": 0,
            "z": 3,
            "elements": [
                "minecraft:concrete@0"
            ]
        },
        {
            "x": 1,
            "y": 12,
            "z": 9,
            "elements": [
                "quark:stone_diorite_bricks_wall@0"
            ]
        },
        {
            "x": 0,
            "y": 8,
            "z": 7,
            "elements": [
                "appliedenergistics2:smooth_sky_stone_slab@8"
            ]
        },
        {
            "x": -4,
            "y": 0,
            "z": 3,
            "elements": [
                "minecraft:concrete@0"
            ]
        },
        {
            "x": -3,
            "y": 0,
            "z": 3,
            "elements": [
                "quark:red_sandstone_wall@0"
            ]
        },
        {
            "x": 1,
            "y": 8,
            "z": 7,
            "elements": [
                "quark:snow_bricks_slab@8"
            ]
        },
        {
            "x": 2,
            "y": 8,
            "z": 7,
            "elements": [
                "quark:snow_bricks_slab@8"
            ]
        },
        {
            "x": -2,
            "y": 0,
            "z": 3,
            "elements": [
                "minecraft:concrete@0"
            ]
        },
        {
            "x": -1,
            "y": 0,
            "z": 3,
            "elements": [
                "minecraft:concrete@0"
            ]
        },
        {
            "x": 0,
            "y": 0,
            "z": 3,
            "elements": [
                "minecraft:concrete@0"
            ]
        },
        {
            "x": 6,
            "y": 12,
            "z": 9,
            "elements": [
                "quark:snow_bricks_stairs@4"
            ]
        },
        {
            "x": 7,
            "y": 12,
            "z": 9,
            "elements": [
                "tconstruct:clear_stained_glass@11"
            ]
        },
        {
            "x": 1,
            "y": 0,
            "z": 3,
            "elements": [
                "minecraft:concrete@0"
            ]
        },
        {
            "x": 6,
            "y": 8,
            "z": 7,
            "elements": [
                "quark:snow_bricks_stairs@0"
            ]
        },
        {
            "x": 2,
            "y": 0,
            "z": 3,
            "elements": [
                "minecraft:concrete@0"
            ]
        },
        {
            "x": 3,
            "y": 0,
            "z": 3,
            "elements": [
                "quark:red_sandstone_wall@0"
            ]
        },
        {
            "x": 7,
            "y": 8,
            "z": 7,
            "elements": [
                "minecraft:stained_glass@11"
            ]
        },
        {
            "x": 4,
            "y": 0,
            "z": 3,
            "elements": [
                "minecraft:concrete@0"
            ]
        },
        {
            "x": 5,
            "y": 0,
            "z": 3,
            "elements": [
                "minecraft:concrete@0"
            ]
        },
        {
            "x": 6,
            "y": 0,
            "z": 3,
            "elements": [
                "quark:snow_bricks_stairs@1"
            ]
        },
        {
            "x": -7,
            "y": 13,
            "z": 9,
            "elements": [
                "minecraft:end_rod@1"
            ]
        },
        {
            "x": -8,
            "y": 9,
            "z": 7,
            "elements": [
                "appliedenergistics2:smooth_sky_stone_stairs@4"
            ]
        },
        {
            "x": -6,
            "y": 13,
            "z": 9,
            "elements": [
                "minecraft:stained_glass_pane@11"
            ]
        },
        {
            "x": -7,
            "y": 9,
            "z": 7,
            "elements": [
                "minecraft:stained_glass@11"
            ]
        },
        {
            "x": -1,
            "y": 17,
            "z": 11,
            "elements": [
                "quark:snow_bricks_slab@0"
            ]
        },
        {
            "x": 0,
            "y": 17,
            "z": 11,
            "elements": [
                "appliedenergistics2:smooth_sky_stone_slab@0"
            ]
        },
        {
            "x": -1,
            "y": 13,
            "z": 9,
            "elements": [
                "quark:stone_diorite_bricks_wall@0"
            ]
        },
        {
            "x": 1,
            "y": 17,
            "z": 11,
            "elements": [
                "quark:snow_bricks_slab@0"
            ]
        },
        {
            "x": 1,
            "y": 13,
            "z": 9,
            "elements": [
                "quark:stone_diorite_bricks_wall@0"
            ]
        },
        {
            "x": -1,
            "y": 9,
            "z": 7,
            "elements": [
                "quark:stone_diorite_bricks_wall@0"
            ]
        },
        {
            "x": -5,
            "y": 1,
            "z": 3,
            "elements": [
                "quark:snow_bricks_stairs@0"
            ]
        },
        {
            "x": 0,
            "y": 9,
            "z": 7,
            "elements": [
                "quark:snow_bricks_stairs@2"
            ]
        },
        {
            "x": -4,
            "y": 1,
            "z": 3,
            "elements": [
                "quark:snow_bricks_stairs@2"
            ]
        },
        {
            "x": -1,
            "y": 5,
            "z": 5,
            "elements": [
                "quark:snow_bricks_slab@0"
            ]
        },
        {
            "x": 1,
            "y": 9,
            "z": 7,
            "elements": [
                "quark:stone_diorite_bricks_wall@0"
            ]
        },
        {
            "x": 0,
            "y": 5,
            "z": 5,
            "elements": [
                "appliedenergistics2:smooth_sky_stone_slab@0"
            ]
        },
        {
            "x": -2,
            "y": 1,
            "z": 3,
            "elements": [
                "quark:snow_bricks_stairs@0"
            ]
        },
        {
            "x": -1,
            "y": 1,
            "z": 3,
            "elements": [
                "minecraft:concrete@0"
            ]
        },
        {
            "x": 1,
            "y": 5,
            "z": 5,
            "elements": [
                "quark:snow_bricks_slab@0"
            ]
        },
        {
            "x": 6,
            "y": 13,
            "z": 9,
            "elements": [
                "minecraft:stained_glass_pane@11"
            ]
        },
        {
            "x": 0,
            "y": 1,
            "z": 3,
            "elements": [
                "minecraft:concrete@0"
            ]
        },
        {
            "x": 1,
            "y": 1,
            "z": 3,
            "elements": [
                "minecraft:concrete@0"
            ]
        },
        {
            "x": 7,
            "y": 13,
            "z": 9,
            "elements": [
                "minecraft:end_rod@1"
            ]
        },
        {
            "x": 2,
            "y": 1,
            "z": 3,
            "elements": [
                "quark:snow_bricks_stairs@1"
            ]
        },
        {
            "x": 7,
            "y": 9,
            "z": 7,
            "elements": [
                "minecraft:stained_glass@11"
            ]
        },
        {
            "x": 8,
            "y": 9,
            "z": 7,
            "elements": [
                "appliedenergistics2:smooth_sky_stone_stairs@5"
            ]
        },
        {
            "x": 4,
            "y": 1,
            "z": 3,
            "elements": [
                "quark:snow_bricks_stairs@2"
            ]
        },
        {
            "x": 5,
            "y": 1,
            "z": 3,
            "elements": [
                "quark:snow_bricks_stairs@1"
            ]
        },
        {
            "x": -2,
            "y": -1,
            "z": 18,
            "elements": [
                "quark:polished_stone@0"
            ]
        },
        {
            "x": -1,
            "y": -1,
            "z": 18,
            "elements": [
                "quark:polished_stone@0"
            ]
        },
        {
            "x": 0,
            "y": -1,
            "z": 18,
            "elements": [
                "quark:polished_stone@0"
            ]
        },
        {
            "x": 1,
            "y": -1,
            "z": 18,
            "elements": [
                "quark:polished_stone@0"
            ]
        },
        {
            "x": -8,
            "y": 10,
            "z": 7,
            "elements": [
                "quark:red_sandstone_wall@0"
            ]
        },
        {
            "x": -6,
            "y": 14,
            "z": 9,
            "elements": [
                "minecraft:stained_glass_pane@11"
            ]
        },
        {
            "x": 2,
            "y": -1,
            "z": 18,
            "elements": [
                "quark:polished_stone@0"
            ]
        },
        {
            "x": -7,
            "y": 10,
            "z": 7,
            "elements": [
                "quark:stone_diorite_bricks_wall@0"
            ]
        },
        {
            "x": -1,
            "y": 14,
            "z": 9,
            "elements": [
                "quark:stone_diorite_bricks_wall@0"
            ]
        },
        {
            "x": 0,
            "y": 14,
            "z": 9,
            "elements": [
                "quark:snow_bricks_stairs@7"
            ]
        },
        {
            "x": -1,
            "y": 10,
            "z": 7,
            "elements": [
                "quark:stone_diorite_bricks_wall@0"
            ]
        },
        {
            "x": 1,
            "y": 14,
            "z": 9,
            "elements": [
                "quark:stone_diorite_bricks_wall@0"
            ]
        },
        {
            "x": 1,
            "y": 10,
            "z": 7,
            "elements": [
                "quark:stone_diorite_bricks_wall@0"
            ]
        },
        {
            "x": -1,
            "y": 2,
            "z": 3,
            "elements": [
                "quark:snow_bricks_stairs@0"
            ]
        },
        {
            "x": 6,
            "y": 14,
            "z": 9,
            "elements": [
                "minecraft:stained_glass_pane@11"
            ]
        },
        {
            "x": 0,
            "y": 2,
            "z": 3,
            "elements": [
                "minecraft:concrete@0"
            ]
        },
        {
            "x": 1,
            "y": 2,
            "z": 3,
            "elements": [
                "quark:snow_bricks_stairs@1"
            ]
        },
        {
            "x": 7,
            "y": 10,
            "z": 7,
            "elements": [
                "quark:stone_diorite_bricks_wall@0"
            ]
        },
        {
            "x": 8,
            "y": 10,
            "z": 7,
            "elements": [
                "quark:red_sandstone_wall@0"
            ]
        },
        {
            "x": -8,
            "y": 11,
            "z": 7,
            "elements": [
                "appliedenergistics2:smooth_sky_stone_stairs@0"
            ]
        },
        {
            "x": -6,
            "y": 15,
            "z": 9,
            "elements": [
                "quark:stone_diorite_bricks_wall@0"
            ]
        },
        {
            "x": -7,
            "y": 11,
            "z": 7,
            "elements": [
                "minecraft:stained_glass@11"
            ]
        },
        {
            "x": -1,
            "y": 19,
            "z": 11,
            "elements": [
                "quark:snow_bricks_slab@0"
            ]
        },
        {
            "x": 0,
            "y": 19,
            "z": 11,
            "elements": [
                "appliedenergistics2:smooth_sky_stone_slab@0"
            ]
        },
        {
            "x": -2,
            "y": 15,
            "z": 9,
            "elements": [
                "quark:snow_bricks_slab@0"
            ]
        },
        {
            "x": -1,
            "y": 15,
            "z": 9,
            "elements": [
                "quark:snow_bricks_slab@0"
            ]
        },
        {
            "x": 1,
            "y": 19,
            "z": 11,
            "elements": [
                "quark:snow_bricks_slab@0"
            ]
        },
        {
            "x": 0,
            "y": 15,
            "z": 9,
            "elements": [
                "appliedenergistics2:smooth_sky_stone_slab@0"
            ]
        },
        {
            "x": -1,
            "y": 11,
            "z": 7,
            "elements": [
                "quark:stone_diorite_bricks_wall@0"
            ]
        },
        {
            "x": -7,
            "y": -1,
            "z": 1,
            "elements": [
                "quark:polished_stone@0"
            ]
        },
        {
            "x": 1,
            "y": 15,
            "z": 9,
            "elements": [
                "quark:snow_bricks_slab@0"
            ]
        },
        {
            "x": 2,
            "y": 15,
            "z": 9,
            "elements": [
                "quark:snow_bricks_slab@0"
            ]
        },
        {
            "x": -6,
            "y": -1,
            "z": 1,
            "elements": [
                "quark:polished_stone@0"
            ]
        },
        {
            "x": -5,
            "y": -1,
            "z": 1,
            "elements": [
                "quark:polished_stone@0"
            ]
        },
        {
            "x": -1,
            "y": 7,
            "z": 5,
            "elements": [
                "quark:snow_bricks_slab@0"
            ]
        },
        {
            "x": 1,
            "y": 11,
            "z": 7,
            "elements": [
                "quark:stone_diorite_bricks_wall@0"
            ]
        },
        {
            "x": 0,
            "y": 7,
            "z": 5,
            "elements": [
                "appliedenergistics2:smooth_sky_stone_slab@0"
            ]
        },
        {
            "x": -4,
            "y": -1,
            "z": 1,
            "elements": [
                "quark:polished_stone@0"
            ]
        },
        {
            "x": -3,
            "y": -1,
            "z": 1,
            "elements": [
                "quark:polished_stone@0"
            ]
        },
        {
            "x": 1,
            "y": 7,
            "z": 5,
            "elements": [
                "quark:snow_bricks_slab@0"
            ]
        },
        {
            "x": 6,
            "y": 15,
            "z": 9,
            "elements": [
                "quark:stone_diorite_bricks_wall@0"
            ]
        },
        {
            "x": 0,
            "y": 3,
            "z": 3,
            "elements": [
                "appliedenergistics2:smooth_sky_stone_slab@0"
            ]
        },
        {
            "x": -2,
            "y": -1,
            "z": 1,
            "elements": [
                "quark:polished_stone@0"
            ]
        },
        {
            "x": -1,
            "y": -1,
            "z": 1,
            "elements": [
                "minecraft:stonebrick@0"
            ]
        },
        {
            "x": 0,
            "y": -1,
            "z": 1,
            "elements": [
                "minecraft:stonebrick@0"
            ]
        },
        {
            "x": 1,
            "y": -1,
            "z": 1,
            "elements": [
                "minecraft:stonebrick@0"
            ]
        },
        {
            "x": 7,
            "y": 11,
            "z": 7,
            "elements": [
                "tconstruct:clear_stained_glass@11"
            ]
        },
        {
            "x": 8,
            "y": 11,
            "z": 7,
            "elements": [
                "appliedenergistics2:smooth_sky_stone_stairs@1"
            ]
        },
        {
            "x": 2,
            "y": -1,
            "z": 1,
            "elements": [
                "quark:polished_stone@0"
            ]
        },
        {
            "x": 3,
            "y": -1,
            "z": 1,
            "elements": [
                "quark:polished_stone@0"
            ]
        },
        {
            "x": 4,
            "y": -1,
            "z": 1,
            "elements": [
                "quark:polished_stone@0"
            ]
        },
        {
            "x": 5,
            "y": -1,
            "z": 1,
            "elements": [
                "quark:polished_stone@0"
            ]
        },
        {
            "x": 6,
            "y": -1,
            "z": 1,
            "elements": [
                "quark:polished_stone@0"
            ]
        },
        {
            "x": 7,
            "y": -1,
            "z": 1,
            "elements": [
                "quark:polished_stone@0"
            ]
        },
        {
            "x": -6,
            "y": 16,
            "z": 9,
            "elements": [
                "quark:stone_diorite_bricks_wall@0"
            ]
        },
        {
            "x": -7,
            "y": 12,
            "z": 7,
            "elements": [
                "minecraft:stained_glass@11"
            ]
        },
        {
            "x": -6,
            "y": 12,
            "z": 7,
            "elements": [
                "quark:snow_bricks_stairs@5"
            ]
        },
        {
            "x": -1,
            "y": 12,
            "z": 7,
            "elements": [
                "quark:stone_diorite_bricks_wall@0"
            ]
        },
        {
            "x": 1,
            "y": 12,
            "z": 7,
            "elements": [
                "quark:stone_diorite_bricks_wall@0"
            ]
        },
        {
            "x": 1,
            "y": 0,
            "z": -1,
            "elements": [
                "quark:snow_bricks_stairs@1"
            ]
        },
        {
            "x": 6,
            "y": 16,
            "z": 9,
            "elements": [
                "quark:stone_diorite_bricks_wall@0"
            ]
        },
        {
            "x": -2,
            "y": 0,
            "z": 1,
            "elements": [
                "quark:stone_diorite_wall@0"
            ]
        },
        {
            "x": -1,
            "y": 0,
            "z": 1,
            "elements": [
                "minecraft:concrete@0"
            ]
        },
        {
            "x": 0,
            "y": 0,
            "z": -1,
            "elements": [
                "quark:snow_bricks_stairs@2"
            ]
        },
        {
            "x": -1,
            "y": 0,
            "z": -1,
            "elements": [
                "quark:snow_bricks_stairs@0"
            ]
        },
        {
            "x": 0,
            "y": 0,
            "z": 1,
            "elements": [
                "minecraft:concrete@0"
            ]
        },
        {
            "x": 6,
            "y": 12,
            "z": 7,
            "elements": [
                "quark:snow_bricks_stairs@4"
            ]
        },
        {
            "x": 7,
            "y": 12,
            "z": 7,
            "elements": [
                "tconstruct:clear_stained_glass@11"
            ]
        },
        {
            "x": 1,
            "y": 0,
            "z": 1,
            "elements": [
                "minecraft:concrete@0"
            ]
        },
        {
            "x": 2,
            "y": 0,
            "z": 1,
            "elements": [
                "quark:stone_diorite_wall@0"
            ]
        },
        {
            "x": -7,
            "y": 13,
            "z": 7,
            "elements": [
                "minecraft:end_rod@1"
            ]
        },
        {
            "x": -6,
            "y": 13,
            "z": 7,
            "elements": [
                "minecraft:stained_glass_pane@11"
            ]
        },
        {
            "x": -3,
            "y": 17,
            "z": 9,
            "elements": [
                "quark:snow_bricks_slab@0"
            ]
        },
        {
            "x": -1,
            "y": 13,
            "z": 7,
            "elements": [
                "quark:stone_diorite_bricks_wall@0"
            ]
        },
        {
            "x": 3,
            "y": 17,
            "z": 9,
            "elements": [
                "quark:snow_bricks_slab@0"
            ]
        },
        {
            "x": 1,
            "y": 13,
            "z": 7,
            "elements": [
                "quark:stone_diorite_bricks_wall@0"
            ]
        },
        {
            "x": 2,
            "y": -1,
            "z": -1,
            "elements": [
                "quark:polished_stone@0"
            ]
        },
        {
            "x": 1,
            "y": -1,
            "z": -1,
            "elements": [
                "minecraft:stonebrick@0"
            ]
        },
        {
            "x": 0,
            "y": -1,
            "z": -1,
            "elements": [
                "minecraft:stonebrick@0"
            ]
        },
        {
            "x": -1,
            "y": 1,
            "z": 1,
            "elements": [
                "quark:snow_bricks_stairs@0"
            ]
        },
        {
            "x": -1,
            "y": -1,
            "z": -1,
            "elements": [
                "minecraft:stonebrick@0"
            ]
        },
        {
            "x": 6,
            "y": 13,
            "z": 7,
            "elements": [
                "minecraft:stained_glass_pane@11"
            ]
        },
        {
            "x": 0,
            "y": 1,
            "z": 1,
            "elements": [
                "appliedenergistics2:smooth_sky_stone_stairs@2"
            ]
        },
        {
            "x": 7,
            "y": 13,
            "z": 7,
            "elements": [
                "minecraft:end_rod@1"
            ]
        },
        {
            "x": 1,
            "y": 1,
            "z": 1,
            "elements": [
                "quark:snow_bricks_stairs@1"
            ]
        },
        {
            "x": -2,
            "y": -1,
            "z": -1,
            "elements": [
                "quark:polished_stone@0"
            ]
        },
        {
            "x": -2,
            "y": -1,
            "z": 16,
            "elements": [
                "quark:polished_stone@0"
            ]
        },
        {
            "x": -1,
            "y": -1,
            "z": 16,
            "elements": [
                "minecraft:stonebrick@0"
            ]
        },
        {
            "x": 0,
            "y": -1,
            "z": 16,
            "elements": [
                "modularmachinery:blockfluidoutputhatch"
            ]
        },
        {
            "x": 1,
            "y": -1,
            "z": 16,
            "elements": [
                "minecraft:stonebrick@0"
            ]
        },
        {
            "x": -6,
            "y": 14,
            "z": 7,
            "elements": [
                "minecraft:stained_glass_pane@11"
            ]
        },
        {
            "x": 2,
            "y": -1,
            "z": 16,
            "elements": [
                "quark:polished_stone@0"
            ]
        },
        {
            "x": -1,
            "y": 14,
            "z": 7,
            "elements": [
                "quark:stone_diorite_bricks_wall@0"
            ]
        },
        {
            "x": 0,
            "y": 14,
            "z": 7,
            "elements": [
                "quark:snow_bricks_stairs@6"
            ]
        },
        {
            "x": 1,
            "y": 14,
            "z": 7,
            "elements": [
                "quark:stone_diorite_bricks_wall@0"
            ]
        },
        {
            "x": 6,
            "y": 14,
            "z": 7,
            "elements": [
                "minecraft:stained_glass_pane@11"
            ]
        },
        {
            "x": -1,
            "y": 0,
            "z": 16,
            "elements": [
                "quark:snow_bricks_stairs@0"
            ]
        },
        {
            "x": 0,
            "y": 0,
            "z": 16,
            "elements": [
                "modularmachinery:blockinputbus"
            ]
        },
        {
            "x": 1,
            "y": 0,
            "z": 16,
            "elements": [
                "quark:snow_bricks_stairs@1"
            ]
        },
        {
            "x": -6,
            "y": 15,
            "z": 7,
            "elements": [
                "quark:stone_diorite_bricks_wall@0"
            ]
        },
        {
            "x": -3,
            "y": 19,
            "z": 9,
            "elements": [
                "quark:snow_bricks_slab@0"
            ]
        },
        {
            "x": -2,
            "y": 15,
            "z": 7,
            "elements": [
                "quark:snow_bricks_slab@0"
            ]
        },
        {
            "x": -1,
            "y": 15,
            "z": 7,
            "elements": [
                "quark:snow_bricks_slab@0"
            ]
        },
        {
            "x": 0,
            "y": 15,
            "z": 7,
            "elements": [
                "appliedenergistics2:smooth_sky_stone_slab@0"
            ]
        },
        {
            "x": 3,
            "y": 19,
            "z": 9,
            "elements": [
                "quark:snow_bricks_slab@0"
            ]
        },
        {
            "x": 1,
            "y": 15,
            "z": 7,
            "elements": [
                "quark:snow_bricks_slab@0"
            ]
        },
        {
            "x": 2,
            "y": 15,
            "z": 7,
            "elements": [
                "quark:snow_bricks_slab@0"
            ]
        },
        {
            "x": 6,
            "y": 15,
            "z": 7,
            "elements": [
                "quark:stone_diorite_bricks_wall@0"
            ]
        },
        {
            "x": -6,
            "y": 16,
            "z": 7,
            "elements": [
                "quark:stone_diorite_bricks_wall@0"
            ]
        },
        {
            "x": 0,
            "y": 20,
            "z": 9,
            "elements": [
                "quark:snow_bricks_stairs@3"
            ]
        },
        {
            "x": 6,
            "y": 16,
            "z": 7,
            "elements": [
                "quark:stone_diorite_bricks_wall@0"
            ]
        },
        {
            "x": -3,
            "y": 17,
            "z": 7,
            "elements": [
                "quark:snow_bricks_slab@0"
            ]
        },
        {
            "x": 3,
            "y": 17,
            "z": 7,
            "elements": [
                "quark:snow_bricks_slab@0"
            ]
        },
        {
            "x": -7,
            "y": -1,
            "z": 14,
            "elements": [
                "quark:polished_stone@0"
            ]
        },
        {
            "x": -6,
            "y": -1,
            "z": 14,
            "elements": [
                "minecraft:stonebrick@0"
            ]
        },
        {
            "x": -5,
            "y": -1,
            "z": 14,
            "elements": [
                "minecraft:stonebrick@0"
            ]
        },
        {
            "x": -4,
            "y": -1,
            "z": 14,
            "elements": [
                "minecraft:stonebrick@0"
            ]
        },
        {
            "x": -3,
            "y": -1,
            "z": 14,
            "elements": [
                "quark:polished_stone@0"
            ]
        },
        {
            "x": -2,
            "y": -1,
            "z": 14,
            "elements": [
                "quark:polished_stone@0"
            ]
        },
        {
            "x": -1,
            "y": -1,
            "z": 14,
            "elements": [
                "minecraft:stonebrick@0"
            ]
        },
        {
            "x": 0,
            "y": -1,
            "z": 14,
            "elements": [
                "minecraft:stonebrick@0"
            ]
        },
        {
            "x": 1,
            "y": -1,
            "z": 14,
            "elements": [
                "minecraft:stonebrick@0"
            ]
        },
        {
            "x": 2,
            "y": -1,
            "z": 14,
            "elements": [
                "quark:polished_stone@0"
            ]
        },
        {
            "x": 3,
            "y": -1,
            "z": 14,
            "elements": [
                "quark:polished_stone@0"
            ]
        },
        {
            "x": 4,
            "y": -1,
            "z": 14,
            "elements": [
                "minecraft:stonebrick@0"
            ]
        },
        {
            "x": 5,
            "y": -1,
            "z": 14,
            "elements": [
                "minecraft:stonebrick@0"
            ]
        },
        {
            "x": 6,
            "y": -1,
            "z": 14,
            "elements": [
                "minecraft:stonebrick@0"
            ]
        },
        {
            "x": 7,
            "y": -1,
            "z": 14,
            "elements": [
                "quark:polished_stone@0"
            ]
        },
        {
            "x": -6,
            "y": 0,
            "z": 14,
            "elements": [
                "quark:snow_bricks_stairs@3"
            ]
        },
        {
            "x": -5,
            "y": 0,
            "z": 14,
            "elements": [
                "quark:snow_bricks_stairs@3"
            ]
        },
        {
            "x": -4,
            "y": 0,
            "z": 14,
            "elements": [
                "quark:snow_bricks_stairs@3"
            ]
        },
        {
            "x": -2,
            "y": 0,
            "z": 14,
            "elements": [
                "quark:stone_diorite_wall@0"
            ]
        },
        {
            "x": -1,
            "y": 0,
            "z": 14,
            "elements": [
                "minecraft:concrete@0"
            ]
        },
        {
            "x": 0,
            "y": 0,
            "z": 14,
            "elements": [
                "minecraft:concrete@0"
            ]
        },
        {
